Workbook

Sheet README
B2: ASPIRE COMBINED UNDERWRITING MODEL v2 - DEMO: 8 sample deals, Deal sheet populated
B4: HOW TO RUN A DEAL
B5: Deal sheet: sections A, B and existing positions as always; DEAL PROFILE (right of the bank data): ISO, industry, new/renewal, credit score. State is optional and only informational. Position comes from C42.
B6: Read section C (cash flow), C2 (house-book indicators, same colour code), D (decision on the requested offer), E (max offer at the sizing line), F (final offer). Decision Summary has the full read-out; Comparable Deals lists the deals behind it.
B8: HOW THE HOUSE BOOK CHANGES THE OFFER
B9: 1. Historical Score matches the deal to seven cohorts (new/renewal + industry + position ... down to the whole seasoned book) and picks the first one with enough seasoned deals and dollars.
B10: 2. Its principal lost rate is blended toward the book by credibility Z = n/(n+K) and divided by the book rate -> relative index (1.00 = book).
B11: 3. The index lands on a row of the modifier table (Controls section 5). Supportive book -> SIZING FLEX moves the sizing lines toward the red lines (recommended 90% for Strong positive, 45% for Mild positive), so the max offer is larger and metrics may show YELLOW. Neutral -> flex 0 = the tool exactly as built. Negative -> green lines plus a fund multiplier, shorter band, higher factor tier, weekly.
B12: 4. Section E sizes the max offer at the sizing lines (column H of section C). Offer Engine shows green-line base vs sized vs final side by side and re-checks every metric at the final offer: yellow is allowed, red never.
B14: HARD RULES
B15: History never removes a knockout, never turns a metric red (flex is capped below 100%), never exceeds the sized max, and is Neutral whenever no cohort meets the minimums.
B17: COLOUR KEY
B18: Blue on yellow = input. Green font = link to Controls. Purple bold (column H, section C) = sizing line in use. Same GREEN / YELLOW / RED cells in C2 as in C.

Sheet Deal
B1: UNDERWRITING TOOL
B2: DECISION | C2: =C62 -> CONDITIONAL | D2: =IF(C62="","",C60&" red flag(s) vs limit "&C61&" | "&COUNTIF(F38:F45,"GREEN")&"G / "&COUNTIF(F38:F45,"YELLOW")&"Y / "&COUNTIF(F38:F45,"RED")&"R | score "&TEXT(C65,"0.0")&"/"&D65&" = "&C66&" | FINAL: "&IF(C77="","-",C77)) -> 0 red flag(s) vs limit 2 | 7G / 1Y / 0R | score 7.5/8 = Strong | FINAL: CONDITIONAL
B4: A. OFFER | J4: MONEYBADGER CROSS-CHECK
B5: Fund $ | C5: Factor | D5: =IF($E$6="Weekly","Term (weeks)","Term (daily pmts)") -> Term (weeks) | E5: Freq | F5: Fee % | J5: Metric | K5: This tool | L5: MoneyBadger | M5: Diff
B6: 40000 | C6: 1.45 | D6: 24 | E6: Weekly | F6: =Controls!$B$15 -> 0.05 | J6: =IF($E$6="Weekly","Weekly remittance","Daily remittance") -> Weekly remittance | K6: =IF(OR($E$6="",C8="",C24=0),"",IF($E$6="Weekly",D8,C8)) -> 2416.6667 | L6: =IF(OR(L7="",C24=0),"",L7*C24/IF($E$6="Weekly",$L$8,$L$9)) -> 2417.1562 | M6: =IF(OR(K6="",L6=""),"",L6-K6) -> 0.48958333
B7: Payback | C7: Daily $ | D7: Weekly $ | E7: Monthly $ | F7: Term (mo) | G7: Net $ | J7: Holdback % | K7: =IF(OR(D8="",C24=0),"",E8/C24) -> 0.12135169 | L7: =IF(OR($E$6="",C8="",C24=0),"",ROUND(IF($E$6="Weekly",D8*$L$8,C8*$L$9)/C24*100,2)/100) -> 0.1121 | M7: =IF(OR(K7="",L7=""),"",L7-K7) -> -0.0092516908
B8: =IF(OR(B6="",C6=""),"",B6*C6) -> 58000 | C8: =IF(OR(B8="",D6="",D6=0),"",IF(E6="Weekly",(B8/D6)/5,B8/D6)) -> 483.33333 | D8: =IF(C8="","",C8*5) -> 2416.6667 | E8: =IF(C8="","",C8*$K$9) -> 10466.583 | F8: =IF(OR(D6="",D6=0),"",IF(E6="Weekly",D6,D6/5)/($K$9/5)) -> 5.5414454 | G8: =IF(B6="","",B6-(B6*F6)) -> 38000 | J8: Weeks / month | K8: =Controls!$B$28 -> 4.331 | L8: =Controls!$B$30 -> 4 | M8: =IF(OR(K8="",L8=""),"",L8-K8) -> -0.331
J9: Days / month | K9: =Controls!$B$29 -> 21.655 | L9: =Controls!$B$31 -> 21 | M9: =IF(OR(K9="",L9=""),"",L9-K9) -> -0.655
B10: B. BANK DATA (up to 12 months)
B11: Month - NEWEST FIRST | C11: True rev $ | D11: Avg daily bal $ | E11: Neg days | F11: NSFs | G11: MoM % | J11: DEAL PROFILE (house-book match inputs)
B12: Aug | C12: 88000 | D12: 7400 | E12: 0 | F12: 0 | G12: =IF(OR(C12="",C13=""),"",(C12-C13)/C13) -> 0.047619048 | J12: ISO | K12: Fundwell | L12: =IF(K12="","",COUNTIF('Historical Data'!$K$2:$K$9,K12)&" deals in book") -> 4 deals in book
B13: Jul | C13: 84000 | D13: 6900 | E13: 0 | F13: 1 | G13: =IF(OR(C13="",C14=""),"",(C13-C14)/C14) -> -0.076923077 | J13: Industry (SIC major group) | K13: Eating & Drinking Places | L13: =IF(K13="","",COUNTIF('Historical Data'!$Y$2:$Y$9,K13)&" deals in book") -> 1 deals in book
B14: Jun | C14: 91000 | D14: 8100 | E14: 0 | F14: 0 | G14: =IF(OR(C14="",C15=""),"",(C14-C15)/C15) -> 0.1097561 | J14: State (optional - informational only) | K14: NJ | L14: =IF(K14="","not needed for an offer",COUNTIF('Historical Data'!$J$2:$J$9,K14)&" deals in book") -> 4 deals in book
B15: May | C15: 82000 | D15: 6500 | E15: 1 | F15: 0 | G15: =IF(OR(C15="",C16=""),"",(C15-C16)/C16) | J15: New deal or renewal | K15: New Deal | L15: =IF(K15="","required for history match","")
G16: =IF(OR(C16="",C17=""),"",(C16-C17)/C17) | J16: Credit score (FICO) | K16: 672 | L16: =IF(K16="","not scored",IF(K16>=Controls!$B$12,"GREEN",IF(K16>=Controls!$C$12,"YELLOW","RED"))) -> GREEN
G17: =IF(OR(C17="",C18=""),"",(C17-C18)/C18) | J17: Position for matching = C42 (existing positions + 1). Bands and thresholds: Controls.
G18: =IF(OR(C18="",C19=""),"",(C18-C19)/C19)
G19: =IF(OR(C19="",C20=""),"",(C19-C20)/C20)
G20: =IF(OR(C20="",C21=""),"",(C20-C21)/C21)
G21: =IF(OR(C21="",C22=""),"",(C21-C22)/C22)
G22: =IF(OR(C22="",C23=""),"",(C22-C23)/C23)
B24: AVG / TOTAL (months entered) | C24: =IF(COUNT(C12:C23)=0,0,AVERAGE(C12:C23)) -> 86250 | D24: =IF(COUNT(D12:D23)=0,0,AVERAGE(D12:D23)) -> 7225 | E24: =SUM(E12:E23) -> 1 | F24: =SUM(F12:F23) -> 1 | G24: =IFERROR(AVERAGE(G12:G22),"") -> 0.026817356
B26: EXISTING POSITIONS (freq Monthly = leverage only, NOT a position)
B27: Funder | C27: Funded $ | D27: Payment | E27: Freq | F27: Daily equiv | G27: Start Date | H27: Est Term | I27: Est term (mo) | J27: Mo. remaining
E28: Weekly | F28: =IF(D28<>"",IF(E28="Daily",D28,IF(E28="Weekly",D28/5,D28/$K$9)),IF(C28="","",C28*Controls!$B$33/(Controls!$B$23*$K$9))) | H28: =IF(OR(C28="",D28=""),"",ROUND(C28*Controls!$B$33/D28,0)) | I28: =IF(H28="","",H28/IF(E28="Daily",$K$9,IF(E28="Weekly",$K$9/5,1))) | J28: =IF(OR(I28="",G28=""),"",MAX(0,I28-(TODAY()-G28)/Controls!$B$32))
E29: Weekly | F29: =IF(D29<>"",IF(E29="Daily",D29,IF(E29="Weekly",D29/5,D29/$K$9)),IF(C29="","",C29*Controls!$B$33/(Controls!$B$23*$K$9))) | H29: =IF(OR(C29="",D29=""),"",ROUND(C29*Controls!$B$33/D29,0)) | I29: =IF(H29="","",H29/IF(E29="Daily",$K$9,IF(E29="Weekly",$K$9/5,1))) | J29: =IF(OR(I29="",G29=""),"",MAX(0,I29-(TODAY()-G29)/Controls!$B$32))
E30: Weekly | F30: =IF(D30<>"",IF(E30="Daily",D30,IF(E30="Weekly",D30/5,D30/$K$9)),IF(C30="","",C30*Controls!$B$33/(Controls!$B$23*$K$9))) | H30: =IF(OR(C30="",D30=""),"",ROUND(C30*Controls!$B$33/D30,0)) | I30: =IF(H30="","",H30/IF(E30="Daily",$K$9,IF(E30="Weekly",$K$9/5,1))) | J30: =IF(OR(I30="",G30=""),"",MAX(0,I30-(TODAY()-G30)/Controls!$B$32))
E31: Weekly | F31: =IF(D31<>"",IF(E31="Daily",D31,IF(E31="Weekly",D31/5,D31/$K$9)),IF(C31="","",C31*Controls!$B$33/(Controls!$B$23*$K$9))) | H31: =IF(OR(C31="",D31=""),"",ROUND(C31*Controls!$B$33/D31,0)) | I31: =IF(H31="","",H31/IF(E31="Daily",$K$9,IF(E31="Weekly",$K$9/5,1))) | J31: =IF(OR(I31="",G31=""),"",MAX(0,I31-(TODAY()-G31)/Controls!$B$32))
E32: Weekly | F32: =IF(D32<>"",IF(E32="Daily",D32,IF(E32="Weekly",D32/5,D32/$K$9)),IF(C32="","",C32*Controls!$B$33/(Controls!$B$23*$K$9))) | H32: =IF(OR(C32="",D32=""),"",ROUND(C32*Controls!$B$33/D32,0)) | I32: =IF(H32="","",H32/IF(E32="Daily",$K$9,IF(E32="Weekly",$K$9/5,1))) | J32: =IF(OR(I32="",G32=""),"",MAX(0,I32-(TODAY()-G32)/Controls!$B$32))
E33: Weekly | F33: =IF(D33<>"",IF(E33="Daily",D33,IF(E33="Weekly",D33/5,D33/$K$9)),IF(C33="","",C33*Controls!$B$33/(Controls!$B$23*$K$9))) | H33: =IF(OR(C33="",D33=""),"",ROUND(C33*Controls!$B$33/D33,0)) | I33: =IF(H33="","",H33/IF(E33="Daily",$K$9,IF(E33="Weekly",$K$9/5,1))) | J33: =IF(OR(I33="",G33=""),"",MAX(0,I33-(TODAY()-G33)/Controls!$B$32))
B34: Positions (excl. Monthly) | C34: =SUMPRODUCT(((C28:C33<>"")+(D28:D33<>"")>0)*(E28:E33<>"Monthly")) -> 0 | D34: Total existing daily | E34: =SUM(F28:F33) -> 0 | F34: =E34*$K$9 -> 0 | G34: /month
B36: C. METRICS
B37: Metric | C37: Value | D37: Green | E37: Red | F37: Status | G37: Knockout | H37: Sizing line
B38: Total LVG (all debt / rev) | C38: =IF(C24=0,"",(E34+IF(C8="",0,C8))*$K$9/C24) -> 0.12135169 | D38: =Controls!$B$5 -> 0.3 | E38: =Controls!$C$5 -> 0.45 | F38: =IF(C38="","",IF(C38>=G38,"KNOCKOUT",IF(C38<=D38,"GREEN",IF(C38>=E38,"RED","YELLOW")))) -> GREEN | G38: =Controls!$D$5 -> 0.55 | H38: =D38+'Historical Score'!$C$42*(E38-D38) -> 0.3
B39: New holdback SP% | C39: =IF(OR(C24=0,E8=""),"",E8/C24) -> 0.12135169 | D39: =Controls!$B$6 -> 0.18 | E39: =Controls!$C$6 -> 0.25 | F39: =IF(C39="","",IF(C39>=G39,"KNOCKOUT",IF(C39<=D39,"GREEN",IF(C39>=E39,"RED","YELLOW")))) -> GREEN | G39: =Controls!$D$6 -> 0.35 | H39: =D39+'Historical Score'!$C$42*(E39-D39) -> 0.18
B40: Daily debt / balance | C40: =IF(D24=0,"",(E34+IF(C8="",0,C8))/D24) -> 0.066897347 | D40: =Controls!$B$7 -> 0.18 | E40: =Controls!$C$7 -> 0.3 | F40: =IF(C40="","",IF(C40>=G40,"KNOCKOUT",IF(C40<=D40,"GREEN",IF(C40>=E40,"RED","YELLOW")))) -> GREEN | G40: =Controls!$D$7 -> 0.35 | H40: =D40+'Historical Score'!$C$42*(E40-D40) -> 0.18
B41: Fund / revenue | C41: =IF(OR(C24=0,B6=""),"",B6/C24) -> 0.46376812 | D41: =Controls!$B$8 -> 0.6 | E41: =Controls!$C$8 -> 0.9 | F41: =IF(C41="","",IF(C41>=G41,"KNOCKOUT",IF(C41<=D41,"GREEN",IF(C41>=E41,"RED","YELLOW")))) -> GREEN | G41: =Controls!$D$8 -> 1.25 | H41: =D41+'Historical Score'!$C$42*(E41-D41) -> 0.6
B42: # positions (incl. new) | C42: =IF(C24=0,"",C34+1) -> 1 | D42: =Controls!$B$9 -> 2 | E42: =Controls!$C$9 -> 5 | F42: =IF(C42="","",IF(C42>=G42,"KNOCKOUT",IF(C42<=D42,"GREEN",IF(C42>=E42,"RED","YELLOW")))) -> GREEN | G42: =Controls!$D$9 -> 6
B43: Revenue trend (avg MoM) | C43: =G24 -> 0.026817356 | D43: =Controls!$B$10 -> -0.05 | E43: =Controls!$C$10 -> -0.15 | F43: =IF(C24=0,"",IF(NOT(ISNUMBER(C43)),"YELLOW",IF(C43<=G43,"KNOCKOUT",IF(C43>=D43,"GREEN",IF(C43<=E43,"RED","YELLOW"))))) -> GREEN | G43: =Controls!$D$10 -> -0.3
B44: Neg days + NSFs (total) | C44: =E24+F24 -> 2 | D44: =Controls!$B$11 -> 1 | E44: =Controls!$C$11 -> 6 | F44: =IF(C44="","",IF(C44>=G44,"KNOCKOUT",IF(C44<=D44,"GREEN",IF(C44>=E44,"RED","YELLOW")))) -> YELLOW | G44: =Controls!$D$11 -> 10
...

Sheet Decision Summary
B1: DECISION SUMMARY
B4: Item | C4: Value | D4: Detail
B5: DECISION | C5: =IF(Deal!$C$24=0,"",IF(OR(Deal!$C$73="-",Deal!$C$73="",'Offer Engine'!$E$8="",'Offer Engine'!$E$8=0,'Offer Engine'!$E$8<Controls!$B$14,'Offer Engine'!$E$41>=Controls!$B$13),"DECLINE",IF(C25<>"","MANUAL REVIEW",IF(OR(COUNTIF('Offer Engine'!$F$26:$F$33,"YELLOW")+COUNTIF('Offer Engine'!$F$26:$F$33,"RED")>0,'Historical Score'!$C$40>=4),"CONDITIONAL","APPROVE")))) -> CONDITIONAL | D5: =IF(C5="","Enter bank data + deal profile.",IF(C5="DECLINE",IF(COUNTIF(Deal!$F$42:$F$45,"KNOCKOUT")>0,"Merchant knockout: "&INDEX(Deal!$B$42:$B$45,MATCH("KNOCKOUT",Deal!$F$42:$F$45,0))&".",IF(OR('Offer Engine'!$E$8="",'Offer Engine'!$E$8=0),"No clean room under the sizing line.",IF('Offer Engine'!$E$8<Controls!$B$14,"Final fund "&TEXT('Offer Engine'!$E$8,"$#,##0")&" is below the minimum "&TEXT(Controls!$B$14,"$#,##0")&".","Red flags at the final offer reached the limit."))),IF(C5="MANUAL REVIEW","Triggers: "&C25,IF(C5="APPROVE","All metrics green at the final offer; evidence neutral or better.","Yellows remain at the final offer or the evidence is negative - see the metric rows.")))) -> Yellows remain at the final offer or the evidence is negative - see the metric rows.
B6: Recommended funding amount | C6: ='Offer Engine'!$E$8 -> 49000 | D6: =IF(OR(C6="",C6="-"),"","green-line max "&IF(ISNUMBER('Offer Engine'!$C$8),TEXT('Offer Engine'!$C$8,"$#,##0"),"-")&" | sized max "&IF(ISNUMBER('Offer Engine'!$D$8),TEXT('Offer Engine'!$D$8,"$#,##0"),"-")&" | final = "&TEXT(C6/'Offer Engine'!$D$8,"0%")&" of sized (requested "&IF(Deal!$B$6="","n/a",TEXT(Deal!$B$6,"$#,##0"))&")") -> green-line max $49,000 | sized max $49,000 | final = 100% of sized (requested $40,000)
B7: Recommended factor rate | C7: ='Offer Engine'!$E$7 -> 1.45 | D7: =IF(C7="","","band "&TEXT('Offer Engine'!$D$7,"0.00")&IF('Offer Engine'!$E$7>'Offer Engine'!$D$7," -> raised one tier by the modifier","")) -> band 1.45
B8: Recommended term | C8: ='Offer Engine'!$E$17 -> 20 | D8: =IF(C8="","",IF('Offer Engine'!$E$16="Weekly","weeks","daily payments")&" ("&TEXT('Offer Engine'!$E$22,"0.0")&" months; sized "&'Offer Engine'!$D$6&" daily pmts"&IF('Offer Engine'!$E$6<'Offer Engine'!$D$6,", shortened by the modifier","")&")") -> weeks (4.6 months; sized 100 daily pmts)
B9: Payment | C9: ='Offer Engine'!$E$18 -> 3552.5 | D9: =IF(C9="","","per "&IF('Offer Engine'!$E$16="Weekly","week","business day")&"; daily-equivalent "&TEXT('Offer Engine'!$E$9,"$#,##0.00")&", monthly "&TEXT('Offer Engine'!$E$19,"$#,##0")&"; payback "&TEXT('Offer Engine'!$E$20,"$#,##0")&", net "&TEXT('Offer Engine'!$E$21,"$#,##0")) -> per week; daily-equivalent $710.50, monthly $15,386; payback $71,050, net $46,550
B10: Daily or weekly | C10: ='Offer Engine'!$E$16 -> Weekly | D10: =IF('Offer Engine'!$C$13="Weekly","Weekly required by the modifier","As proposed on the Deal sheet") -> As proposed on the Deal sheet
B11: Sizing line used | C11: ='Offer Engine'!$C$15 -> 0 | D11: =IF(C11=0,"green lines (the cash-flow tool as built)",TEXT(C11,"0%")&" of the way from the green line to the red line - the book is supportive, yellows allowed") -> green lines (the cash-flow tool as built)
B12: Holdback % | C12: ='Offer Engine'!$E$27 -> 0.17838699 | D12: =IF(C12="","",'Offer Engine'!$F$27&" (green "&TEXT(Controls!$B$6,"0%")&" / red "&TEXT(Controls!$C$6,"0%")&")") -> GREEN (green 18% / red 25%)
B13: Total leverage (all debt / revenue) | C13: ='Offer Engine'!$E$26 -> 0.17838699 | D13: =IF(C13="","",'Offer Engine'!$F$26&" (green "&TEXT(Controls!$B$5,"0%")&" / red "&TEXT(Controls!$C$5,"0%")&")") -> GREEN (green 30% / red 45%)
B14: Funding-to-revenue | C14: ='Offer Engine'!$E$29 -> 0.56811594 | D14: =IF(C14="","",'Offer Engine'!$F$29&" (green "&TEXT(Controls!$B$8,"0.00")&" / red "&TEXT(Controls!$C$8,"0.00")&")") -> GREEN (green 0.60 / red 0.90)
B15: Daily debt-to-balance | C15: ='Offer Engine'!$E$28 -> 0.0983391 | D15: =IF(C15="","",'Offer Engine'!$F$28&" (green "&TEXT(Controls!$B$7,"0%")&" / red "&TEXT(Controls!$C$7,"0%")&")") -> GREEN (green 18% / red 30%)
B16: Number of positions (incl. new) | C16: =Deal!$C$42 -> 1 | D16: =IF(C16="","",Deal!$F$42) -> GREEN
B17: Historical modifier | C17: ='Historical Score'!$C$41 -> Neutral | D17: =IF(C17="","","index "&TEXT('Historical Score'!$C$39,"0.00")&" (1.00 = seasoned book); sizing flex "&TEXT('Historical Score'!$C$42,"0%")&", fund x "&TEXT('Historical Score'!$C$43,"0.00")&", term step "&'Historical Score'!$C$44&", factor step "&'Historical Score'!$C$45) -> index 1.03 (1.00 = seasoned book); sizing flex 0%, fund x 1.00, term step 0, factor step 0
B18: Cash-flow risk score | C18: =Deal!$C$65 -> 7.5 | D18: =IF(C18="","","of "&Deal!$D$65&" scored metrics = "&Deal!$C$66&" (scaled "&TEXT(Deal!$D$67,"0.0")&"/7 for the bands)") -> of 8 scored metrics = Strong (scaled 6.6/7 for the bands)
B19: Number of comparable deals (seasoned / all) | C19: ='Historical Score'!$C$31 -> 5 / 6 | D19: ='Historical Score'!$C$30 -> T6: new/renewal only
B20: Percentage of comparable deals seasoned | C20: ='Historical Score'!$C$32 -> 0.83333333 | D20: ="credibility Z "&TEXT('Historical Score'!$C$37,"0.00")&" (n / (n + K))" -> credibility Z 0.14 (n / (n + K))
B21: Comparable-cohort principal lost rate | C21: ='Historical Score'!$C$33 -> 0.50833333 | D21: =IF(C21="","too few seasoned deals to show a rate","vs seasoned book "&TEXT('Historical Score'!$C$10,"0.0%")&"; blended "&TEXT('Historical Score'!$C$38,"0.0%")&"; collected on defaults "&IF('Historical Score'!$C$36="","n/a",TEXT('Historical Score'!$C$36,"0%"))) -> vs seasoned book 41.0%; blended 42.4%; collected on defaults 32%
B22: Comparable-cohort return on funded capital | C22: ='Historical Score'!$C$35 -> -0.38333333 | D22: ="seasoned deals only" -> seasoned deals only
B23: Largest historical impact | C23: ='Historical Score'!$C$48 -> New/renewal only | D23: ='Historical Score'!$C$49 -> 42.4% vs 41.0% book (5 seasoned deals)
B24: Metric that limited the offer | C24: =IF(Deal!$D$70="","",Deal!$D$70) -> SP% holdback is the limit | D24: =IF(Deal!$C$70="","",IF(Deal!$C$70=0,"existing debt already exceeds the sizing line",IF(Deal!$C$72=FLOOR(Deal!$H$41*Deal!$C$24*Deal!$D$72/Deal!$C$70,5),"term also capped by the fund/revenue sizing line","term set by the score band"))) -> term also capped by the fund/revenue sizing line
B25: Manual-review triggers fired | C25: =IF(AND(Controls!$B$74="Y",'Offer Engine'!$C$14="Y"),"Severe historical modifier; ","")&IF(AND(Controls!$B$75="Y",Deal!$F$45="RED",COUNTIF('Offer Engine'!$F$26:$F$32,"RED")>0),"Credit RED plus another RED; ","")&IF(AND(Controls!$B$76="Y",ISNUMBER(Deal!$C$42),IF(ISNUMBER(Deal!$C$42),Deal!$C$42,0)>=Controls!$C$76),"Positions incl. new at/above "&Controls!$C$76&"; ","")&IF(AND(Controls!$B$77="Y",Deal!$K$15="New Deal",ISNUMBER(Deal!$C$42),IF(ISNUMBER(Deal!$C$42),Deal!$C$42,0)>=Controls!$C$77,OR(Deal!$K$13="General Building Contractors",Deal!$K$13="Special Trade Contractors",Deal!$K$13="Heavy Construction")),"New "&Controls!$C$77&"rd+ position construction deal; ","")&IF(AND(Controls!$B$78="Y",OR(AND(Deal!$K$12<>"",COUNTIF('Historical Data'!$K$2:$K$9,Deal!$K$12)=0),AND(Deal!$K$13<>"",COUNTIF('Historical Data'!$Y$2:$Y$9,Deal!$K$13)=0))),"ISO or industry not in house book; ","")&IF(AND(Controls!$B$79="Y",ISNUMBER('Offer Engine'!$E$8),IF(ISNUMBER('Offer Engine'!$E$8),'Offer Engine'!$E$8,0)<Controls!$B$14,IF(ISNUMBER('Offer Engine'!$E$8),'Offer Engine'!$E$8,0)>0),"Final fund below minimum; ","")&IF(AND(Controls!$B$80="Y",'Historical Score'!$C$29=7),"No cohort met the minimums; ","") | D25: ="blank = none" -> blank = none
B26: Evidence: ISO | C26: ='Historical Score'!$C$50 -> Fundwell: 3 seasoned deals, lost 43.0% vs 41.0% book, Z 0.09 -> neutral
B27: Evidence: industry | C27: ='Historical Score'!$C$51 -> Eating & Drinking Places: 1 seasoned deals - too few to rate
B28: Evidence: new deal / renewal | C28: ='Historical Score'!$C$52 -> New Deal: 5 seasoned deals, lost 50.8% vs 41.0% book -> neutral
B29: Evidence: position | C29: ='Historical Score'!$C$53 -> position 1: 1 seasoned deals - too few to rate
B30: Evidence: state (informational) | C30: ='Historical Score'!$C$54 -> NJ: 3 seasoned deals, lost 43.0% vs 41.0% book - informational only
B31: Warnings | C31: ='Historical Score'!$C$56 -> Tighter tiers 1-5 too small;
B32: Reds at the requested offer | C32: =IF(COUNTIF(Deal!$F$38:$F$45,"RED")+COUNTIF(Deal!$F$38:$F$45,"KNOCKOUT")=0,"none",IF(Deal!$F$38="RED","total leverage; ","")&IF(Deal!$F$39="RED","holdback; ","")&IF(Deal!$F$40="RED","daily debt/balance; ","")&IF(Deal!$F$41="RED","fund/revenue; ","")&IF(Deal!$F$42="RED","positions; ","")&IF(Deal!$F$43="RED","revenue trend; ","")&IF(Deal!$F$44="RED","neg days/NSFs; ","")&IF(Deal!$F$45="RED","credit; ","")&IF(COUNTIF(Deal!$F$38:$F$45,"KNOCKOUT")>0,"KNOCKOUT present","")) -> none
B33: Greens at the requested offer | C33: =IF(COUNTIF(Deal!$F$38:$F$45,"GREEN")=0,"none",IF(Deal!$F$38="GREEN","leverage; ","")&IF(Deal!$F$39="GREEN","holdback; ","")&IF(Deal!$F$40="GREEN","daily debt/balance; ","")&IF(Deal!$F$41="GREEN","fund/revenue; ","")&IF(Deal!$F$42="GREEN","positions; ","")&IF(Deal!$F$43="GREEN","revenue trend; ","")&IF(Deal!$F$44="GREEN","clean neg days/NSFs; ","")&IF(Deal!$F$45="GREEN","credit; ","")) -> leverage; holdback; daily debt/balance; fund/revenue; positions; revenue trend; credit;

Sheet Offer Engine
B1: OFFER ENGINE - green-line base -> sized at the house-book sizing line -> final after the modifier
B2: Base = the cash-flow tool exactly as built (green lines). Sized = Deal section E (sizing line, moved toward the red line only when the book is supportive). Final = sized x multiplier, term / factor steps. Final daily payment never exceeds the sized max daily.
B4: Item | C4: Base (green line) | D4: Sized (sizing line) | E4: Final (modifier) | F4: Status | G4: How
B5: Max daily payment | C5: =IF(Deal!$C$24=0,"",MAX(0,MIN(Deal!$D$39*Deal!$C$24/Deal!$K$9,(Deal!$D$38*Deal!$C$24-Deal!$F$34)/Deal!$K$9,IF(Deal!$D$24=0,0,Deal!$D$40*Deal!$D$24-Deal!$E$34)))) -> 716.9245 | D5: =Deal!$C$70 -> 716.9245 | E5: =Deal!$C$70 -> 716.9245 | G5: weakest of holdback / total LVG / daily-debt-to-balance at that line
B6: Term (daily payments) | C6: =IF(OR(C5="",C5=0),"",MAX(20,MIN(INDEX(Controls!$B$19:$B$22,MATCH(Deal!$D$67,Controls!$A$19:$A$22,1)),FLOOR(Controls!$B$23*Deal!$K$9,5),FLOOR(Deal!$D$41*Deal!$C$24*C7/C5,5)))) -> 100 | D6: =Deal!$C$72 -> 100 | E6: =IF(OR(D6="",D8="-"),"",MAX(20,MIN(D6,INDEX(Controls!$B$19:$B$22,MAX(1,MATCH(Deal!$D$67,Controls!$A$19:$A$22,1)+C11))))) -> 100 | G6: band term; final steps down the band table
B7: Factor | C7: =Deal!$D$72 -> 1.45 | D7: =Deal!$D$72 -> 1.45 | E7: =IF(D7="","",INDEX(Controls!$B$24:$D$24,MIN(3,MAX(1,MATCH(D7,Controls!$B$24:$D$24,0)+C12)))) -> 1.45 | G7: next approved tier when stepped; never above 1.49
B8: Fund $ | C8: =IF(COUNTIF(Deal!$F$42:$F$45,"KNOCKOUT")>0,"-",IF(OR(C5="",C5=0,C6="",C7=""),"",FLOOR(C5*C6/C7,500))) -> 49000 | D8: =Deal!$C$73 -> 49000 | E8: =IF(D8="-","-",IF(OR(D8="",E6="",E7=""),"",MAX(0,FLOOR(MIN(D8*C10,D5*E6/E7),500)))) -> 49000 | G8: final = MIN(sized x multiplier, sized max daily x final term / final factor)
B9: Daily payment | C9: =IF(OR(C8="",C8="-"),"",C8*C7/C6) -> 710.5 | D9: =IF(OR(D8="",D8="-"),"",D8*D7/D6) -> 710.5 | E9: =IF(OR(E8="",E8="-",E8=0),"",E8*E7/E6) -> 710.5 | G9: fund x factor / term
B10: Fund multiplier (Controls) | C10: ='Historical Score'!$C$43 -> 1
B11: Term step | C11: ='Historical Score'!$C$44 -> 0
B12: Factor step | C12: ='Historical Score'!$C$45 -> 0
B13: Frequency rule | C13: ='Historical Score'!$C$46 -> As proposed
B14: Manual review flag | C14: ='Historical Score'!$C$47 -> N
B15: Sizing flex | C15: ='Historical Score'!$C$42 -> 0 | G15: share of the way from the green line to the red line used for sizing
B16: Frequency (final) | C16: =IF(Deal!$E$6="","Daily",Deal!$E$6) -> Weekly | D16: =IF(Deal!$E$6="","Daily",Deal!$E$6) -> Weekly | E16: =IF(C13="Weekly","Weekly",IF(Deal!$E$6="","Daily",Deal!$E$6)) -> Weekly
B17: Term in final units | C17: =IF(OR(C6="",C8="-"),"",IF(C16="Weekly",C6/5,C6)) -> 20 | D17: =IF(OR(D6="",D8="-"),"",IF(D16="Weekly",D6/5,D6)) -> 20 | E17: =IF(OR(E6="",E8="-"),"",IF(E16="Weekly",E6/5,E6)) -> 20 | G17: weeks or daily payments
B18: Payment in final units | C18: =IF(C9="","",IF(C16="Weekly",C9*5,C9)) -> 3552.5 | D18: =IF(D9="","",IF(D16="Weekly",D9*5,D9)) -> 3552.5 | E18: =IF(E9="","",IF(E16="Weekly",E9*5,E9)) -> 3552.5
B19: Monthly payment | C19: =IF(C9="","",C9*Controls!$B$29) -> 15385.878 | D19: =IF(D9="","",D9*Controls!$B$29) -> 15385.878 | E19: =IF(E9="","",E9*Controls!$B$29) -> 15385.878
B20: Payback | C20: =IF(OR(C8="",C8="-"),"",C8*C7) -> 71050 | D20: =IF(OR(D8="",D8="-"),"",D8*D7) -> 71050 | E20: =IF(OR(E8="",E8="-"),"",E8*E7) -> 71050
B21: Net disbursed | C21: =IF(OR(C8="",C8="-"),"",C8*(1-Controls!$B$15)) -> 46550 | D21: =IF(OR(D8="",D8="-"),"",D8*(1-Controls!$B$15)) -> 46550 | E21: =IF(OR(E8="",E8="-"),"",E8*(1-Controls!$B$15)) -> 46550
B22: Term (months) | C22: =IF(C6="","",C6/Controls!$B$29) -> 4.6178712 | D22: =IF(D6="","",D6/Controls!$B$29) -> 4.6178712 | E22: =IF(E6="","",E6/Controls!$B$29) -> 4.6178712
B24: METRICS AT THE FINAL OFFER (yellow allowed when the book is supportive; RED / KNOCKOUT never)
B25: Metric | C25: Base | D25: Sized | E25: Final | F25: Status (final) | G25: Green / Red / Knockout
B26: Total LVG (all debt / rev) | C26: =IF(OR(Deal!$C$24=0,C9=""),"",(Deal!$E$34+C9)*Controls!$B$29/Deal!$C$24) -> 0.17838699 | D26: =IF(OR(Deal!$C$24=0,D9=""),"",(Deal!$E$34+D9)*Controls!$B$29/Deal!$C$24) -> 0.17838699 | E26: =IF(OR(Deal!$C$24=0,E9=""),"",(Deal!$E$34+E9)*Controls!$B$29/Deal!$C$24) -> 0.17838699 | F26: =IF(E26="","",IF(E26>=Controls!$D$5,"KNOCKOUT",IF(E26<=Controls!$B$5,"GREEN",IF(E26>=Controls!$C$5,"RED","YELLOW")))) -> GREEN | G26: =TEXT(Controls!$B$5,"0.0%")&" / "&TEXT(Controls!$C$5,"0.0%")&" / "&TEXT(Controls!$D$5,"0.0%") -> 30.0% / 45.0% / 55.0%
B27: New holdback SP% | C27: =IF(OR(Deal!$C$24=0,C9=""),"",C9*Controls!$B$29/Deal!$C$24) -> 0.17838699 | D27: =IF(OR(Deal!$C$24=0,D9=""),"",D9*Controls!$B$29/Deal!$C$24) -> 0.17838699 | E27: =IF(OR(Deal!$C$24=0,E9=""),"",E9*Controls!$B$29/Deal!$C$24) -> 0.17838699 | F27: =IF(E27="","",IF(E27>=Controls!$D$6,"KNOCKOUT",IF(E27<=Controls!$B$6,"GREEN",IF(E27>=Controls!$C$6,"RED","YELLOW")))) -> GREEN | G27: =TEXT(Controls!$B$6,"0.0%")&" / "&TEXT(Controls!$C$6,"0.0%")&" / "&TEXT(Controls!$D$6,"0.0%") -> 18.0% / 25.0% / 35.0%
B28: Daily debt / balance | C28: =IF(OR(Deal!$D$24=0,C9=""),"",(Deal!$E$34+C9)/Deal!$D$24) -> 0.0983391 | D28: =IF(OR(Deal!$D$24=0,D9=""),"",(Deal!$E$34+D9)/Deal!$D$24) -> 0.0983391 | E28: =IF(OR(Deal!$D$24=0,E9=""),"",(Deal!$E$34+E9)/Deal!$D$24) -> 0.0983391 | F28: =IF(E28="","",IF(E28>=Controls!$D$7,"KNOCKOUT",IF(E28<=Controls!$B$7,"GREEN",IF(E28>=Controls!$C$7,"RED","YELLOW")))) -> GREEN | G28: =TEXT(Controls!$B$7,"0.0%")&" / "&TEXT(Controls!$C$7,"0.0%")&" / "&TEXT(Controls!$D$7,"0.0%") -> 18.0% / 30.0% / 35.0%
B29: Fund / revenue | C29: =IF(OR(Deal!$C$24=0,C8="",C8="-"),"",C8/Deal!$C$24) -> 0.56811594 | D29: =IF(OR(Deal!$C$24=0,D8="",D8="-"),"",D8/Deal!$C$24) -> 0.56811594 | E29: =IF(OR(Deal!$C$24=0,E8="",E8="-"),"",E8/Deal!$C$24) -> 0.56811594 | F29: =IF(E29="","",IF(E29>=Controls!$D$8,"KNOCKOUT",IF(E29<=Controls!$B$8,"GREEN",IF(E29>=Controls!$C$8,"RED","YELLOW")))) -> GREEN | G29: =TEXT(Controls!$B$8,"0.00")&" / "&TEXT(Controls!$C$8,"0.00")&" / "&TEXT(Controls!$D$8,"0.00") -> 0.60 / 0.90 / 1.25
B30: # positions (incl. new) | E30: =Deal!$C$42 -> 1 | F30: =Deal!$F$42 -> GREEN | G30: merchant-side, unchanged by the offer
B31: Revenue trend (avg MoM) | E31: =Deal!$C$43 -> 0.026817356 | F31: =Deal!$F$43 -> GREEN | G31: merchant-side, unchanged by the offer
B32: Neg days + NSFs (total) | E32: =Deal!$C$44 -> 2 | F32: =Deal!$F$44 -> YELLOW | G32: merchant-side, unchanged by the offer
B33: Credit score (FICO) | E33: =Deal!$C$45 -> 672 | F33: =Deal!$F$45 -> GREEN | G33: merchant-side, unchanged by the offer
B35: SAFETY PROOF
B36: Final fund <= sized max fund | E36: =IF(OR(E8="",E8="-",D8="",D8="-"),"OK",IF(E8<=D8,"OK","FAIL")) -> OK
B37: Final daily payment <= sized max daily | E37: =IF(OR(E9="",D5=""),"OK",IF(E9<=D5+0.005,"OK","FAIL")) -> OK
B38: No offer-side metric RED / KNOCKOUT at the final offer | E38: =IF(COUNTIF(F26:F29,"RED")+COUNTIF(F26:F29,"KNOCKOUT")=0,"OK","FAIL") -> OK
B39: Merchant knockouts untouched | E39: =IF(COUNTIF(Deal!$F$42:$F$45,"KNOCKOUT")>0,IF(E8="-","OK","FAIL"),"OK") -> OK
B40: Sizing flex below 100% (sizing line never reaches the red line) | E40: =IF(C15<1,"OK","FAIL") -> OK
B41: Red flags at the final offer (offer-side + merchant-side) | E41: =COUNTIF(F26:F33,"RED")+COUNTIF(F26:F33,"KNOCKOUT") -> 0

Sheet Historical Score
A1: HISTORICAL SCORE - comparable cohorts, credibility and the modifier
A2: Rates use SEASONED deals only (age >= multiple x contracted term). Blended = Z x cohort + (1-Z) x seasoned book, Z = n/(n+K). Index = blended / book.
A4: DEAL BEING MATCHED
B5: New deal or renewal | C5: =IF(Deal!$K$15="","",Deal!$K$15) -> New Deal
B6: Position (Deal C42) | C6: =IF(Deal!$C$42="","",Deal!$C$42) -> 1
B7: Industry | C7: =IF(Deal!$K$13="","",Deal!$K$13) -> Eating & Drinking Places
B8: ISO | C8: =IF(Deal!$K$12="","",Deal!$K$12) -> Fundwell
B9: State (informational) | C9: =IF(Deal!$K$14="","",Deal!$K$14) -> NJ
B10: Seasoned-book principal lost rate (baseline) | C10: =IF($L$20="",0,$L$20) -> 0.41
B11: Seasoned-book deals / funded | C11: =TEXT($E$20,"#,##0")&" / "&TEXT($G$20,"$#,##0") -> 7 / $150,000
A13: Tier | B13: Cohort | C13: Keys | D13: Deals (all) | E13: Seasoned | F13: % seasoned | G13: Funded $ (seasoned) | H13: Open n | I13: Open % | J13: Default n | K13: Default % | L13: Principal lost rate | M13: Collected on defaults | N13: Return on funded | O13: Avg adv/rev | P13: Avg term (bd) | Q13: Avg factor | R13: Avg deal size | S13: Avg days on book | T13: Renewal share | U13: Meets minimums? | V13: Credibility Z | W13: Blended lost rate | X13: Relative index | Y13: Meets min (1/0) | Z13: Impact vs book | AA13: Rate shown?
A14: 1 | B14: T1: new/renewal + industry + position | C14: NR + industry + position | D14: =SUMPRODUCT('Historical Data'!$AV$2:$AV$9*'Historical Data'!$AD$2:$AD$9) -> 1 | E14: =SUMPRODUCT('Historical Data'!$AV$2:$AV$9*'Historical Data'!$AP$2:$AP$9) -> 1 | F14: =IF(D14=0,"",E14/D14) -> 1 | G14: =SUMPRODUCT('Historical Data'!$AV$2:$AV$9*'Historical Data'!$AP$2:$AP$9*'Historical Data'!$N$2:$N$9) -> 10000 | H14: =SUMPRODUCT('Historical Data'!$AV$2:$AV$9*'Historical Data'!$AP$2:$AP$9*'Historical Data'!$AH$2:$AH$9) -> 0 | I14: =IF(E14=0,"",H14/E14) -> 0 | J14: =SUMPRODUCT('Historical Data'!$AV$2:$AV$9*'Historical Data'!$AP$2:$AP$9*'Historical Data'!$AE$2:$AE$9) -> 0 | K14: =IF(E14=0,"",J14/E14) -> 0 | L14: =IF(OR(E14<Controls!$B$43,G14=0),"",SUMPRODUCT('Historical Data'!$AV$2:$AV$9*'Historical Data'!$AP$2:$AP$9*'Historical Data'!$AK$2:$AK$9)/G14) | M14: =IF(OR(E14<Controls!$B$43,SUMPRODUCT('Historical Data'!$AV$2:$AV$9*'Historical Data'!$AP$2:$AP$9*'Historical Data'!$AE$2:$AE$9*'Historical Data'!$N$2:$N$9)=0),"",SUMPRODUCT('Historical Data'!$AV$2:$AV$9*'Historical Data'!$AP$2:$AP$9*'Historical Data'!$AE$2:$AE$9*'Historical Data'!$Q$2:$Q$9)/SUMPRODUCT('Historical Data'!$AV$2:$AV$9*'Historical Data'!$AP$2:$AP$9*'Historical Data'!$AE$2:$AE$9*'Historical Data'!$N$2:$N$9)) | N14: =IF(OR(E14<Controls!$B$43,G14=0),"",SUMPRODUCT('Historical Data'!$AV$2:$AV$9*'Historical Data'!$AP$2:$AP$9*'Historical Data'!$AJ$2:$AJ$9)/G14) | O14: =IF(SUMPRODUCT('Historical Data'!$AV$2:$AV$9*'Historical Data'!$AP$2:$AP$9*'Historical Data'!$AM$2:$AM$9)=0,"",SUMPRODUCT('Historical Data'!$AV$2:$AV$9*'Historical Data'!$AP$2:$AP$9*'Historical Data'!$AM$2:$AM$9*'Historical Data'!$AL$2:$AL$9)/SUMPRODUCT('Historical Data'!$AV$2:$AV$9*'Historical Data'!$AP$2:$AP$9*'Historical Data'!$AM$2:$AM$9)) -> 0.2 | P14: =IF(E14=0,"",SUMPRODUCT('Historical Data'!$AV$2:$AV$9*'Historical Data'!$AP$2:$AP$9*'Historical Data'!$AA$2:$AA$9)/E14) -> 108.275 | Q14: =IF(E14=0,"",SUMPRODUCT('Historical Data'!$AV$2:$AV$9*'Historical Data'!$AP$2:$AP$9*'Historical Data'!$M$2:$M$9)/E14) -> 1.5 | R14: =IF(E14=0,"",G14/E14) -> 10000 | S14: =IF(E14=0,"",SUMPRODUCT('Historical Data'!$AV$2:$AV$9*'Historical Data'!$AP$2:$AP$9*'Historical Data'!$AN$2:$AN$9)/E14) -> 105 | T14: =IF(E14=0,"",SUMPRODUCT('Historical Data'!$AV$2:$AV$9*'Historical Data'!$AP$2:$AP$9*'Historical Data'!$AO$2:$AO$9)/E14) -> 0 | U14: =IF(AND(E14>=Controls!$B$40,G14>=Controls!$B$41),"Yes","No") -> No | V14: =IF(E14+Controls!$B$42=0,0,E14/(E14+Controls!$B$42)) -> 0.032258065 | W14: =IF(L14="",$C$10,V14*L14+(1-V14)*$C$10) -> 0.41 | X14: =IF(OR($C$10="",$C$10=0),"",W14/$C$10) -> 1 | Y14: =IF(U14="Yes",1,0) -> 0 | Z14: =IF(L14="",0,ABS(W14-$C$10)) -> 0 | AA14: =IF(L14="","No","Yes") -> No
A15: 2 | B15: T2: new/renewal + ISO + position | C15: NR + ISO + position | D15: =SUMPRODUCT('Historical Data'!$AW$2:$AW$9*'Historical Data'!$AD$2:$AD$9) -> 2 | E15: =SUMPRODUCT('Historical Data'!$AW$2:$AW$9*'Historical Data'!$AP$2:$AP$9) -> 1 | F15: =IF(D15=0,"",E15/D15) -> 0.5 | G15: =SUMPRODUCT('Historical Data'!$AW$2:$AW$9*'Historical Data'!$AP$2:$AP$9*'Historical Data'!$N$2:$N$9) -> 10000 | H15: =SUMPRODUCT('Historical Data'!$AW$2:$AW$9*'Historical Data'!$AP$2:$AP$9*'Historical Data'!$AH$2:$AH$9) -> 0 | I15: =IF(E15=0,"",H15/E15) -> 0 | J15: =SUMPRODUCT('Historical Data'!$AW$2:$AW$9*'Historical Data'!$AP$2:$AP$9*'Historical Data'!$AE$2:$AE$9) -> 0 | K15: =IF(E15=0,"",J15/E15) -> 0 | L15: =IF(OR(E15<Controls!$B$43,G15=0),"",SUMPRODUCT('Historical Data'!$AW$2:$AW$9*'Historical Data'!$AP$2:$AP$9*'Historical Data'!$AK$2:$AK$9)/G15) | M15: =IF(OR(E15<Controls!$B$43,SUMPRODUCT('Historical Data'!$AW$2:$AW$9*'Historical Data'!$AP$2:$AP$9*'Historical Data'!$AE$2:$AE$9*'Historical Data'!$N$2:$N$9)=0),"",SUMPRODUCT('Historical Data'!$AW$2:$AW$9*'Historical Data'!$AP$2:$AP$9*'Historical Data'!$AE$2:$AE$9*'Historical Data'!$Q$2:$Q$9)/SUMPRODUCT('Historical Data'!$AW$2:$AW$9*'Historical Data'!$AP$2:$AP$9*'Historical Data'!$AE$2:$AE$9*'Historical Data'!$N$2:$N$9)) | N15: =IF(OR(E15<Controls!$B$43,G15=0),"",SUMPRODUCT('Historical Data'!$AW$2:$AW$9*'Historical Data'!$AP$2:$AP$9*'Historical Data'!$AJ$2:$AJ$9)/G15) | O15: =IF(SUMPRODUCT('Historical Data'!$AW$2:$AW$9*'Historical Data'!$AP$2:$AP$9*'Historical Data'!$AM$2:$AM$9)=0,"",SUMPRODUCT('Historical Data'!$AW$2:$AW$9*'Historical Data'!$AP$2:$AP$9*'Historical Data'!$AM$2:$AM$9*'Historical Data'!$AL$2:$AL$9)/SUMPRODUCT('Historical Data'!$AW$2:$AW$9*'Historical Data'!$AP$2:$AP$9*'Historical Data'!$AM$2:$AM$9)) -> 0.2 | P15: =IF(E15=0,"",SUMPRODUCT('Historical Data'!$AW$2:$AW$9*'Historical Data'!$AP$2:$AP$9*'Historical Data'!$AA$2:$AA$9)/E15) -> 108.275 | Q15: =IF(E15=0,"",SUMPRODUCT('Historical Data'!$AW$2:$AW$9*'Historical Data'!$AP$2:$AP$9*'Historical Data'!$M$2:$M$9)/E15) -> 1.5 | R15: =IF(E15=0,"",G15/E15) -> 10000 | S15: =IF(E15=0,"",SUMPRODUCT('Historical Data'!$AW$2:$AW$9*'Historical Data'!$AP$2:$AP$9*'Historical Data'!$AN$2:$AN$9)/E15) -> 105 | T15: =IF(E15=0,"",SUMPRODUCT('Historical Data'!$AW$2:$AW$9*'Historical Data'!$AP$2:$AP$9*'Historical Data'!$AO$2:$AO$9)/E15) -> 0 | U15: =IF(AND(E15>=Controls!$B$40,G15>=Controls!$B$41),"Yes","No") -> No | V15: =IF(E15+Controls!$B$42=0,0,E15/(E15+Controls!$B$42)) -> 0.032258065 | W15: =IF(L15="",$C$10,V15*L15+(1-V15)*$C$10) -> 0.41 | X15: =IF(OR($C$10="",$C$10=0),"",W15/$C$10) -> 1 | Y15: =IF(U15="Yes",1,0) -> 0 | Z15: =IF(L15="",0,ABS(W15-$C$10)) -> 0 | AA15: =IF(L15="","No","Yes") -> No
A16: 3 | B16: T3: new/renewal + industry | C16: NR + industry | D16: =SUMPRODUCT('Historical Data'!$AX$2:$AX$9*'Historical Data'!$AD$2:$AD$9) -> 1 | E16: =SUMPRODUCT('Historical Data'!$AX$2:$AX$9*'Historical Data'!$AP$2:$AP$9) -> 1 | F16: =IF(D16=0,"",E16/D16) -> 1 | G16: =SUMPRODUCT('Historical Data'!$AX$2:$AX$9*'Historical Data'!$AP$2:$AP$9*'Historical Data'!$N$2:$N$9) -> 10000 | H16: =SUMPRODUCT('Historical Data'!$AX$2:$AX$9*'Historical Data'!$AP$2:$AP$9*'Historical Data'!$AH$2:$AH$9) -> 0 | I16: =IF(E16=0,"",H16/E16) -> 0 | J16: =SUMPRODUCT('Historical Data'!$AX$2:$AX$9*'Historical Data'!$AP$2:$AP$9*'Historical Data'!$AE$2:$AE$9) -> 0 | K16: =IF(E16=0,"",J16/E16) -> 0 | L16: =IF(OR(E16<Controls!$B$43,G16=0),"",SUMPRODUCT('Historical Data'!$AX$2:$AX$9*'Historical Data'!$AP$2:$AP$9*'Historical Data'!$AK$2:$AK$9)/G16) | M16: =IF(OR(E16<Controls!$B$43,SUMPRODUCT('Historical Data'!$AX$2:$AX$9*'Historical Data'!$AP$2:$AP$9*'Historical Data'!$AE$2:$AE$9*'Historical Data'!$N$2:$N$9)=0),"",SUMPRODUCT('Historical Data'!$AX$2:$AX$9*'Historical Data'!$AP$2:$AP$9*'Historical Data'!$AE$2:$AE$9*'Historical Data'!$Q$2:$Q$9)/SUMPRODUCT('Historical Data'!$AX$2:$AX$9*'Historical Data'!$AP$2:$AP$9*'Historical Data'!$AE$2:$AE$9*'Historical Data'!$N$2:$N$9)) | N16: =IF(OR(E16<Controls!$B$43,G16=0),"",SUMPRODUCT('Historical Data'!$AX$2:$AX$9*'Historical Data'!$AP$2:$AP$9*'Historical Data'!$AJ$2:$AJ$9)/G16) | O16: =IF(SUMPRODUCT('Historical Data'!$AX$2:$AX$9*'Historical Data'!$AP$2:$AP$9*'Historical Data'!$AM$2:$AM$9)=0,"",SUMPRODUCT('Historical Data'!$AX$2:$AX$9*'Historical Data'!$AP$2:$AP$9*'Historical Data'!$AM$2:$AM$9*'Historical Data'!$AL$2:$AL$9)/SUMPRODUCT('Historical Data'!$AX$2:$AX$9*'Historical Data'!$AP$2:$AP$9*'Historical Data'!$AM$2:$AM$9)) -> 0.2 | P16: =IF(E16=0,"",SUMPRODUCT('Historical Data'!$AX$2:$AX$9*'Historical Data'!$AP$2:$AP$9*'Historical Data'!$AA$2:$AA$9)/E16) -> 108.275 | Q16: =IF(E16=0,"",SUMPRODUCT('Historical Data'!$AX$2:$AX$9*'Historical Data'!$AP$2:$AP$9*'Historical Data'!$M$2:$M$9)/E16) -> 1.5 | R16: =IF(E16=0,"",G16/E16) -> 10000 | S16: =IF(E16=0,"",SUMPRODUCT('Historical Data'!$AX$2:$AX$9*'Historical Data'!$AP$2:$AP$9*'Historical Data'!$AN$2:$AN$9)/E16) -> 105 | T16: =IF(E16=0,"",SUMPRODUCT('Historical Data'!$AX$2:$AX$9*'Historical Data'!$AP$2:$AP$9*'Historical Data'!$AO$2:$AO$9)/E16) -> 0 | U16: =IF(AND(E16>=Controls!$B$40,G16>=Controls!$B$41),"Yes","No") -> No | V16: =IF(E16+Controls!$B$42=0,0,E16/(E16+Controls!$B$42)) -> 0.032258065 | W16: =IF(L16="",$C$10,V16*L16+(1-V16)*$C$10) -> 0.41 | X16: =IF(OR($C$10="",$C$10=0),"",W16/$C$10) -> 1 | Y16: =IF(U16="Yes",1,0) -> 0 | Z16: =IF(L16="",0,ABS(W16-$C$10)) -> 0 | AA16: =IF(L16="","No","Yes") -> No
A17: 4 | B17: T4: new/renewal + ISO | C17: NR + ISO | D17: =SUMPRODUCT('Historical Data'!$AY$2:$AY$9*'Historical Data'!$AD$2:$AD$9) -> 3 | E17: =SUMPRODUCT('Historical Data'!$AY$2:$AY$9*'Historical Data'!$AP$2:$AP$9) -> 2 | F17: =IF(D17=0,"",E17/D17) -> 0.66666667 | G17: =SUMPRODUCT('Historical Data'!$AY$2:$AY$9*'Historical Data'!$AP$2:$AP$9*'Historical Data'!$N$2:$N$9) -> 40000 | H17: =SUMPRODUCT('Historical Data'!$AY$2:$AY$9*'Historical Data'!$AP$2:$AP$9*'Historical Data'!$AH$2:$AH$9) -> 0 | I17: =IF(E17=0,"",H17/E17) -> 0 | J17: =SUMPRODUCT('Historical Data'!$AY$2:$AY$9*'Historical Data'!$AP$2:$AP$9*'Historical Data'!$AE$2:$AE$9) -> 1 | K17: =IF(E17=0,"",J17/E17) -> 0.5 | L17: =IF(OR(E17<Controls!$B$43,G17=0),"",SUMPRODUCT('Historical Data'!$AY$2:$AY$9*'Historical Data'!$AP$2:$AP$9*'Historical Data'!$AK$2:$AK$9)/G17) -> 0.525 | M17: =IF(OR(E17<Controls!$B$43,SUMPRODUCT('Historical Data'!$AY$2:$AY$9*'Historical Data'!$AP$2:$AP$9*'Historical Data'!$AE$2:$AE$9*'Historical Data'!$N$2:$N$9)=0),"",SUMPRODUCT('Historical Data'!$AY$2:$AY$9*'Historical Data'!$AP$2:$AP$9*'Historical Data'!$AE$2:$AE$9*'Historical Data'!$Q$2:$Q$9)/SUMPRODUCT('Historical Data'!$AY$2:$AY$9*'Historical Data'!$AP$2:$AP$9*'Historical Data'!$AE$2:$AE$9*'Historical Data'!$N$2:$N$9)) -> 0.3 | N17: =IF(OR(E17<Controls!$B$43,G17=0),"",SUMPRODUCT('Historical Data'!$AY$2:$AY$9*'Historical Data'!$AP$2:$AP$9*'Historical Data'!$AJ$2:$AJ$9)/G17) -> -0.4 | O17: =IF(SUMPRODUCT('Historical Data'!$AY$2:$AY$9*'Historical Data'!$AP$2:$AP$9*'Historical Data'!$AM$2:$AM$9)=0,"",SUMPRODUCT('Historical Data'!$AY$2:$AY$9*'Historical Data'!$AP$2:$AP$9*'Historical Data'!$AM$2:$AM$9*'Historical Data'!$AL$2:$AL$9)/SUMPRODUCT('Historical Data'!$AY$2:$AY$9*'Historical Data'!$AP$2:$AP$9*'Historical Data'!$AM$2:$AM$9)) -> 0.35 | P17: =IF(E17=0,"",SUMPRODUCT('Historical Data'!$AY$2:$AY$9*'Historical Data'!$AP$2:$AP$9*'Historical Data'!$AA$2:$AA$9)/E17) -> 119.1025 | Q17: =IF(E17=0,"",SUMPRODUCT('Historical Data'!$AY$2:$AY$9*'Historical Data'!$AP$2:$AP$9*'Historical Data'!$M$2:$M$9)/E17) -> 1.5 | R17: =IF(E17=0,"",G17/E17) -> 20000 | S17: =IF(E17=0,"",SUMPRODUCT('Historical Data'!$AY$2:$AY$9*'Historical Data'!$AP$2:$AP$9*'Historical Data'!$AN$2:$AN$9)/E17) -> 85.5 | T17: =IF(E17=0,"",SUMPRODUCT('Historical Data'!$AY$2:$AY$9*'Historical Data'!$AP$2:$AP$9*'Historical Data'!$AO$2:$AO$9)/E17) -> 0 | U17: =IF(AND(E17>=Controls!$B$40,G17>=Controls!$B$41),"Yes","No") -> No | V17: =IF(E17+Controls!$B$42=0,0,E17/(E17+Controls!$B$42)) -> 0.0625 | W17: =IF(L17="",$C$10,V17*L17+(1-V17)*$C$10) -> 0.4171875 | X17: =IF(OR($C$10="",$C$10=0),"",W17/$C$10) -> 1.0175305 | Y17: =IF(U17="Yes",1,0) -> 0 | Z17: =IF(L17="",0,ABS(W17-$C$10)) -> 0.0071875 | AA17: =IF(L17="","No","Yes") -> Yes
A18: 5 | B18: T5: new/renewal + position | C18: NR + position | D18: =SUMPRODUCT('Historical Data'!$AZ$2:$AZ$9*'Historical Data'!$AD$2:$AD$9) -> 2 | E18: =SUMPRODUCT('Historical Data'!$AZ$2:$AZ$9*'Historical Data'!$AP$2:$AP$9) -> 1 | F18: =IF(D18=0,"",E18/D18) -> 0.5 | G18: =SUMPRODUCT('Historical Data'!$AZ$2:$AZ$9*'Historical Data'!$AP$2:$AP$9*'Historical Data'!$N$2:$N$9) -> 10000 | H18: =SUMPRODUCT('Historical Data'!$AZ$2:$AZ$9*'Historical Data'!$AP$2:$AP$9*'Historical Data'!$AH$2:$AH$9) -> 0 | I18: =IF(E18=0,"",H18/E18) -> 0 | J18: =SUMPRODUCT('Historical Data'!$AZ$2:$AZ$9*'Historical Data'!$AP$2:$AP$9*'Historical Data'!$AE$2:$AE$9) -> 0 | K18: =IF(E18=0,"",J18/E18) -> 0 | L18: =IF(OR(E18<Controls!$B$43,G18=0),"",SUMPRODUCT('Historical Data'!$AZ$2:$AZ$9*'Historical Data'!$AP$2:$AP$9*'Historical Data'!$AK$2:$AK$9)/G18) | M18: =IF(OR(E18<Controls!$B$43,SUMPRODUCT('Historical Data'!$AZ$2:$AZ$9*'Historical Data'!$AP$2:$AP$9*'Historical Data'!$AE$2:$AE$9*'Historical Data'!$N$2:$N$9)=0),"",SUMPRODUCT('Historical Data'!$AZ$2:$AZ$9*'Historical Data'!$AP$2:$AP$9*'Historical Data'!$AE$2:$AE$9*'Historical Data'!$Q$2:$Q$9)/SUMPRODUCT('Historical Data'!$AZ$2:$AZ$9*'Historical Data'!$AP$2:$AP$9*'Historical Data'!$AE$2:$AE$9*'Historical Data'!$N$2:$N$9)) | N18: =IF(OR(E18<Controls!$B$43,G18=0),"",SUMPRODUCT('Historical Data'!$AZ$2:$AZ$9*'Historical Data'!$AP$2:$AP$9*'Historical Data'!$AJ$2:$AJ$9)/G18) | O18: =IF(SUMPRODUCT('Historical Data'!$AZ$2:$AZ$9*'Historical Data'!$AP$2:$AP$9*'Historical Data'!$AM$2:$AM$9)=0,"",SUMPRODUCT('Historical Data'!$AZ$2:$AZ$9*'Historical Data'!$AP$2:$AP$9*'Historical Data'!$AM$2:$AM$9*'Historical Data'!$AL$2:$AL$9)/SUMPRODUCT('Historical Data'!$AZ$2:$AZ$9*'Historical Data'!$AP$2:$AP$9*'Historical Data'!$AM$2:$AM$9)) -> 0.2 | P18: =IF(E18=0,"",SUMPRODUCT('Historical Data'!$AZ$2:$AZ$9*'Historical Data'!$AP$2:$AP$9*'Historical Data'!$AA$2:$AA$9)/E18) -> 108.275 | Q18: =IF(E18=0,"",SUMPRODUCT('Historical Data'!$AZ$2:$AZ$9*'Historical Data'!$AP$2:$AP$9*'Historical Data'!$M$2:$M$9)/E18) -> 1.5 | R18: =IF(E18=0,"",G18/E18) -> 10000 | S18: =IF(E18=0,"",SUMPRODUCT('Historical Data'!$AZ$2:$AZ$9*'Historical Data'!$AP$2:$AP$9*'Historical Data'!$AN$2:$AN$9)/E18) -> 105 | T18: =IF(E18=0,"",SUMPRODUCT('Historical Data'!$AZ$2:$AZ$9*'Historical Data'!$AP$2:$AP$9*'Historical Data'!$AO$2:$AO$9)/E18) -> 0 | U18: =IF(AND(E18>=Controls!$B$40,G18>=Controls!$B$41),"Yes","No") -> No | V18: =IF(E18+Controls!$B$42=0,0,E18/(E18+Controls!$B$42)) -> 0.032258065 | W18: =IF(L18="",$C$10,V18*L18+(1-V18)*$C$10) -> 0.41 | X18: =IF(OR($C$10="",$C$10=0),"",W18/$C$10) -> 1 | Y18: =IF(U18="Yes",1,0) -> 0 | Z18: =IF(L18="",0,ABS(W18-$C$10)) -> 0 | AA18: =IF(L18="","No","Yes") -> No
A19: 6 | B19: T6: new/renewal only | C19: NR | D19: =SUMPRODUCT('Historical Data'!$BA$2:$BA$9*'Historical Data'!$AD$2:$AD$9) -> 6 | E19: =SUMPRODUCT('Historical Data'!$BA$2:$BA$9*'Historical Data'!$AP$2:$AP$9) -> 5 | F19: =IF(D19=0,"",E19/D19) -> 0.83333333 | G19: =SUMPRODUCT('Historical Data'!$BA$2:$BA$9*'Historical Data'!$AP$2:$AP$9*'Historical Data'!$N$2:$N$9) -> 120000 | H19: =SUMPRODUCT('Historical Data'!$BA$2:$BA$9*'Historical Data'!$AP$2:$AP$9*'Historical Data'!$AH$2:$AH$9) -> 0 | I19: =IF(E19=0,"",H19/E19) -> 0 | J19: =SUMPRODUCT('Historical Data'!$BA$2:$BA$9*'Historical Data'!$AP$2:$AP$9*'Historical Data'!$AE$2:$AE$9) -> 3 | K19: =IF(E19=0,"",J19/E19) -> 0.6 | L19: =IF(OR(E19<Controls!$B$43,G19=0),"",SUMPRODUCT('Historical Data'!$BA$2:$BA$9*'Historical Data'!$AP$2:$AP$9*'Historical Data'!$AK$2:$AK$9)/G19) -> 0.50833333 | M19: =IF(OR(E19<Controls!$B$43,SUMPRODUCT('Historical Data'!$BA$2:$BA$9*'Historical Data'!$AP$2:$AP$9*'Historical Data'!$AE$2:$AE$9*'Historical Data'!$N$2:$N$9)=0),"",SUMPRODUCT('Historical Data'!$BA$2:$BA$9*'Historical Data'!$AP$2:$AP$9*'Historical Data'!$AE$2:$AE$9*'Historical Data'!$Q$2:$Q$9)/SUMPRODUCT('Historical Data'!$BA$2:$BA$9*'Historical Data'!$AP$2:$AP$9*'Historical Data'!$AE$2:$AE$9*'Historical Data'!$N$2:$N$9)) -> 0.32222222 | N19: =IF(OR(E19<Controls!$B$43,G19=0),"",SUMPRODUCT('Historical Data'!$BA$2:$BA$9*'Historical Data'!$AP$2:$AP$9*'Historical Data'!$AJ$2:$AJ$9)/G19) -> -0.38333333 | O19: =IF(SUMPRODUCT('Historical Data'!$BA$2:$BA$9*'Historical Data'!$AP$2:$AP$9*'Historical Data'!$AM$2:$AM$9)=0,"",SUMPRODUCT('Historical Data'!$BA$2:$BA$9*'Historical Data'!$AP$2:$AP$9*'Historical Data'!$AM$2:$AM$9*'Historical Data'!$AL$2:$AL$9)/SUMPRODUCT('Historical Data'!$BA$2:$BA$9*'Historical Data'!$AP$2:$AP$9*'Historical Data'!$AM$2:$AM$9)) -> 0.35 | P19: =IF(E19=0,"",SUMPRODUCT('Historical Data'!$BA$2:$BA$9*'Historical Data'!$AP$2:$AP$9*'Historical Data'!$AA$2:$AA$9)/E19) -> 107.641 | Q19: =IF(E19=0,"",SUMPRODUCT('Historical Data'!$BA$2:$BA$9*'Historical Data'!$AP$2:$AP$9*'Historical Data'!$M$2:$M$9)/E19) -> 1.5 | R19: =IF(E19=0,"",G19/E19) -> 24000 | S19: =IF(E19=0,"",SUMPRODUCT('Historical Data'!$BA$2:$BA$9*'Historical Data'!$AP$2:$AP$9*'Historical Data'!$AN$2:$AN$9)/E19) -> 85.4 | T19: =IF(E19=0,"",SUMPRODUCT('Historical Data'!$BA$2:$BA$9*'Historical Data'!$AP$2:$AP$9*'Historical Data'!$AO$2:$AO$9)/E19) -> 0 | U19: =IF(AND(E19>=Controls!$B$40,G19>=Controls!$B$41),"Yes","No") -> Yes | V19: =IF(E19+Controls!$B$42=0,0,E19/(E19+Controls!$B$42)) -> 0.14285714 | W19: =IF(L19="",$C$10,V19*L19+(1-V19)*$C$10) -> 0.42404762 | X19: =IF(OR($C$10="",$C$10=0),"",W19/$C$10) -> 1.0342625 | Y19: =IF(U19="Yes",1,0) -> 1 | Z19: =IF(L19="",0,ABS(W19-$C$10)) -> 0.014047619 | AA19: =IF(L19="","No","Yes") -> Yes
A20: 7 | B20: T7: seasoned book (baseline) | C20: all seasoned deals in window | D20: =SUMPRODUCT('Historical Data'!$BB$2:$BB$9*'Historical Data'!$AD$2:$AD$9) -> 8 | E20: =SUMPRODUCT('Historical Data'!$BB$2:$BB$9*'Historical Data'!$AP$2:$AP$9) -> 7 | F20: =IF(D20=0,"",E20/D20) -> 0.875 | G20: =SUMPRODUCT('Historical Data'!$BB$2:$BB$9*'Historical Data'!$AP$2:$AP$9*'Historical Data'!$N$2:$N$9) -> 150000 | H20: =SUMPRODUCT('Historical Data'!$BB$2:$BB$9*'Historical Data'!$AP$2:$AP$9*'Historical Data'!$AH$2:$AH$9) -> 0 | I20: =IF(E20=0,"",H20/E20) -> 0 | J20: =SUMPRODUCT('Historical Data'!$BB$2:$BB$9*'Historical Data'!$AP$2:$AP$9*'Historical Data'!$AE$2:$AE$9) -> 4 | K20: =IF(E20=0,"",J20/E20) -> 0.57142857 | L20: =IF(OR(E20<Controls!$B$43,G20=0),"",SUMPRODUCT('Historical Data'!$BB$2:$BB$9*'Historical Data'!$AP$2:$AP$9*'Historical Data'!$AK$2:$AK$9)/G20) -> 0.41 | M20: =IF(OR(E20<Controls!$B$43,SUMPRODUCT('Historical Data'!$BB$2:$BB$9*'Historical Data'!$AP$2:$AP$9*'Historical Data'!$AE$2:$AE$9*'Historical Data'!$N$2:$N$9)=0),"",SUMPRODUCT('Historical Data'!$BB$2:$BB$9*'Historical Data'!$AP$2:$AP$9*'Historical Data'!$AE$2:$AE$9*'Historical Data'!$Q$2:$Q$9)/SUMPRODUCT('Historical Data'!$BB$2:$BB$9*'Historical Data'!$AP$2:$AP$9*'Historical Data'!$AE$2:$AE$9*'Historical Data'!$N$2:$N$9)) -> 0.385 | N20: =IF(OR(E20<Controls!$B$43,G20=0),"",SUMPRODUCT('Historical Data'!$BB$2:$BB$9*'Historical Data'!$AP$2:$AP$9*'Historical Data'!$AJ$2:$AJ$9)/G20) -> -0.24333333 | O20: =IF(SUMPRODUCT('Historical Data'!$BB$2:$BB$9*'Historical Data'!$AP$2:$AP$9*'Historical Data'!$AM$2:$AM$9)=0,"",SUMPRODUCT('Historical Data'!$BB$2:$BB$9*'Historical Data'!$AP$2:$AP$9*'Historical Data'!$AM$2:$AM$9*'Historical Data'!$AL$2:$AL$9)/SUMPRODUCT('Historical Data'!$BB$2:$BB$9*'Historical Data'!$AP$2:$AP$9*'Historical Data'!$AM$2:$AM$9)) -> 0.35 | P20: =IF(E20=0,"",SUMPRODUCT('Historical Data'!$BB$2:$BB$9*'Historical Data'!$AP$2:$AP$9*'Historical Data'!$AA$2:$AA$9)/E20) -> 103.54643 | Q20: =IF(E20=0,"",SUMPRODUCT('Historical Data'!$BB$2:$BB$9*'Historical Data'!$AP$2:$AP$9*'Historical Data'!$M$2:$M$9)/E20) -> 1.5 | R20: =IF(E20=0,"",G20/E20) -> 21428.571 | S20: =IF(E20=0,"",SUMPRODUCT('Historical Data'!$BB$2:$BB$9*'Historical Data'!$AP$2:$AP$9*'Historical Data'!$AN$2:$AN$9)/E20) -> 94.142857 | T20: =IF(E20=0,"",SUMPRODUCT('Historical Data'!$BB$2:$BB$9*'Historical Data'!$AP$2:$AP$9*'Historical Data'!$AO$2:$AO$9)/E20) -> 0.28571429 | U20: =IF(AND(E20>=Controls!$B$40,G20>=Controls!$B$41),"Yes","No") -> Yes | V20: =IF(E20+Controls!$B$42=0,0,E20/(E20+Controls!$B$42)) -> 0.18918919 | W20: =IF(L20="",$C$10,V20*L20+(1-V20)*$C$10) -> 0.41 | X20: =IF(OR($C$10="",$C$10=0),"",W20/$C$10) -> 1 | Y20: =IF(U20="Yes",1,0) -> 1 | Z20: =IF(L20="",0,ABS(W20-$C$10)) -> 0 | AA20: =IF(L20="","No","Yes") -> Yes
B21: SINGLE-DIMENSION EVIDENCE (C2 block on Deal; largest-impact test)
A22: S1 | B22: Position only | C22: Position only | D22: =SUMPRODUCT('Historical Data'!$AQ$2:$AQ$9*'Historical Data'!$AD$2:$AD$9) -> 2 | E22: =SUMPRODUCT('Historical Data'!$AQ$2:$AQ$9*'Historical Data'!$AP$2:$AP$9) -> 1 | F22: =IF(D22=0,"",E22/D22) -> 0.5 | G22: =SUMPRODUCT('Historical Data'!$AQ$2:$AQ$9*'Historical Data'!$AP$2:$AP$9*'Historical Data'!$N$2:$N$9) -> 10000 | H22: =SUMPRODUCT('Historical Data'!$AQ$2:$AQ$9*'Historical Data'!$AP$2:$AP$9*'Historical Data'!$AH$2:$AH$9) -> 0 | I22: =IF(E22=0,"",H22/E22) -> 0 | J22: =SUMPRODUCT('Historical Data'!$AQ$2:$AQ$9*'Historical Data'!$AP$2:$AP$9*'Historical Data'!$AE$2:$AE$9) -> 0 | K22: =IF(E22=0,"",J22/E22) -> 0 | L22: =IF(OR(E22<Controls!$B$43,G22=0),"",SUMPRODUCT('Historical Data'!$AQ$2:$AQ$9*'Historical Data'!$AP$2:$AP$9*'Historical Data'!$AK$2:$AK$9)/G22) | M22: =IF(OR(E22<Controls!$B$43,SUMPRODUCT('Historical Data'!$AQ$2:$AQ$9*'Historical Data'!$AP$2:$AP$9*'Historical Data'!$AE$2:$AE$9*'Historical Data'!$N$2:$N$9)=0),"",SUMPRODUCT('Historical Data'!$AQ$2:$AQ$9*'Historical Data'!$AP$2:$AP$9*'Historical Data'!$AE$2:$AE$9*'Historical Data'!$Q$2:$Q$9)/SUMPRODUCT('Historical Data'!$AQ$2:$AQ$9*'Historical Data'!$AP$2:$AP$9*'Historical Data'!$AE$2:$AE$9*'Historical Data'!$N$2:$N$9)) | N22: =IF(OR(E22<Controls!$B$43,G22=0),"",SUMPRODUCT('Historical Data'!$AQ$2:$AQ$9*'Historical Data'!$AP$2:$AP$9*'Historical Data'!$AJ$2:$AJ$9)/G22) | O22: =IF(SUMPRODUCT('Historical Data'!$AQ$2:$AQ$9*'Historical Data'!$AP$2:$AP$9*'Historical Data'!$AM$2:$AM$9)=0,"",SUMPRODUCT('Historical Data'!$AQ$2:$AQ$9*'Historical Data'!$AP$2:$AP$9*'Historical Data'!$AM$2:$AM$9*'Historical Data'!$AL$2:$AL$9)/SUMPRODUCT('Historical Data'!$AQ$2:$AQ$9*'Historical Data'!$AP$2:$AP$9*'Historical Data'!$AM$2:$AM$9)) -> 0.2 | P22: =IF(E22=0,"",SUMPRODUCT('Historical Data'!$AQ$2:$AQ$9*'Historical Data'!$AP$2:$AP$9*'Historical Data'!$AA$2:$AA$9)/E22) -> 108.275 | Q22: =IF(E22=0,"",SUMPRODUCT('Historical Data'!$AQ$2:$AQ$9*'Historical Data'!$AP$2:$AP$9*'Historical Data'!$M$2:$M$9)/E22) -> 1.5 | R22: =IF(E22=0,"",G22/E22) -> 10000 | S22: =IF(E22=0,"",SUMPRODUCT('Historical Data'!$AQ$2:$AQ$9*'Historical Data'!$AP$2:$AP$9*'Historical Data'!$AN$2:$AN$9)/E22) -> 105 | T22: =IF(E22=0,"",SUMPRODUCT('Historical Data'!$AQ$2:$AQ$9*'Historical Data'!$AP$2:$AP$9*'Historical Data'!$AO$2:$AO$9)/E22) -> 0 | U22: =IF(AND(E22>=Controls!$B$40,G22>=Controls!$B$41),"Yes","No") -> No | V22: =IF(E22+Controls!$B$42=0,0,E22/(E22+Controls!$B$42)) -> 0.032258065 | W22: =IF(L22="",$C$10,V22*L22+(1-V22)*$C$10) -> 0.41 | X22: =IF(OR($C$10="",$C$10=0),"",W22/$C$10) -> 1 | Y22: =IF(U22="Yes",1,0) -> 0 | Z22: =IF(L22="",0,ABS(W22-$C$10)) -> 0 | AA22: =IF(L22="","No","Yes") -> No
A23: S2 | B23: New/renewal only | C23: New/renewal only | D23: =SUMPRODUCT('Historical Data'!$AR$2:$AR$9*'Historical Data'!$AD$2:$AD$9) -> 6 | E23: =SUMPRODUCT('Historical Data'!$AR$2:$AR$9*'Historical Data'!$AP$2:$AP$9) -> 5 | F23: =IF(D23=0,"",E23/D23) -> 0.83333333 | G23: =SUMPRODUCT('Historical Data'!$AR$2:$AR$9*'Historical Data'!$AP$2:$AP$9*'Historical Data'!$N$2:$N$9) -> 120000 | H23: =SUMPRODUCT('Historical Data'!$AR$2:$AR$9*'Historical Data'!$AP$2:$AP$9*'Historical Data'!$AH$2:$AH$9) -> 0 | I23: =IF(E23=0,"",H23/E23) -> 0 | J23: =SUMPRODUCT('Historical Data'!$AR$2:$AR$9*'Historical Data'!$AP$2:$AP$9*'Historical Data'!$AE$2:$AE$9) -> 3 | K23: =IF(E23=0,"",J23/E23) -> 0.6 | L23: =IF(OR(E23<Controls!$B$43,G23=0),"",SUMPRODUCT('Historical Data'!$AR$2:$AR$9*'Historical Data'!$AP$2:$AP$9*'Historical Data'!$AK$2:$AK$9)/G23) -> 0.50833333 | M23: =IF(OR(E23<Controls!$B$43,SUMPRODUCT('Historical Data'!$AR$2:$AR$9*'Historical Data'!$AP$2:$AP$9*'Historical Data'!$AE$2:$AE$9*'Historical Data'!$N$2:$N$9)=0),"",SUMPRODUCT('Historical Data'!$AR$2:$AR$9*'Historical Data'!$AP$2:$AP$9*'Historical Data'!$AE$2:$AE$9*'Historical Data'!$Q$2:$Q$9)/SUMPRODUCT('Historical Data'!$AR$2:$AR$9*'Historical Data'!$AP$2:$AP$9*'Historical Data'!$AE$2:$AE$9*'Historical Data'!$N$2:$N$9)) -> 0.32222222 | N23: =IF(OR(E23<Controls!$B$43,G23=0),"",SUMPRODUCT('Historical Data'!$AR$2:$AR$9*'Historical Data'!$AP$2:$AP$9*'Historical Data'!$AJ$2:$AJ$9)/G23) -> -0.38333333 | O23: =IF(SUMPRODUCT('Historical Data'!$AR$2:$AR$9*'Historical Data'!$AP$2:$AP$9*'Historical Data'!$AM$2:$AM$9)=0,"",SUMPRODUCT('Historical Data'!$AR$2:$AR$9*'Historical Data'!$AP$2:$AP$9*'Historical Data'!$AM$2:$AM$9*'Historical Data'!$AL$2:$AL$9)/SUMPRODUCT('Historical Data'!$AR$2:$AR$9*'Historical Data'!$AP$2:$AP$9*'Historical Data'!$AM$2:$AM$9)) -> 0.35 | P23: =IF(E23=0,"",SUMPRODUCT('Historical Data'!$AR$2:$AR$9*'Historical Data'!$AP$2:$AP$9*'Historical Data'!$AA$2:$AA$9)/E23) -> 107.641 | Q23: =IF(E23=0,"",SUMPRODUCT('Historical Data'!$AR$2:$AR$9*'Historical Data'!$AP$2:$AP$9*'Historical Data'!$M$2:$M$9)/E23) -> 1.5 | R23: =IF(E23=0,"",G23/E23) -> 24000 | S23: =IF(E23=0,"",SUMPRODUCT('Historical Data'!$AR$2:$AR$9*'Historical Data'!$AP$2:$AP$9*'Historical Data'!$AN$2:$AN$9)/E23) -> 85.4 | T23: =IF(E23=0,"",SUMPRODUCT('Historical Data'!$AR$2:$AR$9*'Historical Data'!$AP$2:$AP$9*'Historical Data'!$AO$2:$AO$9)/E23) -> 0 | U23: =IF(AND(E23>=Controls!$B$40,G23>=Controls!$B$41),"Yes","No") -> Yes | V23: =IF(E23+Controls!$B$42=0,0,E23/(E23+Controls!$B$42)) -> 0.14285714 | W23: =IF(L23="",$C$10,V23*L23+(1-V23)*$C$10) -> 0.42404762 | X23: =IF(OR($C$10="",$C$10=0),"",W23/$C$10) -> 1.0342625 | Y23: =IF(U23="Yes",1,0) -> 1 | Z23: =IF(L23="",0,ABS(W23-$C$10)) -> 0.014047619 | AA23: =IF(L23="","No","Yes") -> Yes
A24: S3 | B24: Industry only | C24: Industry only | D24: =SUMPRODUCT('Historical Data'!$AS$2:$AS$9*'Historical Data'!$AD$2:$AD$9) -> 1 | E24: =SUMPRODUCT('Historical Data'!$AS$2:$AS$9*'Historical Data'!$AP$2:$AP$9) -> 1 | F24: =IF(D24=0,"",E24/D24) -> 1 | G24: =SUMPRODUCT('Historical Data'!$AS$2:$AS$9*'Historical Data'!$AP$2:$AP$9*'Historical Data'!$N$2:$N$9) -> 10000 | H24: =SUMPRODUCT('Historical Data'!$AS$2:$AS$9*'Historical Data'!$AP$2:$AP$9*'Historical Data'!$AH$2:$AH$9) -> 0 | I24: =IF(E24=0,"",H24/E24) -> 0 | J24: =SUMPRODUCT('Historical Data'!$AS$2:$AS$9*'Historical Data'!$AP$2:$AP$9*'Historical Data'!$AE$2:$AE$9) -> 0 | K24: =IF(E24=0,"",J24/E24) -> 0 | L24: =IF(OR(E24<Controls!$B$43,G24=0),"",SUMPRODUCT('Historical Data'!$AS$2:$AS$9*'Historical Data'!$AP$2:$AP$9*'Historical Data'!$AK$2:$AK$9)/G24) | M24: =IF(OR(E24<Controls!$B$43,SUMPRODUCT('Historical Data'!$AS$2:$AS$9*'Historical Data'!$AP$2:$AP$9*'Historical Data'!$AE$2:$AE$9*'Historical Data'!$N$2:$N$9)=0),"",SUMPRODUCT('Historical Data'!$AS$2:$AS$9*'Historical Data'!$AP$2:$AP$9*'Historical Data'!$AE$2:$AE$9*'Historical Data'!$Q$2:$Q$9)/SUMPRODUCT('Historical Data'!$AS$2:$AS$9*'Historical Data'!$AP$2:$AP$9*'Historical Data'!$AE$2:$AE$9*'Historical Data'!$N$2:$N$9)) | N24: =IF(OR(E24<Controls!$B$43,G24=0),"",SUMPRODUCT('Historical Data'!$AS$2:$AS$9*'Historical Data'!$AP$2:$AP$9*'Historical Data'!$AJ$2:$AJ$9)/G24) | O24: =IF(SUMPRODUCT('Historical Data'!$AS$2:$AS$9*'Historical Data'!$AP$2:$AP$9*'Historical Data'!$AM$2:$AM$9)=0,"",SUMPRODUCT('Historical Data'!$AS$2:$AS$9*'Historical Data'!$AP$2:$AP$9*'Historical Data'!$AM$2:$AM$9*'Historical Data'!$AL$2:$AL$9)/SUMPRODUCT('Historical Data'!$AS$2:$AS$9*'Historical Data'!$AP$2:$AP$9*'Historical Data'!$AM$2:$AM$9)) -> 0.2 | P24: =IF(E24=0,"",SUMPRODUCT('Historical Data'!$AS$2:$AS$9*'Historical Data'!$AP$2:$AP$9*'Historical Data'!$AA$2:$AA$9)/E24) -> 108.275 | Q24: =IF(E24=0,"",SUMPRODUCT('Historical Data'!$AS$2:$AS$9*'Historical Data'!$AP$2:$AP$9*'Historical Data'!$M$2:$M$9)/E24) -> 1.5 | R24: =IF(E24=0,"",G24/E24) -> 10000 | S24: =IF(E24=0,"",SUMPRODUCT('Historical Data'!$AS$2:$AS$9*'Historical Data'!$AP$2:$AP$9*'Historical Data'!$AN$2:$AN$9)/E24) -> 105 | T24: =IF(E24=0,"",SUMPRODUCT('Historical Data'!$AS$2:$AS$9*'Historical Data'!$AP$2:$AP$9*'Historical Data'!$AO$2:$AO$9)/E24) -> 0 | U24: =IF(AND(E24>=Controls!$B$40,G24>=Controls!$B$41),"Yes","No") -> No | V24: =IF(E24+Controls!$B$42=0,0,E24/(E24+Controls!$B$42)) -> 0.032258065 | W24: =IF(L24="",$C$10,V24*L24+(1-V24)*$C$10) -> 0.41 | X24: =IF(OR($C$10="",$C$10=0),"",W24/$C$10) -> 1 | Y24: =IF(U24="Yes",1,0) -> 0 | Z24: =IF(L24="",0,ABS(W24-$C$10)) -> 0 | AA24: =IF(L24="","No","Yes") -> No
A25: S4 | B25: ISO only | C25: ISO only | D25: =SUMPRODUCT('Historical Data'!$AT$2:$AT$9*'Historical Data'!$AD$2:$AD$9) -> 4 | E25: =SUMPRODUCT('Historical Data'!$AT$2:$AT$9*'Historical Data'!$AP$2:$AP$9) -> 3 | F25: =IF(D25=0,"",E25/D25) -> 0.75 | G25: =SUMPRODUCT('Historical Data'!$AT$2:$AT$9*'Historical Data'!$AP$2:$AP$9*'Historical Data'!$N$2:$N$9) -> 50000 | H25: =SUMPRODUCT('Historical Data'!$AT$2:$AT$9*'Historical Data'!$AP$2:$AP$9*'Historical Data'!$AH$2:$AH$9) -> 0 | I25: =IF(E25=0,"",H25/E25) -> 0 | J25: =SUMPRODUCT('Historical Data'!$AT$2:$AT$9*'Historical Data'!$AP$2:$AP$9*'Historical Data'!$AE$2:$AE$9) -> 2 | K25: =IF(E25=0,"",J25/E25) -> 0.66666667 | L25: =IF(OR(E25<Controls!$B$43,G25=0),"",SUMPRODUCT('Historical Data'!$AT$2:$AT$9*'Historical Data'!$AP$2:$AP$9*'Historical Data'!$AK$2:$AK$9)/G25) -> 0.43 | M25: =IF(OR(E25<Controls!$B$43,SUMPRODUCT('Historical Data'!$AT$2:$AT$9*'Historical Data'!$AP$2:$AP$9*'Historical Data'!$AE$2:$AE$9*'Historical Data'!$N$2:$N$9)=0),"",SUMPRODUCT('Historical Data'!$AT$2:$AT$9*'Historical Data'!$AP$2:$AP$9*'Historical Data'!$AE$2:$AE$9*'Historical Data'!$Q$2:$Q$9)/SUMPRODUCT('Historical Data'!$AT$2:$AT$9*'Historical Data'!$AP$2:$AP$9*'Historical Data'!$AE$2:$AE$9*'Historical Data'!$N$2:$N$9)) -> 0.4625 | N25: =IF(OR(E25<Controls!$B$43,G25=0),"",SUMPRODUCT('Historical Data'!$AT$2:$AT$9*'Historical Data'!$AP$2:$AP$9*'Historical Data'!$AJ$2:$AJ$9)/G25) -> -0.33 | O25: =IF(SUMPRODUCT('Historical Data'!$AT$2:$AT$9*'Historical Data'!$AP$2:$AP$9*'Historical Data'!$AM$2:$AM$9)=0,"",SUMPRODUCT('Historical Data'!$AT$2:$AT$9*'Historical Data'!$AP$2:$AP$9*'Historical Data'!$AM$2:$AM$9*'Historical Data'!$AL$2:$AL$9)/SUMPRODUCT('Historical Data'!$AT$2:$AT$9*'Historical Data'!$AP$2:$AP$9*'Historical Data'!$AM$2:$AM$9)) -> 0.4 | P25: =IF(E25=0,"",SUMPRODUCT('Historical Data'!$AT$2:$AT$9*'Historical Data'!$AP$2:$AP$9*'Historical Data'!$AA$2:$AA$9)/E25) -> 108.275 | Q25: =IF(E25=0,"",SUMPRODUCT('Historical Data'!$AT$2:$AT$9*'Historical Data'!$AP$2:$AP$9*'Historical Data'!$M$2:$M$9)/E25) -> 1.5 | R25: =IF(E25=0,"",G25/E25) -> 16666.667 | S25: =IF(E25=0,"",SUMPRODUCT('Historical Data'!$AT$2:$AT$9*'Historical Data'!$AP$2:$AP$9*'Historical Data'!$AN$2:$AN$9)/E25) -> 99.333333 | T25: =IF(E25=0,"",SUMPRODUCT('Historical Data'!$AT$2:$AT$9*'Historical Data'!$AP$2:$AP$9*'Historical Data'!$AO$2:$AO$9)/E25) -> 0.33333333 | U25: =IF(AND(E25>=Controls!$B$40,G25>=Controls!$B$41),"Yes","No") -> Yes | V25: =IF(E25+Controls!$B$42=0,0,E25/(E25+Controls!$B$42)) -> 0.090909091 | W25: =IF(L25="",$C$10,V25*L25+(1-V25)*$C$10) -> 0.41181818 | X25: =IF(OR($C$10="",$C$10=0),"",W25/$C$10) -> 1.0044346 | Y25: =IF(U25="Yes",1,0) -> 1 | Z25: =IF(L25="",0,ABS(W25-$C$10)) -> 0.0018181818 | AA25: =IF(L25="","No","Yes") -> Yes
