Workbook

Sheet Deal
B1: UNDERWRITING TOOL
B2: DECISION | C2: =C62
B4: A. OFFER | J4: MONEYBADGER CROSS-CHECK
B5: Fund $ | C5: Factor | D5: =IF($E$6="Weekly","Term (weeks)","Term (daily pmts)") | E5: Freq | F5: Fee % | J5: Metric | K5: This tool | L5: MoneyBadger | M5: Diff
B6: 40000 | C6: 1.45 | D6: 24 | E6: Weekly | F6: 0.05 | J6: =IF($E$6="Weekly","Weekly remittance","Daily remittance") | K6: =IF(OR($E$6="",C8="",C24=0),"",IF($E$6="Weekly",D8,C8)) | L6: =IF(OR(L7="",C24=0),"",L7*C24/IF($E$6="Weekly",$L$8,$L$9)) | M6: =IF(OR(K6="",L6=""),"",L6-K6)
B7: Payback | C7: Daily $ | D7: Weekly $ | E7: Monthly $ | F7: Term (mo) | G7: Net $ | J7: Holdback % | K7: =IF(OR(D8="",C24=0),"",E8/C24) | L7: =IF(OR($E$6="",C8="",C24=0),"",ROUND(IF($E$6="Weekly",D8*$L$8,C8*$L$9)/C24*100,2)/100) | M7: =IF(OR(K7="",L7=""),"",L7-K7)
B8: =IF(OR(B6="",C6=""),"",B6*C6) | C8: =IF(OR(B8="",D6="",D6=0),"",IF(E6="Weekly",(B8/D6)/5,B8/D6)) | D8: =IF(C8="","",C8*5) | E8: =IF(C8="","",C8*$K$9) | F8: =IF(OR(D6="",D6=0),"",IF(E6="Weekly",D6,D6/5)/($K$9/5)) | G8: =IF(B6="","",B6-(B6*F6)) | J8: Weeks / month | K8: 4.331 | L8: 4 | M8: =IF(OR(K8="",L8=""),"",L8-K8)
J9: Days / month | K9: 21.655 | L9: 21 | M9: =IF(OR(K9="",L9=""),"",L9-K9)
B10: B. BANK DATA
B11: Month - NEWEST FIRST | C11: True rev $ | D11: Avg daily bal $ | E11: Neg days | F11: NSFs | G11: MoM % | J11: DEAL PROFILE
B12: Aug | C12: 88000 | D12: 7400 | E12: 0 | F12: 0 | G12: =IF(OR(C12="",C13=""),"",(C12-C13)/C13) | J12: ISO | K12: Fundwell | L12: =IF(K12="","",COUNTIF('Historical Data'!$K$2:$K$9,K12)&" deals in book")
B13: Jul | C13: 84000 | D13: 6900 | E13: 0 | F13: 1 | G13: =IF(OR(C13="",C14=""),"",(C13-C14)/C14) | J13: Industry | K13: Eating & Drinking Places | L13: =IF(K13="","",COUNTIF('Historical Data'!$Y$2:$Y$9,K13)&" deals in book")
B14: Jun | C14: 91000 | D14: 8100 | E14: 0 | F14: 0 | G14: =IF(OR(C14="",C15=""),"",(C14-C15)/C15) | J14: New deal or renewal | K14: New Deal
B15: May | C15: 82000 | D15: 6500 | E15: 1 | F15: 0 | G15: =IF(OR(C15="",C16=""),"",(C15-C16)/C16) | J15: Credit score | K15: 672 | L15: =IF(K15="","",IF(K15>=D45,"GREEN",IF(K15>=E45,"YELLOW","RED")))
G16: =IF(OR(C16="",C17=""),"",(C16-C17)/C17)
G17: =IF(OR(C17="",C18=""),"",(C17-C18)/C18)
G18: =IF(OR(C18="",C19=""),"",(C18-C19)/C19)
G19: =IF(OR(C19="",C20=""),"",(C19-C20)/C20)
G20: =IF(OR(C20="",C21=""),"",(C20-C21)/C21)
G21: =IF(OR(C21="",C22=""),"",(C21-C22)/C22)
G22: =IF(OR(C22="",C23=""),"",(C22-C23)/C23)
B24: AVG / TOTAL (months entered) | C24: =IF(COUNT(C12:C23)=0,0,AVERAGE(C12:C23)) | D24: =IF(COUNT(D12:D23)=0,0,AVERAGE(D12:D23)) | E24: =SUM(E12:E23) | F24: =SUM(F12:F23) | G24: =IFERROR(AVERAGE(G12:G22),"")
B26: EXISTING POSITIONS
B27: Funder | C27: Funded $ | D27: Payment | E27: Freq | F27: Daily equiv | G27: Start Date | H27: Est Term | I27: Est term (mo) | J27: Mo. remaining
C28: 100000 | D28: 3000 | E28: Weekly | F28: =IF(D28<>"",IF(E28="Daily",D28,IF(E28="Weekly",D28/5,D28/$K$9)),IF(C28="","",C28*Controls!$B$17/(Controls!$B$9*$K$9))) | G28: 46127 | H28: =IF(OR(C28="",D28=""),"",ROUND(C28*Controls!$B$17/D28,0)) | I28: =IF(H28="","",H28/IF(E28="Daily",$K$9,IF(E28="Weekly",$K$9/5,1))) | J28: =IF(OR(I28="",G28=""),"",MAX(0,I28-(TODAY()-G28)/Controls!$B$16))
E29: Weekly | F29: =IF(D29<>"",IF(E29="Daily",D29,IF(E29="Weekly",D29/5,D29/$K$9)),IF(C29="","",C29*Controls!$B$17/(Controls!$B$9*$K$9))) | H29: =IF(OR(C29="",D29=""),"",ROUND(C29*Controls!$B$17/D29,0)) | I29: =IF(H29="","",H29/IF(E29="Daily",$K$9,IF(E29="Weekly",$K$9/5,1))) | J29: =IF(OR(I29="",G29=""),"",MAX(0,I29-(TODAY()-G29)/Controls!$B$16))
E30: Weekly | F30: =IF(D30<>"",IF(E30="Daily",D30,IF(E30="Weekly",D30/5,D30/$K$9)),IF(C30="","",C30*Controls!$B$17/(Controls!$B$9*$K$9))) | H30: =IF(OR(C30="",D30=""),"",ROUND(C30*Controls!$B$17/D30,0)) | I30: =IF(H30="","",H30/IF(E30="Daily",$K$9,IF(E30="Weekly",$K$9/5,1))) | J30: =IF(OR(I30="",G30=""),"",MAX(0,I30-(TODAY()-G30)/Controls!$B$16))
E31: Weekly | F31: =IF(D31<>"",IF(E31="Daily",D31,IF(E31="Weekly",D31/5,D31/$K$9)),IF(C31="","",C31*Controls!$B$17/(Controls!$B$9*$K$9))) | H31: =IF(OR(C31="",D31=""),"",ROUND(C31*Controls!$B$17/D31,0)) | I31: =IF(H31="","",H31/IF(E31="Daily",$K$9,IF(E31="Weekly",$K$9/5,1))) | J31: =IF(OR(I31="",G31=""),"",MAX(0,I31-(TODAY()-G31)/Controls!$B$16))
E32: Weekly | F32: =IF(D32<>"",IF(E32="Daily",D32,IF(E32="Weekly",D32/5,D32/$K$9)),IF(C32="","",C32*Controls!$B$17/(Controls!$B$9*$K$9))) | H32: =IF(OR(C32="",D32=""),"",ROUND(C32*Controls!$B$17/D32,0)) | I32: =IF(H32="","",H32/IF(E32="Daily",$K$9,IF(E32="Weekly",$K$9/5,1))) | J32: =IF(OR(I32="",G32=""),"",MAX(0,I32-(TODAY()-G32)/Controls!$B$16))
E33: Weekly | F33: =IF(D33<>"",IF(E33="Daily",D33,IF(E33="Weekly",D33/5,D33/$K$9)),IF(C33="","",C33*Controls!$B$17/(Controls!$B$9*$K$9))) | H33: =IF(OR(C33="",D33=""),"",ROUND(C33*Controls!$B$17/D33,0)) | I33: =IF(H33="","",H33/IF(E33="Daily",$K$9,IF(E33="Weekly",$K$9/5,1))) | J33: =IF(OR(I33="",G33=""),"",MAX(0,I33-(TODAY()-G33)/Controls!$B$16))
B34: Positions (excl. Monthly) | C34: =SUMPRODUCT(((C28:C33<>"")+(D28:D33<>"")>0)*(E28:E33<>"Monthly")) | D34: Total existing daily | E34: =SUM(F28:F33) | F34: =E34*$K$9 | G34: /month
B36: C. METRICS
B37: Metric | C37: Value | D37: Green | E37: Red | F37: Status | G37: Knockout | H37: Sizing line
B38: Total LVG (all debt / rev) | C38: =IF(C24=0,"",(E34+IF(C8="",0,C8))*$K$9/C24) | D38: 0.3 | E38: 0.45 | F38: =IF(C38="","",IF(C38>=G38,"KNOCKOUT",IF(C38<=D38,"GREEN",IF(C38>=E38,"RED","YELLOW")))) | G38: 0.55 | H38: =D38+'Historical Score'!$C$35*(E38-D38)
B39: New holdback SP% | C39: =IF(OR(C24=0,E8=""),"",E8/C24) | D39: 0.18 | E39: 0.25 | F39: =IF(C39="","",IF(C39>=G39,"KNOCKOUT",IF(C39<=D39,"GREEN",IF(C39>=E39,"RED","YELLOW")))) | G39: 0.35 | H39: =D39+'Historical Score'!$C$35*(E39-D39)
B40: Daily debt / balance | C40: =IF(D24=0,"",(E34+IF(C8="",0,C8))/D24) | D40: 0.18 | E40: 0.3 | F40: =IF(C40="","",IF(C40>=G40,"KNOCKOUT",IF(C40<=D40,"GREEN",IF(C40>=E40,"RED","YELLOW")))) | G40: 0.35 | H40: =D40+'Historical Score'!$C$35*(E40-D40)
B41: Fund / revenue | C41: =IF(OR(C24=0,B6=""),"",B6/C24) | D41: 0.6 | E41: 0.9 | F41: =IF(C41="","",IF(C41>=G41,"KNOCKOUT",IF(C41<=D41,"GREEN",IF(C41>=E41,"RED","YELLOW")))) | G41: 1.25 | H41: =D41+'Historical Score'!$C$35*(E41-D41)
B42: # positions (incl. new) | C42: =IF(C24=0,"",C34+1) | D42: 2 | E42: 5 | F42: =IF(C42="","",IF(C42>=G42,"KNOCKOUT",IF(C42<=D42,"GREEN",IF(C42>=E42,"RED","YELLOW")))) | G42: 6
B43: Revenue trend (avg MoM) | C43: =G24 | D43: -0.05 | E43: -0.15 | F43: =IF(C24=0,"",IF(NOT(ISNUMBER(C43)),"YELLOW",IF(C43<=G43,"KNOCKOUT",IF(C43>=D43,"GREEN",IF(C43<=E43,"RED","YELLOW"))))) | G43: -0.3
B44: Neg days + NSFs (total) | C44: =E24+F24 | D44: 1 | E44: 6 | F44: =IF(C44="","",IF(C44>=G44,"KNOCKOUT",IF(C44<=D44,"GREEN",IF(C44>=E44,"RED","YELLOW")))) | G44: 10
...

Sheet Historical Score
A1: HISTORICAL SCORE
A2: Seasoned = age >= multiple x contracted term OR the deal reached a terminal status (Closed family, Written-Off, Bankruptcy, Settlement). SIDE NOTE: a blend rate and a credibility factor are under consideration; not built.
A4: DEAL BEING MATCHED
B5: New deal or renewal | C5: =IF(Deal!$K$14="","",Deal!$K$14)
B6: Position (Deal C42) | C6: =IF(Deal!$C$42="","",Deal!$C$42)
B7: Industry | C7: =IF(Deal!$K$13="","",Deal!$K$13)
B8: ISO | C8: =IF(Deal!$K$12="","",Deal!$K$12)
B10: Seasoned-book principal lost rate | C10: =IF($F$21="",0,$F$21)
B11: Seasoned-book return on funded | C11: =IF($G$21="",0,$G$21)
B13: Cohort | C13: Seasoned deals | D13: Funded $ (seasoned) | E13: Meets min? | F13: Principal lost rate | G13: Return on funded | H13: Index
B14: New/renewal + ISO + industry | C14: =SUMPRODUCT('Historical Data'!$AU$2:$AU$9*'Historical Data'!$AP$2:$AP$9) | D14: =SUMPRODUCT('Historical Data'!$AU$2:$AU$9*'Historical Data'!$AP$2:$AP$9*'Historical Data'!$N$2:$N$9) | E14: =IF(AND(C14>=Controls!$B$24,D14>=Controls!$B$25),"Yes","No") | F14: =IF(D14=0,"",SUMPRODUCT('Historical Data'!$AU$2:$AU$9*'Historical Data'!$AP$2:$AP$9*'Historical Data'!$AK$2:$AK$9)/D14) | G14: =IF(D14=0,"",SUMPRODUCT('Historical Data'!$AU$2:$AU$9*'Historical Data'!$AP$2:$AP$9*'Historical Data'!$AJ$2:$AJ$9)/D14) | H14: =IF(OR(F14="",$C$10=0),"",F14/$C$10)
B15: New/renewal + industry + position | C15: =SUMPRODUCT('Historical Data'!$AV$2:$AV$9*'Historical Data'!$AP$2:$AP$9) | D15: =SUMPRODUCT('Historical Data'!$AV$2:$AV$9*'Historical Data'!$AP$2:$AP$9*'Historical Data'!$N$2:$N$9) | E15: =IF(AND(C15>=Controls!$B$24,D15>=Controls!$B$25),"Yes","No") | F15: =IF(D15=0,"",SUMPRODUCT('Historical Data'!$AV$2:$AV$9*'Historical Data'!$AP$2:$AP$9*'Historical Data'!$AK$2:$AK$9)/D15) | G15: =IF(D15=0,"",SUMPRODUCT('Historical Data'!$AV$2:$AV$9*'Historical Data'!$AP$2:$AP$9*'Historical Data'!$AJ$2:$AJ$9)/D15) | H15: =IF(OR(F15="",$C$10=0),"",F15/$C$10)
B16: New/renewal + ISO + position | C16: =SUMPRODUCT('Historical Data'!$AW$2:$AW$9*'Historical Data'!$AP$2:$AP$9) | D16: =SUMPRODUCT('Historical Data'!$AW$2:$AW$9*'Historical Data'!$AP$2:$AP$9*'Historical Data'!$N$2:$N$9) | E16: =IF(AND(C16>=Controls!$B$24,D16>=Controls!$B$25),"Yes","No") | F16: =IF(D16=0,"",SUMPRODUCT('Historical Data'!$AW$2:$AW$9*'Historical Data'!$AP$2:$AP$9*'Historical Data'!$AK$2:$AK$9)/D16) | G16: =IF(D16=0,"",SUMPRODUCT('Historical Data'!$AW$2:$AW$9*'Historical Data'!$AP$2:$AP$9*'Historical Data'!$AJ$2:$AJ$9)/D16) | H16: =IF(OR(F16="",$C$10=0),"",F16/$C$10)
B17: New/renewal + industry | C17: =SUMPRODUCT('Historical Data'!$AX$2:$AX$9*'Historical Data'!$AP$2:$AP$9) | D17: =SUMPRODUCT('Historical Data'!$AX$2:$AX$9*'Historical Data'!$AP$2:$AP$9*'Historical Data'!$N$2:$N$9) | E17: =IF(AND(C17>=Controls!$B$24,D17>=Controls!$B$25),"Yes","No") | F17: =IF(D17=0,"",SUMPRODUCT('Historical Data'!$AX$2:$AX$9*'Historical Data'!$AP$2:$AP$9*'Historical Data'!$AK$2:$AK$9)/D17) | G17: =IF(D17=0,"",SUMPRODUCT('Historical Data'!$AX$2:$AX$9*'Historical Data'!$AP$2:$AP$9*'Historical Data'!$AJ$2:$AJ$9)/D17) | H17: =IF(OR(F17="",$C$10=0),"",F17/$C$10)
B18: New/renewal + ISO | C18: =SUMPRODUCT('Historical Data'!$AY$2:$AY$9*'Historical Data'!$AP$2:$AP$9) | D18: =SUMPRODUCT('Historical Data'!$AY$2:$AY$9*'Historical Data'!$AP$2:$AP$9*'Historical Data'!$N$2:$N$9) | E18: =IF(AND(C18>=Controls!$B$24,D18>=Controls!$B$25),"Yes","No") | F18: =IF(D18=0,"",SUMPRODUCT('Historical Data'!$AY$2:$AY$9*'Historical Data'!$AP$2:$AP$9*'Historical Data'!$AK$2:$AK$9)/D18) | G18: =IF(D18=0,"",SUMPRODUCT('Historical Data'!$AY$2:$AY$9*'Historical Data'!$AP$2:$AP$9*'Historical Data'!$AJ$2:$AJ$9)/D18) | H18: =IF(OR(F18="",$C$10=0),"",F18/$C$10)
B19: New/renewal + position | C19: =SUMPRODUCT('Historical Data'!$AZ$2:$AZ$9*'Historical Data'!$AP$2:$AP$9) | D19: =SUMPRODUCT('Historical Data'!$AZ$2:$AZ$9*'Historical Data'!$AP$2:$AP$9*'Historical Data'!$N$2:$N$9) | E19: =IF(AND(C19>=Controls!$B$24,D19>=Controls!$B$25),"Yes","No") | F19: =IF(D19=0,"",SUMPRODUCT('Historical Data'!$AZ$2:$AZ$9*'Historical Data'!$AP$2:$AP$9*'Historical Data'!$AK$2:$AK$9)/D19) | G19: =IF(D19=0,"",SUMPRODUCT('Historical Data'!$AZ$2:$AZ$9*'Historical Data'!$AP$2:$AP$9*'Historical Data'!$AJ$2:$AJ$9)/D19) | H19: =IF(OR(F19="",$C$10=0),"",F19/$C$10)
B20: New/renewal only | C20: =SUMPRODUCT('Historical Data'!$AR$2:$AR$9*'Historical Data'!$AP$2:$AP$9) | D20: =SUMPRODUCT('Historical Data'!$AR$2:$AR$9*'Historical Data'!$AP$2:$AP$9*'Historical Data'!$N$2:$N$9) | E20: =IF(AND(C20>=Controls!$B$24,D20>=Controls!$B$25),"Yes","No") | F20: =IF(D20=0,"",SUMPRODUCT('Historical Data'!$AR$2:$AR$9*'Historical Data'!$AP$2:$AP$9*'Historical Data'!$AK$2:$AK$9)/D20) | G20: =IF(D20=0,"",SUMPRODUCT('Historical Data'!$AR$2:$AR$9*'Historical Data'!$AP$2:$AP$9*'Historical Data'!$AJ$2:$AJ$9)/D20) | H20: =IF(OR(F20="",$C$10=0),"",F20/$C$10)
B21: Whole seasoned book | C21: =SUMPRODUCT('Historical Data'!$AP$2:$AP$9) | D21: =SUMPRODUCT('Historical Data'!$AP$2:$AP$9*'Historical Data'!$N$2:$N$9) | E21: =IF(AND(C21>=Controls!$B$24,D21>=Controls!$B$25),"Yes","No") | F21: =IF(D21=0,"",SUMPRODUCT('Historical Data'!$AP$2:$AP$9*'Historical Data'!$AK$2:$AK$9)/D21) | G21: =IF(D21=0,"",SUMPRODUCT('Historical Data'!$AP$2:$AP$9*'Historical Data'!$AJ$2:$AJ$9)/D21) | H21: =IF(OR(F21="",$C$10=0),"",F21/$C$10)
B22: SINGLE-DIMENSION EVIDENCE (feeds C2 on the Deal sheet; does not pick the cohort) | I22: |PLR - book|
B23: Position only | C23: =SUMPRODUCT('Historical Data'!$AQ$2:$AQ$9*'Historical Data'!$AP$2:$AP$9) | D23: =SUMPRODUCT('Historical Data'!$AQ$2:$AQ$9*'Historical Data'!$AP$2:$AP$9*'Historical Data'!$N$2:$N$9) | E23: =IF(AND(C23>=Controls!$B$24,D23>=Controls!$B$25),"Yes","No") | F23: =IF(D23=0,"",SUMPRODUCT('Historical Data'!$AQ$2:$AQ$9*'Historical Data'!$AP$2:$AP$9*'Historical Data'!$AK$2:$AK$9)/D23) | G23: =IF(D23=0,"",SUMPRODUCT('Historical Data'!$AQ$2:$AQ$9*'Historical Data'!$AP$2:$AP$9*'Historical Data'!$AJ$2:$AJ$9)/D23) | H23: =IF(OR(F23="",$C$10=0),"",F23/$C$10) | I23: =IF(F23="",0,ABS(F23-$C$10))
B24: New/renewal only | C24: =SUMPRODUCT('Historical Data'!$AR$2:$AR$9*'Historical Data'!$AP$2:$AP$9) | D24: =SUMPRODUCT('Historical Data'!$AR$2:$AR$9*'Historical Data'!$AP$2:$AP$9*'Historical Data'!$N$2:$N$9) | E24: =IF(AND(C24>=Controls!$B$24,D24>=Controls!$B$25),"Yes","No") | F24: =IF(D24=0,"",SUMPRODUCT('Historical Data'!$AR$2:$AR$9*'Historical Data'!$AP$2:$AP$9*'Historical Data'!$AK$2:$AK$9)/D24) | G24: =IF(D24=0,"",SUMPRODUCT('Historical Data'!$AR$2:$AR$9*'Historical Data'!$AP$2:$AP$9*'Historical Data'!$AJ$2:$AJ$9)/D24) | H24: =IF(OR(F24="",$C$10=0),"",F24/$C$10) | I24: =IF(F24="",0,ABS(F24-$C$10))
B25: Industry only | C25: =SUMPRODUCT('Historical Data'!$AS$2:$AS$9*'Historical Data'!$AP$2:$AP$9) | D25: =SUMPRODUCT('Historical Data'!$AS$2:$AS$9*'Historical Data'!$AP$2:$AP$9*'Historical Data'!$N$2:$N$9) | E25: =IF(AND(C25>=Controls!$B$24,D25>=Controls!$B$25),"Yes","No") | F25: =IF(D25=0,"",SUMPRODUCT('Historical Data'!$AS$2:$AS$9*'Historical Data'!$AP$2:$AP$9*'Historical Data'!$AK$2:$AK$9)/D25) | G25: =IF(D25=0,"",SUMPRODUCT('Historical Data'!$AS$2:$AS$9*'Historical Data'!$AP$2:$AP$9*'Historical Data'!$AJ$2:$AJ$9)/D25) | H25: =IF(OR(F25="",$C$10=0),"",F25/$C$10) | I25: =IF(F25="",0,ABS(F25-$C$10))
B26: ISO only | C26: =SUMPRODUCT('Historical Data'!$AT$2:$AT$9*'Historical Data'!$AP$2:$AP$9) | D26: =SUMPRODUCT('Historical Data'!$AT$2:$AT$9*'Historical Data'!$AP$2:$AP$9*'Historical Data'!$N$2:$N$9) | E26: =IF(AND(C26>=Controls!$B$24,D26>=Controls!$B$25),"Yes","No") | F26: =IF(D26=0,"",SUMPRODUCT('Historical Data'!$AT$2:$AT$9*'Historical Data'!$AP$2:$AP$9*'Historical Data'!$AK$2:$AK$9)/D26) | G26: =IF(D26=0,"",SUMPRODUCT('Historical Data'!$AT$2:$AT$9*'Historical Data'!$AP$2:$AP$9*'Historical Data'!$AJ$2:$AJ$9)/D26) | H26: =IF(OR(F26="",$C$10=0),"",F26/$C$10) | I26: =IF(F26="",0,ABS(F26-$C$10))
A28: RESULT
B29: Primary cohort (lowest row that meets both minimums) | C29: =IF($D$29="","- no deal entered -",INDEX($B$14:$B$21,$D$29)) | D29: =IF($C$5="","",IFERROR(MATCH("Yes",$E$14:$E$21,0),8)) | E29: row # (read by Historical Data)
B30: Seasoned deals in it | C30: =IF(OR($D$29="",$D$29=8),"",INDEX($C$14:$C$21,$D$29))
B31: Principal lost rate | C31: =IF(OR($D$29="",$D$29=8),"",INDEX($F$14:$F$21,$D$29))
B32: Return on funded | C32: =IF(OR($D$29="",$D$29=8),"",INDEX($G$14:$G$21,$D$29))
B33: Index (PLR / book PLR) | C33: =IF(OR($D$29="",$D$29=8),"",INDEX($H$14:$H$21,$D$29))
B34: HOUSE-BOOK OUTCOME | C34: =IF(OR($D$29="",$D$29=8,$C$33=""),"Neutral",IF($C$33<=Controls!$B$29,"Supportive",IF($C$33>Controls!$B$30,"Negative","Neutral")))
B35: Sizing flex applied (Supportive only) | C35: =IF(C34="Supportive",Controls!$B$31,0)
B36: Largest-impact variable | C36: =IF(MAX($I$23:$I$26)=0,"none rated",_xlfn._xlws.XLOOKUP(MAX($I$23:$I$26),$I$23:$I$26,$B$23:$B$26))

Sheet Comparable Deals
A1: COMPARABLE DEALS
A4: Contract ID | B4: DBA | C4: Status | D4: Funded | E4: Position | F4: Industry | G4: ISO | H4: New/renewal | I4: Factor | J4: Advance | K4: Collected | L4: % paid | M4: Net cash | N4: Principal lost | O4: Term (bd) | P4: Age (bd) | Q4: Days on book | R4: Seasoned | S4: Default | T4: Open | U4: In primary cohort
A5: ='Historical Data'!A2 | B5: ='Historical Data'!B2 | C5: ='Historical Data'!D2 | D5: ='Historical Data'!E2 | E5: ='Historical Data'!G2 | F5: ='Historical Data'!Y2 | G5: ='Historical Data'!K2 | H5: ='Historical Data'!L2 | I5: ='Historical Data'!M2 | J5: ='Historical Data'!N2 | K5: ='Historical Data'!Q2 | L5: ='Historical Data'!S2 | M5: ='Historical Data'!AJ2 | N5: ='Historical Data'!AK2 | O5: ='Historical Data'!AA2 | P5: ='Historical Data'!AB2 | Q5: ='Historical Data'!AN2 | R5: ='Historical Data'!AC2 | S5: ='Historical Data'!AE2 | T5: ='Historical Data'!AH2 | U5: ='Historical Data'!BB2
A6: ='Historical Data'!A3 | B6: ='Historical Data'!B3 | C6: ='Historical Data'!D3 | D6: ='Historical Data'!E3 | E6: ='Historical Data'!G3 | F6: ='Historical Data'!Y3 | G6: ='Historical Data'!K3 | H6: ='Historical Data'!L3 | I6: ='Historical Data'!M3 | J6: ='Historical Data'!N3 | K6: ='Historical Data'!Q3 | L6: ='Historical Data'!S3 | M6: ='Historical Data'!AJ3 | N6: ='Historical Data'!AK3 | O6: ='Historical Data'!AA3 | P6: ='Historical Data'!AB3 | Q6: ='Historical Data'!AN3 | R6: ='Historical Data'!AC3 | S6: ='Historical Data'!AE3 | T6: ='Historical Data'!AH3 | U6: ='Historical Data'!BB3
A7: ='Historical Data'!A4 | B7: ='Historical Data'!B4 | C7: ='Historical Data'!D4 | D7: ='Historical Data'!E4 | E7: ='Historical Data'!G4 | F7: ='Historical Data'!Y4 | G7: ='Historical Data'!K4 | H7: ='Historical Data'!L4 | I7: ='Historical Data'!M4 | J7: ='Historical Data'!N4 | K7: ='Historical Data'!Q4 | L7: ='Historical Data'!S4 | M7: ='Historical Data'!AJ4 | N7: ='Historical Data'!AK4 | O7: ='Historical Data'!AA4 | P7: ='Historical Data'!AB4 | Q7: ='Historical Data'!AN4 | R7: ='Historical Data'!AC4 | S7: ='Historical Data'!AE4 | T7: ='Historical Data'!AH4 | U7: ='Historical Data'!BB4
A8: ='Historical Data'!A5 | B8: ='Historical Data'!B5 | C8: ='Historical Data'!D5 | D8: ='Historical Data'!E5 | E8: ='Historical Data'!G5 | F8: ='Historical Data'!Y5 | G8: ='Historical Data'!K5 | H8: ='Historical Data'!L5 | I8: ='Historical Data'!M5 | J8: ='Historical Data'!N5 | K8: ='Historical Data'!Q5 | L8: ='Historical Data'!S5 | M8: ='Historical Data'!AJ5 | N8: ='Historical Data'!AK5 | O8: ='Historical Data'!AA5 | P8: ='Historical Data'!AB5 | Q8: ='Historical Data'!AN5 | R8: ='Historical Data'!AC5 | S8: ='Historical Data'!AE5 | T8: ='Historical Data'!AH5 | U8: ='Historical Data'!BB5
A9: ='Historical Data'!A6 | B9: ='Historical Data'!B6 | C9: ='Historical Data'!D6 | D9: ='Historical Data'!E6 | E9: ='Historical Data'!G6 | F9: ='Historical Data'!Y6 | G9: ='Historical Data'!K6 | H9: ='Historical Data'!L6 | I9: ='Historical Data'!M6 | J9: ='Historical Data'!N6 | K9: ='Historical Data'!Q6 | L9: ='Historical Data'!S6 | M9: ='Historical Data'!AJ6 | N9: ='Historical Data'!AK6 | O9: ='Historical Data'!AA6 | P9: ='Historical Data'!AB6 | Q9: ='Historical Data'!AN6 | R9: ='Historical Data'!AC6 | S9: ='Historical Data'!AE6 | T9: ='Historical Data'!AH6 | U9: ='Historical Data'!BB6
A10: ='Historical Data'!A7 | B10: ='Historical Data'!B7 | C10: ='Historical Data'!D7 | D10: ='Historical Data'!E7 | E10: ='Historical Data'!G7 | F10: ='Historical Data'!Y7 | G10: ='Historical Data'!K7 | H10: ='Historical Data'!L7 | I10: ='Historical Data'!M7 | J10: ='Historical Data'!N7 | K10: ='Historical Data'!Q7 | L10: ='Historical Data'!S7 | M10: ='Historical Data'!AJ7 | N10: ='Historical Data'!AK7 | O10: ='Historical Data'!AA7 | P10: ='Historical Data'!AB7 | Q10: ='Historical Data'!AN7 | R10: ='Historical Data'!AC7 | S10: ='Historical Data'!AE7 | T10: ='Historical Data'!AH7 | U10: ='Historical Data'!BB7
A11: ='Historical Data'!A8 | B11: ='Historical Data'!B8 | C11: ='Historical Data'!D8 | D11: ='Historical Data'!E8 | E11: ='Historical Data'!G8 | F11: ='Historical Data'!Y8 | G11: ='Historical Data'!K8 | H11: ='Historical Data'!L8 | I11: ='Historical Data'!M8 | J11: ='Historical Data'!N8 | K11: ='Historical Data'!Q8 | L11: ='Historical Data'!S8 | M11: ='Historical Data'!AJ8 | N11: ='Historical Data'!AK8 | O11: ='Historical Data'!AA8 | P11: ='Historical Data'!AB8 | Q11: ='Historical Data'!AN8 | R11: ='Historical Data'!AC8 | S11: ='Historical Data'!AE8 | T11: ='Historical Data'!AH8 | U11: ='Historical Data'!BB8
A12: ='Historical Data'!A9 | B12: ='Historical Data'!B9 | C12: ='Historical Data'!D9 | D12: ='Historical Data'!E9 | E12: ='Historical Data'!G9 | F12: ='Historical Data'!Y9 | G12: ='Historical Data'!K9 | H12: ='Historical Data'!L9 | I12: ='Historical Data'!M9 | J12: ='Historical Data'!N9 | K12: ='Historical Data'!Q9 | L12: ='Historical Data'!S9 | M12: ='Historical Data'!AJ9 | N12: ='Historical Data'!AK9 | O12: ='Historical Data'!AA9 | P12: ='Historical Data'!AB9 | Q12: ='Historical Data'!AN9 | R12: ='Historical Data'!AC9 | S12: ='Historical Data'!AE9 | T12: ='Historical Data'!AH9 | U12: ='Historical Data'!BB9

Sheet Historical Data
A1: Contract ID | B1: DBA | C1: Legal name | D1: Status | E1: Start date | F1: Last active | G1: Position | H1: SIC | I1: SIC2 | J1: State | K1: ISO | L1: New or renewal | M1: Factor | N1: Advance | O1: Commission | P1: Payback | Q1: Collected | R1: Balance | S1: % paid | T1: Exp dur (raw) | U1: NSF count | V1: Avg rev/mo | W1: Holdback % | X1: Biz start | Y1: Industry | Z1: Pay frequency | AA1: Term (bus. days) | AB1: Age at as-of (bus. days) | AC1: Seasoned | AD1: In window | AE1: Default | AF1: Resolved | AG1: Closed family | AH1: Open | AI1: Status valid | AJ1: Net cash | AK1: Principal lost | AL1: Adv / revenue | AM1: Has revenue | AN1: Days on book (bus.) | AO1: Renewal | AP1: Eligible (seasoned & in window) | AQ1: m: position | AR1: m: new/renewal | AS1: m: industry | AT1: m: ISO | AU1: NR+ISO+Ind | AV1: NR+Ind+Pos | AW1: NR+ISO+Pos | AX1: NR+Ind | AY1: NR+ISO | AZ1: NR+Pos | BA1: In primary cohort
A2: A-001 | B2: Ridgeline Cafe | C2: Ridgeline Cafe LLC | D2: Closed | E2: 45672 | F2: 45821 | G2: 1 | H2: 5812 | I2: 58 | J2: NJ | K2: Fundwell | L2: New Deal | M2: 1.5 | N2: 10000 | O2: 1000 | P2: 15000 | Q2: 15000 | R2: 0 | S2: 1 | T2: 5 | U2: 0 | V2: 50000 | W2: 0.12 | X2: 43160 | Y2: =IF(I2="","No SIC",IFERROR(VLOOKUP(I2,Ref!$A$2:$B$65,2,FALSE()),"Unclassified")) | Z2: =IF(T2="","",IF(T2<12,"Daily","Weekly")) | AA2: =IF(T2="",0,IF(T2<12,T2*Controls!$B$13,T2*5)) | AB2: =IF(E2="",0,NETWORKDAYS(E2,Controls!$B$20,Ref!$K$2:$K$42)) | AC2: =IF(OR(AF2=1,AND(AA2>0,AB2>=Controls!$B$23*AA2)),1,0) | AD2: =IF(AND(E2<>"",E2>=Controls!$B$21,E2<=Controls!$B$22),1,0) | AE2: =IF(IFERROR(VLOOKUP(D2,Controls!$A$36:$E$46,2,FALSE()),"No")="Yes",1,0) | AF2: =IF(IFERROR(VLOOKUP(D2,Controls!$A$36:$E$46,3,FALSE()),"No")="Yes",1,0) | AG2: =IF(IFERROR(VLOOKUP(D2,Controls!$A$36:$E$46,4,FALSE()),"No")="Yes",1,0) | AH2: =IF(IFERROR(VLOOKUP(D2,Controls!$A$36:$E$46,5,FALSE()),"No")="Yes",1,0) | AI2: =IF(ISNUMBER(MATCH(D2,Controls!$A$36:$A$46,0)),1,0) | AJ2: =Q2-N2 | AK2: =IF(AE2=1,MAX(0,N2-Q2),0) | AL2: =IF(OR(V2="",V2=0),0,N2/V2) | AM2: =IF(OR(V2="",V2=0),0,1) | AN2: =IF(OR(E2="",F2=""),0,NETWORKDAYS(E2,F2,Ref!$K$2:$K$42)) | AO2: =IF(L2="Renewal",1,0) | AP2: =AC2*AD2 | AQ2: =IF(AND(G2<>"",'Historical Score'!$C$6<>""),IF(G2='Historical Score'!$C$6,1,0),0) | AR2: =IF(AND(L2<>"",'Historical Score'!$C$5<>""),IF(L2='Historical Score'!$C$5,1,0),0) | AS2: =IF(AND(Y2<>"",'Historical Score'!$C$7<>""),IF(Y2='Historical Score'!$C$7,1,0),0) | AT2: =IF(AND(K2<>"",'Historical Score'!$C$8<>""),IF(K2='Historical Score'!$C$8,1,0),0) | AU2: =AR2*AT2*AS2 | AV2: =AR2*AS2*AQ2 | AW2: =AR2*AT2*AQ2 | AX2: =AR2*AS2 | AY2: =AR2*AT2 | AZ2: =AR2*AQ2 | BA2: =IF(OR(AD2=0,'Historical Score'!$D$29=""),0,CHOOSE('Historical Score'!$D$29,AU2,AV2,AW2,AX2,AY2,AZ2,AR2,1))
A3: A-002 | B3: Delta Freight | C3: Delta Freight Group LLC | D3: Closed | E3: 45698 | F3: 45848 | G3: 2 | H3: 4213 | I3: 42 | J3: TX | K3: Westwood | L3: Renewal | M3: 1.5 | N3: 20000 | O3: 2000 | P3: 30000 | Q3: 30000 | R3: 0 | S3: 1 | T3: 20 | U3: 0 | V3: 100000 | W3: 0.09 | X3: 42170 | Y3: =IF(I3="","No SIC",IFERROR(VLOOKUP(I3,Ref!$A$2:$B$65,2,FALSE()),"Unclassified")) | Z3: =IF(T3="","",IF(T3<12,"Daily","Weekly")) | AA3: =IF(T3="",0,IF(T3<12,T3*Controls!$B$13,T3*5)) | AB3: =IF(E3="",0,NETWORKDAYS(E3,Controls!$B$20,Ref!$K$2:$K$42)) | AC3: =IF(OR(AF3=1,AND(AA3>0,AB3>=Controls!$B$23*AA3)),1,0) | AD3: =IF(AND(E3<>"",E3>=Controls!$B$21,E3<=Controls!$B$22),1,0) | AE3: =IF(IFERROR(VLOOKUP(D3,Controls!$A$36:$E$46,2,FALSE()),"No")="Yes",1,0) | AF3: =IF(IFERROR(VLOOKUP(D3,Controls!$A$36:$E$46,3,FALSE()),"No")="Yes",1,0) | AG3: =IF(IFERROR(VLOOKUP(D3,Controls!$A$36:$E$46,4,FALSE()),"No")="Yes",1,0) | AH3: =IF(IFERROR(VLOOKUP(D3,Controls!$A$36:$E$46,5,FALSE()),"No")="Yes",1,0) | AI3: =IF(ISNUMBER(MATCH(D3,Controls!$A$36:$A$46,0)),1,0) | AJ3: =Q3-N3 | AK3: =IF(AE3=1,MAX(0,N3-Q3),0) | AL3: =IF(OR(V3="",V3=0),0,N3/V3) | AM3: =IF(OR(V3="",V3=0),0,1) | AN3: =IF(OR(E3="",F3=""),0,NETWORKDAYS(E3,F3,Ref!$K$2:$K$42)) | AO3: =IF(L3="Renewal",1,0) | AP3: =AC3*AD3 | AQ3: =IF(AND(G3<>"",'Historical Score'!$C$6<>""),IF(G3='Historical Score'!$C$6,1,0),0) | AR3: =IF(AND(L3<>"",'Historical Score'!$C$5<>""),IF(L3='Historical Score'!$C$5,1,0),0) | AS3: =IF(AND(Y3<>"",'Historical Score'!$C$7<>""),IF(Y3='Historical Score'!$C$7,1,0),0) | AT3: =IF(AND(K3<>"",'Historical Score'!$C$8<>""),IF(K3='Historical Score'!$C$8,1,0),0) | AU3: =AR3*AT3*AS3 | AV3: =AR3*AS3*AQ3 | AW3: =AR3*AT3*AQ3 | AX3: =AR3*AS3 | AY3: =AR3*AT3 | AZ3: =AR3*AQ3 | BA3: =IF(OR(AD3=0,'Historical Score'!$D$29=""),0,CHOOSE('Historical Score'!$D$29,AU3,AV3,AW3,AX3,AY3,AZ3,AR3,1))
A4: A-003 | B4: Kane Construction | C4: Kane Construction Inc | D4: Legal | E4: 45721 | F4: 45813 | G4: 3 | H4: 1542 | I4: 15 | J4: NJ | K4: Fundwell | L4: New Deal | M4: 1.5 | N4: 30000 | O4: 3000 | P4: 45000 | Q4: 9000 | R4: 36000 | S4: 0.2 | T4: 6 | U4: 4 | V4: 60000 | W4: 0.15 | X4: 43840 | Y4: =IF(I4="","No SIC",IFERROR(VLOOKUP(I4,Ref!$A$2:$B$65,2,FALSE()),"Unclassified")) | Z4: =IF(T4="","",IF(T4<12,"Daily","Weekly")) | AA4: =IF(T4="",0,IF(T4<12,T4*Controls!$B$13,T4*5)) | AB4: =IF(E4="",0,NETWORKDAYS(E4,Controls!$B$20,Ref!$K$2:$K$42)) | AC4: =IF(OR(AF4=1,AND(AA4>0,AB4>=Controls!$B$23*AA4)),1,0) | AD4: =IF(AND(E4<>"",E4>=Controls!$B$21,E4<=Controls!$B$22),1,0) | AE4: =IF(IFERROR(VLOOKUP(D4,Controls!$A$36:$E$46,2,FALSE()),"No")="Yes",1,0) | AF4: =IF(IFERROR(VLOOKUP(D4,Controls!$A$36:$E$46,3,FALSE()),"No")="Yes",1,0) | AG4: =IF(IFERROR(VLOOKUP(D4,Controls!$A$36:$E$46,4,FALSE()),"No")="Yes",1,0) | AH4: =IF(IFERROR(VLOOKUP(D4,Controls!$A$36:$E$46,5,FALSE()),"No")="Yes",1,0) | AI4: =IF(ISNUMBER(MATCH(D4,Controls!$A$36:$A$46,0)),1,0) | AJ4: =Q4-N4 | AK4: =IF(AE4=1,MAX(0,N4-Q4),0) | AL4: =IF(OR(V4="",V4=0),0,N4/V4) | AM4: =IF(OR(V4="",V4=0),0,1) | AN4: =IF(OR(E4="",F4=""),0,NETWORKDAYS(E4,F4,Ref!$K$2:$K$42)) | AO4: =IF(L4="Renewal",1,0) | AP4: =AC4*AD4 | AQ4: =IF(AND(G4<>"",'Historical Score'!$C$6<>""),IF(G4='Historical Score'!$C$6,1,0),0) | AR4: =IF(AND(L4<>"",'Historical Score'!$C$5<>""),IF(L4='Historical Score'!$C$5,1,0),0) | AS4: =IF(AND(Y4<>"",'Historical Score'!$C$7<>""),IF(Y4='Historical Score'!$C$7,1,0),0) | AT4: =IF(AND(K4<>"",'Historical Score'!$C$8<>""),IF(K4='Historical Score'!$C$8,1,0),0) | AU4: =AR4*AT4*AS4 | AV4: =AR4*AS4*AQ4 | AW4: =AR4*AT4*AQ4 | AX4: =AR4*AS4 | AY4: =AR4*AT4 | AZ4: =AR4*AQ4 | BA4: =IF(OR(AD4=0,'Historical Score'!$D$29=""),0,CHOOSE('Historical Score'!$D$29,AU4,AV4,AW4,AX4,AY4,AZ4,AR4,1))
A5: A-004 | B5: Baymont Auto Body | C5: Baymont Auto Body LLC | D5: In House Collection | E5: 45768 | F5: 45889 | G5: 3 | H5: 7538 | I5: 75 | J5: TX | K5: Westwood | L5: New Deal | M5: 1.5 | N5: 40000 | O5: 4000 | P5: 60000 | Q5: 20000 | R5: 40000 | S5: 0.33333333 | T5: 24 | U5: 7 | V5: 80000 | W5: 0.11 | X5: 41182 | Y5: =IF(I5="","No SIC",IFERROR(VLOOKUP(I5,Ref!$A$2:$B$65,2,FALSE()),"Unclassified")) | Z5: =IF(T5="","",IF(T5<12,"Daily","Weekly")) | AA5: =IF(T5="",0,IF(T5<12,T5*Controls!$B$13,T5*5)) | AB5: =IF(E5="",0,NETWORKDAYS(E5,Controls!$B$20,Ref!$K$2:$K$42)) | AC5: =IF(OR(AF5=1,AND(AA5>0,AB5>=Controls!$B$23*AA5)),1,0) | AD5: =IF(AND(E5<>"",E5>=Controls!$B$21,E5<=Controls!$B$22),1,0) | AE5: =IF(IFERROR(VLOOKUP(D5,Controls!$A$36:$E$46,2,FALSE()),"No")="Yes",1,0) | AF5: =IF(IFERROR(VLOOKUP(D5,Controls!$A$36:$E$46,3,FALSE()),"No")="Yes",1,0) | AG5: =IF(IFERROR(VLOOKUP(D5,Controls!$A$36:$E$46,4,FALSE()),"No")="Yes",1,0) | AH5: =IF(IFERROR(VLOOKUP(D5,Controls!$A$36:$E$46,5,FALSE()),"No")="Yes",1,0) | AI5: =IF(ISNUMBER(MATCH(D5,Controls!$A$36:$A$46,0)),1,0) | AJ5: =Q5-N5 | AK5: =IF(AE5=1,MAX(0,N5-Q5),0) | AL5: =IF(OR(V5="",V5=0),0,N5/V5) | AM5: =IF(OR(V5="",V5=0),0,1) | AN5: =IF(OR(E5="",F5=""),0,NETWORKDAYS(E5,F5,Ref!$K$2:$K$42)) | AO5: =IF(L5="Renewal",1,0) | AP5: =AC5*AD5 | AQ5: =IF(AND(G5<>"",'Historical Score'!$C$6<>""),IF(G5='Historical Score'!$C$6,1,0),0) | AR5: =IF(AND(L5<>"",'Historical Score'!$C$5<>""),IF(L5='Historical Score'!$C$5,1,0),0) | AS5: =IF(AND(Y5<>"",'Historical Score'!$C$7<>""),IF(Y5='Historical Score'!$C$7,1,0),0) | AT5: =IF(AND(K5<>"",'Historical Score'!$C$8<>""),IF(K5='Historical Score'!$C$8,1,0),0) | AU5: =AR5*AT5*AS5 | AV5: =AR5*AS5*AQ5 | AW5: =AR5*AT5*AQ5 | AX5: =AR5*AS5 | AY5: =AR5*AT5 | AZ5: =AR5*AQ5 | BA5: =IF(OR(AD5=0,'Historical Score'!$D$29=""),0,CHOOSE('Historical Score'!$D$29,AU5,AV5,AW5,AX5,AY5,AZ5,AR5,1))
A6: A-005 | B6: Sunset Nails | C6: Sunset Nails Corp | D6: Written-Off | E6: 45789 | F6: 45973 | G6: 2 | H6: 7231 | I6: 72 | J6: NJ | K6: Fundwell | L6: Renewal | M6: 1.5 | N6: 10000 | O6: 1000 | P6: 15000 | Q6: 9500 | R6: 5500 | S6: 0.63333333 | T6: 4 | U6: 2 | V6: 20000 | W6: 0.14 | X6: 43774 | Y6: =IF(I6="","No SIC",IFERROR(VLOOKUP(I6,Ref!$A$2:$B$65,2,FALSE()),"Unclassified")) | Z6: =IF(T6="","",IF(T6<12,"Daily","Weekly")) | AA6: =IF(T6="",0,IF(T6<12,T6*Controls!$B$13,T6*5)) | AB6: =IF(E6="",0,NETWORKDAYS(E6,Controls!$B$20,Ref!$K$2:$K$42)) | AC6: =IF(OR(AF6=1,AND(AA6>0,AB6>=Controls!$B$23*AA6)),1,0) | AD6: =IF(AND(E6<>"",E6>=Controls!$B$21,E6<=Controls!$B$22),1,0) | AE6: =IF(IFERROR(VLOOKUP(D6,Controls!$A$36:$E$46,2,FALSE()),"No")="Yes",1,0) | AF6: =IF(IFERROR(VLOOKUP(D6,Controls!$A$36:$E$46,3,FALSE()),"No")="Yes",1,0) | AG6: =IF(IFERROR(VLOOKUP(D6,Controls!$A$36:$E$46,4,FALSE()),"No")="Yes",1,0) | AH6: =IF(IFERROR(VLOOKUP(D6,Controls!$A$36:$E$46,5,FALSE()),"No")="Yes",1,0) | AI6: =IF(ISNUMBER(MATCH(D6,Controls!$A$36:$A$46,0)),1,0) | AJ6: =Q6-N6 | AK6: =IF(AE6=1,MAX(0,N6-Q6),0) | AL6: =IF(OR(V6="",V6=0),0,N6/V6) | AM6: =IF(OR(V6="",V6=0),0,1) | AN6: =IF(OR(E6="",F6=""),0,NETWORKDAYS(E6,F6,Ref!$K$2:$K$42)) | AO6: =IF(L6="Renewal",1,0) | AP6: =AC6*AD6 | AQ6: =IF(AND(G6<>"",'Historical Score'!$C$6<>""),IF(G6='Historical Score'!$C$6,1,0),0) | AR6: =IF(AND(L6<>"",'Historical Score'!$C$5<>""),IF(L6='Historical Score'!$C$5,1,0),0) | AS6: =IF(AND(Y6<>"",'Historical Score'!$C$7<>""),IF(Y6='Historical Score'!$C$7,1,0),0) | AT6: =IF(AND(K6<>"",'Historical Score'!$C$8<>""),IF(K6='Historical Score'!$C$8,1,0),0) | AU6: =AR6*AT6*AS6 | AV6: =AR6*AS6*AQ6 | AW6: =AR6*AT6*AQ6 | AX6: =AR6*AS6 | AY6: =AR6*AT6 | AZ6: =AR6*AQ6 | BA6: =IF(OR(AD6=0,'Historical Score'!$D$29=""),0,CHOOSE('Historical Score'!$D$29,AU6,AV6,AW6,AX6,AY6,AZ6,AR6,1))
A7: A-006 | B7: Orchard Supply | C7: Orchard Supply Co LLC | D7: Bankruptcy | E7: 45826 | F7: 45918 | G7: 4 | J7: TX | K7: Westwood | L7: New Deal | M7: 1.5 | N7: 20000 | O7: 2000 | P7: 30000 | Q7: 0 | R7: 30000 | S7: 0 | T7: 16 | U7: 9 | V7: 100000 | W7: 0.1 | X7: 44305 | Y7: =IF(I7="","No SIC",IFERROR(VLOOKUP(I7,Ref!$A$2:$B$65,2,FALSE()),"Unclassified")) | Z7: =IF(T7="","",IF(T7<12,"Daily","Weekly")) | AA7: =IF(T7="",0,IF(T7<12,T7*Controls!$B$13,T7*5)) | AB7: =IF(E7="",0,NETWORKDAYS(E7,Controls!$B$20,Ref!$K$2:$K$42)) | AC7: =IF(OR(AF7=1,AND(AA7>0,AB7>=Controls!$B$23*AA7)),1,0) | AD7: =IF(AND(E7<>"",E7>=Controls!$B$21,E7<=Controls!$B$22),1,0) | AE7: =IF(IFERROR(VLOOKUP(D7,Controls!$A$36:$E$46,2,FALSE()),"No")="Yes",1,0) | AF7: =IF(IFERROR(VLOOKUP(D7,Controls!$A$36:$E$46,3,FALSE()),"No")="Yes",1,0) | AG7: =IF(IFERROR(VLOOKUP(D7,Controls!$A$36:$E$46,4,FALSE()),"No")="Yes",1,0) | AH7: =IF(IFERROR(VLOOKUP(D7,Controls!$A$36:$E$46,5,FALSE()),"No")="Yes",1,0) | AI7: =IF(ISNUMBER(MATCH(D7,Controls!$A$36:$A$46,0)),1,0) | AJ7: =Q7-N7 | AK7: =IF(AE7=1,MAX(0,N7-Q7),0) | AL7: =IF(OR(V7="",V7=0),0,N7/V7) | AM7: =IF(OR(V7="",V7=0),0,1) | AN7: =IF(OR(E7="",F7=""),0,NETWORKDAYS(E7,F7,Ref!$K$2:$K$42)) | AO7: =IF(L7="Renewal",1,0) | AP7: =AC7*AD7 | AQ7: =IF(AND(G7<>"",'Historical Score'!$C$6<>""),IF(G7='Historical Score'!$C$6,1,0),0) | AR7: =IF(AND(L7<>"",'Historical Score'!$C$5<>""),IF(L7='Historical Score'!$C$5,1,0),0) | AS7: =IF(AND(Y7<>"",'Historical Score'!$C$7<>""),IF(Y7='Historical Score'!$C$7,1,0),0) | AT7: =IF(AND(K7<>"",'Historical Score'!$C$8<>""),IF(K7='Historical Score'!$C$8,1,0),0) | AU7: =AR7*AT7*AS7 | AV7: =AR7*AS7*AQ7 | AW7: =AR7*AT7*AQ7 | AX7: =AR7*AS7 | AY7: =AR7*AT7 | AZ7: =AR7*AQ7 | BA7: =IF(OR(AD7=0,'Historical Score'!$D$29=""),0,CHOOSE('Historical Score'!$D$29,AU7,AV7,AW7,AX7,AY7,AZ7,AR7,1))
A8: A-007 | B8: Pinewood Dental | C8: Pinewood Dental PC | D8: Open | E8: 46030 | F8: 46237 | G8: 1 | H8: 8021 | I8: 80 | J8: NJ | K8: Fundwell | L8: New Deal | M8: 1.5 | N8: 50000 | O8: 5000 | P8: 75000 | Q8: 30000 | R8: 45000 | S8: 0.4 | T8: 6 | U8: 0 | V8: 250000 | W8: 0.08 | X8: 40211 | Y8: =IF(I8="","No SIC",IFERROR(VLOOKUP(I8,Ref!$A$2:$B$65,2,FALSE()),"Unclassified")) | Z8: =IF(T8="","",IF(T8<12,"Daily","Weekly")) | AA8: =IF(T8="",0,IF(T8<12,T8*Controls!$B$13,T8*5)) | AB8: =IF(E8="",0,NETWORKDAYS(E8,Controls!$B$20,Ref!$K$2:$K$42)) | AC8: =IF(OR(AF8=1,AND(AA8>0,AB8>=Controls!$B$23*AA8)),1,0) | AD8: =IF(AND(E8<>"",E8>=Controls!$B$21,E8<=Controls!$B$22),1,0) | AE8: =IF(IFERROR(VLOOKUP(D8,Controls!$A$36:$E$46,2,FALSE()),"No")="Yes",1,0) | AF8: =IF(IFERROR(VLOOKUP(D8,Controls!$A$36:$E$46,3,FALSE()),"No")="Yes",1,0) | AG8: =IF(IFERROR(VLOOKUP(D8,Controls!$A$36:$E$46,4,FALSE()),"No")="Yes",1,0) | AH8: =IF(IFERROR(VLOOKUP(D8,Controls!$A$36:$E$46,5,FALSE()),"No")="Yes",1,0) | AI8: =IF(ISNUMBER(MATCH(D8,Controls!$A$36:$A$46,0)),1,0) | AJ8: =Q8-N8 | AK8: =IF(AE8=1,MAX(0,N8-Q8),0) | AL8: =IF(OR(V8="",V8=0),0,N8/V8) | AM8: =IF(OR(V8="",V8=0),0,1) | AN8: =IF(OR(E8="",F8=""),0,NETWORKDAYS(E8,F8,Ref!$K$2:$K$42)) | AO8: =IF(L8="Renewal",1,0) | AP8: =AC8*AD8 | AQ8: =IF(AND(G8<>"",'Historical Score'!$C$6<>""),IF(G8='Historical Score'!$C$6,1,0),0) | AR8: =IF(AND(L8<>"",'Historical Score'!$C$5<>""),IF(L8='Historical Score'!$C$5,1,0),0) | AS8: =IF(AND(Y8<>"",'Historical Score'!$C$7<>""),IF(Y8='Historical Score'!$C$7,1,0),0) | AT8: =IF(AND(K8<>"",'Historical Score'!$C$8<>""),IF(K8='Historical Score'!$C$8,1,0),0) | AU8: =AR8*AT8*AS8 | AV8: =AR8*AS8*AQ8 | AW8: =AR8*AT8*AQ8 | AX8: =AR8*AS8 | AY8: =AR8*AT8 | AZ8: =AR8*AQ8 | BA8: =IF(OR(AD8=0,'Historical Score'!$D$29=""),0,CHOOSE('Historical Score'!$D$29,AU8,AV8,AW8,AX8,AY8,AZ8,AR8,1))
A9: A-008 | B9: Harbor Cleaning | C9: Harbor Cleaning Services LLC | D9: Closed/NSF Unpaid | E9: 45852 | F9: 46006 | G9: 3 | H9: 7349 | I9: 73 | J9: TX | K9: Westwood | L9: New Deal | M9: 1.5 | N9: 20000 | O9: 2000 | P9: 30000 | Q9: 30000 | R9: 0 | S9: 1 | T9: 20 | U9: 11 | W9: 0.13 | X9: 44781 | Y9: =IF(I9="","No SIC",IFERROR(VLOOKUP(I9,Ref!$A$2:$B$65,2,FALSE()),"Unclassified")) | Z9: =IF(T9="","",IF(T9<12,"Daily","Weekly")) | AA9: =IF(T9="",0,IF(T9<12,T9*Controls!$B$13,T9*5)) | AB9: =IF(E9="",0,NETWORKDAYS(E9,Controls!$B$20,Ref!$K$2:$K$42)) | AC9: =IF(OR(AF9=1,AND(AA9>0,AB9>=Controls!$B$23*AA9)),1,0) | AD9: =IF(AND(E9<>"",E9>=Controls!$B$21,E9<=Controls!$B$22),1,0) | AE9: =IF(IFERROR(VLOOKUP(D9,Controls!$A$36:$E$46,2,FALSE()),"No")="Yes",1,0) | AF9: =IF(IFERROR(VLOOKUP(D9,Controls!$A$36:$E$46,3,FALSE()),"No")="Yes",1,0) | AG9: =IF(IFERROR(VLOOKUP(D9,Controls!$A$36:$E$46,4,FALSE()),"No")="Yes",1,0) | AH9: =IF(IFERROR(VLOOKUP(D9,Controls!$A$36:$E$46,5,FALSE()),"No")="Yes",1,0) | AI9: =IF(ISNUMBER(MATCH(D9,Controls!$A$36:$A$46,0)),1,0) | AJ9: =Q9-N9 | AK9: =IF(AE9=1,MAX(0,N9-Q9),0) | AL9: =IF(OR(V9="",V9=0),0,N9/V9) | AM9: =IF(OR(V9="",V9=0),0,1) | AN9: =IF(OR(E9="",F9=""),0,NETWORKDAYS(E9,F9,Ref!$K$2:$K$42)) | AO9: =IF(L9="Renewal",1,0) | AP9: =AC9*AD9 | AQ9: =IF(AND(G9<>"",'Historical Score'!$C$6<>""),IF(G9='Historical Score'!$C$6,1,0),0) | AR9: =IF(AND(L9<>"",'Historical Score'!$C$5<>""),IF(L9='Historical Score'!$C$5,1,0),0) | AS9: =IF(AND(Y9<>"",'Historical Score'!$C$7<>""),IF(Y9='Historical Score'!$C$7,1,0),0) | AT9: =IF(AND(K9<>"",'Historical Score'!$C$8<>""),IF(K9='Historical Score'!$C$8,1,0),0) | AU9: =AR9*AT9*AS9 | AV9: =AR9*AS9*AQ9 | AW9: =AR9*AT9*AQ9 | AX9: =AR9*AS9 | AY9: =AR9*AT9 | AZ9: =AR9*AQ9 | BA9: =IF(OR(AD9=0,'Historical Score'!$D$29=""),0,CHOOSE('Historical Score'!$D$29,AU9,AV9,AW9,AX9,AY9,AZ9,AR9,1))

Sheet Controls
A1: CONTROLS
A3: 1. PRICING BANDS
A4: Score >= | B4: Term cap (daily pmts) | C4: Factor
A5: 0 | B5: 100 | C5: 1.49
A6: 5 | B6: 130 | C6: 1.45
A7: 6 | B7: 150 | C7: 1.45
A8: 7 | B8: 195 | C8: 1.4
A9: Max term (months) | B9: 9
A11: 2. CONVERSION CONSTANTS
A12: Weeks per month (ours) | B12: 4.331
A13: Business days per month (ours) | B13: 21.655
A14: MoneyBadger weeks per month | B14: 4
A15: MoneyBadger business days per month | B15: 21
A16: Calendar days per month | B16: 30.4375
A17: Assumed factor on existing positions | B17: 1.45
A19: 3. HISTORICAL EVIDENCE SETTINGS
A20: As-of date (date of the CRM export) | B20: 46259
A21: Window: funded on or after | B21: 45597
A22: Window: funded on or before | B22: 46259
A23: Seasoning multiple (age >= multiple x term) | B23: 1.25
A24: Minimum seasoned deals for a cohort to be primary | B24: 3
A25: Minimum seasoned funded $ for a cohort to be primary | B25: 30000
A26: Seasoned deals for the sample-size indicator to be GREEN | B26: 5
A28: 4. HOUSE-BOOK OUTCOME (index = primary cohort PLR / seasoned-book PLR)
A29: SUPPORTIVE when index at or below | B29: 0.85
A30: NEGATIVE when index above | B30: 1.15
A31: Supportive: sizing flex (0 = green line, 1 = red line) | B31: 0.5
A32: Negative: fund cut % (Section F, planned) | B32: 0.2
A34: 5. STATUS
A35: Status | B35: Default? | C35: Resolved? | D35: Closed? | E35: Open? | F35: Deals in file
A36: Closed | B36: No | C36: Yes | D36: Yes | E36: No | F36: =COUNTIF('Historical Data'!$D$2:$D$9,A36)
A37: Open | B37: No | C37: No | D37: No | E37: Yes | F37: =COUNTIF('Historical Data'!$D$2:$D$9,A37)
A38: Legal | B38: Yes | C38: No | D38: No | E38: No | F38: =COUNTIF('Historical Data'!$D$2:$D$9,A38)
A39: In House Collection | B39: Yes | C39: No | D39: No | E39: No | F39: =COUNTIF('Historical Data'!$D$2:$D$9,A39)
A40: Lowered Payments | B40: No | C40: No | D40: No | E40: No | F40: =COUNTIF('Historical Data'!$D$2:$D$9,A40)
A41: Written-Off | B41: Yes | C41: Yes | D41: No | E41: No | F41: =COUNTIF('Historical Data'!$D$2:$D$9,A41)
A42: Bankruptcy | B42: Yes | C42: Yes | D42: No | E42: No | F42: =COUNTIF('Historical Data'!$D$2:$D$9,A42)
A43: Settlement Agreement | B43: Yes | C43: Yes | D43: No | E43: No | F43: =COUNTIF('Historical Data'!$D$2:$D$9,A43)
A44: Closed/NSF | B44: No | C44: Yes | D44: Yes | E44: No | F44: =COUNTIF('Historical Data'!$D$2:$D$9,A44)
A45: Closed/NSF Unpaid | B45: No | C45: Yes | D45: Yes | E45: No | F45: =COUNTIF('Historical Data'!$D$2:$D$9,A45)
...

Sheet Ref
A1: SIC2 | B1: Industry (SIC major group) | C1: Division | E1: ISO (house-book spelling) | G1: Industry list | K1: Fed holiday | M1: Status list
A2: 01 | B2: Agricultural Production - Crops | C2: Agriculture, Forestry & Fishing | E2: Ace Partners | G2: Administration of Economic Programs | K2: 45292 | M2: Closed
A3: 02 | B3: Agricultural Production - Livestock | C3: Agriculture, Forestry & Fishing | E3: Advance Consolidations | G3: Agricultural Production - Crops | K3: 45306 | M3: Open
A4: 07 | B4: Agricultural Services | C4: Agriculture, Forestry & Fishing | E4: ALLSTATE FUND PROS LLC | G4: Agricultural Production - Livestock | K4: 45341 | M4: Legal
A5: 08 | B5: Forestry | C5: Agriculture, Forestry & Fishing | E5: Alternative Solutions Funding | G5: Agricultural Services | K5: 45439 | M5: In House Collection
A6: 13 | B6: Oil & Gas Extraction | C6: Mining | E6: alvara capital | G6: Air Transportation | K6: 45462 | M6: Lowered Payments
A7: 14 | B7: Nonmetallic Minerals Mining | C7: Mining | E7: American Funding Association 1 | G7: Amusement & Recreation Services | K7: 45477 | M7: Written-Off
A8: 15 | B8: General Building Contractors | C8: Construction | E8: Amerishop Financial services | G8: Apparel & Accessory Stores | K8: 45537 | M8: Bankruptcy
A9: 16 | B9: Heavy Construction | C9: Construction | E9: Aspire Funding | G9: Apparel & Textile Products | K9: 45579 | M9: Settlement Agreement
A10: 17 | B10: Special Trade Contractors | C10: Construction | E10: Atla Finance | G10: Auto Dealers & Gas Stations | K10: 45607 | M10: Closed/NSF
A11: 20 | B11: Food & Kindred Products | C11: Manufacturing | E11: AVON ADVANCE | G11: Auto Repair & Services | K11: 45624 | M11: Closed/NSF Unpaid
A12: 23 | B12: Apparel & Textile Products | C12: Manufacturing | E12: Ballicci | G12: Building Materials & Garden Supply | K12: 45651 | M12: At-Risk
A13: 24 | B13: Lumber & Wood Products | C13: Manufacturing | E13: BFA 3 | G13: Business Services | K13: 45658
A14: 25 | B14: Furniture & Fixtures | C14: Manufacturing | E14: Bingo advance LLC | G14: Chemicals & Allied Products | K14: 45677
A15: 27 | B15: Printing & Publishing | C15: Manufacturing | E15: Birkin Capital Inc | G15: Communications | K15: 45705
A16: 28 | B16: Chemicals & Allied Products | C16: Manufacturing | E16: biz advance now | G16: Eating & Drinking Places | K16: 45803
A17: 30 | B17: Rubber & Plastics | C17: Manufacturing | E17: Biz fuel | G17: Educational Services | K17: 45827
A18: 32 | B18: Stone, Clay, Glass & Concrete | C18: Manufacturing | E18: BizFin LLC | G18: Electric, Gas & Sanitary Services | K18: 45842
A19: 33 | B19: Primary Metal Industries | C19: Manufacturing | E19: black flag funding | G19: Electronic & Electrical Equipment | K19: 45901
A20: 34 | B20: Fabricated Metal Products | C20: Manufacturing | E20: Black Tie Funding | G20: Engineering, Accounting & Management | K20: 45943
A21: 35 | B21: Industrial Machinery & Equipment | C21: Manufacturing | E21: Blue Oak Advance | G21: Environmental Quality & Housing | K21: 45972
A22: 36 | B22: Electronic & Electrical Equipment | C22: Manufacturing | E22: bridge consolidation | G22: Fabricated Metal Products | K22: 45988
A23: 37 | B23: Transportation Equipment | C23: Manufacturing | E23: Broadway Advance LLC | G23: Food & Kindred Products | K23: 46016
A24: 38 | B24: Instruments & Related Products | C24: Manufacturing | E24: Business Fund USA 4 | G24: Food Stores | K24: 46023
... A42: 59 | B42: Miscellaneous Retail | C42: Retail Trade | E42: ecp business capital | G42: Miscellaneous Manufacturing | K42: 46716
A43: 62 | B43: Security & Commodity Brokers | C43: Finance, Insurance & Real Estate | E43: Elite Advance 5 | G43: Miscellaneous Repair Services
A44: 63 | B44: Insurance Carriers | C44: Finance, Insurance & Real Estate | E44: elite finance team | G44: Miscellaneous Retail
A45: 64 | B45: Insurance Agents & Brokers | C45: Finance, Insurance & Real Estate | E45: ELITE FUNDING PARTNERS LLC 6 | G45: Motion Pictures
A46: 65 | B46: Real Estate | C46: Finance, Insurance & Real Estate | E46: EVR GREEN LLC | G46: Museums & Botanical Gardens
A47: 70 | B47: Hotels & Lodging | C47: Services | E47: EZ ADVANCE LLC | G47: National Security & Intl Affairs
A48: 72 | B48: Personal Services | C48: Services | E48: ez alternative solutions | G48: Nonmetallic Minerals Mining
A49: 73 | B49: Business Services | C49: Services | E49: FC ADVANCE | G49: Oil & Gas Extraction
A50: 75 | B50: Auto Repair & Services | C50: Services | E50: Fidelity Funding | G50: Personal Services
A51: 76 | B51: Miscellaneous Repair Services | C51: Services | E51: FIFTH VENTURE | G51: Primary Metal Industries
A52: 78 | B52: Motion Pictures | C52: Services | E52: FIMACAP INC | G52: Printing & Publishing
A53: 79 | B53: Amusement & Recreation Services | C53: Services | E53: Financial Express LLC | G53: Real Estate
A54: 80 | B54: Health Services | C54: Services | E54: Financity | G54: Rubber & Plastics
... A65: 97 | B65: National Security & Intl Affairs | C65: Public Administration | E65: Go Ai Ez LLC Dba:Gova Funding | G65: Wholesale Trade - Nondurable Goods
E66: GREYSTONE | G66: No SIC
E67: GROWTH RATE CAPITAL INC | G67: Unclassified
...
