Workbook
Name D26D33: #REF!

Sheet README
B2: ASPIRE COMBINED UNDERWRITING MODEL - cash-flow engine + house-book evidence (v1)
B4: HOW TO RUN A DEAL (everything happens on the Deal sheet)
B5: 1. Section A: requested fund, factor, term, frequency (optional - the engine sizes an offer from bank data even if blank).
B6: 2. Section B: up to 12 months of true revenue, average daily balance, negative days, NSFs - newest month first.
B7: 3. Existing positions: funder, funded $, payment, frequency, start date. Monthly-frequency debt = leverage only, not a position.
B8: 4. DEAL PROFILE (right of the bank data): ISO, industry (SIC major group), state, new deal or renewal, credit score. Position is automatic; override only if you know better.
B9: 5. Read Section F at the bottom: final decision, fund, factor, term, payment, frequency, modifier, comparables, confidence, stipulations and the written conclusion.
B10: 6. Decision Summary has the full 20-item output; Comparable Deals lists every house-book deal behind it by Contract ID; Historical Score shows all seven tiers and the credibility math.
B12: THE THREE LAYERS
B13: Layer 1 - Deal sheet sections A-E: the original cash-flow tool. Seven metrics plus credit score, green/yellow/red/knockout, score, cash-flow maximum daily payment (weakest of holdback, total leverage, daily-debt-to-balance green lines), term band, factor band, cash-flow max fund. Thresholds live on Controls.
B14: Layer 2 - Historical Data + Historical Score: 1,067 house-book deals, seasoned = age >= 1.25 x contracted term at the as-of date. Seven matching tiers (new/renewal + industry + position ... down to the seasoned book). Primary cohort = first tier with >= 10 seasoned deals and >= $150k seasoned funded. Credibility Z = n/(n+30). Blended lost rate = Z x cohort + (1-Z) x book. Relative index = blended / book -> modifier level (Controls table). Confidence High / Medium / Low; Low caps the modifier at one step from neutral.
B15: Layer 3 - Offer Engine + Decision Summary: adjusted fund = MIN(cash-flow max x multiplier, cash-flow max daily x adjusted term / adjusted factor). Term shortens by bands, factor rises by approved tiers, frequency may switch to weekly. All four offer-side metrics are recomputed and must stay off red. Decision = DECLINE / MANUAL REVIEW / CONDITIONAL / APPROVE.
... B34: CONVERSIONS: money with 5 and 21.655 (weekly / 5 = daily; monthly / 21.655 = daily); time with 4.331 (weeks / 4.331 = months). MoneyBadger uses 4 and 21.

Sheet Deal
B1: UNDERWRITING TOOL
B2: DECISION | C2: =C52 | D2: =IF(C52="","",C50&" red flag(s) vs limit "&C51&" | "&COUNTIF(F38:F45,"GREEN")&"G / "&COUNTIF(F38:F45,"YELLOW")&"Y / "&COUNTIF(F38:F45,"RED")&"R | score "&TEXT(C55,"0.0")&"/"&D55&" = "&C56&" | FINAL (with house book): "&IF(C67="","-",C67))
B4: A. OFFER | J4: MONEYBADGER CROSS-CHECK
B5: Fund $ | C5: Factor | D5: =IF($E$6="Weekly","Term (weeks)","Term (daily pmts)") | E5: Freq | F5: Fee % | J5: Metric | K5: This tool | L5: MoneyBadger | M5: Diff
F6: =Controls!$B$15 | J6: =IF($E$6="Weekly","Weekly remittance","Daily remittance") | K6: =IF(OR($E$6="",C8="",C24=0),"",IF($E$6="Weekly",D8,C8)) | L6: =IF(OR(L7="",C24=0),"",L7*C24/IF($E$6="Weekly",$L$8,$L$9)) | M6: =IF(OR(K6="",L6=""),"",L6-K6)
B7: Payback | C7: Daily $ | D7: Weekly $ | E7: Monthly $ | F7: Term (mo) | G7: Net $ | J7: Holdback % | K7: =IF(OR(D8="",C24=0),"",E8/C24) | L7: =IF(OR($E$6="",C8="",C24=0),"",ROUND(IF($E$6="Weekly",D8*$L$8,C8*$L$9)/C24*100,2)/100) | M7: =IF(OR(K7="",L7=""),"",L7-K7)
B8: =IF(OR(B6="",C6=""),"",B6*C6) | C8: =IF(OR(B8="",D6="",D6=0),"",IF(E6="Weekly",(B8/D6)/5,B8/D6)) | D8: =IF(C8="","",C8*5) | E8: =IF(C8="","",C8*$K$9) | F8: =IF(OR(D6="",D6=0),"",IF(E6="Weekly",D6,D6/5)/($K$9/5)) | G8: =IF(B6="","",B6-(B6*F6)) | J8: Weeks / month | K8: =Controls!$B$28 | L8: =Controls!$B$30 | M8: =IF(OR(K8="",L8=""),"",L8-K8)
J9: Days / month | K9: =Controls!$B$29 | L9: =Controls!$B$31 | M9: =IF(OR(K9="",L9=""),"",L9-K9)
B10: B. BANK DATA (up to 12 months)
B11: Month - NEWEST FIRST | C11: True rev $ | D11: Avg daily bal $ | E11: Neg days | F11: NSFs | G11: MoM % | J11: DEAL PROFILE (house-book match inputs)
B12: Jul | E12: 0 | F12: 0 | G12: =IF(OR(C12="",C13=""),"",(C12-C13)/C13) | J12: ISO | L12: =IF(K12="","",COUNTIF('Historical Data'!$K$2:$K$1068,K12)&" deals in book")
B13: Jun | E13: 0 | F13: 0 | G13: =IF(OR(C13="",C14=""),"",(C13-C14)/C14) | J13: Industry (SIC major group) | L13: =IF(K13="","",COUNTIF('Historical Data'!$Y$2:$Y$1068,K13)&" deals in book")
B14: May | E14: 0 | F14: 0 | G14: =IF(OR(C14="",C15=""),"",(C14-C15)/C15) | J14: State | L14: =IF(K14="","",COUNTIF('Historical Data'!$J$2:$J$1068,K14)&" deals in book")
B15: Apr | E15: 0 | F15: 0 | G15: =IF(OR(C15="",C16=""),"",(C15-C16)/C16) | J15: New deal or renewal | L15: =IF(K15="","REQUIRED for history match","")
G16: =IF(OR(C16="",C17=""),"",(C16-C17)/C17) | J16: Credit score (FICO) | L16: =IF(K16="","not scored",IF(K16>=Controls!$B$12,"GREEN",IF(K16>=Controls!$C$12,"YELLOW","RED")))
G17: =IF(OR(C17="",C18=""),"",(C17-C18)/C18) | J17: Proposed position (auto) | K17: =IF(C42="","",C42) | L17: auto: positions incl. new
G18: =IF(OR(C18="",C19=""),"",(C18-C19)/C19) | J18: Position override (optional) | L18: =IF(K18="","",IF(K18<>K17,"override in use",""))
G19: =IF(OR(C19="",C20=""),"",(C19-C20)/C20)
G20: =IF(OR(C20="",C21=""),"",(C20-C21)/C21)
G21: =IF(OR(C21="",C22=""),"",(C21-C22)/C22)
G22: =IF(OR(C22="",C23=""),"",(C22-C23)/C23)
B24: AVG / TOTAL (months entered) | C24: =IF(COUNT(C12:C23)=0,0,AVERAGE(C12:C23)) | D24: =IF(COUNT(D12:D23)=0,0,AVERAGE(D12:D23)) | E24: =SUM(E12:E23) | F24: =SUM(F12:F23) | G24: =IFERROR(AVERAGE(G12:G22),"")
B26: EXISTING POSITIONS (freq Monthly = leverage only, NOT a position)
B27: Funder | C27: Funded $ | D27: Payment | E27: Freq | F27: Daily equiv | G27: Start Date | H27: Est Term | I27: Est term (mo) | J27: Mo. remaining
E28: Weekly | F28: =IF(D28<>"",IF(E28="Daily",D28,IF(E28="Weekly",D28/5,D28/$K$9)),IF(C28="","",C28*Controls!$B$33/(Controls!$B$23*$K$9))) | H28: =IF(OR(C28="",D28=""),"",ROUND(C28*Controls!$B$33/D28,0)) | I28: =IF(H28="","",H28/IF(E28="Daily",$K$9,IF(E28="Weekly",$K$9/5,1))) | J28: =IF(OR(I28="",G28=""),"",MAX(0,I28-(TODAY()-G28)/Controls!$B$32))
E29: Weekly | F29: =IF(D29<>"",IF(E29="Daily",D29,IF(E29="Weekly",D29/5,D29/$K$9)),IF(C29="","",C29*Controls!$B$33/(Controls!$B$23*$K$9))) | H29: =IF(OR(C29="",D29=""),"",ROUND(C29*Controls!$B$33/D29,0)) | I29: =IF(H29="","",H29/IF(E29="Daily",$K$9,IF(E29="Weekly",$K$9/5,1))) | J29: =IF(OR(I29="",G29=""),"",MAX(0,I29-(TODAY()-G29)/Controls!$B$32))
E30: Weekly | F30: =IF(D30<>"",IF(E30="Daily",D30,IF(E30="Weekly",D30/5,D30/$K$9)),IF(C30="","",C30*Controls!$B$33/(Controls!$B$23*$K$9))) | H30: =IF(OR(C30="",D30=""),"",ROUND(C30*Controls!$B$33/D30,0)) | I30: =IF(H30="","",H30/IF(E30="Daily",$K$9,IF(E30="Weekly",$K$9/5,1))) | J30: =IF(OR(I30="",G30=""),"",MAX(0,I30-(TODAY()-G30)/Controls!$B$32))
E31: Weekly | F31: =IF(D31<>"",IF(E31="Daily",D31,IF(E31="Weekly",D31/5,D31/$K$9)),IF(C31="","",C31*Controls!$B$33/(Controls!$B$23*$K$9))) | H31: =IF(OR(C31="",D31=""),"",ROUND(C31*Controls!$B$33/D31,0)) | I31: =IF(H31="","",H31/IF(E31="Daily",$K$9,IF(E31="Weekly",$K$9/5,1))) | J31: =IF(OR(I31="",G31=""),"",MAX(0,I31-(TODAY()-G31)/Controls!$B$32))
E32: Weekly | F32: =IF(D32<>"",IF(E32="Daily",D32,IF(E32="Weekly",D32/5,D32/$K$9)),IF(C32="","",C32*Controls!$B$33/(Controls!$B$23*$K$9))) | H32: =IF(OR(C32="",D32=""),"",ROUND(C32*Controls!$B$33/D32,0)) | I32: =IF(H32="","",H32/IF(E32="Daily",$K$9,IF(E32="Weekly",$K$9/5,1))) | J32: =IF(OR(I32="",G32=""),"",MAX(0,I32-(TODAY()-G32)/Controls!$B$32))
E33: Weekly | F33: =IF(D33<>"",IF(E33="Daily",D33,IF(E33="Weekly",D33/5,D33/$K$9)),IF(C33="","",C33*Controls!$B$33/(Controls!$B$23*$K$9))) | H33: =IF(OR(C33="",D33=""),"",ROUND(C33*Controls!$B$33/D33,0)) | I33: =IF(H33="","",H33/IF(E33="Daily",$K$9,IF(E33="Weekly",$K$9/5,1))) | J33: =IF(OR(I33="",G33=""),"",MAX(0,I33-(TODAY()-G33)/Controls!$B$32))
B34: Positions (excl. Monthly) | C34: =SUMPRODUCT(((C28:C33<>"")+(D28:D33<>"")>0)*(E28:E33<>"Monthly")) | D34: Total existing daily | E34: =SUM(F28:F33) | F34: =E34*$K$9 | G34: /month
B36: C. METRICS
B37: Metric | C37: Value | D37: Green | E37: Red | F37: Status | G37: Knockout
B38: Total LVG (all debt / rev) | C38: =IF(C24=0,"",(E34+IF(C8="",0,C8))*$K$9/C24) | D38: =Controls!$B$5 | E38: =Controls!$C$5 | F38: =IF(C38="","",IF(C38>=G38,"KNOCKOUT",IF(C38<=D38,"GREEN",IF(C38>=E38,"RED","YELLOW")))) | G38: =Controls!$D$5
B39: New holdback SP% | C39: =IF(OR(C24=0,E8=""),"",E8/C24) | D39: =Controls!$B$6 | E39: =Controls!$C$6 | F39: =IF(C39="","",IF(C39>=G39,"KNOCKOUT",IF(C39<=D39,"GREEN",IF(C39>=E39,"RED","YELLOW")))) | G39: =Controls!$D$6
B40: Daily debt / balance | C40: =IF(D24=0,"",(E34+IF(C8="",0,C8))/D24) | D40: =Controls!$B$7 | E40: =Controls!$C$7 | F40: =IF(C40="","",IF(C40>=G40,"KNOCKOUT",IF(C40<=D40,"GREEN",IF(C40>=E40,"RED","YELLOW")))) | G40: =Controls!$D$7
B41: Fund / revenue | C41: =IF(OR(C24=0,B6=""),"",B6/C24) | D41: =Controls!$B$8 | E41: =Controls!$C$8 | F41: =IF(C41="","",IF(C41>=G41,"KNOCKOUT",IF(C41<=D41,"GREEN",IF(C41>=E41,"RED","YELLOW")))) | G41: =Controls!$D$8
B42: # positions (incl. new) | C42: =IF(C24=0,"",C34+1) | D42: =Controls!$B$9 | E42: =Controls!$C$9 | F42: =IF(C42="","",IF(C42>=G42,"KNOCKOUT",IF(C42<=D42,"GREEN",IF(C42>=E42,"RED","YELLOW")))) | G42: =Controls!$D$9
B43: Revenue trend (avg MoM) | C43: =G24 | D43: =Controls!$B$10 | E43: =Controls!$C$10 | F43: =IF(C24=0,"",IF(NOT(ISNUMBER(C43)),"YELLOW",IF(C43<=G43,"KNOCKOUT",IF(C43>=D43,"GREEN",IF(C43<=E43,"RED","YELLOW"))))) | G43: =Controls!$D$10
B44: Neg days + NSFs (total) | C44: =E24+F24 | D44: =Controls!$B$11 | E44: =Controls!$C$11 | F44: =IF(C44="","",IF(C44>=G44,"KNOCKOUT",IF(C44<=D44,"GREEN",IF(C44>=E44,"RED","YELLOW")))) | G44: =Controls!$D$11
...

Sheet Decision Summary
B1: DECISION SUMMARY
B2: Everything an underwriter needs to sign or override. Cash flow sets the ceiling (Layer 1); house-book evidence sets how much of it to use (Layers 2-3).
B4: Item | C4: Value | D4: Detail
B5: DECISION | C5: =IF(Deal!$C$24=0,"",IF(OR(Deal!$C$63="-",Deal!$C$63="",'Offer Engine'!$D$8="",'Offer Engine'!$D$8=0,'Offer Engine'!$D$8<Controls!$B$14,'Offer Engine'!$D$40>=Controls!$B$13),"DECLINE",IF(C28<>"","MANUAL REVIEW",IF(OR(COUNTIF('Offer Engine'!$E$26:$E$33,"YELLOW")+COUNTIF('Offer Engine'!$E$26:$E$33,"RED")>0,'Offer Engine'!$C$10>=4,C31>0),"CONDITIONAL","APPROVE")))) | D5: =IF(C5="","Enter bank data + deal profile.",IF(C5="DECLINE",IF(COUNTIF(Deal!$F$42:$F$45,"KNOCKOUT")>0,"Merchant knockout: "&INDEX(Deal!$B$42:$B$45,MATCH("KNOCKOUT",Deal!$F$42:$F$45,0))&".",IF(OR('Offer Engine'!$D$8="",'Offer Engine'!$D$8=0),"No clean room under the green lines.",IF('Offer Engine'!$D$8<Controls!$B$14,"Adjusted fund "&TEXT('Offer Engine'!$D$8,"$#,##0")&" is below the minimum "&TEXT(Controls!$B$14,"$#,##0")&".","Red flags at the adjusted offer reached the limit."))),IF(C5="MANUAL REVIEW","Triggers: "&C28,IF(C5="APPROVE","All metrics green at the adjusted offer; evidence neutral or better; standard stips only.","Yellows/reds remain, evidence is negative, or conditional stips apply - see below."))))
B6: Recommended funding amount | C6: ='Offer Engine'!$D$8 | D6: =IF(OR(C6="",C6="-"),"",IF(ISNUMBER(Deal!$C$63),"cash-flow max "&TEXT(Deal!$C$63,"$#,##0")&" -> "&TEXT(C6/Deal!$C$63,"0%")&" used (requested "&IF(Deal!$B$6="","n/a",TEXT(Deal!$B$6,"$#,##0"))&")",""))
B7: Recommended factor rate | C7: ='Offer Engine'!$D$7 | D7: =IF(C7="","","base "&TEXT('Offer Engine'!$C$7,"0.00")&IF('Offer Engine'!$D$7>'Offer Engine'!$C$7," -> raised one approved tier by history",""))
B8: Recommended term | C8: ='Offer Engine'!$D$17 | D8: =IF(C8="","",IF('Offer Engine'!$D$16="Weekly","weeks","daily payments")&" ("&TEXT('Offer Engine'!$D$22,"0.0")&" months; base "&'Offer Engine'!$C$6&" daily pmts"&IF('Offer Engine'!$D$6<'Offer Engine'!$C$6,", shortened by history","")&")")
B9: Payment | C9: ='Offer Engine'!$D$18 | D9: =IF(C9="","","per "&IF('Offer Engine'!$D$16="Weekly","week","business day")&"; daily-equivalent "&TEXT('Offer Engine'!$D$9,"$#,##0.00")&", monthly "&TEXT('Offer Engine'!$D$19,"$#,##0")&"; payback "&TEXT('Offer Engine'!$D$20,"$#,##0")&", net "&TEXT('Offer Engine'!$D$21,"$#,##0"))
B10: Daily or weekly | C10: ='Offer Engine'!$D$16 | D10: =IF('Offer Engine'!$C$14="Weekly","Weekly required by the historical modifier","As proposed on the Deal sheet")
B11: Holdback % | C11: ='Offer Engine'!$D$27 | D11: =IF(C11="","",'Offer Engine'!$E$27&" (green line "&TEXT(Controls!$B$6,"0%")&")")
B12: Total leverage (all debt / revenue) | C12: ='Offer Engine'!$D$26 | D12: =IF(C12="","",'Offer Engine'!$E$26&" (green line "&TEXT(Controls!$B$5,"0%")&")")
B13: Funding-to-revenue | C13: ='Offer Engine'!$D$29 | D13: =IF(C13="","",'Offer Engine'!$E$29&" (green line "&TEXT(Controls!$B$8,"0.00")&"x)")
B14: Daily debt-to-balance | C14: ='Offer Engine'!$D$28 | D14: =IF(C14="","",'Offer Engine'!$E$28&" (green line "&TEXT(Controls!$B$7,"0%")&")")
B15: Number of positions (incl. new) | C15: =Deal!$C$42 | D15: =IF(C15="","",Deal!$F$42&IF(Deal!$K$18<>""," (position override "&Deal!$K$18&" used for matching)",""))
B16: Historical risk modifier | C16: ='Historical Score'!$C$43 | D16: =IF(C16="","","relative index "&TEXT('Historical Score'!$C$39,"0.00")&" (1.00 = seasoned book); fund x "&TEXT('Offer Engine'!$D$11,"0.00")&", term step "&'Offer Engine'!$D$12&", factor step "&'Offer Engine'!$D$13&IF('Historical Score'!$C$42<>'Historical Score'!$C$40,"; capped by Low confidence",""))
B17: Cash-flow risk score | C17: =Deal!$C$55 | D17: =IF(C17="","","of "&Deal!$D$55&" scored metrics = "&Deal!$C$56&" (scaled "&TEXT(Deal!$D$57,"0.0")&"/7 for pricing bands)")
B18: Overall confidence in the historical evidence | C18: ='Historical Score'!$C$41 | D18: ="Z = "&TEXT('Historical Score'!$C$37,"0.00")&"; open share "&IF('Historical Score'!$C$34="","n/a",TEXT('Historical Score'!$C$34,"0%"))&"; "&IF('Historical Score'!$C$29=7,"no specific cohort met the minimums","primary tier "&'Historical Score'!$C$29)
B19: Number of comparable deals (seasoned / all matches) | C19: ='Historical Score'!$C$31 | D19: ='Historical Score'!$C$30
B20: Percentage of comparable deals seasoned | C20: ='Historical Score'!$C$32 | D20: ="unseasoned deals are listed on Comparable Deals but never rated"
B21: Comparable-cohort principal lost rate | C21: ='Historical Score'!$C$33 | D21: =IF(C21="","too few seasoned deals to show a rate","vs seasoned book "&TEXT('Historical Score'!$C$10,"0.0%")&"; blended (credibility-weighted) "&TEXT('Historical Score'!$C$38,"0.0%")&"; collected on defaults "&IF('Historical Score'!$C$36="","n/a",TEXT('Historical Score'!$C$36,"0%")))
B22: Comparable-cohort return on funded capital | C22: ='Historical Score'!$C$35 | D22: =IF(C22="","","seasoned deals only; open deals in the cohort depress this figure")
B23: Largest historical impact | C23: ='Historical Score'!$C$44 | D23: ='Historical Score'!$C$45
B24: Metric that limited the offer | C24: =IF(Deal!$D$60="","",Deal!$D$60) | D24: =IF(Deal!$C$60="","",IF(Deal!$C$60=0,"existing debt already exceeds a green line",IF(Deal!$C$62=FLOOR(Deal!$D$41*Deal!$C$24*Deal!$D$62/Deal!$C$60,5),"term also capped by the fund/revenue green line","term set by the score band")))
B25: ISO / industry / state / position evidence | C25: ='Historical Score'!$C$46 | D25: ='Historical Score'!$C$47&" | "&'Historical Score'!$C$48&" | "&'Historical Score'!$C$49&IF('Historical Score'!$C$50="No",""," | CONFLICT: "&'Historical Score'!$C$50)
B26: Required stipulations | C26: =C27&IF(D26="","","; "&D26) | D26: =IF(AND(Controls!$B$91="Y",'Offer Engine'!$C$10>=4),"No-stacking covenant with default-to-daily; ","")&IF(AND(Controls!$B$92="Y",Deal!$F$44<>"GREEN",Deal!$F$44<>""),"Bank login verification (Plaid/DecisionLogic); ","")&IF(AND(Controls!$B$93="Y",Deal!$C$34>=2),"Payoff/balance letter for each existing position; ","")&IF(AND(Controls!$B$94="Y",Deal!$F$45<>"GREEN",Deal!$F$45<>""),"Landlord/lease letter; ","")&IF(AND(Controls!$B$95="Y",'Historical Score'!$C$41="Low"),"Underwriter review of historical evidence; ","")&IF(AND(Controls!$B$96="Y",'Offer Engine'!$C$14="Weekly"),"Weekly remittance only; ","")&IF(AND(Controls!$B$97="Y",Deal!$K$15="Renewal"),"Prior-contract payoff and renewal history; ","")
B27: Standard stipulations | C27: =IF(Controls!$B$90="Y",Controls!$A$90,"") | D27: ="always required"
B28: Manual-review triggers fired | C28: =IF(AND(Controls!$B$79="Y",'Offer Engine'!$C$15="Y"),"Severe historical modifier; ","")&IF(AND(Controls!$B$80="Y",'Historical Score'!$C$41="Low",COUNTIF('Offer Engine'!$E$26:$E$33,"RED")>0),"Low confidence with a RED metric; ","")&IF(AND(Controls!$B$81="Y",Deal!$F$45="RED",COUNTIF('Offer Engine'!$E$26:$E$32,"RED")>0),"Credit RED plus another RED; ","")&IF(AND(Controls!$B$82="Y",ISNUMBER(Deal!$C$42),IF(ISNUMBER(Deal!$C$42),Deal!$C$42,0)>=Controls!$C$82),"Positions incl. new at/above "&Controls!$C$82&"; ","")&IF(AND(Controls!$B$83="Y",Deal!$K$15="New Deal",ISNUMBER('Historical Score'!$C$6),IF(ISNUMBER('Historical Score'!$C$6),'Historical Score'!$C$6,0)>=Controls!$C$83,OR(Deal!$K$13="General Building Contractors",Deal!$K$13="Special Trade Contractors",Deal!$K$13="Heavy Construction")),"New 3rd+ position construction deal; ","")&IF(AND(Controls!$B$84="Y",OR(AND(Deal!$K$12<>"",COUNTIF('Historical Data'!$K$2:$K$1068,Deal!$K$12)=0),AND(Deal!$K$13<>"",COUNTIF('Historical Data'!$Y$2:$Y$1068,Deal!$K$13)=0))),"ISO or industry not in house book; ","")&IF(AND(Controls!$B$85="Y",ISNUMBER('Offer Engine'!$D$8),IF(ISNUMBER('Offer Engine'!$D$8),'Offer Engine'!$D$8,0)<Controls!$B$14,IF(ISNUMBER('Offer Engine'!$D$8),'Offer Engine'!$D$8,0)>0),"Adjusted fund below minimum; ","")&IF(AND(Controls!$B$86="Y",ISNUMBER('Historical Score'!$C$34),IF(ISNUMBER('Historical Score'!$C$34),'Historical Score'!$C$34,0)>Controls!$B$43),"Cohort open share high; ","") | D28: ="blank = none"
B29: Main risks / positive factors | C29: =IF(COUNTIF(Deal!$F$38:$F$45,"RED")+COUNTIF(Deal!$F$38:$F$45,"KNOCKOUT")=0,"Risks: none red on the requested offer","Risks: "&IF(Deal!$F$38="RED","total leverage; ","")&IF(Deal!$F$39="RED","holdback; ","")&IF(Deal!$F$40="RED","daily debt/balance; ","")&IF(Deal!$F$41="RED","fund/revenue; ","")&IF(Deal!$F$42="RED","positions; ","")&IF(Deal!$F$43="RED","revenue trend; ","")&IF(Deal!$F$44="RED","neg days/NSFs; ","")&IF(Deal!$F$45="RED","credit; ","")&IF(COUNTIF(Deal!$F$38:$F$45,"KNOCKOUT")>0,"KNOCKOUT present",""))&IF('Offer Engine'!$C$10>=4," | history: "&'Historical Score'!$C$43,"") | D29: ="Positives: "&IF(COUNTIF(Deal!$F$38:$F$45,"GREEN")=0,"none green",IF(Deal!$F$38="GREEN","leverage; ","")&IF(Deal!$F$39="GREEN","holdback; ","")&IF(Deal!$F$40="GREEN","daily debt/balance; ","")&IF(Deal!$F$41="GREEN","fund/revenue; ","")&IF(Deal!$F$42="GREEN","positions; ","")&IF(Deal!$F$43="GREEN","revenue trend; ","")&IF(Deal!$F$44="GREEN","clean neg days/NSFs; ","")&IF(Deal!$F$45="GREEN","credit; ",""))&IF('Offer Engine'!$C$10<=2,"history: "&'Historical Score'!$C$43,"")&IF(Deal!$K$15="Renewal"," | renewal (strongest surviving positive in the book)","")
B30: Underwriter's conclusion | C30: =IF(Deal!$C$24=0,"Enter bank data.",IF(Deal!$C$63="-","Do not fund: "&INDEX(Deal!$B$42:$B$45,MATCH("KNOCKOUT",Deal!$F$42:$F$45,0))&" is past its knockout line; history cannot override a knockout.",IF(OR(Deal!$C$63="",Deal!$C$63=0),"Cash flow leaves no clean room under the green lines - "&Deal!$D$60&".","Cash flow supports up to "&TEXT(Deal!$C$63,"$#,##0")&" ("&Deal!$D$60&", "&Deal!$C$62&" daily pmts @ "&TEXT(Deal!$D$62,"0.00")&"). "&IF(C5="DECLINE","The deal is declined: "&D5&" For reference, ","The recommendation is "&TEXT(C6,"$#,##0")&" ("&TEXT(C6/Deal!$C$63,"0%")&" of the maximum) at "&TEXT(C7,"0.00")&" over "&TEXT(C8,"0")&IF(C10="Weekly"," weeks"," daily payments")&", "&TEXT(C9,"$#,##0")&IF(C10="Weekly","/week","/day")&", because ")&"the primary comparable cohort ("&'Historical Score'!$C$30&") holds "&'Historical Score'!$C$31&" seasoned deals with a principal lost rate of "&IF('Historical Score'!$C$33="","n/a",TEXT('Historical Score'!$C$33,"0.0%"))&" against "&TEXT('Historical Score'!$C$10,"0.0%")&" for the seasoned book; at credibility "&TEXT('Historical Score'!$C$37,"0.00")&" that blends to "&TEXT('Historical Score'!$C$38,"0.0%")&" (index "&TEXT('Historical Score'!$C$39,"0.00")&"), which is "&LOWER('Historical Score'!$C$43)&IF('Historical Score'!$C$42<>'Historical Score'!$C$40," after the low-confidence cap","")&". Confidence is "&LOWER('Historical Score'!$C$41)&". "&IF(Deal!$K$15="Renewal","Renewal status is the strongest surviving positive in the book. ","")&'Historical Score'!$C$46&". "&'Historical Score'!$C$47&". "&'Historical Score'!$C$48&". "&IF(C28<>"","Sent to manual review: "&C28,"")&IF(D26<>""," Conditional stips: "&D26,""))))
B31: Risk-based conditional stips (drive CONDITIONAL) | C31: =IF(AND(Controls!$B$91="Y",'Offer Engine'!$C$10>=4),1,0)+IF(AND(Controls!$B$92="Y",Deal!$F$44<>"GREEN",Deal!$F$44<>""),1,0)+IF(AND(Controls!$B$94="Y",Deal!$F$45<>"GREEN",Deal!$F$45<>""),1,0)+IF(AND(Controls!$B$95="Y",'Historical Score'!$C$41="Low"),1,0)+IF(AND(Controls!$B$96="Y",'Offer Engine'!$C$14="Weekly"),1,0) | D31: ="documentary stips (payoff letters, renewal history) do not by themselves make a deal CONDITIONAL"

Sheet Offer Engine
B1: OFFER ENGINE - base cash-flow offer, historical adjustment, adjusted offer
B2: Adjusted fund = MIN(base fund x multiplier, cash-flow max daily x adjusted term / adjusted factor). The second term keeps the daily payment at or below the cash-flow maximum even when the term is shortened.
B4: Item | C4: Base (cash flow only) | D4: Adjusted (with history) | E4: Status | F4: How
B5: Cash-flow max daily payment | C5: =Deal!$C$60 | D5: =Deal!$C$60 | F5: Deal C60 - weakest of holdback / total LVG / daily-debt-to-balance green lines
B6: Term (daily payments) | C6: =Deal!$C$62 | D6: =IF(OR(C6="",C8="-"),"",MAX(20,MIN(C6,INDEX(Controls!$B$19:$B$22,MAX(1,MATCH(Deal!$D$57,Controls!$A$19:$A$22,1)+C12))))) | F6: Base band term; step moves down the Controls band table
B7: Factor | C7: =Deal!$D$62 | D7: =IF(C7="","",INDEX(Controls!$B$24:$D$24,MIN(3,MAX(1,MATCH(C7,Controls!$B$24:$D$24,0)+C13)))) | F7: Next approved tier, never above 1.49
B8: Fund $ | C8: =Deal!$C$63 | D8: =IF(C8="-","-",IF(OR(C8="",D6="",D7=""),"",MAX(0,FLOOR(MIN(C8*C11,C5*D6/D7),500)))) | F8: Never above the base fund
B9: Daily payment | C9: =IF(OR(C8="",C8="-"),"",C8*C7/C6) | D9: =IF(OR(D8="",D8="-",D8=0),"",D8*D7/D6) | F9: fund x factor / term
B10: Historical modifier level (after confidence cap) | C10: ='Historical Score'!$C$42 | D10: ='Historical Score'!$C$42 | F10: 1 strong positive .. 3 neutral .. 6 severe
B11: Fund multiplier | C11: =INDEX(Controls!$C$54:$C$59,C10) | D11: =INDEX(Controls!$C$54:$C$59,C10) | F11: Controls modifier table
B12: Term step (bands) | C12: =INDEX(Controls!$D$54:$D$59,C10) | D12: =INDEX(Controls!$D$54:$D$59,C10)
B13: Factor step (tiers) | C13: =INDEX(Controls!$E$54:$E$59,C10) | D13: =INDEX(Controls!$E$54:$E$59,C10)
B14: Frequency rule | C14: =INDEX(Controls!$F$54:$F$59,C10) | D14: =INDEX(Controls!$F$54:$F$59,C10)
B15: Manual review flag from modifier | C15: =INDEX(Controls!$G$54:$G$59,C10) | D15: =INDEX(Controls!$G$54:$G$59,C10)
B16: Frequency (final) | C16: =IF(Deal!$E$6="","Daily",Deal!$E$6) | D16: =IF(C14="Weekly","Weekly",IF(Deal!$E$6="","Daily",Deal!$E$6)) | F16: Proposed frequency unless the modifier requires weekly
B17: Term in final units (weeks or daily pmts) | C17: =IF(OR(C6="",C8="-"),"",IF(C16="Weekly",C6/5,C6)) | D17: =IF(OR(D6="",D8="-"),"",IF(D16="Weekly",D6/5,D6))
B18: Payment in final units | C18: =IF(C9="","",IF(C16="Weekly",C9*5,C9)) | D18: =IF(D9="","",IF(D16="Weekly",D9*5,D9))
B19: Monthly payment | C19: =IF(C9="","",C9*Controls!$B$29) | D19: =IF(D9="","",D9*Controls!$B$29)
B20: Payback | C20: =IF(OR(C8="",C8="-"),"",C8*C7) | D20: =IF(OR(D8="",D8="-"),"",D8*D7)
B21: Net disbursed (after fee) | C21: =IF(OR(C8="",C8="-"),"",C8*(1-Controls!$B$15)) | D21: =IF(OR(D8="",D8="-"),"",D8*(1-Controls!$B$15))
B22: Term (months) | C22: =IF(C6="","",C6/Controls!$B$29) | D22: =IF(D6="","",D6/Controls!$B$29)
B24: METRICS RE-CHECKED AT EACH OFFER (must stay off RED / KNOCKOUT)
B25: Metric | C25: Base offer | D25: Adjusted offer | E25: Status (adjusted) | F25: Green / Red / Knockout
B26: Total LVG (all debt / rev) | C26: =IF(OR(Deal!$C$24=0,C9=""),"",(Deal!$E$34+C9)*Controls!$B$29/Deal!$C$24) | D26: =IF(OR(Deal!$C$24=0,D9=""),"",(Deal!$E$34+D9)*Controls!$B$29/Deal!$C$24) | E26: =IF(D26="","",IF(D26>=Controls!$D$5,"KNOCKOUT",IF(D26<=Controls!$B$5,"GREEN",IF(D26>=Controls!$C$5,"RED","YELLOW")))) | F26: =TEXT(Controls!$B$5,"0.0%")&" / "&TEXT(Controls!$C$5,"0.0%")&" / "&TEXT(Controls!$D$5,"0.0%")
B27: New holdback SP% | C27: =IF(OR(Deal!$C$24=0,C9=""),"",C9*Controls!$B$29/Deal!$C$24) | D27: =IF(OR(Deal!$C$24=0,D9=""),"",D9*Controls!$B$29/Deal!$C$24) | E27: =IF(D27="","",IF(D27>=Controls!$D$6,"KNOCKOUT",IF(D27<=Controls!$B$6,"GREEN",IF(D27>=Controls!$C$6,"RED","YELLOW")))) | F27: =TEXT(Controls!$B$6,"0.0%")&" / "&TEXT(Controls!$C$6,"0.0%")&" / "&TEXT(Controls!$D$6,"0.0%")
B28: Daily debt / balance | C28: =IF(OR(Deal!$D$24=0,C9=""),"",(Deal!$E$34+C9)/Deal!$D$24) | D28: =IF(OR(Deal!$D$24=0,D9=""),"",(Deal!$E$34+D9)/Deal!$D$24) | E28: =IF(D28="","",IF(D28>=Controls!$D$7,"KNOCKOUT",IF(D28<=Controls!$B$7,"GREEN",IF(D28>=Controls!$C$7,"RED","YELLOW")))) | F28: =TEXT(Controls!$B$7,"0.0%")&" / "&TEXT(Controls!$C$7,"0.0%")&" / "&TEXT(Controls!$D$7,"0.0%")
B29: Fund / revenue | C29: =IF(OR(Deal!$C$24=0,C8="",C8="-"),"",C8/Deal!$C$24) | D29: =IF(OR(Deal!$C$24=0,D8="",D8="-"),"",D8/Deal!$C$24) | E29: =IF(D29="","",IF(D29>=Controls!$D$8,"KNOCKOUT",IF(D29<=Controls!$B$8,"GREEN",IF(D29>=Controls!$C$8,"RED","YELLOW")))) | F29: =TEXT(Controls!$B$8,"0.00")&" / "&TEXT(Controls!$C$8,"0.00")&" / "&TEXT(Controls!$D$8,"0.00")
B30: # positions (incl. new) | C30: =Deal!$C$42 | D30: =Deal!$C$42 | E30: =Deal!$F$42 | F30: merchant-side metric - unchanged by the offer
B31: Revenue trend (avg MoM) | C31: =Deal!$C$43 | D31: =Deal!$C$43 | E31: =Deal!$F$43 | F31: merchant-side metric - unchanged by the offer
B32: Neg days + NSFs (total) | C32: =Deal!$C$44 | D32: =Deal!$C$44 | E32: =Deal!$F$44 | F32: merchant-side metric - unchanged by the offer
B33: Credit score (FICO) | C33: =Deal!$C$45 | D33: =Deal!$C$45 | E33: =Deal!$F$45 | F33: merchant-side metric - unchanged by the offer
B35: SAFETY PROOF
B36: Adjusted fund <= cash-flow max fund | D36: =IF(OR(D8="",D8="-",C8="",C8="-"),"OK",IF(D8<=C8,"OK","FAIL"))
B37: Adjusted daily payment <= cash-flow max daily | D37: =IF(OR(D9="",C5=""),"OK",IF(D9<=C5+0.005,"OK","FAIL"))
B38: No offer-side metric RED or KNOCKOUT at adjusted offer | D38: =IF(COUNTIF(E26:E29,"RED")+COUNTIF(E26:E29,"KNOCKOUT")=0,"OK","FAIL")
B39: Merchant knockouts untouched (history cannot remove them) | D39: =IF(COUNTIF(Deal!$F$42:$F$45,"KNOCKOUT")>0,IF(D8="-","OK","FAIL"),"OK")
B40: Red flags at adjusted offer (offer-side + merchant-side) | D40: =COUNTIF(E26:E33,"RED")+COUNTIF(E26:E33,"KNOCKOUT")

Sheet Historical Score
A1: HISTORICAL SCORE - comparable cohorts, credibility and the risk modifier
A2: Rates use SEASONED deals only (age >= seasoning multiple x contracted term, as of the Controls date). Unseasoned deals are counted, never rated. Blended lost rate = Z x cohort + (1-Z) x seasoned book, Z = n/(n+K).
A4: DEAL BEING MATCHED (from the Deal sheet)
B5: New deal or renewal | C5: =IF(Deal!$K$15="","",Deal!$K$15)
B6: Proposed position (effective) | C6: =IF(Deal!$K$18<>"",Deal!$K$18,Deal!$K$17)
B7: Industry | C7: =IF(Deal!$K$13="","",Deal!$K$13)
B8: ISO | C8: =IF(Deal!$K$12="","",Deal!$K$12)
B9: State | C9: =IF(Deal!$K$14="","",Deal!$K$14)
B10: Seasoned-book principal lost rate (baseline) | C10: =$L$20
B11: Seasoned-book deals / funded | C11: =TEXT($E$20,"#,##0")&" / "&TEXT($G$20,"$#,##0")
A13: Tier | B13: Cohort | C13: Keys | D13: Deals (all) | E13: Seasoned | F13: % seasoned | G13: Funded $ (seasoned) | H13: Open n | I13: Open % | J13: Default n | K13: Default % | L13: Principal lost rate | M13: Collected on defaults | N13: Return on funded | O13: Avg adv/rev | P13: Avg term (bd) | Q13: Avg factor | R13: Avg deal size | S13: Avg days on book | T13: Renewal share | U13: Seasoned enough? | V13: Credibility Z | W13: Blended lost rate | X13: Relative index | Y13: Meets min | Z13: Impact vs book | AA13: Lost rate shown?
A14: 1 | B14: T1: new/renewal + industry + position | C14: NR + industry + position | D14: =SUMPRODUCT('Historical Data'!$AV$2:$AV$1068*'Historical Data'!$AD$2:$AD$1068) | E14: =SUMPRODUCT('Historical Data'!$AV$2:$AV$1068*'Historical Data'!$AP$2:$AP$1068) | F14: =IF(D14=0,"",E14/D14) | G14: =SUMPRODUCT('Historical Data'!$AV$2:$AV$1068*'Historical Data'!$AP$2:$AP$1068*'Historical Data'!$N$2:$N$1068) | H14: =SUMPRODUCT('Historical Data'!$AV$2:$AV$1068*'Historical Data'!$AP$2:$AP$1068*'Historical Data'!$AH$2:$AH$1068) | I14: =IF(E14=0,"",H14/E14) | J14: =SUMPRODUCT('Historical Data'!$AV$2:$AV$1068*'Historical Data'!$AP$2:$AP$1068*'Historical Data'!$AE$2:$AE$1068) | K14: =IF(E14=0,"",J14/E14) | L14: =IF(OR(E14<Controls!$B$47,G14=0),"",SUMPRODUCT('Historical Data'!$AV$2:$AV$1068*'Historical Data'!$AP$2:$AP$1068*'Historical Data'!$AK$2:$AK$1068)/G14) | M14: =IF(OR(E14<Controls!$B$47,SUMPRODUCT('Historical Data'!$AV$2:$AV$1068*'Historical Data'!$AP$2:$AP$1068*'Historical Data'!$AE$2:$AE$1068*'Historical Data'!$N$2:$N$1068)=0),"",SUMPRODUCT('Historical Data'!$AV$2:$AV$1068*'Historical Data'!$AP$2:$AP$1068*'Historical Data'!$AE$2:$AE$1068*'Historical Data'!$Q$2:$Q$1068)/SUMPRODUCT('Historical Data'!$AV$2:$AV$1068*'Historical Data'!$AP$2:$AP$1068*'Historical Data'!$AE$2:$AE$1068*'Historical Data'!$N$2:$N$1068)) | N14: =IF(OR(E14<Controls!$B$47,G14=0),"",SUMPRODUCT('Historical Data'!$AV$2:$AV$1068*'Historical Data'!$AP$2:$AP$1068*'Historical Data'!$AJ$2:$AJ$1068)/G14) | O14: =IF(SUMPRODUCT('Historical Data'!$AV$2:$AV$1068*'Historical Data'!$AP$2:$AP$1068*'Historical Data'!$AM$2:$AM$1068)=0,"",SUMPRODUCT('Historical Data'!$AV$2:$AV$1068*'Historical Data'!$AP$2:$AP$1068*'Historical Data'!$AM$2:$AM$1068*'Historical Data'!$AL$2:$AL$1068)/SUMPRODUCT('Historical Data'!$AV$2:$AV$1068*'Historical Data'!$AP$2:$AP$1068*'Historical Data'!$AM$2:$AM$1068)) | P14: =IF(E14=0,"",SUMPRODUCT('Historical Data'!$AV$2:$AV$1068*'Historical Data'!$AP$2:$AP$1068*'Historical Data'!$AA$2:$AA$1068)/E14) | Q14: =IF(E14=0,"",SUMPRODUCT('Historical Data'!$AV$2:$AV$1068*'Historical Data'!$AP$2:$AP$1068*'Historical Data'!$M$2:$M$1068)/E14) | R14: =IF(E14=0,"",G14/E14) | S14: =IF(E14=0,"",SUMPRODUCT('Historical Data'!$AV$2:$AV$1068*'Historical Data'!$AP$2:$AP$1068*'Historical Data'!$AN$2:$AN$1068)/E14) | T14: =IF(E14=0,"",SUMPRODUCT('Historical Data'!$AV$2:$AV$1068*'Historical Data'!$AP$2:$AP$1068*'Historical Data'!$AO$2:$AO$1068)/E14) | U14: =IF(AND(E14>=Controls!$B$40,G14>=Controls!$B$41,IF(I14="",1,I14)<=Controls!$B$43),"Yes","No") | V14: =IF(E14+Controls!$B$42=0,0,E14/(E14+Controls!$B$42)) | W14: =IF(L14="",$C$10,V14*L14+(1-V14)*$C$10) | X14: =IF(OR($C$10="",$C$10=0),"",W14/$C$10) | Y14: =IF(AND(E14>=Controls!$B$40,G14>=Controls!$B$41),1,0) | Z14: =IF(L14="",0,ABS(W14-$C$10)) | AA14: =IF(L14="","No","Yes")
A15: 2 | B15: T2: new/renewal + ISO + position | C15: NR + ISO + position | D15: =SUMPRODUCT('Historical Data'!$AW$2:$AW$1068*'Historical Data'!$AD$2:$AD$1068) | E15: =SUMPRODUCT('Historical Data'!$AW$2:$AW$1068*'Historical Data'!$AP$2:$AP$1068) | F15: =IF(D15=0,"",E15/D15) | G15: =SUMPRODUCT('Historical Data'!$AW$2:$AW$1068*'Historical Data'!$AP$2:$AP$1068*'Historical Data'!$N$2:$N$1068) | H15: =SUMPRODUCT('Historical Data'!$AW$2:$AW$1068*'Historical Data'!$AP$2:$AP$1068*'Historical Data'!$AH$2:$AH$1068) | I15: =IF(E15=0,"",H15/E15) | J15: =SUMPRODUCT('Historical Data'!$AW$2:$AW$1068*'Historical Data'!$AP$2:$AP$1068*'Historical Data'!$AE$2:$AE$1068) | K15: =IF(E15=0,"",J15/E15) | L15: =IF(OR(E15<Controls!$B$47,G15=0),"",SUMPRODUCT('Historical Data'!$AW$2:$AW$1068*'Historical Data'!$AP$2:$AP$1068*'Historical Data'!$AK$2:$AK$1068)/G15) | M15: =IF(OR(E15<Controls!$B$47,SUMPRODUCT('Historical Data'!$AW$2:$AW$1068*'Historical Data'!$AP$2:$AP$1068*'Historical Data'!$AE$2:$AE$1068*'Historical Data'!$N$2:$N$1068)=0),"",SUMPRODUCT('Historical Data'!$AW$2:$AW$1068*'Historical Data'!$AP$2:$AP$1068*'Historical Data'!$AE$2:$AE$1068*'Historical Data'!$Q$2:$Q$1068)/SUMPRODUCT('Historical Data'!$AW$2:$AW$1068*'Historical Data'!$AP$2:$AP$1068*'Historical Data'!$AE$2:$AE$1068*'Historical Data'!$N$2:$N$1068)) | N15: =IF(OR(E15<Controls!$B$47,G15=0),"",SUMPRODUCT('Historical Data'!$AW$2:$AW$1068*'Historical Data'!$AP$2:$AP$1068*'Historical Data'!$AJ$2:$AJ$1068)/G15) | O15: =IF(SUMPRODUCT('Historical Data'!$AW$2:$AW$1068*'Historical Data'!$AP$2:$AP$1068*'Historical Data'!$AM$2:$AM$1068)=0,"",SUMPRODUCT('Historical Data'!$AW$2:$AW$1068*'Historical Data'!$AP$2:$AP$1068*'Historical Data'!$AM$2:$AM$1068*'Historical Data'!$AL$2:$AL$1068)/SUMPRODUCT('Historical Data'!$AW$2:$AW$1068*'Historical Data'!$AP$2:$AP$1068*'Historical Data'!$AM$2:$AM$1068)) | P15: =IF(E15=0,"",SUMPRODUCT('Historical Data'!$AW$2:$AW$1068*'Historical Data'!$AP$2:$AP$1068*'Historical Data'!$AA$2:$AA$1068)/E15) | Q15: =IF(E15=0,"",SUMPRODUCT('Historical Data'!$AW$2:$AW$1068*'Historical Data'!$AP$2:$AP$1068*'Historical Data'!$M$2:$M$1068)/E15) | R15: =IF(E15=0,"",G15/E15) | S15: =IF(E15=0,"",SUMPRODUCT('Historical Data'!$AW$2:$AW$1068*'Historical Data'!$AP$2:$AP$1068*'Historical Data'!$AN$2:$AN$1068)/E15) | T15: =IF(E15=0,"",SUMPRODUCT('Historical Data'!$AW$2:$AW$1068*'Historical Data'!$AP$2:$AP$1068*'Historical Data'!$AO$2:$AO$1068)/E15) | U15: =IF(AND(E15>=Controls!$B$40,G15>=Controls!$B$41,IF(I15="",1,I15)<=Controls!$B$43),"Yes","No") | V15: =IF(E15+Controls!$B$42=0,0,E15/(E15+Controls!$B$42)) | W15: =IF(L15="",$C$10,V15*L15+(1-V15)*$C$10) | X15: =IF(OR($C$10="",$C$10=0),"",W15/$C$10) | Y15: =IF(AND(E15>=Controls!$B$40,G15>=Controls!$B$41),1,0) | Z15: =IF(L15="",0,ABS(W15-$C$10)) | AA15: =IF(L15="","No","Yes")
A16: 3 | B16: T3: new/renewal + industry | C16: NR + industry | D16: =SUMPRODUCT('Historical Data'!$AX$2:$AX$1068*'Historical Data'!$AD$2:$AD$1068) | E16: =SUMPRODUCT('Historical Data'!$AX$2:$AX$1068*'Historical Data'!$AP$2:$AP$1068) | F16: =IF(D16=0,"",E16/D16) | G16: =SUMPRODUCT('Historical Data'!$AX$2:$AX$1068*'Historical Data'!$AP$2:$AP$1068*'Historical Data'!$N$2:$N$1068) | H16: =SUMPRODUCT('Historical Data'!$AX$2:$AX$1068*'Historical Data'!$AP$2:$AP$1068*'Historical Data'!$AH$2:$AH$1068) | I16: =IF(E16=0,"",H16/E16) | J16: =SUMPRODUCT('Historical Data'!$AX$2:$AX$1068*'Historical Data'!$AP$2:$AP$1068*'Historical Data'!$AE$2:$AE$1068) | K16: =IF(E16=0,"",J16/E16) | L16: =IF(OR(E16<Controls!$B$47,G16=0),"",SUMPRODUCT('Historical Data'!$AX$2:$AX$1068*'Historical Data'!$AP$2:$AP$1068*'Historical Data'!$AK$2:$AK$1068)/G16) | M16: =IF(OR(E16<Controls!$B$47,SUMPRODUCT('Historical Data'!$AX$2:$AX$1068*'Historical Data'!$AP$2:$AP$1068*'Historical Data'!$AE$2:$AE$1068*'Historical Data'!$N$2:$N$1068)=0),"",SUMPRODUCT('Historical Data'!$AX$2:$AX$1068*'Historical Data'!$AP$2:$AP$1068*'Historical Data'!$AE$2:$AE$1068*'Historical Data'!$Q$2:$Q$1068)/SUMPRODUCT('Historical Data'!$AX$2:$AX$1068*'Historical Data'!$AP$2:$AP$1068*'Historical Data'!$AE$2:$AE$1068*'Historical Data'!$N$2:$N$1068)) | N16: =IF(OR(E16<Controls!$B$47,G16=0),"",SUMPRODUCT('Historical Data'!$AX$2:$AX$1068*'Historical Data'!$AP$2:$AP$1068*'Historical Data'!$AJ$2:$AJ$1068)/G16) | O16: =IF(SUMPRODUCT('Historical Data'!$AX$2:$AX$1068*'Historical Data'!$AP$2:$AP$1068*'Historical Data'!$AM$2:$AM$1068)=0,"",SUMPRODUCT('Historical Data'!$AX$2:$AX$1068*'Historical Data'!$AP$2:$AP$1068*'Historical Data'!$AM$2:$AM$1068*'Historical Data'!$AL$2:$AL$1068)/SUMPRODUCT('Historical Data'!$AX$2:$AX$1068*'Historical Data'!$AP$2:$AP$1068*'Historical Data'!$AM$2:$AM$1068)) | P16: =IF(E16=0,"",SUMPRODUCT('Historical Data'!$AX$2:$AX$1068*'Historical Data'!$AP$2:$AP$1068*'Historical Data'!$AA$2:$AA$1068)/E16) | Q16: =IF(E16=0,"",SUMPRODUCT('Historical Data'!$AX$2:$AX$1068*'Historical Data'!$AP$2:$AP$1068*'Historical Data'!$M$2:$M$1068)/E16) | R16: =IF(E16=0,"",G16/E16) | S16: =IF(E16=0,"",SUMPRODUCT('Historical Data'!$AX$2:$AX$1068*'Historical Data'!$AP$2:$AP$1068*'Historical Data'!$AN$2:$AN$1068)/E16) | T16: =IF(E16=0,"",SUMPRODUCT('Historical Data'!$AX$2:$AX$1068*'Historical Data'!$AP$2:$AP$1068*'Historical Data'!$AO$2:$AO$1068)/E16) | U16: =IF(AND(E16>=Controls!$B$40,G16>=Controls!$B$41,IF(I16="",1,I16)<=Controls!$B$43),"Yes","No") | V16: =IF(E16+Controls!$B$42=0,0,E16/(E16+Controls!$B$42)) | W16: =IF(L16="",$C$10,V16*L16+(1-V16)*$C$10) | X16: =IF(OR($C$10="",$C$10=0),"",W16/$C$10) | Y16: =IF(AND(E16>=Controls!$B$40,G16>=Controls!$B$41),1,0) | Z16: =IF(L16="",0,ABS(W16-$C$10)) | AA16: =IF(L16="","No","Yes")
A17: 4 | B17: T4: new/renewal + ISO | C17: NR + ISO | D17: =SUMPRODUCT('Historical Data'!$AY$2:$AY$1068*'Historical Data'!$AD$2:$AD$1068) | E17: =SUMPRODUCT('Historical Data'!$AY$2:$AY$1068*'Historical Data'!$AP$2:$AP$1068) | F17: =IF(D17=0,"",E17/D17) | G17: =SUMPRODUCT('Historical Data'!$AY$2:$AY$1068*'Historical Data'!$AP$2:$AP$1068*'Historical Data'!$N$2:$N$1068) | H17: =SUMPRODUCT('Historical Data'!$AY$2:$AY$1068*'Historical Data'!$AP$2:$AP$1068*'Historical Data'!$AH$2:$AH$1068) | I17: =IF(E17=0,"",H17/E17) | J17: =SUMPRODUCT('Historical Data'!$AY$2:$AY$1068*'Historical Data'!$AP$2:$AP$1068*'Historical Data'!$AE$2:$AE$1068) | K17: =IF(E17=0,"",J17/E17) | L17: =IF(OR(E17<Controls!$B$47,G17=0),"",SUMPRODUCT('Historical Data'!$AY$2:$AY$1068*'Historical Data'!$AP$2:$AP$1068*'Historical Data'!$AK$2:$AK$1068)/G17) | M17: =IF(OR(E17<Controls!$B$47,SUMPRODUCT('Historical Data'!$AY$2:$AY$1068*'Historical Data'!$AP$2:$AP$1068*'Historical Data'!$AE$2:$AE$1068*'Historical Data'!$N$2:$N$1068)=0),"",SUMPRODUCT('Historical Data'!$AY$2:$AY$1068*'Historical Data'!$AP$2:$AP$1068*'Historical Data'!$AE$2:$AE$1068*'Historical Data'!$Q$2:$Q$1068)/SUMPRODUCT('Historical Data'!$AY$2:$AY$1068*'Historical Data'!$AP$2:$AP$1068*'Historical Data'!$AE$2:$AE$1068*'Historical Data'!$N$2:$N$1068)) | N17: =IF(OR(E17<Controls!$B$47,G17=0),"",SUMPRODUCT('Historical Data'!$AY$2:$AY$1068*'Historical Data'!$AP$2:$AP$1068*'Historical Data'!$AJ$2:$AJ$1068)/G17) | O17: =IF(SUMPRODUCT('Historical Data'!$AY$2:$AY$1068*'Historical Data'!$AP$2:$AP$1068*'Historical Data'!$AM$2:$AM$1068)=0,"",SUMPRODUCT('Historical Data'!$AY$2:$AY$1068*'Historical Data'!$AP$2:$AP$1068*'Historical Data'!$AM$2:$AM$1068*'Historical Data'!$AL$2:$AL$1068)/SUMPRODUCT('Historical Data'!$AY$2:$AY$1068*'Historical Data'!$AP$2:$AP$1068*'Historical Data'!$AM$2:$AM$1068)) | P17: =IF(E17=0,"",SUMPRODUCT('Historical Data'!$AY$2:$AY$1068*'Historical Data'!$AP$2:$AP$1068*'Historical Data'!$AA$2:$AA$1068)/E17) | Q17: =IF(E17=0,"",SUMPRODUCT('Historical Data'!$AY$2:$AY$1068*'Historical Data'!$AP$2:$AP$1068*'Historical Data'!$M$2:$M$1068)/E17) | R17: =IF(E17=0,"",G17/E17) | S17: =IF(E17=0,"",SUMPRODUCT('Historical Data'!$AY$2:$AY$1068*'Historical Data'!$AP$2:$AP$1068*'Historical Data'!$AN$2:$AN$1068)/E17) | T17: =IF(E17=0,"",SUMPRODUCT('Historical Data'!$AY$2:$AY$1068*'Historical Data'!$AP$2:$AP$1068*'Historical Data'!$AO$2:$AO$1068)/E17) | U17: =IF(AND(E17>=Controls!$B$40,G17>=Controls!$B$41,IF(I17="",1,I17)<=Controls!$B$43),"Yes","No") | V17: =IF(E17+Controls!$B$42=0,0,E17/(E17+Controls!$B$42)) | W17: =IF(L17="",$C$10,V17*L17+(1-V17)*$C$10) | X17: =IF(OR($C$10="",$C$10=0),"",W17/$C$10) | Y17: =IF(AND(E17>=Controls!$B$40,G17>=Controls!$B$41),1,0) | Z17: =IF(L17="",0,ABS(W17-$C$10)) | AA17: =IF(L17="","No","Yes")
A18: 5 | B18: T5: new/renewal + position | C18: NR + position | D18: =SUMPRODUCT('Historical Data'!$AZ$2:$AZ$1068*'Historical Data'!$AD$2:$AD$1068) | E18: =SUMPRODUCT('Historical Data'!$AZ$2:$AZ$1068*'Historical Data'!$AP$2:$AP$1068) | F18: =IF(D18=0,"",E18/D18) | G18: =SUMPRODUCT('Historical Data'!$AZ$2:$AZ$1068*'Historical Data'!$AP$2:$AP$1068*'Historical Data'!$N$2:$N$1068) | H18: =SUMPRODUCT('Historical Data'!$AZ$2:$AZ$1068*'Historical Data'!$AP$2:$AP$1068*'Historical Data'!$AH$2:$AH$1068) | I18: =IF(E18=0,"",H18/E18) | J18: =SUMPRODUCT('Historical Data'!$AZ$2:$AZ$1068*'Historical Data'!$AP$2:$AP$1068*'Historical Data'!$AE$2:$AE$1068) | K18: =IF(E18=0,"",J18/E18) | L18: =IF(OR(E18<Controls!$B$47,G18=0),"",SUMPRODUCT('Historical Data'!$AZ$2:$AZ$1068*'Historical Data'!$AP$2:$AP$1068*'Historical Data'!$AK$2:$AK$1068)/G18) | M18: =IF(OR(E18<Controls!$B$47,SUMPRODUCT('Historical Data'!$AZ$2:$AZ$1068*'Historical Data'!$AP$2:$AP$1068*'Historical Data'!$AE$2:$AE$1068*'Historical Data'!$N$2:$N$1068)=0),"",SUMPRODUCT('Historical Data'!$AZ$2:$AZ$1068*'Historical Data'!$AP$2:$AP$1068*'Historical Data'!$AE$2:$AE$1068*'Historical Data'!$Q$2:$Q$1068)/SUMPRODUCT('Historical Data'!$AZ$2:$AZ$1068*'Historical Data'!$AP$2:$AP$1068*'Historical Data'!$AE$2:$AE$1068*'Historical Data'!$N$2:$N$1068)) | N18: =IF(OR(E18<Controls!$B$47,G18=0),"",SUMPRODUCT('Historical Data'!$AZ$2:$AZ$1068*'Historical Data'!$AP$2:$AP$1068*'Historical Data'!$AJ$2:$AJ$1068)/G18) | O18: =IF(SUMPRODUCT('Historical Data'!$AZ$2:$AZ$1068*'Historical Data'!$AP$2:$AP$1068*'Historical Data'!$AM$2:$AM$1068)=0,"",SUMPRODUCT('Historical Data'!$AZ$2:$AZ$1068*'Historical Data'!$AP$2:$AP$1068*'Historical Data'!$AM$2:$AM$1068*'Historical Data'!$AL$2:$AL$1068)/SUMPRODUCT('Historical Data'!$AZ$2:$AZ$1068*'Historical Data'!$AP$2:$AP$1068*'Historical Data'!$AM$2:$AM$1068)) | P18: =IF(E18=0,"",SUMPRODUCT('Historical Data'!$AZ$2:$AZ$1068*'Historical Data'!$AP$2:$AP$1068*'Historical Data'!$AA$2:$AA$1068)/E18) | Q18: =IF(E18=0,"",SUMPRODUCT('Historical Data'!$AZ$2:$AZ$1068*'Historical Data'!$AP$2:$AP$1068*'Historical Data'!$M$2:$M$1068)/E18) | R18: =IF(E18=0,"",G18/E18) | S18: =IF(E18=0,"",SUMPRODUCT('Historical Data'!$AZ$2:$AZ$1068*'Historical Data'!$AP$2:$AP$1068*'Historical Data'!$AN$2:$AN$1068)/E18) | T18: =IF(E18=0,"",SUMPRODUCT('Historical Data'!$AZ$2:$AZ$1068*'Historical Data'!$AP$2:$AP$1068*'Historical Data'!$AO$2:$AO$1068)/E18) | U18: =IF(AND(E18>=Controls!$B$40,G18>=Controls!$B$41,IF(I18="",1,I18)<=Controls!$B$43),"Yes","No") | V18: =IF(E18+Controls!$B$42=0,0,E18/(E18+Controls!$B$42)) | W18: =IF(L18="",$C$10,V18*L18+(1-V18)*$C$10) | X18: =IF(OR($C$10="",$C$10=0),"",W18/$C$10) | Y18: =IF(AND(E18>=Controls!$B$40,G18>=Controls!$B$41),1,0) | Z18: =IF(L18="",0,ABS(W18-$C$10)) | AA18: =IF(L18="","No","Yes")
A19: 6 | B19: T6: new/renewal only | C19: NR | D19: =SUMPRODUCT('Historical Data'!$BA$2:$BA$1068*'Historical Data'!$AD$2:$AD$1068) | E19: =SUMPRODUCT('Historical Data'!$BA$2:$BA$1068*'Historical Data'!$AP$2:$AP$1068) | F19: =IF(D19=0,"",E19/D19) | G19: =SUMPRODUCT('Historical Data'!$BA$2:$BA$1068*'Historical Data'!$AP$2:$AP$1068*'Historical Data'!$N$2:$N$1068) | H19: =SUMPRODUCT('Historical Data'!$BA$2:$BA$1068*'Historical Data'!$AP$2:$AP$1068*'Historical Data'!$AH$2:$AH$1068) | I19: =IF(E19=0,"",H19/E19) | J19: =SUMPRODUCT('Historical Data'!$BA$2:$BA$1068*'Historical Data'!$AP$2:$AP$1068*'Historical Data'!$AE$2:$AE$1068) | K19: =IF(E19=0,"",J19/E19) | L19: =IF(OR(E19<Controls!$B$47,G19=0),"",SUMPRODUCT('Historical Data'!$BA$2:$BA$1068*'Historical Data'!$AP$2:$AP$1068*'Historical Data'!$AK$2:$AK$1068)/G19) | M19: =IF(OR(E19<Controls!$B$47,SUMPRODUCT('Historical Data'!$BA$2:$BA$1068*'Historical Data'!$AP$2:$AP$1068*'Historical Data'!$AE$2:$AE$1068*'Historical Data'!$N$2:$N$1068)=0),"",SUMPRODUCT('Historical Data'!$BA$2:$BA$1068*'Historical Data'!$AP$2:$AP$1068*'Historical Data'!$AE$2:$AE$1068*'Historical Data'!$Q$2:$Q$1068)/SUMPRODUCT('Historical Data'!$BA$2:$BA$1068*'Historical Data'!$AP$2:$AP$1068*'Historical Data'!$AE$2:$AE$1068*'Historical Data'!$N$2:$N$1068)) | N19: =IF(OR(E19<Controls!$B$47,G19=0),"",SUMPRODUCT('Historical Data'!$BA$2:$BA$1068*'Historical Data'!$AP$2:$AP$1068*'Historical Data'!$AJ$2:$AJ$1068)/G19) | O19: =IF(SUMPRODUCT('Historical Data'!$BA$2:$BA$1068*'Historical Data'!$AP$2:$AP$1068*'Historical Data'!$AM$2:$AM$1068)=0,"",SUMPRODUCT('Historical Data'!$BA$2:$BA$1068*'Historical Data'!$AP$2:$AP$1068*'Historical Data'!$AM$2:$AM$1068*'Historical Data'!$AL$2:$AL$1068)/SUMPRODUCT('Historical Data'!$BA$2:$BA$1068*'Historical Data'!$AP$2:$AP$1068*'Historical Data'!$AM$2:$AM$1068)) | P19: =IF(E19=0,"",SUMPRODUCT('Historical Data'!$BA$2:$BA$1068*'Historical Data'!$AP$2:$AP$1068*'Historical Data'!$AA$2:$AA$1068)/E19) | Q19: =IF(E19=0,"",SUMPRODUCT('Historical Data'!$BA$2:$BA$1068*'Historical Data'!$AP$2:$AP$1068*'Historical Data'!$M$2:$M$1068)/E19) | R19: =IF(E19=0,"",G19/E19) | S19: =IF(E19=0,"",SUMPRODUCT('Historical Data'!$BA$2:$BA$1068*'Historical Data'!$AP$2:$AP$1068*'Historical Data'!$AN$2:$AN$1068)/E19) | T19: =IF(E19=0,"",SUMPRODUCT('Historical Data'!$BA$2:$BA$1068*'Historical Data'!$AP$2:$AP$1068*'Historical Data'!$AO$2:$AO$1068)/E19) | U19: =IF(AND(E19>=Controls!$B$40,G19>=Controls!$B$41,IF(I19="",1,I19)<=Controls!$B$43),"Yes","No") | V19: =IF(E19+Controls!$B$42=0,0,E19/(E19+Controls!$B$42)) | W19: =IF(L19="",$C$10,V19*L19+(1-V19)*$C$10) | X19: =IF(OR($C$10="",$C$10=0),"",W19/$C$10) | Y19: =IF(AND(E19>=Controls!$B$40,G19>=Controls!$B$41),1,0) | Z19: =IF(L19="",0,ABS(W19-$C$10)) | AA19: =IF(L19="","No","Yes")
A20: 7 | B20: T7: seasoned book (baseline) | C20: all seasoned deals in window | D20: =SUMPRODUCT('Historical Data'!$BB$2:$BB$1068*'Historical Data'!$AD$2:$AD$1068) | E20: =SUMPRODUCT('Historical Data'!$BB$2:$BB$1068*'Historical Data'!$AP$2:$AP$1068) | F20: =IF(D20=0,"",E20/D20) | G20: =SUMPRODUCT('Historical Data'!$BB$2:$BB$1068*'Historical Data'!$AP$2:$AP$1068*'Historical Data'!$N$2:$N$1068) | H20: =SUMPRODUCT('Historical Data'!$BB$2:$BB$1068*'Historical Data'!$AP$2:$AP$1068*'Historical Data'!$AH$2:$AH$1068) | I20: =IF(E20=0,"",H20/E20) | J20: =SUMPRODUCT('Historical Data'!$BB$2:$BB$1068*'Historical Data'!$AP$2:$AP$1068*'Historical Data'!$AE$2:$AE$1068) | K20: =IF(E20=0,"",J20/E20) | L20: =IF(OR(E20<Controls!$B$47,G20=0),"",SUMPRODUCT('Historical Data'!$BB$2:$BB$1068*'Historical Data'!$AP$2:$AP$1068*'Historical Data'!$AK$2:$AK$1068)/G20) | M20: =IF(OR(E20<Controls!$B$47,SUMPRODUCT('Historical Data'!$BB$2:$BB$1068*'Historical Data'!$AP$2:$AP$1068*'Historical Data'!$AE$2:$AE$1068*'Historical Data'!$N$2:$N$1068)=0),"",SUMPRODUCT('Historical Data'!$BB$2:$BB$1068*'Historical Data'!$AP$2:$AP$1068*'Historical Data'!$AE$2:$AE$1068*'Historical Data'!$Q$2:$Q$1068)/SUMPRODUCT('Historical Data'!$BB$2:$BB$1068*'Historical Data'!$AP$2:$AP$1068*'Historical Data'!$AE$2:$AE$1068*'Historical Data'!$N$2:$N$1068)) | N20: =IF(OR(E20<Controls!$B$47,G20=0),"",SUMPRODUCT('Historical Data'!$BB$2:$BB$1068*'Historical Data'!$AP$2:$AP$1068*'Historical Data'!$AJ$2:$AJ$1068)/G20) | O20: =IF(SUMPRODUCT('Historical Data'!$BB$2:$BB$1068*'Historical Data'!$AP$2:$AP$1068*'Historical Data'!$AM$2:$AM$1068)=0,"",SUMPRODUCT('Historical Data'!$BB$2:$BB$1068*'Historical Data'!$AP$2:$AP$1068*'Historical Data'!$AM$2:$AM$1068*'Historical Data'!$AL$2:$AL$1068)/SUMPRODUCT('Historical Data'!$BB$2:$BB$1068*'Historical Data'!$AP$2:$AP$1068*'Historical Data'!$AM$2:$AM$1068)) | P20: =IF(E20=0,"",SUMPRODUCT('Historical Data'!$BB$2:$BB$1068*'Historical Data'!$AP$2:$AP$1068*'Historical Data'!$AA$2:$AA$1068)/E20) | Q20: =IF(E20=0,"",SUMPRODUCT('Historical Data'!$BB$2:$BB$1068*'Historical Data'!$AP$2:$AP$1068*'Historical Data'!$M$2:$M$1068)/E20) | R20: =IF(E20=0,"",G20/E20) | S20: =IF(E20=0,"",SUMPRODUCT('Historical Data'!$BB$2:$BB$1068*'Historical Data'!$AP$2:$AP$1068*'Historical Data'!$AN$2:$AN$1068)/E20) | T20: =IF(E20=0,"",SUMPRODUCT('Historical Data'!$BB$2:$BB$1068*'Historical Data'!$AP$2:$AP$1068*'Historical Data'!$AO$2:$AO$1068)/E20) | U20: =IF(AND(E20>=Controls!$B$40,G20>=Controls!$B$41,IF(I20="",1,I20)<=Controls!$B$43),"Yes","No") | V20: =IF(E20+Controls!$B$42=0,0,E20/(E20+Controls!$B$42)) | W20: =IF(L20="",$C$10,V20*L20+(1-V20)*$C$10) | X20: =IF(OR($C$10="",$C$10=0),"",W20/$C$10) | Y20: =IF(AND(E20>=Controls!$B$40,G20>=Controls!$B$41),1,0) | Z20: =IF(L20="",0,ABS(W20-$C$10)) | AA20: =IF(L20="","No","Yes")
B21: SINGLE-DIMENSION EVIDENCE (informational + largest-impact test)
A22: S1 | B22: Position only | C22: Position only | D22: =SUMPRODUCT('Historical Data'!$AQ$2:$AQ$1068*'Historical Data'!$AD$2:$AD$1068) | E22: =SUMPRODUCT('Historical Data'!$AQ$2:$AQ$1068*'Historical Data'!$AP$2:$AP$1068) | F22: =IF(D22=0,"",E22/D22) | G22: =SUMPRODUCT('Historical Data'!$AQ$2:$AQ$1068*'Historical Data'!$AP$2:$AP$1068*'Historical Data'!$N$2:$N$1068) | H22: =SUMPRODUCT('Historical Data'!$AQ$2:$AQ$1068*'Historical Data'!$AP$2:$AP$1068*'Historical Data'!$AH$2:$AH$1068) | I22: =IF(E22=0,"",H22/E22) | J22: =SUMPRODUCT('Historical Data'!$AQ$2:$AQ$1068*'Historical Data'!$AP$2:$AP$1068*'Historical Data'!$AE$2:$AE$1068) | K22: =IF(E22=0,"",J22/E22) | L22: =IF(OR(E22<Controls!$B$47,G22=0),"",SUMPRODUCT('Historical Data'!$AQ$2:$AQ$1068*'Historical Data'!$AP$2:$AP$1068*'Historical Data'!$AK$2:$AK$1068)/G22) | M22: =IF(OR(E22<Controls!$B$47,SUMPRODUCT('Historical Data'!$AQ$2:$AQ$1068*'Historical Data'!$AP$2:$AP$1068*'Historical Data'!$AE$2:$AE$1068*'Historical Data'!$N$2:$N$1068)=0),"",SUMPRODUCT('Historical Data'!$AQ$2:$AQ$1068*'Historical Data'!$AP$2:$AP$1068*'Historical Data'!$AE$2:$AE$1068*'Historical Data'!$Q$2:$Q$1068)/SUMPRODUCT('Historical Data'!$AQ$2:$AQ$1068*'Historical Data'!$AP$2:$AP$1068*'Historical Data'!$AE$2:$AE$1068*'Historical Data'!$N$2:$N$1068)) | N22: =IF(OR(E22<Controls!$B$47,G22=0),"",SUMPRODUCT('Historical Data'!$AQ$2:$AQ$1068*'Historical Data'!$AP$2:$AP$1068*'Historical Data'!$AJ$2:$AJ$1068)/G22) | O22: =IF(SUMPRODUCT('Historical Data'!$AQ$2:$AQ$1068*'Historical Data'!$AP$2:$AP$1068*'Historical Data'!$AM$2:$AM$1068)=0,"",SUMPRODUCT('Historical Data'!$AQ$2:$AQ$1068*'Historical Data'!$AP$2:$AP$1068*'Historical Data'!$AM$2:$AM$1068*'Historical Data'!$AL$2:$AL$1068)/SUMPRODUCT('Historical Data'!$AQ$2:$AQ$1068*'Historical Data'!$AP$2:$AP$1068*'Historical Data'!$AM$2:$AM$1068)) | P22: =IF(E22=0,"",SUMPRODUCT('Historical Data'!$AQ$2:$AQ$1068*'Historical Data'!$AP$2:$AP$1068*'Historical Data'!$AA$2:$AA$1068)/E22) | Q22: =IF(E22=0,"",SUMPRODUCT('Historical Data'!$AQ$2:$AQ$1068*'Historical Data'!$AP$2:$AP$1068*'Historical Data'!$M$2:$M$1068)/E22) | R22: =IF(E22=0,"",G22/E22) | S22: =IF(E22=0,"",SUMPRODUCT('Historical Data'!$AQ$2:$AQ$1068*'Historical Data'!$AP$2:$AP$1068*'Historical Data'!$AN$2:$AN$1068)/E22) | T22: =IF(E22=0,"",SUMPRODUCT('Historical Data'!$AQ$2:$AQ$1068*'Historical Data'!$AP$2:$AP$1068*'Historical Data'!$AO$2:$AO$1068)/E22) | U22: =IF(AND(E22>=Controls!$B$40,G22>=Controls!$B$41,IF(I22="",1,I22)<=Controls!$B$43),"Yes","No") | V22: =IF(E22+Controls!$B$42=0,0,E22/(E22+Controls!$B$42)) | W22: =IF(L22="",$C$10,V22*L22+(1-V22)*$C$10) | X22: =IF(OR($C$10="",$C$10=0),"",W22/$C$10) | Y22: =IF(AND(E22>=Controls!$B$40,G22>=Controls!$B$41),1,0) | Z22: =IF(L22="",0,ABS(W22-$C$10)) | AA22: =IF(L22="","No","Yes")
A23: S2 | B23: New/renewal only | C23: New/renewal only | D23: =SUMPRODUCT('Historical Data'!$AR$2:$AR$1068*'Historical Data'!$AD$2:$AD$1068) | E23: =SUMPRODUCT('Historical Data'!$AR$2:$AR$1068*'Historical Data'!$AP$2:$AP$1068) | F23: =IF(D23=0,"",E23/D23) | G23: =SUMPRODUCT('Historical Data'!$AR$2:$AR$1068*'Historical Data'!$AP$2:$AP$1068*'Historical Data'!$N$2:$N$1068) | H23: =SUMPRODUCT('Historical Data'!$AR$2:$AR$1068*'Historical Data'!$AP$2:$AP$1068*'Historical Data'!$AH$2:$AH$1068) | I23: =IF(E23=0,"",H23/E23) | J23: =SUMPRODUCT('Historical Data'!$AR$2:$AR$1068*'Historical Data'!$AP$2:$AP$1068*'Historical Data'!$AE$2:$AE$1068) | K23: =IF(E23=0,"",J23/E23) | L23: =IF(OR(E23<Controls!$B$47,G23=0),"",SUMPRODUCT('Historical Data'!$AR$2:$AR$1068*'Historical Data'!$AP$2:$AP$1068*'Historical Data'!$AK$2:$AK$1068)/G23) | M23: =IF(OR(E23<Controls!$B$47,SUMPRODUCT('Historical Data'!$AR$2:$AR$1068*'Historical Data'!$AP$2:$AP$1068*'Historical Data'!$AE$2:$AE$1068*'Historical Data'!$N$2:$N$1068)=0),"",SUMPRODUCT('Historical Data'!$AR$2:$AR$1068*'Historical Data'!$AP$2:$AP$1068*'Historical Data'!$AE$2:$AE$1068*'Historical Data'!$Q$2:$Q$1068)/SUMPRODUCT('Historical Data'!$AR$2:$AR$1068*'Historical Data'!$AP$2:$AP$1068*'Historical Data'!$AE$2:$AE$1068*'Historical Data'!$N$2:$N$1068)) | N23: =IF(OR(E23<Controls!$B$47,G23=0),"",SUMPRODUCT('Historical Data'!$AR$2:$AR$1068*'Historical Data'!$AP$2:$AP$1068*'Historical Data'!$AJ$2:$AJ$1068)/G23) | O23: =IF(SUMPRODUCT('Historical Data'!$AR$2:$AR$1068*'Historical Data'!$AP$2:$AP$1068*'Historical Data'!$AM$2:$AM$1068)=0,"",SUMPRODUCT('Historical Data'!$AR$2:$AR$1068*'Historical Data'!$AP$2:$AP$1068*'Historical Data'!$AM$2:$AM$1068*'Historical Data'!$AL$2:$AL$1068)/SUMPRODUCT('Historical Data'!$AR$2:$AR$1068*'Historical Data'!$AP$2:$AP$1068*'Historical Data'!$AM$2:$AM$1068)) | P23: =IF(E23=0,"",SUMPRODUCT('Historical Data'!$AR$2:$AR$1068*'Historical Data'!$AP$2:$AP$1068*'Historical Data'!$AA$2:$AA$1068)/E23) | Q23: =IF(E23=0,"",SUMPRODUCT('Historical Data'!$AR$2:$AR$1068*'Historical Data'!$AP$2:$AP$1068*'Historical Data'!$M$2:$M$1068)/E23) | R23: =IF(E23=0,"",G23/E23) | S23: =IF(E23=0,"",SUMPRODUCT('Historical Data'!$AR$2:$AR$1068*'Historical Data'!$AP$2:$AP$1068*'Historical Data'!$AN$2:$AN$1068)/E23) | T23: =IF(E23=0,"",SUMPRODUCT('Historical Data'!$AR$2:$AR$1068*'Historical Data'!$AP$2:$AP$1068*'Historical Data'!$AO$2:$AO$1068)/E23) | U23: =IF(AND(E23>=Controls!$B$40,G23>=Controls!$B$41,IF(I23="",1,I23)<=Controls!$B$43),"Yes","No") | V23: =IF(E23+Controls!$B$42=0,0,E23/(E23+Controls!$B$42)) | W23: =IF(L23="",$C$10,V23*L23+(1-V23)*$C$10) | X23: =IF(OR($C$10="",$C$10=0),"",W23/$C$10) | Y23: =IF(AND(E23>=Controls!$B$40,G23>=Controls!$B$41),1,0) | Z23: =IF(L23="",0,ABS(W23-$C$10)) | AA23: =IF(L23="","No","Yes")
A24: S3 | B24: Industry only | C24: Industry only | D24: =SUMPRODUCT('Historical Data'!$AS$2:$AS$1068*'Historical Data'!$AD$2:$AD$1068) | E24: =SUMPRODUCT('Historical Data'!$AS$2:$AS$1068*'Historical Data'!$AP$2:$AP$1068) | F24: =IF(D24=0,"",E24/D24) | G24: =SUMPRODUCT('Historical Data'!$AS$2:$AS$1068*'Historical Data'!$AP$2:$AP$1068*'Historical Data'!$N$2:$N$1068) | H24: =SUMPRODUCT('Historical Data'!$AS$2:$AS$1068*'Historical Data'!$AP$2:$AP$1068*'Historical Data'!$AH$2:$AH$1068) | I24: =IF(E24=0,"",H24/E24) | J24: =SUMPRODUCT('Historical Data'!$AS$2:$AS$1068*'Historical Data'!$AP$2:$AP$1068*'Historical Data'!$AE$2:$AE$1068) | K24: =IF(E24=0,"",J24/E24) | L24: =IF(OR(E24<Controls!$B$47,G24=0),"",SUMPRODUCT('Historical Data'!$AS$2:$AS$1068*'Historical Data'!$AP$2:$AP$1068*'Historical Data'!$AK$2:$AK$1068)/G24) | M24: =IF(OR(E24<Controls!$B$47,SUMPRODUCT('Historical Data'!$AS$2:$AS$1068*'Historical Data'!$AP$2:$AP$1068*'Historical Data'!$AE$2:$AE$1068*'Historical Data'!$N$2:$N$1068)=0),"",SUMPRODUCT('Historical Data'!$AS$2:$AS$1068*'Historical Data'!$AP$2:$AP$1068*'Historical Data'!$AE$2:$AE$1068*'Historical Data'!$Q$2:$Q$1068)/SUMPRODUCT('Historical Data'!$AS$2:$AS$1068*'Historical Data'!$AP$2:$AP$1068*'Historical Data'!$AE$2:$AE$1068*'Historical Data'!$N$2:$N$1068)) | N24: =IF(OR(E24<Controls!$B$47,G24=0),"",SUMPRODUCT('Historical Data'!$AS$2:$AS$1068*'Historical Data'!$AP$2:$AP$1068*'Historical Data'!$AJ$2:$AJ$1068)/G24) | O24: =IF(SUMPRODUCT('Historical Data'!$AS$2:$AS$1068*'Historical Data'!$AP$2:$AP$1068*'Historical Data'!$AM$2:$AM$1068)=0,"",SUMPRODUCT('Historical Data'!$AS$2:$AS$1068*'Historical Data'!$AP$2:$AP$1068*'Historical Data'!$AM$2:$AM$1068*'Historical Data'!$AL$2:$AL$1068)/SUMPRODUCT('Historical Data'!$AS$2:$AS$1068*'Historical Data'!$AP$2:$AP$1068*'Historical Data'!$AM$2:$AM$1068)) | P24: =IF(E24=0,"",SUMPRODUCT('Historical Data'!$AS$2:$AS$1068*'Historical Data'!$AP$2:$AP$1068*'Historical Data'!$AA$2:$AA$1068)/E24) | Q24: =IF(E24=0,"",SUMPRODUCT('Historical Data'!$AS$2:$AS$1068*'Historical Data'!$AP$2:$AP$1068*'Historical Data'!$M$2:$M$1068)/E24) | R24: =IF(E24=0,"",G24/E24) | S24: =IF(E24=0,"",SUMPRODUCT('Historical Data'!$AS$2:$AS$1068*'Historical Data'!$AP$2:$AP$1068*'Historical Data'!$AN$2:$AN$1068)/E24) | T24: =IF(E24=0,"",SUMPRODUCT('Historical Data'!$AS$2:$AS$1068*'Historical Data'!$AP$2:$AP$1068*'Historical Data'!$AO$2:$AO$1068)/E24) | U24: =IF(AND(E24>=Controls!$B$40,G24>=Controls!$B$41,IF(I24="",1,I24)<=Controls!$B$43),"Yes","No") | V24: =IF(E24+Controls!$B$42=0,0,E24/(E24+Controls!$B$42)) | W24: =IF(L24="",$C$10,V24*L24+(1-V24)*$C$10) | X24: =IF(OR($C$10="",$C$10=0),"",W24/$C$10) | Y24: =IF(AND(E24>=Controls!$B$40,G24>=Controls!$B$41),1,0) | Z24: =IF(L24="",0,ABS(W24-$C$10)) | AA24: =IF(L24="","No","Yes")
A25: S4 | B25: ISO only | C25: ISO only | D25: =SUMPRODUCT('Historical Data'!$AT$2:$AT$1068*'Historical Data'!$AD$2:$AD$1068) | E25: =SUMPRODUCT('Historical Data'!$AT$2:$AT$1068*'Historical Data'!$AP$2:$AP$1068) | F25: =IF(D25=0,"",E25/D25) | G25: =SUMPRODUCT('Historical Data'!$AT$2:$AT$1068*'Historical Data'!$AP$2:$AP$1068*'Historical Data'!$N$2:$N$1068) | H25: =SUMPRODUCT('Historical Data'!$AT$2:$AT$1068*'Historical Data'!$AP$2:$AP$1068*'Historical Data'!$AH$2:$AH$1068) | I25: =IF(E25=0,"",H25/E25) | J25: =SUMPRODUCT('Historical Data'!$AT$2:$AT$1068*'Historical Data'!$AP$2:$AP$1068*'Historical Data'!$AE$2:$AE$1068) | K25: =IF(E25=0,"",J25/E25) | L25: =IF(OR(E25<Controls!$B$47,G25=0),"",SUMPRODUCT('Historical Data'!$AT$2:$AT$1068*'Historical Data'!$AP$2:$AP$1068*'Historical Data'!$AK$2:$AK$1068)/G25) | M25: =IF(OR(E25<Controls!$B$47,SUMPRODUCT('Historical Data'!$AT$2:$AT$1068*'Historical Data'!$AP$2:$AP$1068*'Historical Data'!$AE$2:$AE$1068*'Historical Data'!$N$2:$N$1068)=0),"",SUMPRODUCT('Historical Data'!$AT$2:$AT$1068*'Historical Data'!$AP$2:$AP$1068*'Historical Data'!$AE$2:$AE$1068*'Historical Data'!$Q$2:$Q$1068)/SUMPRODUCT('Historical Data'!$AT$2:$AT$1068*'Historical Data'!$AP$2:$AP$1068*'Historical Data'!$AE$2:$AE$1068*'Historical Data'!$N$2:$N$1068)) | N25: =IF(OR(E25<Controls!$B$47,G25=0),"",SUMPRODUCT('Historical Data'!$AT$2:$AT$1068*'Historical Data'!$AP$2:$AP$1068*'Historical Data'!$AJ$2:$AJ$1068)/G25) | O25: =IF(SUMPRODUCT('Historical Data'!$AT$2:$AT$1068*'Historical Data'!$AP$2:$AP$1068*'Historical Data'!$AM$2:$AM$1068)=0,"",SUMPRODUCT('Historical Data'!$AT$2:$AT$1068*'Historical Data'!$AP$2:$AP$1068*'Historical Data'!$AM$2:$AM$1068*'Historical Data'!$AL$2:$AL$1068)/SUMPRODUCT('Historical Data'!$AT$2:$AT$1068*'Historical Data'!$AP$2:$AP$1068*'Historical Data'!$AM$2:$AM$1068)) | P25: =IF(E25=0,"",SUMPRODUCT('Historical Data'!$AT$2:$AT$1068*'Historical Data'!$AP$2:$AP$1068*'Historical Data'!$AA$2:$AA$1068)/E25) | Q25: =IF(E25=0,"",SUMPRODUCT('Historical Data'!$AT$2:$AT$1068*'Historical Data'!$AP$2:$AP$1068*'Historical Data'!$M$2:$M$1068)/E25) | R25: =IF(E25=0,"",G25/E25) | S25: =IF(E25=0,"",SUMPRODUCT('Historical Data'!$AT$2:$AT$1068*'Historical Data'!$AP$2:$AP$1068*'Historical Data'!$AN$2:$AN$1068)/E25) | T25: =IF(E25=0,"",SUMPRODUCT('Historical Data'!$AT$2:$AT$1068*'Historical Data'!$AP$2:$AP$1068*'Historical Data'!$AO$2:$AO$1068)/E25) | U25: =IF(AND(E25>=Controls!$B$40,G25>=Controls!$B$41,IF(I25="",1,I25)<=Controls!$B$43),"Yes","No") | V25: =IF(E25+Controls!$B$42=0,0,E25/(E25+Controls!$B$42)) | W25: =IF(L25="",$C$10,V25*L25+(1-V25)*$C$10) | X25: =IF(OR($C$10="",$C$10=0),"",W25/$C$10) | Y25: =IF(AND(E25>=Controls!$B$40,G25>=Controls!$B$41),1,0) | Z25: =IF(L25="",0,ABS(W25-$C$10)) | AA25: =IF(L25="","No","Yes")
