Workbook
Name D26D33: #REF!

Sheet README
A3: PURPOSE OF THIS SHEET
A4: The purpose of this sheet is to combine cashflow-analysis with historical data to automatically generate a recommended offer
A6: METHODOLOGY
A7: In-order to easily make future adjustments, all assumptions and parameters are editable in "Controls"
A9: WORK FLOW
A10: Firstly you input deal data(Revenue, Balances, Existing positions, ISO, Industry, etc.)
A11: Then

Sheet Deal
B1: UNDERWRITING TOOL | G1: PINK = MANUAL INPUT
B2: DECISION | C2: =C62
B4: A. OFFER | J4: MONEYBADGER Discrepancies
B5: Fund $ | C5: Factor | D5: =IF($E$6="Weekly","Term (weeks)","Term (daily pmts)") | E5: Freq | F5: Fee % | J5: Metric | K5: This tool | L5: MoneyBadger | M5: Difference
F6: 0.05 | J6: =IF($E$6="Weekly","Weekly remittance","Daily remittance") | K6: =IF(OR($E$6="",C8="",C24=0),"",IF($E$6="Weekly",D8,C8)) | L6: =IF(OR(L7="",C24=0),"",L7*C24/IF($E$6="Weekly",$L$8,$L$9)) | M6: =IF(OR(K6="",L6=""),"",L6-K6)
B7: Payback | C7: Daily $ | D7: Weekly $ | E7: Monthly $ | F7: Term (month) | G7: Net $ to Merchant | J7: Holdback % | K7: =IF(OR(D8="",C24=0),"",E8/C24) | L7: =IF(OR($E$6="",C8="",C24=0),"",ROUND(IF($E$6="Weekly",D8*$L$8,C8*$L$9)/C24*100,2)/100) | M7: =IF(OR(K7="",L7=""),"",L7-K7)
B8: =IF(OR(B6="",C6=""),"",B6*C6) | C8: =IF(OR(B8="",D6="",D6=0),"",IF(E6="Weekly",(B8/D6)/5,B8/D6)) | D8: =IF(C8="","",C8*5) | E8: =IF(C8="","",C8*$K$9) | F8: =IF(OR(D6="",D6=0),"",IF(E6="Weekly",D6,D6/5)/($K$9/5)) | G8: =IF(B6="","",B6-(B6*F6)) | J8: Weeks / month | K8: 4.331 | L8: 4 | M8: =IF(OR(K8="",L8=""),"",L8-K8)
J9: Days / month | K9: 21.655 | L9: 21 | M9: =IF(OR(K9="",L9=""),"",L9-K9)
B10: B. BANK DATA
B11: Month - MOST RECENT FIRST | C11: True rev $ | D11: Avg daily bal $ | E11: Neg days | F11: NSFs | G11: MoM %(Revenue Trend) | J11: DEAL PROFILE
B12: Aug | C12: 60000 | D12: 2000 | E12: 0 | F12: 0 | G12: =IF(OR(C12="",C13=""),"",(C12-C13)/C13) | J12: ISO | K12: United Secured Capital 8 | L12: =IF(K12="","",COUNTIF('Historical Data'!$K$2:$K$1100,K12)&" deals in book")
B13: Jul | C13: 60000 | D13: 2000 | E13: 0 | F13: 0 | G13: =IF(OR(C13="",C14=""),"",(C13-C14)/C14) | J13: Industry | K13: Real Estate | L13: =IF(K13="","",COUNTIF('Historical Data'!$Y$2:$Y$1100,K13)&" deals in book")
B14: Jun | C14: 60000 | D14: 2000 | E14: 0 | F14: 0 | G14: =IF(OR(C14="",C15=""),"",(C14-C15)/C15) | J14: New deal or renewal | K14: Renewal | L14: =IF(K14="","",COUNTIF('Historical Data'!$L$2:$L$1100,K14)&" deals in book")
B15: May | C15: 60000 | D15: 2000 | E15: 0 | F15: 0 | G15: =IF(OR(C15="",C16=""),"",(C15-C16)/C16) | J15: Credit score | K15: 600
G16: =IF(OR(C16="",C17=""),"",(C16-C17)/C17)
G17: =IF(OR(C17="",C18=""),"",(C17-C18)/C18)
G18: =IF(OR(C18="",C19=""),"",(C18-C19)/C19)
G19: =IF(OR(C19="",C20=""),"",(C19-C20)/C20)
G20: =IF(OR(C20="",C21=""),"",(C20-C21)/C21)
G21: =IF(OR(C21="",C22=""),"",(C21-C22)/C22)
G22: =IF(OR(C22="",C23=""),"",(C22-C23)/C23)
B24: AVG / TOTAL | C24: 60000 | D24: =IF(COUNT(D12:D23)=0,0,AVERAGE(D12:D23)) | E24: =SUM(E12:E23) | F24: =SUM(F12:F23) | G24: =IFERROR(AVERAGE(G12:G22),"")
B26: EXISTING POSITIONS
B27: Funder | C27: Funded $ | D27: Payment | E27: Freq | F27: Daily equiv | G27: Start Date | H27: Est Term | I27: Est term (mo) | J27: Mo. remaining
B28: lendr | C28: 50000 | D28: 1000 | E28: Weekly | F28: =IF(D28<>"",IF(E28="Daily",D28,IF(E28="Weekly",D28/5,D28/$K$9)),IF(C28="","",C28*Controls!$B$17/(Controls!$B$9*$K$9))) | H28: =IF(OR(C28="",D28=""),"",ROUND(C28*Controls!$B$17/D28,0)) | I28: =IF(H28="","",H28/IF(E28="Daily",$K$9,IF(E28="Weekly",$K$9/5,1))) | J28: =IF(OR(I28="",G28=""),"",MAX(0,I28-(TODAY()-G28)/Controls!$B$16))
E29: Weekly | F29: =IF(D29<>"",IF(E29="Daily",D29,IF(E29="Weekly",D29/5,D29/$K$9)),IF(C29="","",C29*Controls!$B$17/(Controls!$B$9*$K$9))) | H29: =IF(OR(C29="",D29=""),"",ROUND(C29*Controls!$B$17/D29,0)) | I29: =IF(H29="","",H29/IF(E29="Daily",$K$9,IF(E29="Weekly",$K$9/5,1))) | J29: =IF(OR(I29="",G29=""),"",MAX(0,I29-(TODAY()-G29)/Controls!$B$16))
E30: Weekly | F30: =IF(D30<>"",IF(E30="Daily",D30,IF(E30="Weekly",D30/5,D30/$K$9)),IF(C30="","",C30*Controls!$B$17/(Controls!$B$9*$K$9))) | H30: =IF(OR(C30="",D30=""),"",ROUND(C30*Controls!$B$17/D30,0)) | I30: =IF(H30="","",H30/IF(E30="Daily",$K$9,IF(E30="Weekly",$K$9/5,1))) | J30: =IF(OR(I30="",G30=""),"",MAX(0,I30-(TODAY()-G30)/Controls!$B$16))
E31: Weekly | F31: =IF(D31<>"",IF(E31="Daily",D31,IF(E31="Weekly",D31/5,D31/$K$9)),IF(C31="","",C31*Controls!$B$17/(Controls!$B$9*$K$9))) | H31: =IF(OR(C31="",D31=""),"",ROUND(C31*Controls!$B$17/D31,0)) | I31: =IF(H31="","",H31/IF(E31="Daily",$K$9,IF(E31="Weekly",$K$9/5,1))) | J31: =IF(OR(I31="",G31=""),"",MAX(0,I31-(TODAY()-G31)/Controls!$B$16))
E32: Weekly | F32: =IF(D32<>"",IF(E32="Daily",D32,IF(E32="Weekly",D32/5,D32/$K$9)),IF(C32="","",C32*Controls!$B$17/(Controls!$B$9*$K$9))) | H32: =IF(OR(C32="",D32=""),"",ROUND(C32*Controls!$B$17/D32,0)) | I32: =IF(H32="","",H32/IF(E32="Daily",$K$9,IF(E32="Weekly",$K$9/5,1))) | J32: =IF(OR(I32="",G32=""),"",MAX(0,I32-(TODAY()-G32)/Controls!$B$16))
E33: Weekly | F33: =IF(D33<>"",IF(E33="Daily",D33,IF(E33="Weekly",D33/5,D33/$K$9)),IF(C33="","",C33*Controls!$B$17/(Controls!$B$9*$K$9))) | H33: =IF(OR(C33="",D33=""),"",ROUND(C33*Controls!$B$17/D33,0)) | I33: =IF(H33="","",H33/IF(E33="Daily",$K$9,IF(E33="Weekly",$K$9/5,1))) | J33: =IF(OR(I33="",G33=""),"",MAX(0,I33-(TODAY()-G33)/Controls!$B$16))
B34: Positions (excl. Monthly) | C34: =SUMPRODUCT(((C28:C33<>"")+(D28:D33<>"")>0)*(E28:E33<>"Monthly")) | D34: Total existing daily | E34: =SUM(F28:F33) | F34: =E34*$K$9 | G34: /month
B36: C. METRICS
B37: Metric | C37: Value | D37: Green | E37: Red | F37: Status | G37: Knockout | H37: Sizing line
B38: Total LVG (all debt / rev) | C38: =IF(C24=0,"",(E34+IF(C8="",0,C8))*$K$9/C24) | D38: 0.3 | E38: 0.45 | F38: =IF(C38="","",IF(C38>=G38,"KNOCKOUT",IF(C38<=D38,"GREEN",IF(C38>=E38,"RED","YELLOW")))) | G38: 0.55 | H38: =D38+'Historical Score'!$C$35*(E38-D38)
B39: New holdback SP% | C39: =IF(OR(C24=0,E8=""),"",E8/C24) | D39: 0.18 | E39: 0.25 | F39: =IF(C39="","",IF(C39>=G39,"KNOCKOUT",IF(C39<=D39,"GREEN",IF(C39>=E39,"RED","YELLOW")))) | G39: 0.35 | H39: =D39+'Historical Score'!$C$35*(E39-D39)
B40: Daily debt / balance | C40: =IF(D24=0,"",(E34+IF(C8="",0,C8))/D24) | D40: 0.18 | E40: 0.3 | F40: =IF(C40="","",IF(C40>=G40,"KNOCKOUT",IF(C40<=D40,"GREEN",IF(C40>=E40,"RED","YELLOW")))) | G40: 0.35 | H40: =D40+'Historical Score'!$C$35*(E40-D40)
B41: Fund / revenue | C41: =IF(OR(C24=0,B6=""),"",B6/C24) | D41: 0.6 | E41: 0.9 | F41: =IF(C41="","",IF(C41>=G41,"KNOCKOUT",IF(C41<=D41,"GREEN",IF(C41>=E41,"RED","YELLOW")))) | G41: 1.25 | H41: =D41+'Historical Score'!$C$35*(E41-D41)
B42: # positions (incl. new) | C42: =IF(C24=0,"",C34+1) | D42: 2 | E42: 5 | F42: =IF(C42="","",IF(C42>=G42,"KNOCKOUT",IF(C42<=D42,"GREEN",IF(C42>=E42,"RED","YELLOW")))) | G42: 6
B43: Revenue trend (avg MoM) | C43: =G24 | D43: -0.05 | E43: -0.15 | F43: =IF(C24=0,"",IF(NOT(ISNUMBER(C43)),"YELLOW",IF(C43<=G43,"KNOCKOUT",IF(C43>=D43,"GREEN",IF(C43<=E43,"RED","YELLOW"))))) | G43: -0.3
B44: Neg days + NSFs (total) | C44: =E24+F24 | D44: 1 | E44: 6 | F44: =IF(C44="","",IF(C44>=G44,"KNOCKOUT",IF(C44<=D44,"GREEN",IF(C44>=E44,"RED","YELLOW")))) | G44: 10
...

Sheet Historical Score
A1: HISTORICAL SCORE
A4: DEAL BEING MATCHED
B5: New deal or renewal | C5: =IF(Deal!$K$14="","",Deal!$K$14)
B6: Position (Deal C42) | C6: =IF(Deal!$C$42="","",Deal!$C$42)
B7: Industry | C7: =IF(Deal!$K$13="","",Deal!$K$13)
B8: ISO | C8: =IF(Deal!$K$12="","",Deal!$K$12)
B10: Seasoned-book principal lost rate | C10: =IF($F$21="",0,$F$21)
B11: Seasoned-book return on funded | C11: =IF($G$21="",0,$G$21)
B13: Cohort | C13: Seasoned deals | D13: Funded $ (seasoned) | E13: Meets min? | F13: Principal lost rate | G13: Return on funded | H13: Index | K13: req NR | L13: req ISO | M13: req Ind | N13: req Pos | O13: <- tier definition: 1 = must match, 0 = ignore
B14: New/renewal + ISO + industry | C14: =SUMPRODUCT('Historical Data'!$AP$2:$AP$1068*('Historical Data'!$AR$2:$AR$1068*$K14+(1-$K14))*('Historical Data'!$AT$2:$AT$1068*$L14+(1-$L14))*('Historical Data'!$AS$2:$AS$1068*$M14+(1-$M14))*('Historical Data'!$AQ$2:$AQ$1068*$N14+(1-$N14))) | D14: =SUMPRODUCT('Historical Data'!$AP$2:$AP$1068*('Historical Data'!$AR$2:$AR$1068*$K14+(1-$K14))*('Historical Data'!$AT$2:$AT$1068*$L14+(1-$L14))*('Historical Data'!$AS$2:$AS$1068*$M14+(1-$M14))*('Historical Data'!$AQ$2:$AQ$1068*$N14+(1-$N14))*'Historical Data'!$N$2:$N$1068) | E14: =IF(AND(C14>=Controls!$B$24,D14>=Controls!$B$25),"Yes","No") | F14: =IF(D14=0,"",SUMPRODUCT('Historical Data'!$AP$2:$AP$1068*('Historical Data'!$AR$2:$AR$1068*$K14+(1-$K14))*('Historical Data'!$AT$2:$AT$1068*$L14+(1-$L14))*('Historical Data'!$AS$2:$AS$1068*$M14+(1-$M14))*('Historical Data'!$AQ$2:$AQ$1068*$N14+(1-$N14))*'Historical Data'!$AK$2:$AK$1068)/D14) | G14: =IF(D14=0,"",SUMPRODUCT('Historical Data'!$AP$2:$AP$1068*('Historical Data'!$AR$2:$AR$1068*$K14+(1-$K14))*('Historical Data'!$AT$2:$AT$1068*$L14+(1-$L14))*('Historical Data'!$AS$2:$AS$1068*$M14+(1-$M14))*('Historical Data'!$AQ$2:$AQ$1068*$N14+(1-$N14))*'Historical Data'!$AJ$2:$AJ$1068)/D14) | H14: =IF(OR(F14="",$C$10=0),"",F14/$C$10) | K14: 1 | L14: 1 | M14: 1 | N14: 0
B15: New/renewal + industry + position | C15: =SUMPRODUCT('Historical Data'!$AP$2:$AP$1068*('Historical Data'!$AR$2:$AR$1068*$K15+(1-$K15))*('Historical Data'!$AT$2:$AT$1068*$L15+(1-$L15))*('Historical Data'!$AS$2:$AS$1068*$M15+(1-$M15))*('Historical Data'!$AQ$2:$AQ$1068*$N15+(1-$N15))) | D15: =SUMPRODUCT('Historical Data'!$AP$2:$AP$1068*('Historical Data'!$AR$2:$AR$1068*$K15+(1-$K15))*('Historical Data'!$AT$2:$AT$1068*$L15+(1-$L15))*('Historical Data'!$AS$2:$AS$1068*$M15+(1-$M15))*('Historical Data'!$AQ$2:$AQ$1068*$N15+(1-$N15))*'Historical Data'!$N$2:$N$1068) | E15: =IF(AND(C15>=Controls!$B$24,D15>=Controls!$B$25),"Yes","No") | F15: =IF(D15=0,"",SUMPRODUCT('Historical Data'!$AP$2:$AP$1068*('Historical Data'!$AR$2:$AR$1068*$K15+(1-$K15))*('Historical Data'!$AT$2:$AT$1068*$L15+(1-$L15))*('Historical Data'!$AS$2:$AS$1068*$M15+(1-$M15))*('Historical Data'!$AQ$2:$AQ$1068*$N15+(1-$N15))*'Historical Data'!$AK$2:$AK$1068)/D15) | G15: =IF(D15=0,"",SUMPRODUCT('Historical Data'!$AP$2:$AP$1068*('Historical Data'!$AR$2:$AR$1068*$K15+(1-$K15))*('Historical Data'!$AT$2:$AT$1068*$L15+(1-$L15))*('Historical Data'!$AS$2:$AS$1068*$M15+(1-$M15))*('Historical Data'!$AQ$2:$AQ$1068*$N15+(1-$N15))*'Historical Data'!$AJ$2:$AJ$1068)/D15) | H15: =IF(OR(F15="",$C$10=0),"",F15/$C$10) | K15: 1 | L15: 0 | M15: 1 | N15: 1
B16: New/renewal + ISO + position | C16: =SUMPRODUCT('Historical Data'!$AP$2:$AP$1068*('Historical Data'!$AR$2:$AR$1068*$K16+(1-$K16))*('Historical Data'!$AT$2:$AT$1068*$L16+(1-$L16))*('Historical Data'!$AS$2:$AS$1068*$M16+(1-$M16))*('Historical Data'!$AQ$2:$AQ$1068*$N16+(1-$N16))) | D16: =SUMPRODUCT('Historical Data'!$AP$2:$AP$1068*('Historical Data'!$AR$2:$AR$1068*$K16+(1-$K16))*('Historical Data'!$AT$2:$AT$1068*$L16+(1-$L16))*('Historical Data'!$AS$2:$AS$1068*$M16+(1-$M16))*('Historical Data'!$AQ$2:$AQ$1068*$N16+(1-$N16))*'Historical Data'!$N$2:$N$1068) | E16: =IF(AND(C16>=Controls!$B$24,D16>=Controls!$B$25),"Yes","No") | F16: =IF(D16=0,"",SUMPRODUCT('Historical Data'!$AP$2:$AP$1068*('Historical Data'!$AR$2:$AR$1068*$K16+(1-$K16))*('Historical Data'!$AT$2:$AT$1068*$L16+(1-$L16))*('Historical Data'!$AS$2:$AS$1068*$M16+(1-$M16))*('Historical Data'!$AQ$2:$AQ$1068*$N16+(1-$N16))*'Historical Data'!$AK$2:$AK$1068)/D16) | G16: =IF(D16=0,"",SUMPRODUCT('Historical Data'!$AP$2:$AP$1068*('Historical Data'!$AR$2:$AR$1068*$K16+(1-$K16))*('Historical Data'!$AT$2:$AT$1068*$L16+(1-$L16))*('Historical Data'!$AS$2:$AS$1068*$M16+(1-$M16))*('Historical Data'!$AQ$2:$AQ$1068*$N16+(1-$N16))*'Historical Data'!$AJ$2:$AJ$1068)/D16) | H16: =IF(OR(F16="",$C$10=0),"",F16/$C$10) | K16: 1 | L16: 1 | M16: 0 | N16: 1
B17: New/renewal + industry | C17: =SUMPRODUCT('Historical Data'!$AP$2:$AP$1068*('Historical Data'!$AR$2:$AR$1068*$K17+(1-$K17))*('Historical Data'!$AT$2:$AT$1068*$L17+(1-$L17))*('Historical Data'!$AS$2:$AS$1068*$M17+(1-$M17))*('Historical Data'!$AQ$2:$AQ$1068*$N17+(1-$N17))) | D17: =SUMPRODUCT('Historical Data'!$AP$2:$AP$1068*('Historical Data'!$AR$2:$AR$1068*$K17+(1-$K17))*('Historical Data'!$AT$2:$AT$1068*$L17+(1-$L17))*('Historical Data'!$AS$2:$AS$1068*$M17+(1-$M17))*('Historical Data'!$AQ$2:$AQ$1068*$N17+(1-$N17))*'Historical Data'!$N$2:$N$1068) | E17: =IF(AND(C17>=Controls!$B$24,D17>=Controls!$B$25),"Yes","No") | F17: =IF(D17=0,"",SUMPRODUCT('Historical Data'!$AP$2:$AP$1068*('Historical Data'!$AR$2:$AR$1068*$K17+(1-$K17))*('Historical Data'!$AT$2:$AT$1068*$L17+(1-$L17))*('Historical Data'!$AS$2:$AS$1068*$M17+(1-$M17))*('Historical Data'!$AQ$2:$AQ$1068*$N17+(1-$N17))*'Historical Data'!$AK$2:$AK$1068)/D17) | G17: =IF(D17=0,"",SUMPRODUCT('Historical Data'!$AP$2:$AP$1068*('Historical Data'!$AR$2:$AR$1068*$K17+(1-$K17))*('Historical Data'!$AT$2:$AT$1068*$L17+(1-$L17))*('Historical Data'!$AS$2:$AS$1068*$M17+(1-$M17))*('Historical Data'!$AQ$2:$AQ$1068*$N17+(1-$N17))*'Historical Data'!$AJ$2:$AJ$1068)/D17) | H17: =IF(OR(F17="",$C$10=0),"",F17/$C$10) | K17: 1 | L17: 0 | M17: 1 | N17: 0
B18: New/renewal + ISO | C18: =SUMPRODUCT('Historical Data'!$AP$2:$AP$1068*('Historical Data'!$AR$2:$AR$1068*$K18+(1-$K18))*('Historical Data'!$AT$2:$AT$1068*$L18+(1-$L18))*('Historical Data'!$AS$2:$AS$1068*$M18+(1-$M18))*('Historical Data'!$AQ$2:$AQ$1068*$N18+(1-$N18))) | D18: =SUMPRODUCT('Historical Data'!$AP$2:$AP$1068*('Historical Data'!$AR$2:$AR$1068*$K18+(1-$K18))*('Historical Data'!$AT$2:$AT$1068*$L18+(1-$L18))*('Historical Data'!$AS$2:$AS$1068*$M18+(1-$M18))*('Historical Data'!$AQ$2:$AQ$1068*$N18+(1-$N18))*'Historical Data'!$N$2:$N$1068) | E18: =IF(AND(C18>=Controls!$B$24,D18>=Controls!$B$25),"Yes","No") | F18: =IF(D18=0,"",SUMPRODUCT('Historical Data'!$AP$2:$AP$1068*('Historical Data'!$AR$2:$AR$1068*$K18+(1-$K18))*('Historical Data'!$AT$2:$AT$1068*$L18+(1-$L18))*('Historical Data'!$AS$2:$AS$1068*$M18+(1-$M18))*('Historical Data'!$AQ$2:$AQ$1068*$N18+(1-$N18))*'Historical Data'!$AK$2:$AK$1068)/D18) | G18: =IF(D18=0,"",SUMPRODUCT('Historical Data'!$AP$2:$AP$1068*('Historical Data'!$AR$2:$AR$1068*$K18+(1-$K18))*('Historical Data'!$AT$2:$AT$1068*$L18+(1-$L18))*('Historical Data'!$AS$2:$AS$1068*$M18+(1-$M18))*('Historical Data'!$AQ$2:$AQ$1068*$N18+(1-$N18))*'Historical Data'!$AJ$2:$AJ$1068)/D18) | H18: =IF(OR(F18="",$C$10=0),"",F18/$C$10) | K18: 1 | L18: 1 | M18: 0 | N18: 0
B19: New/renewal + position | C19: =SUMPRODUCT('Historical Data'!$AP$2:$AP$1068*('Historical Data'!$AR$2:$AR$1068*$K19+(1-$K19))*('Historical Data'!$AT$2:$AT$1068*$L19+(1-$L19))*('Historical Data'!$AS$2:$AS$1068*$M19+(1-$M19))*('Historical Data'!$AQ$2:$AQ$1068*$N19+(1-$N19))) | D19: =SUMPRODUCT('Historical Data'!$AP$2:$AP$1068*('Historical Data'!$AR$2:$AR$1068*$K19+(1-$K19))*('Historical Data'!$AT$2:$AT$1068*$L19+(1-$L19))*('Historical Data'!$AS$2:$AS$1068*$M19+(1-$M19))*('Historical Data'!$AQ$2:$AQ$1068*$N19+(1-$N19))*'Historical Data'!$N$2:$N$1068) | E19: =IF(AND(C19>=Controls!$B$24,D19>=Controls!$B$25),"Yes","No") | F19: =IF(D19=0,"",SUMPRODUCT('Historical Data'!$AP$2:$AP$1068*('Historical Data'!$AR$2:$AR$1068*$K19+(1-$K19))*('Historical Data'!$AT$2:$AT$1068*$L19+(1-$L19))*('Historical Data'!$AS$2:$AS$1068*$M19+(1-$M19))*('Historical Data'!$AQ$2:$AQ$1068*$N19+(1-$N19))*'Historical Data'!$AK$2:$AK$1068)/D19) | G19: =IF(D19=0,"",SUMPRODUCT('Historical Data'!$AP$2:$AP$1068*('Historical Data'!$AR$2:$AR$1068*$K19+(1-$K19))*('Historical Data'!$AT$2:$AT$1068*$L19+(1-$L19))*('Historical Data'!$AS$2:$AS$1068*$M19+(1-$M19))*('Historical Data'!$AQ$2:$AQ$1068*$N19+(1-$N19))*'Historical Data'!$AJ$2:$AJ$1068)/D19) | H19: =IF(OR(F19="",$C$10=0),"",F19/$C$10) | K19: 1 | L19: 0 | M19: 0 | N19: 1
B20: New/renewal only | C20: =SUMPRODUCT('Historical Data'!$AP$2:$AP$1068*('Historical Data'!$AR$2:$AR$1068*$K20+(1-$K20))*('Historical Data'!$AT$2:$AT$1068*$L20+(1-$L20))*('Historical Data'!$AS$2:$AS$1068*$M20+(1-$M20))*('Historical Data'!$AQ$2:$AQ$1068*$N20+(1-$N20))) | D20: =SUMPRODUCT('Historical Data'!$AP$2:$AP$1068*('Historical Data'!$AR$2:$AR$1068*$K20+(1-$K20))*('Historical Data'!$AT$2:$AT$1068*$L20+(1-$L20))*('Historical Data'!$AS$2:$AS$1068*$M20+(1-$M20))*('Historical Data'!$AQ$2:$AQ$1068*$N20+(1-$N20))*'Historical Data'!$N$2:$N$1068) | E20: =IF(AND(C20>=Controls!$B$24,D20>=Controls!$B$25),"Yes","No") | F20: =IF(D20=0,"",SUMPRODUCT('Historical Data'!$AP$2:$AP$1068*('Historical Data'!$AR$2:$AR$1068*$K20+(1-$K20))*('Historical Data'!$AT$2:$AT$1068*$L20+(1-$L20))*('Historical Data'!$AS$2:$AS$1068*$M20+(1-$M20))*('Historical Data'!$AQ$2:$AQ$1068*$N20+(1-$N20))*'Historical Data'!$AK$2:$AK$1068)/D20) | G20: =IF(D20=0,"",SUMPRODUCT('Historical Data'!$AP$2:$AP$1068*('Historical Data'!$AR$2:$AR$1068*$K20+(1-$K20))*('Historical Data'!$AT$2:$AT$1068*$L20+(1-$L20))*('Historical Data'!$AS$2:$AS$1068*$M20+(1-$M20))*('Historical Data'!$AQ$2:$AQ$1068*$N20+(1-$N20))*'Historical Data'!$AJ$2:$AJ$1068)/D20) | H20: =IF(OR(F20="",$C$10=0),"",F20/$C$10) | K20: 1 | L20: 0 | M20: 0 | N20: 0
B21: Whole seasoned book | C21: =SUMPRODUCT('Historical Data'!$AP$2:$AP$1068*('Historical Data'!$AR$2:$AR$1068*$K21+(1-$K21))*('Historical Data'!$AT$2:$AT$1068*$L21+(1-$L21))*('Historical Data'!$AS$2:$AS$1068*$M21+(1-$M21))*('Historical Data'!$AQ$2:$AQ$1068*$N21+(1-$N21))) | D21: =SUMPRODUCT('Historical Data'!$AP$2:$AP$1068*('Historical Data'!$AR$2:$AR$1068*$K21+(1-$K21))*('Historical Data'!$AT$2:$AT$1068*$L21+(1-$L21))*('Historical Data'!$AS$2:$AS$1068*$M21+(1-$M21))*('Historical Data'!$AQ$2:$AQ$1068*$N21+(1-$N21))*'Historical Data'!$N$2:$N$1068) | E21: =IF(AND(C21>=Controls!$B$24,D21>=Controls!$B$25),"Yes","No") | F21: =IF(D21=0,"",SUMPRODUCT('Historical Data'!$AP$2:$AP$1068*('Historical Data'!$AR$2:$AR$1068*$K21+(1-$K21))*('Historical Data'!$AT$2:$AT$1068*$L21+(1-$L21))*('Historical Data'!$AS$2:$AS$1068*$M21+(1-$M21))*('Historical Data'!$AQ$2:$AQ$1068*$N21+(1-$N21))*'Historical Data'!$AK$2:$AK$1068)/D21) | G21: =IF(D21=0,"",SUMPRODUCT('Historical Data'!$AP$2:$AP$1068*('Historical Data'!$AR$2:$AR$1068*$K21+(1-$K21))*('Historical Data'!$AT$2:$AT$1068*$L21+(1-$L21))*('Historical Data'!$AS$2:$AS$1068*$M21+(1-$M21))*('Historical Data'!$AQ$2:$AQ$1068*$N21+(1-$N21))*'Historical Data'!$AJ$2:$AJ$1068)/D21) | H21: =IF(OR(F21="",$C$10=0),"",F21/$C$10) | K21: 0 | L21: 0 | M21: 0 | N21: 0
B22: SINGLE-DIMENSION EVIDENCE | I22: |PLR - book|
B23: Position only | C23: =SUMPRODUCT('Historical Data'!$AQ$2:$AQ$1068*'Historical Data'!$AP$2:$AP$1068) | D23: =SUMPRODUCT('Historical Data'!$AQ$2:$AQ$1068*'Historical Data'!$AP$2:$AP$1068*'Historical Data'!$N$2:$N$1068) | E23: =IF(AND(C23>=Controls!$B$24,D23>=Controls!$B$25),"Yes","No") | F23: =IF(D23=0,"",SUMPRODUCT('Historical Data'!$AQ$2:$AQ$1068*'Historical Data'!$AP$2:$AP$1068*'Historical Data'!$AK$2:$AK$1068)/D23) | G23: =IF(D23=0,"",SUMPRODUCT('Historical Data'!$AQ$2:$AQ$1068*'Historical Data'!$AP$2:$AP$1068*'Historical Data'!$AJ$2:$AJ$1068)/D23) | H23: =IF(OR(F23="",$C$10=0),"",F23/$C$10) | I23: =IF(F23="",0,ABS(F23-$C$10))
B24: New/renewal only | C24: =SUMPRODUCT('Historical Data'!$AR$2:$AR$1068*'Historical Data'!$AP$2:$AP$1068) | D24: =SUMPRODUCT('Historical Data'!$AR$2:$AR$1068*'Historical Data'!$AP$2:$AP$1068*'Historical Data'!$N$2:$N$1068) | E24: =IF(AND(C24>=Controls!$B$24,D24>=Controls!$B$25),"Yes","No") | F24: =IF(D24=0,"",SUMPRODUCT('Historical Data'!$AR$2:$AR$1068*'Historical Data'!$AP$2:$AP$1068*'Historical Data'!$AK$2:$AK$1068)/D24) | G24: =IF(D24=0,"",SUMPRODUCT('Historical Data'!$AR$2:$AR$1068*'Historical Data'!$AP$2:$AP$1068*'Historical Data'!$AJ$2:$AJ$1068)/D24) | H24: =IF(OR(F24="",$C$10=0),"",F24/$C$10) | I24: =IF(F24="",0,ABS(F24-$C$10))
B25: Industry only | C25: =SUMPRODUCT('Historical Data'!$AS$2:$AS$1068*'Historical Data'!$AP$2:$AP$1068) | D25: =SUMPRODUCT('Historical Data'!$AS$2:$AS$1068*'Historical Data'!$AP$2:$AP$1068*'Historical Data'!$N$2:$N$1068) | E25: =IF(AND(C25>=Controls!$B$24,D25>=Controls!$B$25),"Yes","No") | F25: =IF(D25=0,"",SUMPRODUCT('Historical Data'!$AS$2:$AS$1068*'Historical Data'!$AP$2:$AP$1068*'Historical Data'!$AK$2:$AK$1068)/D25) | G25: =IF(D25=0,"",SUMPRODUCT('Historical Data'!$AS$2:$AS$1068*'Historical Data'!$AP$2:$AP$1068*'Historical Data'!$AJ$2:$AJ$1068)/D25) | H25: =IF(OR(F25="",$C$10=0),"",F25/$C$10) | I25: =IF(F25="",0,ABS(F25-$C$10))
B26: ISO only | C26: =SUMPRODUCT('Historical Data'!$AT$2:$AT$1068*'Historical Data'!$AP$2:$AP$1068) | D26: =SUMPRODUCT('Historical Data'!$AT$2:$AT$1068*'Historical Data'!$AP$2:$AP$1068*'Historical Data'!$N$2:$N$1068) | E26: =IF(AND(C26>=Controls!$B$24,D26>=Controls!$B$25),"Yes","No") | F26: =IF(D26=0,"",SUMPRODUCT('Historical Data'!$AT$2:$AT$1068*'Historical Data'!$AP$2:$AP$1068*'Historical Data'!$AK$2:$AK$1068)/D26) | G26: =IF(D26=0,"",SUMPRODUCT('Historical Data'!$AT$2:$AT$1068*'Historical Data'!$AP$2:$AP$1068*'Historical Data'!$AJ$2:$AJ$1068)/D26) | H26: =IF(OR(F26="",$C$10=0),"",F26/$C$10) | I26: =IF(F26="",0,ABS(F26-$C$10))
A28: RESULT
B29: Primary cohort (lowest row that meets both minimums) | C29: =IF($D$29="","- no deal entered -",INDEX($B$14:$B$21,$D$29)) | D29: =IF($C$5="","",MATCH("Yes",$E$14:$E$21,0)) | E29: row # (read by Historical Data) | K29: =IF($D$29="","",INDEX(K$14:K$21,$D$29)) | L29: =IF($D$29="","",INDEX(L$14:L$21,$D$29)) | M29: =IF($D$29="","",INDEX(M$14:M$21,$D$29)) | N29: =IF($D$29="","",INDEX(N$14:N$21,$D$29)) | O29: <- flags of the selected tier (read by Historical Data BA)
B30: Seasoned deals in it | C30: =IF($C$37="NO","",INDEX($C$14:$C$21,$D$29)) | D30: =COUNTA($B$14:$B$21) | E30: fallback row # (whole seasoned book)
B31: Principal lost rate | C31: =IF($C$37="NO","",INDEX($F$14:$F$21,$D$29))
B32: Return on funded | C32: =IF($C$37="NO","",INDEX($G$14:$G$21,$D$29))
B33: Index (PLR / book PLR) | C33: =IF($C$37="NO","",INDEX($H$14:$H$21,$D$29))
B34: HOUSE-BOOK OUTCOME | C34: =IF(OR($C$37="NO",$C$33=""),"Neutral",IF($C$33<=Controls!$B$29,"Supportive",IF($C$33>Controls!$B$30,"Negative","Neutral")))
B35: Sizing flex applied | C35: =IF($C$34="Supportive",Controls!$B$31,IF($C$34="Negative",-Controls!$B$32,0))
B36: Largest-impact variable | C36: {=IF(MAX($I$23:$I$26)=0,"none rated",_xlfn.XLOOKUP(MAX($I$23:$I$26),$I$23:$I$26,$B$23:$B$26))}
B37: HAS EVIDENCE? | C37: =IF(OR($D$29="",$D$29=$D$30),"NO","YES") | D37: <- every guard downstream reads this, not a hard-coded row number

Sheet Comparable Deals
A1: COMPARABLE DEALS
A4: Contract ID | B4: DBA | C4: Status | D4: Funded | E4: Position | F4: Industry | G4: ISO | H4: New/renewal | I4: Factor | J4: Advance | K4: Collected | L4: % paid | M4: Net cash | N4: Principal lost | O4: Term (bd) | P4: Age (bd) | Q4: Days on book | R4: Seasoned | S4: Default | T4: Open | U4: In primary cohort
A5: ='Historical Data'!A2 | B5: ='Historical Data'!B2 | C5: ='Historical Data'!D2 | D5: ='Historical Data'!E2 | E5: ='Historical Data'!G2 | F5: ='Historical Data'!Y2 | G5: ='Historical Data'!K2 | H5: ='Historical Data'!L2 | I5: ='Historical Data'!M2 | J5: ='Historical Data'!N2 | K5: ='Historical Data'!Q2 | L5: ='Historical Data'!S2 | M5: ='Historical Data'!AJ2 | N5: ='Historical Data'!AK2 | O5: ='Historical Data'!AA2 | P5: ='Historical Data'!AB2 | Q5: ='Historical Data'!AN2 | R5: ='Historical Data'!AC2 | S5: ='Historical Data'!AE2 | T5: ='Historical Data'!AH2 | U5: ='Historical Data'!BA2
A6: ='Historical Data'!A3 | B6: ='Historical Data'!B3 | C6: ='Historical Data'!D3 | D6: ='Historical Data'!E3 | E6: ='Historical Data'!G3 | F6: ='Historical Data'!Y3 | G6: ='Historical Data'!K3 | H6: ='Historical Data'!L3 | I6: ='Historical Data'!M3 | J6: ='Historical Data'!N3 | K6: ='Historical Data'!Q3 | L6: ='Historical Data'!S3 | M6: ='Historical Data'!AJ3 | N6: ='Historical Data'!AK3 | O6: ='Historical Data'!AA3 | P6: ='Historical Data'!AB3 | Q6: ='Historical Data'!AN3 | R6: ='Historical Data'!AC3 | S6: ='Historical Data'!AE3 | T6: ='Historical Data'!AH3 | U6: ='Historical Data'!BA3
A7: ='Historical Data'!A4 | B7: ='Historical Data'!B4 | C7: ='Historical Data'!D4 | D7: ='Historical Data'!E4 | E7: ='Historical Data'!G4 | F7: ='Historical Data'!Y4 | G7: ='Historical Data'!K4 | H7: ='Historical Data'!L4 | I7: ='Historical Data'!M4 | J7: ='Historical Data'!N4 | K7: ='Historical Data'!Q4 | L7: ='Historical Data'!S4 | M7: ='Historical Data'!AJ4 | N7: ='Historical Data'!AK4 | O7: ='Historical Data'!AA4 | P7: ='Historical Data'!AB4 | Q7: ='Historical Data'!AN4 | R7: ='Historical Data'!AC4 | S7: ='Historical Data'!AE4 | T7: ='Historical Data'!AH4 | U7: ='Historical Data'!BA4
A8: ='Historical Data'!A5 | B8: ='Historical Data'!B5 | C8: ='Historical Data'!D5 | D8: ='Historical Data'!E5 | E8: ='Historical Data'!G5 | F8: ='Historical Data'!Y5 | G8: ='Historical Data'!K5 | H8: ='Historical Data'!L5 | I8: ='Historical Data'!M5 | J8: ='Historical Data'!N5 | K8: ='Historical Data'!Q5 | L8: ='Historical Data'!S5 | M8: ='Historical Data'!AJ5 | N8: ='Historical Data'!AK5 | O8: ='Historical Data'!AA5 | P8: ='Historical Data'!AB5 | Q8: ='Historical Data'!AN5 | R8: ='Historical Data'!AC5 | S8: ='Historical Data'!AE5 | T8: ='Historical Data'!AH5 | U8: ='Historical Data'!BA5
A9: ='Historical Data'!A6 | B9: ='Historical Data'!B6 | C9: ='Historical Data'!D6 | D9: ='Historical Data'!E6 | E9: ='Historical Data'!G6 | F9: ='Historical Data'!Y6 | G9: ='Historical Data'!K6 | H9: ='Historical Data'!L6 | I9: ='Historical Data'!M6 | J9: ='Historical Data'!N6 | K9: ='Historical Data'!Q6 | L9: ='Historical Data'!S6 | M9: ='Historical Data'!AJ6 | N9: ='Historical Data'!AK6 | O9: ='Historical Data'!AA6 | P9: ='Historical Data'!AB6 | Q9: ='Historical Data'!AN6 | R9: ='Historical Data'!AC6 | S9: ='Historical Data'!AE6 | T9: ='Historical Data'!AH6 | U9: ='Historical Data'!BA6
A10: ='Historical Data'!A7 | B10: ='Historical Data'!B7 | C10: ='Historical Data'!D7 | D10: ='Historical Data'!E7 | E10: ='Historical Data'!G7 | F10: ='Historical Data'!Y7 | G10: ='Historical Data'!K7 | H10: ='Historical Data'!L7 | I10: ='Historical Data'!M7 | J10: ='Historical Data'!N7 | K10: ='Historical Data'!Q7 | L10: ='Historical Data'!S7 | M10: ='Historical Data'!AJ7 | N10: ='Historical Data'!AK7 | O10: ='Historical Data'!AA7 | P10: ='Historical Data'!AB7 | Q10: ='Historical Data'!AN7 | R10: ='Historical Data'!AC7 | S10: ='Historical Data'!AE7 | T10: ='Historical Data'!AH7 | U10: ='Historical Data'!BA7
A11: ='Historical Data'!A8 | B11: ='Historical Data'!B8 | C11: ='Historical Data'!D8 | D11: ='Historical Data'!E8 | E11: ='Historical Data'!G8 | F11: ='Historical Data'!Y8 | G11: ='Historical Data'!K8 | H11: ='Historical Data'!L8 | I11: ='Historical Data'!M8 | J11: ='Historical Data'!N8 | K11: ='Historical Data'!Q8 | L11: ='Historical Data'!S8 | M11: ='Historical Data'!AJ8 | N11: ='Historical Data'!AK8 | O11: ='Historical Data'!AA8 | P11: ='Historical Data'!AB8 | Q11: ='Historical Data'!AN8 | R11: ='Historical Data'!AC8 | S11: ='Historical Data'!AE8 | T11: ='Historical Data'!AH8 | U11: ='Historical Data'!BA8
A12: ='Historical Data'!A9 | B12: ='Historical Data'!B9 | C12: ='Historical Data'!D9 | D12: ='Historical Data'!E9 | E12: ='Historical Data'!G9 | F12: ='Historical Data'!Y9 | G12: ='Historical Data'!K9 | H12: ='Historical Data'!L9 | I12: ='Historical Data'!M9 | J12: ='Historical Data'!N9 | K12: ='Historical Data'!Q9 | L12: ='Historical Data'!S9 | M12: ='Historical Data'!AJ9 | N12: ='Historical Data'!AK9 | O12: ='Historical Data'!AA9 | P12: ='Historical Data'!AB9 | Q12: ='Historical Data'!AN9 | R12: ='Historical Data'!AC9 | S12: ='Historical Data'!AE9 | T12: ='Historical Data'!AH9 | U12: ='Historical Data'!BA9
A13: ='Historical Data'!A10 | B13: ='Historical Data'!B10 | C13: ='Historical Data'!D10 | D13: ='Historical Data'!E10 | E13: ='Historical Data'!G10 | F13: ='Historical Data'!Y10 | G13: ='Historical Data'!K10 | H13: ='Historical Data'!L10 | I13: ='Historical Data'!M10 | J13: ='Historical Data'!N10 | K13: ='Historical Data'!Q10 | L13: ='Historical Data'!S10 | M13: ='Historical Data'!AJ10 | N13: ='Historical Data'!AK10 | O13: ='Historical Data'!AA10 | P13: ='Historical Data'!AB10 | Q13: ='Historical Data'!AN10 | R13: ='Historical Data'!AC10 | S13: ='Historical Data'!AE10 | T13: ='Historical Data'!AH10 | U13: ='Historical Data'!BA10
A14: ='Historical Data'!A11 | B14: ='Historical Data'!B11 | C14: ='Historical Data'!D11 | D14: ='Historical Data'!E11 | E14: ='Historical Data'!G11 | F14: ='Historical Data'!Y11 | G14: ='Historical Data'!K11 | H14: ='Historical Data'!L11 | I14: ='Historical Data'!M11 | J14: ='Historical Data'!N11 | K14: ='Historical Data'!Q11 | L14: ='Historical Data'!S11 | M14: ='Historical Data'!AJ11 | N14: ='Historical Data'!AK11 | O14: ='Historical Data'!AA11 | P14: ='Historical Data'!AB11 | Q14: ='Historical Data'!AN11 | R14: ='Historical Data'!AC11 | S14: ='Historical Data'!AE11 | T14: ='Historical Data'!AH11 | U14: ='Historical Data'!BA11
A15: ='Historical Data'!A12 | B15: ='Historical Data'!B12 | C15: ='Historical Data'!D12 | D15: ='Historical Data'!E12 | E15: ='Historical Data'!G12 | F15: ='Historical Data'!Y12 | G15: ='Historical Data'!K12 | H15: ='Historical Data'!L12 | I15: ='Historical Data'!M12 | J15: ='Historical Data'!N12 | K15: ='Historical Data'!Q12 | L15: ='Historical Data'!S12 | M15: ='Historical Data'!AJ12 | N15: ='Historical Data'!AK12 | O15: ='Historical Data'!AA12 | P15: ='Historical Data'!AB12 | Q15: ='Historical Data'!AN12 | R15: ='Historical Data'!AC12 | S15: ='Historical Data'!AE12 | T15: ='Historical Data'!AH12 | U15: ='Historical Data'!BA12
A16: ='Historical Data'!A13 | B16: ='Historical Data'!B13 | C16: ='Historical Data'!D13 | D16: ='Historical Data'!E13 | E16: ='Historical Data'!G13 | F16: ='Historical Data'!Y13 | G16: ='Historical Data'!K13 | H16: ='Historical Data'!L13 | I16: ='Historical Data'!M13 | J16: ='Historical Data'!N13 | K16: ='Historical Data'!Q13 | L16: ='Historical Data'!S13 | M16: ='Historical Data'!AJ13 | N16: ='Historical Data'!AK13 | O16: ='Historical Data'!AA13 | P16: ='Historical Data'!AB13 | Q16: ='Historical Data'!AN13 | R16: ='Historical Data'!AC13 | S16: ='Historical Data'!AE13 | T16: ='Historical Data'!AH13 | U16: ='Historical Data'!BA13
... A1071: ='Historical Data'!A1068 | B1071: ='Historical Data'!B1068 | C1071: ='Historical Data'!D1068 | D1071: ='Historical Data'!E1068 | E1071: ='Historical Data'!G1068 | F1071: ='Historical Data'!Y1068 | G1071: ='Historical Data'!K1068 | H1071: ='Historical Data'!L1068 | I1071: ='Historical Data'!M1068 | J1071: ='Historical Data'!N1068 | K1071: ='Historical Data'!Q1068 | L1071: ='Historical Data'!S1068 | M1071: ='Historical Data'!AJ1068 | N1071: ='Historical Data'!AK1068 | O1071: ='Historical Data'!AA1068 | P1071: ='Historical Data'!AB1068 | Q1071: ='Historical Data'!AN1068 | R1071: ='Historical Data'!AC1068 | S1071: ='Historical Data'!AE1068 | T1071: ='Historical Data'!AH1068 | U1071: ='Historical Data'!BA1068

Sheet Historical Data
A1: Contract ID | B1: DBA | C1: Legal name | D1: Status | E1: Start date | F1: Last active | G1: Position | H1: SIC | I1: SIC2 | J1: State | K1: ISO | L1: New or renewal | M1: Factor | N1: Advance | O1: Commission | P1: Payback | Q1: Collected | R1: Balance | S1: % paid | T1: Exp dur (raw) | U1: NSF count | V1: Avg rev/mo | W1: Holdback % | X1: Biz start | Y1: Industry | Z1: Pay frequency | AA1: Term (bus. days) | AB1: Age at as-of (bus. days) | AC1: Seasoned | AD1: In window | AE1: Default | AF1: Resolved | AG1: Closed family | AH1: Open | AI1: Status valid | AJ1: Net cash | AK1: Principal lost | AL1: Adv / revenue | AM1: Has revenue | AN1: Days on book (bus.) | AO1: Renewal | AP1: Eligible (seasoned & in window) | AQ1: m: position | AR1: m: new/renewal | AS1: m: industry | AT1: m: ISO | AU1: (retired - combos now defined by the flag table on Historical Score) | BA1: In primary cohort
A2: 5674142980 | B2: The rustic charm bar and grill | C2: The rustic charm LLC | D2: Legal | E2: 45616 | F2: 46118 | G2: 1 | H2: 5813 | I2: 58 | J2: CO | K2: GREYSTONE | L2: New Deal | M2: 1.49 | N2: 15000 | O2: 2100 | P2: 22350 | Q2: 16835.64 | R2: 5514.36 | S2: 0.75327248 | T2: 2.754 | U2: 5 | V2: 50000 | W2: 0.05 | X2: 44701 | Y2: =IF(I2="","No SIC",IFERROR(VLOOKUP(I2,Ref!$A$2:$B$65,2,FALSE()),"Unclassified")) | Z2: =IF(T2="","",IF(T2<12,"Daily","Weekly")) | AA2: =IF(T2="",0,IF(T2<12,T2*Controls!$B$13,T2*5)) | AB2: =IF(E2="",0,NETWORKDAYS(E2,Controls!$B$20,Ref!$K$2:$K$42)) | AC2: =IF(OR(AF2=1,AND(AA2>0,AB2>=Controls!$B$23*AA2)),1,0) | AD2: =IF(AND(E2<>"",E2>=Controls!$B$21,E2<=Controls!$B$22),1,0) | AE2: =IF(IFERROR(VLOOKUP(D2,Controls!$A$36:$E$46,2,FALSE()),"No")="Yes",1,0) | AF2: =IF(IFERROR(VLOOKUP(D2,Controls!$A$36:$E$46,3,FALSE()),"No")="Yes",1,0) | AG2: =IF(IFERROR(VLOOKUP(D2,Controls!$A$36:$E$46,4,FALSE()),"No")="Yes",1,0) | AH2: =IF(IFERROR(VLOOKUP(D2,Controls!$A$36:$E$46,5,FALSE()),"No")="Yes",1,0) | AI2: =IF(ISNUMBER(MATCH(D2,Controls!$A$36:$A$46,0)),1,0) | AJ2: =Q2-N2 | AK2: =IF(AE2=1,MAX(0,N2-Q2),0) | AL2: =IF(OR(V2="",V2=0),0,N2/V2) | AM2: =IF(OR(V2="",V2=0),0,1) | AN2: =IF(OR(E2="",F2=""),0,NETWORKDAYS(E2,F2,Ref!$K$2:$K$42)) | AO2: =IF(L2="Renewal",1,0) | AP2: =AC2*AD2 | AQ2: =IF(AND(G2<>"",'Historical Score'!$C$6<>""),IF(G2='Historical Score'!$C$6,1,0),0) | AR2: =IF(AND(L2<>"",'Historical Score'!$C$5<>""),IF(L2='Historical Score'!$C$5,1,0),0) | AS2: =IF(AND(Y2<>"",'Historical Score'!$C$7<>""),IF(Y2='Historical Score'!$C$7,1,0),0) | AT2: =IF(AND(K2<>"",'Historical Score'!$C$8<>""),IF(K2='Historical Score'!$C$8,1,0),0) | BA2: =IF(AD2=1,(AR2*'Historical Score'!$K$29+1-'Historical Score'!$K$29)*(AT2*'Historical Score'!$L$29+1-'Historical Score'!$L$29)*(AS2*'Historical Score'!$M$29+1-'Historical Score'!$M$29)*(AQ2*'Historical Score'!$N$29+1-'Historical Score'!$N$29),0)
A3: 5674143732 | B3: GUADALUPE CASTANEDA | C3: GUADALUPE CASTANEDA | D3: Written-Off | E3: 45625 | F3: 45786 | G3: 3 | H3: 1442 | I3: 14 | J3: CA | K3: BFA 3 | L3: New Deal | M3: 1.49 | N3: 5000 | O3: 700 | P3: 7450 | Q3: 6305.98 | R3: 1144.02 | S3: 0.84644027 | T3: 2.623 | U3: 24 | V3: 100000 | W3: 0.12 | X3: 34575 | Y3: =IF(I3="","No SIC",IFERROR(VLOOKUP(I3,Ref!$A$2:$B$65,2,FALSE()),"Unclassified")) | Z3: =IF(T3="","",IF(T3<12,"Daily","Weekly")) | AA3: =IF(T3="",0,IF(T3<12,T3*Controls!$B$13,T3*5)) | AB3: =IF(E3="",0,NETWORKDAYS(E3,Controls!$B$20,Ref!$K$2:$K$42)) | AC3: =IF(OR(AF3=1,AND(AA3>0,AB3>=Controls!$B$23*AA3)),1,0) | AD3: =IF(AND(E3<>"",E3>=Controls!$B$21,E3<=Controls!$B$22),1,0) | AE3: =IF(IFERROR(VLOOKUP(D3,Controls!$A$36:$E$46,2,FALSE()),"No")="Yes",1,0) | AF3: =IF(IFERROR(VLOOKUP(D3,Controls!$A$36:$E$46,3,FALSE()),"No")="Yes",1,0) | AG3: =IF(IFERROR(VLOOKUP(D3,Controls!$A$36:$E$46,4,FALSE()),"No")="Yes",1,0) | AH3: =IF(IFERROR(VLOOKUP(D3,Controls!$A$36:$E$46,5,FALSE()),"No")="Yes",1,0) | AI3: =IF(ISNUMBER(MATCH(D3,Controls!$A$36:$A$46,0)),1,0) | AJ3: =Q3-N3 | AK3: =IF(AE3=1,MAX(0,N3-Q3),0) | AL3: =IF(OR(V3="",V3=0),0,N3/V3) | AM3: =IF(OR(V3="",V3=0),0,1) | AN3: =IF(OR(E3="",F3=""),0,NETWORKDAYS(E3,F3,Ref!$K$2:$K$42)) | AO3: =IF(L3="Renewal",1,0) | AP3: =AC3*AD3 | AQ3: =IF(AND(G3<>"",'Historical Score'!$C$6<>""),IF(G3='Historical Score'!$C$6,1,0),0) | AR3: =IF(AND(L3<>"",'Historical Score'!$C$5<>""),IF(L3='Historical Score'!$C$5,1,0),0) | AS3: =IF(AND(Y3<>"",'Historical Score'!$C$7<>""),IF(Y3='Historical Score'!$C$7,1,0),0) | AT3: =IF(AND(K3<>"",'Historical Score'!$C$8<>""),IF(K3='Historical Score'!$C$8,1,0),0) | BA3: =IF(AD3=1,(AR3*'Historical Score'!$K$29+1-'Historical Score'!$K$29)*(AT3*'Historical Score'!$L$29+1-'Historical Score'!$L$29)*(AS3*'Historical Score'!$M$29+1-'Historical Score'!$M$29)*(AQ3*'Historical Score'!$N$29+1-'Historical Score'!$N$29),0)
A4: 5674144092 | B4: DALE JOHNSON SOLE MBR | C4: LEVEL 4 TRANSPORT LLC | D4: Legal | E4: 45630 | F4: 45666 | G4: 2 | H4: 4213 | I4: 42 | J4: CA | K4: Liberty Bell Capital | L4: New Deal | M4: 1.49 | N4: 10000 | O4: 0 | P4: 14900 | Q4: 2421.25 | R4: 12478.75 | S4: 0.1625 | T4: 2.623 | U4: 5 | V4: 60000 | W4: 0.07 | X4: 43873 | Y4: =IF(I4="","No SIC",IFERROR(VLOOKUP(I4,Ref!$A$2:$B$65,2,FALSE()),"Unclassified")) | Z4: =IF(T4="","",IF(T4<12,"Daily","Weekly")) | AA4: =IF(T4="",0,IF(T4<12,T4*Controls!$B$13,T4*5)) | AB4: =IF(E4="",0,NETWORKDAYS(E4,Controls!$B$20,Ref!$K$2:$K$42)) | AC4: =IF(OR(AF4=1,AND(AA4>0,AB4>=Controls!$B$23*AA4)),1,0) | AD4: =IF(AND(E4<>"",E4>=Controls!$B$21,E4<=Controls!$B$22),1,0) | AE4: =IF(IFERROR(VLOOKUP(D4,Controls!$A$36:$E$46,2,FALSE()),"No")="Yes",1,0) | AF4: =IF(IFERROR(VLOOKUP(D4,Controls!$A$36:$E$46,3,FALSE()),"No")="Yes",1,0) | AG4: =IF(IFERROR(VLOOKUP(D4,Controls!$A$36:$E$46,4,FALSE()),"No")="Yes",1,0) | AH4: =IF(IFERROR(VLOOKUP(D4,Controls!$A$36:$E$46,5,FALSE()),"No")="Yes",1,0) | AI4: =IF(ISNUMBER(MATCH(D4,Controls!$A$36:$A$46,0)),1,0) | AJ4: =Q4-N4 | AK4: =IF(AE4=1,MAX(0,N4-Q4),0) | AL4: =IF(OR(V4="",V4=0),0,N4/V4) | AM4: =IF(OR(V4="",V4=0),0,1) | AN4: =IF(OR(E4="",F4=""),0,NETWORKDAYS(E4,F4,Ref!$K$2:$K$42)) | AO4: =IF(L4="Renewal",1,0) | AP4: =AC4*AD4 | AQ4: =IF(AND(G4<>"",'Historical Score'!$C$6<>""),IF(G4='Historical Score'!$C$6,1,0),0) | AR4: =IF(AND(L4<>"",'Historical Score'!$C$5<>""),IF(L4='Historical Score'!$C$5,1,0),0) | AS4: =IF(AND(Y4<>"",'Historical Score'!$C$7<>""),IF(Y4='Historical Score'!$C$7,1,0),0) | AT4: =IF(AND(K4<>"",'Historical Score'!$C$8<>""),IF(K4='Historical Score'!$C$8,1,0),0) | BA4: =IF(AD4=1,(AR4*'Historical Score'!$K$29+1-'Historical Score'!$K$29)*(AT4*'Historical Score'!$L$29+1-'Historical Score'!$L$29)*(AS4*'Historical Score'!$M$29+1-'Historical Score'!$M$29)*(AQ4*'Historical Score'!$N$29+1-'Historical Score'!$N$29),0)
A5: 5674144406 | B5: Lupotec | C5: LUPOTEC INC | D5: Legal | E5: 45632 | F5: 45666 | G5: 2 | H5: 2821 | I5: 28 | J5: CA | K5: Fidelity Funding | L5: New Deal | M5: 1.49 | N5: 20000 | O5: 0 | P5: 29800 | Q5: 3140 | R5: 26660 | S5: 0.10536913 | T5: 3.279 | U5: 6 | V5: 80000 | W5: 0.09 | X5: 44539 | Y5: =IF(I5="","No SIC",IFERROR(VLOOKUP(I5,Ref!$A$2:$B$65,2,FALSE()),"Unclassified")) | Z5: =IF(T5="","",IF(T5<12,"Daily","Weekly")) | AA5: =IF(T5="",0,IF(T5<12,T5*Controls!$B$13,T5*5)) | AB5: =IF(E5="",0,NETWORKDAYS(E5,Controls!$B$20,Ref!$K$2:$K$42)) | AC5: =IF(OR(AF5=1,AND(AA5>0,AB5>=Controls!$B$23*AA5)),1,0) | AD5: =IF(AND(E5<>"",E5>=Controls!$B$21,E5<=Controls!$B$22),1,0) | AE5: =IF(IFERROR(VLOOKUP(D5,Controls!$A$36:$E$46,2,FALSE()),"No")="Yes",1,0) | AF5: =IF(IFERROR(VLOOKUP(D5,Controls!$A$36:$E$46,3,FALSE()),"No")="Yes",1,0) | AG5: =IF(IFERROR(VLOOKUP(D5,Controls!$A$36:$E$46,4,FALSE()),"No")="Yes",1,0) | AH5: =IF(IFERROR(VLOOKUP(D5,Controls!$A$36:$E$46,5,FALSE()),"No")="Yes",1,0) | AI5: =IF(ISNUMBER(MATCH(D5,Controls!$A$36:$A$46,0)),1,0) | AJ5: =Q5-N5 | AK5: =IF(AE5=1,MAX(0,N5-Q5),0) | AL5: =IF(OR(V5="",V5=0),0,N5/V5) | AM5: =IF(OR(V5="",V5=0),0,1) | AN5: =IF(OR(E5="",F5=""),0,NETWORKDAYS(E5,F5,Ref!$K$2:$K$42)) | AO5: =IF(L5="Renewal",1,0) | AP5: =AC5*AD5 | AQ5: =IF(AND(G5<>"",'Historical Score'!$C$6<>""),IF(G5='Historical Score'!$C$6,1,0),0) | AR5: =IF(AND(L5<>"",'Historical Score'!$C$5<>""),IF(L5='Historical Score'!$C$5,1,0),0) | AS5: =IF(AND(Y5<>"",'Historical Score'!$C$7<>""),IF(Y5='Historical Score'!$C$7,1,0),0) | AT5: =IF(AND(K5<>"",'Historical Score'!$C$8<>""),IF(K5='Historical Score'!$C$8,1,0),0) | BA5: =IF(AD5=1,(AR5*'Historical Score'!$K$29+1-'Historical Score'!$K$29)*(AT5*'Historical Score'!$L$29+1-'Historical Score'!$L$29)*(AS5*'Historical Score'!$M$29+1-'Historical Score'!$M$29)*(AQ5*'Historical Score'!$N$29+1-'Historical Score'!$N$29),0)
A6: 5674144409 | B6: AWK ENGINEERING & TRADING LLC | C6: AWK ENGINEERING & TRADING LLC | D6: Legal | E6: 45632 | F6: 45707 | G6: 3 | H6: 8711 | I6: 87 | J6: CA | K6: J Capital Solutions | L6: New Deal | M6: 1.49 | N6: 6000 | O6: 840 | P6: 8940 | Q6: 2136.24 | R6: 6803.76 | S6: 0.23895302 | T6: 3.705 | U6: 12 | V6: 20000 | W6: 0.04 | X6: 44471 | Y6: =IF(I6="","No SIC",IFERROR(VLOOKUP(I6,Ref!$A$2:$B$65,2,FALSE()),"Unclassified")) | Z6: =IF(T6="","",IF(T6<12,"Daily","Weekly")) | AA6: =IF(T6="",0,IF(T6<12,T6*Controls!$B$13,T6*5)) | AB6: =IF(E6="",0,NETWORKDAYS(E6,Controls!$B$20,Ref!$K$2:$K$42)) | AC6: =IF(OR(AF6=1,AND(AA6>0,AB6>=Controls!$B$23*AA6)),1,0) | AD6: =IF(AND(E6<>"",E6>=Controls!$B$21,E6<=Controls!$B$22),1,0) | AE6: =IF(IFERROR(VLOOKUP(D6,Controls!$A$36:$E$46,2,FALSE()),"No")="Yes",1,0) | AF6: =IF(IFERROR(VLOOKUP(D6,Controls!$A$36:$E$46,3,FALSE()),"No")="Yes",1,0) | AG6: =IF(IFERROR(VLOOKUP(D6,Controls!$A$36:$E$46,4,FALSE()),"No")="Yes",1,0) | AH6: =IF(IFERROR(VLOOKUP(D6,Controls!$A$36:$E$46,5,FALSE()),"No")="Yes",1,0) | AI6: =IF(ISNUMBER(MATCH(D6,Controls!$A$36:$A$46,0)),1,0) | AJ6: =Q6-N6 | AK6: =IF(AE6=1,MAX(0,N6-Q6),0) | AL6: =IF(OR(V6="",V6=0),0,N6/V6) | AM6: =IF(OR(V6="",V6=0),0,1) | AN6: =IF(OR(E6="",F6=""),0,NETWORKDAYS(E6,F6,Ref!$K$2:$K$42)) | AO6: =IF(L6="Renewal",1,0) | AP6: =AC6*AD6 | AQ6: =IF(AND(G6<>"",'Historical Score'!$C$6<>""),IF(G6='Historical Score'!$C$6,1,0),0) | AR6: =IF(AND(L6<>"",'Historical Score'!$C$5<>""),IF(L6='Historical Score'!$C$5,1,0),0) | AS6: =IF(AND(Y6<>"",'Historical Score'!$C$7<>""),IF(Y6='Historical Score'!$C$7,1,0),0) | AT6: =IF(AND(K6<>"",'Historical Score'!$C$8<>""),IF(K6='Historical Score'!$C$8,1,0),0) | BA6: =IF(AD6=1,(AR6*'Historical Score'!$K$29+1-'Historical Score'!$K$29)*(AT6*'Historical Score'!$L$29+1-'Historical Score'!$L$29)*(AS6*'Historical Score'!$M$29+1-'Historical Score'!$M$29)*(AQ6*'Historical Score'!$N$29+1-'Historical Score'!$N$29),0)
A7: 5674145076 | B7: GLOBAL RESEARCH CONSULTANTS, LLC | C7: GLOBAL RESEARCH CONSULTANTS, LLC | D7: Closed | E7: 45638 | F7: 45755 | G7: 2 | H7: 8748 | I7: 87 | J7: GA | K7: Secure Capital Solutions 7 | L7: New Deal | M7: 1.49 | N7: 5000 | O7: 700 | P7: 7450 | Q7: 7450 | R7: 0 | S7: 1 | T7: 2.538 | U7: 0 | V7: 100000 | W7: 0.09 | X7: 44305 | Y7: =IF(I7="","No SIC",IFERROR(VLOOKUP(I7,Ref!$A$2:$B$65,2,FALSE()),"Unclassified")) | Z7: =IF(T7="","",IF(T7<12,"Daily","Weekly")) | AA7: =IF(T7="",0,IF(T7<12,T7*Controls!$B$13,T7*5)) | AB7: =IF(E7="",0,NETWORKDAYS(E7,Controls!$B$20,Ref!$K$2:$K$42)) | AC7: =IF(OR(AF7=1,AND(AA7>0,AB7>=Controls!$B$23*AA7)),1,0) | AD7: =IF(AND(E7<>"",E7>=Controls!$B$21,E7<=Controls!$B$22),1,0) | AE7: =IF(IFERROR(VLOOKUP(D7,Controls!$A$36:$E$46,2,FALSE()),"No")="Yes",1,0) | AF7: =IF(IFERROR(VLOOKUP(D7,Controls!$A$36:$E$46,3,FALSE()),"No")="Yes",1,0) | AG7: =IF(IFERROR(VLOOKUP(D7,Controls!$A$36:$E$46,4,FALSE()),"No")="Yes",1,0) | AH7: =IF(IFERROR(VLOOKUP(D7,Controls!$A$36:$E$46,5,FALSE()),"No")="Yes",1,0) | AI7: =IF(ISNUMBER(MATCH(D7,Controls!$A$36:$A$46,0)),1,0) | AJ7: =Q7-N7 | AK7: =IF(AE7=1,MAX(0,N7-Q7),0) | AL7: =IF(OR(V7="",V7=0),0,N7/V7) | AM7: =IF(OR(V7="",V7=0),0,1) | AN7: =IF(OR(E7="",F7=""),0,NETWORKDAYS(E7,F7,Ref!$K$2:$K$42)) | AO7: =IF(L7="Renewal",1,0) | AP7: =AC7*AD7 | AQ7: =IF(AND(G7<>"",'Historical Score'!$C$6<>""),IF(G7='Historical Score'!$C$6,1,0),0) | AR7: =IF(AND(L7<>"",'Historical Score'!$C$5<>""),IF(L7='Historical Score'!$C$5,1,0),0) | AS7: =IF(AND(Y7<>"",'Historical Score'!$C$7<>""),IF(Y7='Historical Score'!$C$7,1,0),0) | AT7: =IF(AND(K7<>"",'Historical Score'!$C$8<>""),IF(K7='Historical Score'!$C$8,1,0),0) | BA7: =IF(AD7=1,(AR7*'Historical Score'!$K$29+1-'Historical Score'!$K$29)*(AT7*'Historical Score'!$L$29+1-'Historical Score'!$L$29)*(AS7*'Historical Score'!$M$29+1-'Historical Score'!$M$29)*(AQ7*'Historical Score'!$N$29+1-'Historical Score'!$N$29),0)
A8: 5674146645 | B8: ELIZABETH CONVENIENT STORE & HAIR BRAIDING | C8: ELIZABETH CONVENIENT STORE & HAIR BRAIDING LLC | D8: Closed | E8: 45660 | F8: 45702 | G8: 5 | H8: 5411 | I8: 54 | J8: AZ | K8: ELITE FUNDING PARTNERS LLC 6 | L8: Renewal | M8: 1.4575 | N8: 4000 | O8: 560 | P8: 5830 | Q8: 5830 | R8: 0 | S8: 1 | T8: 1.967 | U8: 2 | V8: 250000 | W8: 0.04 | X8: 41745 | Y8: =IF(I8="","No SIC",IFERROR(VLOOKUP(I8,Ref!$A$2:$B$65,2,FALSE()),"Unclassified")) | Z8: =IF(T8="","",IF(T8<12,"Daily","Weekly")) | AA8: =IF(T8="",0,IF(T8<12,T8*Controls!$B$13,T8*5)) | AB8: =IF(E8="",0,NETWORKDAYS(E8,Controls!$B$20,Ref!$K$2:$K$42)) | AC8: =IF(OR(AF8=1,AND(AA8>0,AB8>=Controls!$B$23*AA8)),1,0) | AD8: =IF(AND(E8<>"",E8>=Controls!$B$21,E8<=Controls!$B$22),1,0) | AE8: =IF(IFERROR(VLOOKUP(D8,Controls!$A$36:$E$46,2,FALSE()),"No")="Yes",1,0) | AF8: =IF(IFERROR(VLOOKUP(D8,Controls!$A$36:$E$46,3,FALSE()),"No")="Yes",1,0) | AG8: =IF(IFERROR(VLOOKUP(D8,Controls!$A$36:$E$46,4,FALSE()),"No")="Yes",1,0) | AH8: =IF(IFERROR(VLOOKUP(D8,Controls!$A$36:$E$46,5,FALSE()),"No")="Yes",1,0) | AI8: =IF(ISNUMBER(MATCH(D8,Controls!$A$36:$A$46,0)),1,0) | AJ8: =Q8-N8 | AK8: =IF(AE8=1,MAX(0,N8-Q8),0) | AL8: =IF(OR(V8="",V8=0),0,N8/V8) | AM8: =IF(OR(V8="",V8=0),0,1) | AN8: =IF(OR(E8="",F8=""),0,NETWORKDAYS(E8,F8,Ref!$K$2:$K$42)) | AO8: =IF(L8="Renewal",1,0) | AP8: =AC8*AD8 | AQ8: =IF(AND(G8<>"",'Historical Score'!$C$6<>""),IF(G8='Historical Score'!$C$6,1,0),0) | AR8: =IF(AND(L8<>"",'Historical Score'!$C$5<>""),IF(L8='Historical Score'!$C$5,1,0),0) | AS8: =IF(AND(Y8<>"",'Historical Score'!$C$7<>""),IF(Y8='Historical Score'!$C$7,1,0),0) | AT8: =IF(AND(K8<>"",'Historical Score'!$C$8<>""),IF(K8='Historical Score'!$C$8,1,0),0) | BA8: =IF(AD8=1,(AR8*'Historical Score'!$K$29+1-'Historical Score'!$K$29)*(AT8*'Historical Score'!$L$29+1-'Historical Score'!$L$29)*(AS8*'Historical Score'!$M$29+1-'Historical Score'!$M$29)*(AQ8*'Historical Score'!$N$29+1-'Historical Score'!$N$29),0)
A9: 5674147185 | B9: Arete Gallery Inc | C9: Arete Gallery Inc | D9: Closed | E9: 45665 | F9: 45772 | G9: 4 | H9: 8412 | I9: 84 | J9: PA | K9: Pathway Catalyst | L9: New Deal | M9: 1.49 | N9: 3500 | O9: 490 | P9: 5215 | Q9: 5215 | R9: 0 | S9: 1 | T9: 1.937 | U9: 0 | W9: 0.15 | X9: 44105 | Y9: =IF(I9="","No SIC",IFERROR(VLOOKUP(I9,Ref!$A$2:$B$65,2,FALSE()),"Unclassified")) | Z9: =IF(T9="","",IF(T9<12,"Daily","Weekly")) | AA9: =IF(T9="",0,IF(T9<12,T9*Controls!$B$13,T9*5)) | AB9: =IF(E9="",0,NETWORKDAYS(E9,Controls!$B$20,Ref!$K$2:$K$42)) | AC9: =IF(OR(AF9=1,AND(AA9>0,AB9>=Controls!$B$23*AA9)),1,0) | AD9: =IF(AND(E9<>"",E9>=Controls!$B$21,E9<=Controls!$B$22),1,0) | AE9: =IF(IFERROR(VLOOKUP(D9,Controls!$A$36:$E$46,2,FALSE()),"No")="Yes",1,0) | AF9: =IF(IFERROR(VLOOKUP(D9,Controls!$A$36:$E$46,3,FALSE()),"No")="Yes",1,0) | AG9: =IF(IFERROR(VLOOKUP(D9,Controls!$A$36:$E$46,4,FALSE()),"No")="Yes",1,0) | AH9: =IF(IFERROR(VLOOKUP(D9,Controls!$A$36:$E$46,5,FALSE()),"No")="Yes",1,0) | AI9: =IF(ISNUMBER(MATCH(D9,Controls!$A$36:$A$46,0)),1,0) | AJ9: =Q9-N9 | AK9: =IF(AE9=1,MAX(0,N9-Q9),0) | AL9: =IF(OR(V9="",V9=0),0,N9/V9) | AM9: =IF(OR(V9="",V9=0),0,1) | AN9: =IF(OR(E9="",F9=""),0,NETWORKDAYS(E9,F9,Ref!$K$2:$K$42)) | AO9: =IF(L9="Renewal",1,0) | AP9: =AC9*AD9 | AQ9: =IF(AND(G9<>"",'Historical Score'!$C$6<>""),IF(G9='Historical Score'!$C$6,1,0),0) | AR9: =IF(AND(L9<>"",'Historical Score'!$C$5<>""),IF(L9='Historical Score'!$C$5,1,0),0) | AS9: =IF(AND(Y9<>"",'Historical Score'!$C$7<>""),IF(Y9='Historical Score'!$C$7,1,0),0) | AT9: =IF(AND(K9<>"",'Historical Score'!$C$8<>""),IF(K9='Historical Score'!$C$8,1,0),0) | BA9: =IF(AD9=1,(AR9*'Historical Score'!$K$29+1-'Historical Score'!$K$29)*(AT9*'Historical Score'!$L$29+1-'Historical Score'!$L$29)*(AS9*'Historical Score'!$M$29+1-'Historical Score'!$M$29)*(AQ9*'Historical Score'!$N$29+1-'Historical Score'!$N$29),0)
A10: 5674147188 | B10: S&E ENTERPRISE | C10: S&E ENTERPRISE LLC | D10: Closed | E10: 45666 | F10: 45722 | G10: 2 | H10: 6531 | I10: 65 | J10: RI | K10: Triumph Cap Fund | L10: New Deal | M10: 1.49 | N10: 5000 | O10: 700 | P10: 7450 | Q10: 7450 | R10: 0 | S10: 1 | T10: 2.443 | U10: 0 | W10: 0.06 | X10: 45005 | Y10: =IF(I10="","No SIC",IFERROR(VLOOKUP(I10,Ref!$A$2:$B$65,2,FALSE()),"Unclassified")) | Z10: =IF(T10="","",IF(T10<12,"Daily","Weekly")) | AA10: =IF(T10="",0,IF(T10<12,T10*Controls!$B$13,T10*5)) | AB10: =IF(E10="",0,NETWORKDAYS(E10,Controls!$B$20,Ref!$K$2:$K$42)) | AC10: =IF(OR(AF10=1,AND(AA10>0,AB10>=Controls!$B$23*AA10)),1,0) | AD10: =IF(AND(E10<>"",E10>=Controls!$B$21,E10<=Controls!$B$22),1,0) | AE10: =IF(IFERROR(VLOOKUP(D10,Controls!$A$36:$E$46,2,FALSE()),"No")="Yes",1,0) | AF10: =IF(IFERROR(VLOOKUP(D10,Controls!$A$36:$E$46,3,FALSE()),"No")="Yes",1,0) | AG10: =IF(IFERROR(VLOOKUP(D10,Controls!$A$36:$E$46,4,FALSE()),"No")="Yes",1,0) | AH10: =IF(IFERROR(VLOOKUP(D10,Controls!$A$36:$E$46,5,FALSE()),"No")="Yes",1,0) | AI10: =IF(ISNUMBER(MATCH(D10,Controls!$A$36:$A$46,0)),1,0) | AJ10: =Q10-N10 | AK10: =IF(AE10=1,MAX(0,N10-Q10),0) | AL10: =IF(OR(V10="",V10=0),0,N10/V10) | AM10: =IF(OR(V10="",V10=0),0,1) | AN10: =IF(OR(E10="",F10=""),0,NETWORKDAYS(E10,F10,Ref!$K$2:$K$42)) | AO10: =IF(L10="Renewal",1,0) | AP10: =AC10*AD10 | AQ10: =IF(AND(G10<>"",'Historical Score'!$C$6<>""),IF(G10='Historical Score'!$C$6,1,0),0) | AR10: =IF(AND(L10<>"",'Historical Score'!$C$5<>""),IF(L10='Historical Score'!$C$5,1,0),0) | AS10: =IF(AND(Y10<>"",'Historical Score'!$C$7<>""),IF(Y10='Historical Score'!$C$7,1,0),0) | AT10: =IF(AND(K10<>"",'Historical Score'!$C$8<>""),IF(K10='Historical Score'!$C$8,1,0),0) | BA10: =IF(AD10=1,(AR10*'Historical Score'!$K$29+1-'Historical Score'!$K$29)*(AT10*'Historical Score'!$L$29+1-'Historical Score'!$L$29)*(AS10*'Historical Score'!$M$29+1-'Historical Score'!$M$29)*(AQ10*'Historical Score'!$N$29+1-'Historical Score'!$N$29),0)
A11: 5674147393 | B11: Beeson Farms & Hauling LLC | C11: Beeson Farms & Hauling LLC | D11: Closed | E11: 45667 | F11: 45756 | G11: 5 | H11: 0191 | I11: 01 | J11: NC | K11: Key Capital Funding | L11: New Deal | M11: 1.49 | N11: 30000 | O11: 4200 | P11: 44700 | Q11: 44700 | R11: 0 | S11: 1 | T11: 20.19 | U11: 0 | W11: 0.05 | X11: 43579 | Y11: =IF(I11="","No SIC",IFERROR(VLOOKUP(I11,Ref!$A$2:$B$65,2,FALSE()),"Unclassified")) | Z11: =IF(T11="","",IF(T11<12,"Daily","Weekly")) | AA11: =IF(T11="",0,IF(T11<12,T11*Controls!$B$13,T11*5)) | AB11: =IF(E11="",0,NETWORKDAYS(E11,Controls!$B$20,Ref!$K$2:$K$42)) | AC11: =IF(OR(AF11=1,AND(AA11>0,AB11>=Controls!$B$23*AA11)),1,0) | AD11: =IF(AND(E11<>"",E11>=Controls!$B$21,E11<=Controls!$B$22),1,0) | AE11: =IF(IFERROR(VLOOKUP(D11,Controls!$A$36:$E$46,2,FALSE()),"No")="Yes",1,0) | AF11: =IF(IFERROR(VLOOKUP(D11,Controls!$A$36:$E$46,3,FALSE()),"No")="Yes",1,0) | AG11: =IF(IFERROR(VLOOKUP(D11,Controls!$A$36:$E$46,4,FALSE()),"No")="Yes",1,0) | AH11: =IF(IFERROR(VLOOKUP(D11,Controls!$A$36:$E$46,5,FALSE()),"No")="Yes",1,0) | AI11: =IF(ISNUMBER(MATCH(D11,Controls!$A$36:$A$46,0)),1,0) | AJ11: =Q11-N11 | AK11: =IF(AE11=1,MAX(0,N11-Q11),0) | AL11: =IF(OR(V11="",V11=0),0,N11/V11) | AM11: =IF(OR(V11="",V11=0),0,1) | AN11: =IF(OR(E11="",F11=""),0,NETWORKDAYS(E11,F11,Ref!$K$2:$K$42)) | AO11: =IF(L11="Renewal",1,0) | AP11: =AC11*AD11 | AQ11: =IF(AND(G11<>"",'Historical Score'!$C$6<>""),IF(G11='Historical Score'!$C$6,1,0),0) | AR11: =IF(AND(L11<>"",'Historical Score'!$C$5<>""),IF(L11='Historical Score'!$C$5,1,0),0) | AS11: =IF(AND(Y11<>"",'Historical Score'!$C$7<>""),IF(Y11='Historical Score'!$C$7,1,0),0) | AT11: =IF(AND(K11<>"",'Historical Score'!$C$8<>""),IF(K11='Historical Score'!$C$8,1,0),0) | BA11: =IF(AD11=1,(AR11*'Historical Score'!$K$29+1-'Historical Score'!$K$29)*(AT11*'Historical Score'!$L$29+1-'Historical Score'!$L$29)*(AS11*'Historical Score'!$M$29+1-'Historical Score'!$M$29)*(AQ11*'Historical Score'!$N$29+1-'Historical Score'!$N$29),0)
A12: 5674147441 | B12: SJ HOSPICE SERVICES | C12: SJ HOSPICE SERVICES LLC | D12: Closed | E12: 45670 | F12: 45783 | G12: 2 | H12: 8082 | I12: 80 | J12: TX | K12: ICB FUNDING | L12: New Deal | M12: 1.39 | N12: 8500 | O12: 765 | P12: 11815 | Q12: 11815 | R12: 0 | S12: 1 | T12: 2.539 | U12: 0 | W12: 0.04 | X12: 42892 | Y12: =IF(I12="","No SIC",IFERROR(VLOOKUP(I12,Ref!$A$2:$B$65,2,FALSE()),"Unclassified")) | Z12: =IF(T12="","",IF(T12<12,"Daily","Weekly")) | AA12: =IF(T12="",0,IF(T12<12,T12*Controls!$B$13,T12*5)) | AB12: =IF(E12="",0,NETWORKDAYS(E12,Controls!$B$20,Ref!$K$2:$K$42)) | AC12: =IF(OR(AF12=1,AND(AA12>0,AB12>=Controls!$B$23*AA12)),1,0) | AD12: =IF(AND(E12<>"",E12>=Controls!$B$21,E12<=Controls!$B$22),1,0) | AE12: =IF(IFERROR(VLOOKUP(D12,Controls!$A$36:$E$46,2,FALSE()),"No")="Yes",1,0) | AF12: =IF(IFERROR(VLOOKUP(D12,Controls!$A$36:$E$46,3,FALSE()),"No")="Yes",1,0) | AG12: =IF(IFERROR(VLOOKUP(D12,Controls!$A$36:$E$46,4,FALSE()),"No")="Yes",1,0) | AH12: =IF(IFERROR(VLOOKUP(D12,Controls!$A$36:$E$46,5,FALSE()),"No")="Yes",1,0) | AI12: =IF(ISNUMBER(MATCH(D12,Controls!$A$36:$A$46,0)),1,0) | AJ12: =Q12-N12 | AK12: =IF(AE12=1,MAX(0,N12-Q12),0) | AL12: =IF(OR(V12="",V12=0),0,N12/V12) | AM12: =IF(OR(V12="",V12=0),0,1) | AN12: =IF(OR(E12="",F12=""),0,NETWORKDAYS(E12,F12,Ref!$K$2:$K$42)) | AO12: =IF(L12="Renewal",1,0) | AP12: =AC12*AD12 | AQ12: =IF(AND(G12<>"",'Historical Score'!$C$6<>""),IF(G12='Historical Score'!$C$6,1,0),0) | AR12: =IF(AND(L12<>"",'Historical Score'!$C$5<>""),IF(L12='Historical Score'!$C$5,1,0),0) | AS12: =IF(AND(Y12<>"",'Historical Score'!$C$7<>""),IF(Y12='Historical Score'!$C$7,1,0),0) | AT12: =IF(AND(K12<>"",'Historical Score'!$C$8<>""),IF(K12='Historical Score'!$C$8,1,0),0) | BA12: =IF(AD12=1,(AR12*'Historical Score'!$K$29+1-'Historical Score'!$K$29)*(AT12*'Historical Score'!$L$29+1-'Historical Score'!$L$29)*(AS12*'Historical Score'!$M$29+1-'Historical Score'!$M$29)*(AQ12*'Historical Score'!$N$29+1-'Historical Score'!$N$29),0)
A13: 5674147491 | B13: ROPP JERSEY CHEESE LLC | C13: ROPP JERSEY CHEESE LLC | D13: Legal | E13: 45670 | F13: 46234 | G13: 1 | H13: 5812 | I13: 58 | J13: IL | K13: ROYAL FUNDING GROUP | L13: New Deal | M13: 1.49 | N13: 12000 | O13: 1680 | P13: 17880 | Q13: 9022 | R13: 8858 | S13: 0.50458613 | T13: 2.706 | U13: 12 | W13: 0.13 | X13: 38507 | Y13: =IF(I13="","No SIC",IFERROR(VLOOKUP(I13,Ref!$A$2:$B$65,2,FALSE()),"Unclassified")) | Z13: =IF(T13="","",IF(T13<12,"Daily","Weekly")) | AA13: =IF(T13="",0,IF(T13<12,T13*Controls!$B$13,T13*5)) | AB13: =IF(E13="",0,NETWORKDAYS(E13,Controls!$B$20,Ref!$K$2:$K$42)) | AC13: =IF(OR(AF13=1,AND(AA13>0,AB13>=Controls!$B$23*AA13)),1,0) | AD13: =IF(AND(E13<>"",E13>=Controls!$B$21,E13<=Controls!$B$22),1,0) | AE13: =IF(IFERROR(VLOOKUP(D13,Controls!$A$36:$E$46,2,FALSE()),"No")="Yes",1,0) | AF13: =IF(IFERROR(VLOOKUP(D13,Controls!$A$36:$E$46,3,FALSE()),"No")="Yes",1,0) | AG13: =IF(IFERROR(VLOOKUP(D13,Controls!$A$36:$E$46,4,FALSE()),"No")="Yes",1,0) | AH13: =IF(IFERROR(VLOOKUP(D13,Controls!$A$36:$E$46,5,FALSE()),"No")="Yes",1,0) | AI13: =IF(ISNUMBER(MATCH(D13,Controls!$A$36:$A$46,0)),1,0) | AJ13: =Q13-N13 | AK13: =IF(AE13=1,MAX(0,N13-Q13),0) | AL13: =IF(OR(V13="",V13=0),0,N13/V13) | AM13: =IF(OR(V13="",V13=0),0,1) | AN13: =IF(OR(E13="",F13=""),0,NETWORKDAYS(E13,F13,Ref!$K$2:$K$42)) | AO13: =IF(L13="Renewal",1,0) | AP13: =AC13*AD13 | AQ13: =IF(AND(G13<>"",'Historical Score'!$C$6<>""),IF(G13='Historical Score'!$C$6,1,0),0) | AR13: =IF(AND(L13<>"",'Historical Score'!$C$5<>""),IF(L13='Historical Score'!$C$5,1,0),0) | AS13: =IF(AND(Y13<>"",'Historical Score'!$C$7<>""),IF(Y13='Historical Score'!$C$7,1,0),0) | AT13: =IF(AND(K13<>"",'Historical Score'!$C$8<>""),IF(K13='Historical Score'!$C$8,1,0),0) | BA13: =IF(AD13=1,(AR13*'Historical Score'!$K$29+1-'Historical Score'!$K$29)*(AT13*'Historical Score'!$L$29+1-'Historical Score'!$L$29)*(AS13*'Historical Score'!$M$29+1-'Historical Score'!$M$29)*(AQ13*'Historical Score'!$N$29+1-'Historical Score'!$N$29),0)
A14: 5674147495 | B14: ISHI MEDICAL EQUIPMENT & SUPPLIES INC Calle Primera | C14: ISHI MEDICAL EQUIPMENT & SUPPLIES INC Calle Primera | D14: Legal | E14: 45670 | F14: 45721 | G14: 3 | H14: 5047 | I14: 50 | J14: CA | K14: Key Capital Funding | L14: New Deal | M14: 1.49 | N14: 12000 | O14: 1680 | P14: 17880 | Q14: 3184 | R14: 14696 | S14: 0.17807606 | T14: 2.951 | U14: 15 | W14: 0.09 | X14: 38507 | Y14: =IF(I14="","No SIC",IFERROR(VLOOKUP(I14,Ref!$A$2:$B$65,2,FALSE()),"Unclassified")) | Z14: =IF(T14="","",IF(T14<12,"Daily","Weekly")) | AA14: =IF(T14="",0,IF(T14<12,T14*Controls!$B$13,T14*5)) | AB14: =IF(E14="",0,NETWORKDAYS(E14,Controls!$B$20,Ref!$K$2:$K$42)) | AC14: =IF(OR(AF14=1,AND(AA14>0,AB14>=Controls!$B$23*AA14)),1,0) | AD14: =IF(AND(E14<>"",E14>=Controls!$B$21,E14<=Controls!$B$22),1,0) | AE14: =IF(IFERROR(VLOOKUP(D14,Controls!$A$36:$E$46,2,FALSE()),"No")="Yes",1,0) | AF14: =IF(IFERROR(VLOOKUP(D14,Controls!$A$36:$E$46,3,FALSE()),"No")="Yes",1,0) | AG14: =IF(IFERROR(VLOOKUP(D14,Controls!$A$36:$E$46,4,FALSE()),"No")="Yes",1,0) | AH14: =IF(IFERROR(VLOOKUP(D14,Controls!$A$36:$E$46,5,FALSE()),"No")="Yes",1,0) | AI14: =IF(ISNUMBER(MATCH(D14,Controls!$A$36:$A$46,0)),1,0) | AJ14: =Q14-N14 | AK14: =IF(AE14=1,MAX(0,N14-Q14),0) | AL14: =IF(OR(V14="",V14=0),0,N14/V14) | AM14: =IF(OR(V14="",V14=0),0,1) | AN14: =IF(OR(E14="",F14=""),0,NETWORKDAYS(E14,F14,Ref!$K$2:$K$42)) | AO14: =IF(L14="Renewal",1,0) | AP14: =AC14*AD14 | AQ14: =IF(AND(G14<>"",'Historical Score'!$C$6<>""),IF(G14='Historical Score'!$C$6,1,0),0) | AR14: =IF(AND(L14<>"",'Historical Score'!$C$5<>""),IF(L14='Historical Score'!$C$5,1,0),0) | AS14: =IF(AND(Y14<>"",'Historical Score'!$C$7<>""),IF(Y14='Historical Score'!$C$7,1,0),0) | AT14: =IF(AND(K14<>"",'Historical Score'!$C$8<>""),IF(K14='Historical Score'!$C$8,1,0),0) | BA14: =IF(AD14=1,(AR14*'Historical Score'!$K$29+1-'Historical Score'!$K$29)*(AT14*'Historical Score'!$L$29+1-'Historical Score'!$L$29)*(AS14*'Historical Score'!$M$29+1-'Historical Score'!$M$29)*(AQ14*'Historical Score'!$N$29+1-'Historical Score'!$N$29),0)
A15: 5674147827 | B15: Delta Security Services LLC | C15: Delta Security Services LLC | D15: Closed | E15: 45673 | F15: 45791 | G15: 1 | H15: 7382 | I15: 73 | J15: WA | K15: First Path Capital | L15: Renewal | M15: 1.49 | N15: 5000 | O15: 700 | P15: 7450 | Q15: 7450 | R15: 0 | S15: 1 | T15: 2.623 | U15: 0 | W15: 0.06 | Y15: =IF(I15="","No SIC",IFERROR(VLOOKUP(I15,Ref!$A$2:$B$65,2,FALSE()),"Unclassified")) | Z15: =IF(T15="","",IF(T15<12,"Daily","Weekly")) | AA15: =IF(T15="",0,IF(T15<12,T15*Controls!$B$13,T15*5)) | AB15: =IF(E15="",0,NETWORKDAYS(E15,Controls!$B$20,Ref!$K$2:$K$42)) | AC15: =IF(OR(AF15=1,AND(AA15>0,AB15>=Controls!$B$23*AA15)),1,0) | AD15: =IF(AND(E15<>"",E15>=Controls!$B$21,E15<=Controls!$B$22),1,0) | AE15: =IF(IFERROR(VLOOKUP(D15,Controls!$A$36:$E$46,2,FALSE()),"No")="Yes",1,0) | AF15: =IF(IFERROR(VLOOKUP(D15,Controls!$A$36:$E$46,3,FALSE()),"No")="Yes",1,0) | AG15: =IF(IFERROR(VLOOKUP(D15,Controls!$A$36:$E$46,4,FALSE()),"No")="Yes",1,0) | AH15: =IF(IFERROR(VLOOKUP(D15,Controls!$A$36:$E$46,5,FALSE()),"No")="Yes",1,0) | AI15: =IF(ISNUMBER(MATCH(D15,Controls!$A$36:$A$46,0)),1,0) | AJ15: =Q15-N15 | AK15: =IF(AE15=1,MAX(0,N15-Q15),0) | AL15: =IF(OR(V15="",V15=0),0,N15/V15) | AM15: =IF(OR(V15="",V15=0),0,1) | AN15: =IF(OR(E15="",F15=""),0,NETWORKDAYS(E15,F15,Ref!$K$2:$K$42)) | AO15: =IF(L15="Renewal",1,0) | AP15: =AC15*AD15 | AQ15: =IF(AND(G15<>"",'Historical Score'!$C$6<>""),IF(G15='Historical Score'!$C$6,1,0),0) | AR15: =IF(AND(L15<>"",'Historical Score'!$C$5<>""),IF(L15='Historical Score'!$C$5,1,0),0) | AS15: =IF(AND(Y15<>"",'Historical Score'!$C$7<>""),IF(Y15='Historical Score'!$C$7,1,0),0) | AT15: =IF(AND(K15<>"",'Historical Score'!$C$8<>""),IF(K15='Historical Score'!$C$8,1,0),0) | BA15: =IF(AD15=1,(AR15*'Historical Score'!$K$29+1-'Historical Score'!$K$29)*(AT15*'Historical Score'!$L$29+1-'Historical Score'!$L$29)*(AS15*'Historical Score'!$M$29+1-'Historical Score'!$M$29)*(AQ15*'Historical Score'!$N$29+1-'Historical Score'!$N$29),0)
