Workbook
Name D26D33: #REF!

Sheet Deal
B1: UNDERWRITING TOOL
B2: DECISION | C2: =C62 -> CONDITIONAL
B4: A. OFFER | J4: MONEYBADGER CROSS-CHECK
B5: Fund $ | C5: Factor | D5: =IF($E$6="Weekly","Term (weeks)","Term (daily pmts)") -> Term (weeks) | E5: Freq | F5: Fee % | J5: Metric | K5: This tool | L5: MoneyBadger | M5: Diff
B6: 40000 | C6: 1.45 | D6: 24 | E6: Weekly | F6: =Controls!$B$15 -> 0.05 | J6: =IF($E$6="Weekly","Weekly remittance","Daily remittance") -> Weekly remittance | K6: =IF(OR($E$6="",C8="",C24=0),"",IF($E$6="Weekly",D8,C8)) -> 2416.6667 | L6: =IF(OR(L7="",C24=0),"",L7*C24/IF($E$6="Weekly",$L$8,$L$9)) -> 2417.1562 | M6: =IF(OR(K6="",L6=""),"",L6-K6) -> 0.48958333
B7: Payback | C7: Daily $ | D7: Weekly $ | E7: Monthly $ | F7: Term (mo) | G7: Net $ | J7: Holdback % | K7: =IF(OR(D8="",C24=0),"",E8/C24) -> 0.12135169 | L7: =IF(OR($E$6="",C8="",C24=0),"",ROUND(IF($E$6="Weekly",D8*$L$8,C8*$L$9)/C24*100,2)/100) -> 0.1121 | M7: =IF(OR(K7="",L7=""),"",L7-K7) -> -0.0092516908
B8: =IF(OR(B6="",C6=""),"",B6*C6) -> 58000 | C8: =IF(OR(B8="",D6="",D6=0),"",IF(E6="Weekly",(B8/D6)/5,B8/D6)) -> 483.33333 | D8: =IF(C8="","",C8*5) -> 2416.6667 | E8: =IF(C8="","",C8*$K$9) -> 10466.583 | F8: =IF(OR(D6="",D6=0),"",IF(E6="Weekly",D6,D6/5)/($K$9/5)) -> 5.5414454 | G8: =IF(B6="","",B6-(B6*F6)) -> 38000 | J8: Weeks / month | K8: =Controls!$B$28 -> 4.331 | L8: =Controls!$B$30 -> 4 | M8: =IF(OR(K8="",L8=""),"",L8-K8) -> -0.331
J9: Days / month | K9: =Controls!$B$29 -> 21.655 | L9: =Controls!$B$31 -> 21 | M9: =IF(OR(K9="",L9=""),"",L9-K9) -> -0.655
B10: B. BANK DATA
B11: Month - NEWEST FIRST | C11: True rev $ | D11: Avg daily bal $ | E11: Neg days | F11: NSFs | G11: MoM % | J11: DEAL PROFILE
B12: Aug | C12: 88000 | D12: 7400 | E12: 0 | F12: 0 | G12: =IF(OR(C12="",C13=""),"",(C12-C13)/C13) -> 0.047619048 | J12: ISO | K12: Fundwell | L12: =IF(K12="","",COUNTIF('Historical Data'!$K$2:$K$9,K12)&" deals in book") -> 4 deals in book
B13: Jul | C13: 84000 | D13: 6900 | E13: 0 | F13: 1 | G13: =IF(OR(C13="",C14=""),"",(C13-C14)/C14) -> -0.076923077 | J13: Industry | K13: Eating & Drinking Places | L13: =IF(K13="","",COUNTIF('Historical Data'!$Y$2:$Y$9,K13)&" deals in book") -> 1 deals in book
B14: Jun | C14: 91000 | D14: 8100 | E14: 0 | F14: 0 | G14: =IF(OR(C14="",C15=""),"",(C14-C15)/C15) -> 0.1097561 | J14: New deal or renewal | K14: New Deal
B15: May | C15: 82000 | D15: 6500 | E15: 1 | F15: 0 | G15: =IF(OR(C15="",C16=""),"",(C15-C16)/C16) | J15: Credit score | K15: 672
G16: =IF(OR(C16="",C17=""),"",(C16-C17)/C17)
G17: =IF(OR(C17="",C18=""),"",(C17-C18)/C18)
G18: =IF(OR(C18="",C19=""),"",(C18-C19)/C19)
G19: =IF(OR(C19="",C20=""),"",(C19-C20)/C20)
G20: =IF(OR(C20="",C21=""),"",(C20-C21)/C21)
G21: =IF(OR(C21="",C22=""),"",(C21-C22)/C22)
G22: =IF(OR(C22="",C23=""),"",(C22-C23)/C23)
B24: AVG / TOTAL (months entered) | C24: =IF(COUNT(C12:C23)=0,0,AVERAGE(C12:C23)) -> 86250 | D24: =IF(COUNT(D12:D23)=0,0,AVERAGE(D12:D23)) -> 7225 | E24: =SUM(E12:E23) -> 1 | F24: =SUM(F12:F23) -> 1 | G24: =IFERROR(AVERAGE(G12:G22),"") -> 0.026817356
B26: EXISTING POSITIONS
B27: Funder | C27: Funded $ | D27: Payment | E27: Freq | F27: Daily equiv | G27: Start Date | H27: Est Term | I27: Est term (mo) | J27: Mo. remaining
C28: 100000 | D28: 3000 | E28: Weekly | F28: =IF(D28<>"",IF(E28="Daily",D28,IF(E28="Weekly",D28/5,D28/$K$9)),IF(C28="","",C28*Controls!$B$33/(Controls!$B$23*$K$9))) -> 600 | G28: 46127 | H28: =IF(OR(C28="",D28=""),"",ROUND(C28*Controls!$B$33/D28,0)) -> 48 | I28: =IF(H28="","",H28/IF(E28="Daily",$K$9,IF(E28="Weekly",$K$9/5,1))) -> 11.082891 | J28: =IF(OR(I28="",G28=""),"",MAX(0,I28-(TODAY()-G28)/Controls!$B$32)) -> 6.2861762
E29: Weekly | F29: =IF(D29<>"",IF(E29="Daily",D29,IF(E29="Weekly",D29/5,D29/$K$9)),IF(C29="","",C29*Controls!$B$33/(Controls!$B$23*$K$9))) | H29: =IF(OR(C29="",D29=""),"",ROUND(C29*Controls!$B$33/D29,0)) | I29: =IF(H29="","",H29/IF(E29="Daily",$K$9,IF(E29="Weekly",$K$9/5,1))) | J29: =IF(OR(I29="",G29=""),"",MAX(0,I29-(TODAY()-G29)/Controls!$B$32))
E30: Weekly | F30: =IF(D30<>"",IF(E30="Daily",D30,IF(E30="Weekly",D30/5,D30/$K$9)),IF(C30="","",C30*Controls!$B$33/(Controls!$B$23*$K$9))) | H30: =IF(OR(C30="",D30=""),"",ROUND(C30*Controls!$B$33/D30,0)) | I30: =IF(H30="","",H30/IF(E30="Daily",$K$9,IF(E30="Weekly",$K$9/5,1))) | J30: =IF(OR(I30="",G30=""),"",MAX(0,I30-(TODAY()-G30)/Controls!$B$32))
E31: Weekly | F31: =IF(D31<>"",IF(E31="Daily",D31,IF(E31="Weekly",D31/5,D31/$K$9)),IF(C31="","",C31*Controls!$B$33/(Controls!$B$23*$K$9))) | H31: =IF(OR(C31="",D31=""),"",ROUND(C31*Controls!$B$33/D31,0)) | I31: =IF(H31="","",H31/IF(E31="Daily",$K$9,IF(E31="Weekly",$K$9/5,1))) | J31: =IF(OR(I31="",G31=""),"",MAX(0,I31-(TODAY()-G31)/Controls!$B$32))
E32: Weekly | F32: =IF(D32<>"",IF(E32="Daily",D32,IF(E32="Weekly",D32/5,D32/$K$9)),IF(C32="","",C32*Controls!$B$33/(Controls!$B$23*$K$9))) | H32: =IF(OR(C32="",D32=""),"",ROUND(C32*Controls!$B$33/D32,0)) | I32: =IF(H32="","",H32/IF(E32="Daily",$K$9,IF(E32="Weekly",$K$9/5,1))) | J32: =IF(OR(I32="",G32=""),"",MAX(0,I32-(TODAY()-G32)/Controls!$B$32))
E33: Weekly | F33: =IF(D33<>"",IF(E33="Daily",D33,IF(E33="Weekly",D33/5,D33/$K$9)),IF(C33="","",C33*Controls!$B$33/(Controls!$B$23*$K$9))) | H33: =IF(OR(C33="",D33=""),"",ROUND(C33*Controls!$B$33/D33,0)) | I33: =IF(H33="","",H33/IF(E33="Daily",$K$9,IF(E33="Weekly",$K$9/5,1))) | J33: =IF(OR(I33="",G33=""),"",MAX(0,I33-(TODAY()-G33)/Controls!$B$32))
B34: Positions (excl. Monthly) | C34: =SUMPRODUCT(((C28:C33<>"")+(D28:D33<>"")>0)*(E28:E33<>"Monthly")) -> 1 | D34: Total existing daily | E34: =SUM(F28:F33) -> 600 | F34: =E34*$K$9 -> 12993 | G34: /month
B36: C. METRICS
B37: Metric | C37: Value | D37: Green | E37: Red | F37: Status | G37: Knockout | H37: Sizing line
B38: Total LVG (all debt / rev) | C38: =IF(C24=0,"",(E34+IF(C8="",0,C8))*$K$9/C24) -> 0.27199517 | D38: =Controls!$B$5 -> 0.3 | E38: =Controls!$C$5 -> 0.45 | F38: =IF(C38="","",IF(C38>=G38,"KNOCKOUT",IF(C38<=D38,"GREEN",IF(C38>=E38,"RED","YELLOW")))) -> GREEN | G38: =Controls!$D$5 -> 0.55 | H38: =D38+'Historical Score'!$C$36*(E38-D38) -> 0.3
B39: New holdback SP% | C39: =IF(OR(C24=0,E8=""),"",E8/C24) -> 0.12135169 | D39: =Controls!$B$6 -> 0.18 | E39: =Controls!$C$6 -> 0.25 | F39: =IF(C39="","",IF(C39>=G39,"KNOCKOUT",IF(C39<=D39,"GREEN",IF(C39>=E39,"RED","YELLOW")))) -> GREEN | G39: =Controls!$D$6 -> 0.35 | H39: =D39+'Historical Score'!$C$36*(E39-D39) -> 0.18
B40: Daily debt / balance | C40: =IF(D24=0,"",(E34+IF(C8="",0,C8))/D24) -> 0.14994233 | D40: =Controls!$B$7 -> 0.18 | E40: =Controls!$C$7 -> 0.3 | F40: =IF(C40="","",IF(C40>=G40,"KNOCKOUT",IF(C40<=D40,"GREEN",IF(C40>=E40,"RED","YELLOW")))) -> GREEN | G40: =Controls!$D$7 -> 0.35 | H40: =D40+'Historical Score'!$C$36*(E40-D40) -> 0.18
B41: Fund / revenue | C41: =IF(OR(C24=0,B6=""),"",B6/C24) -> 0.46376812 | D41: =Controls!$B$8 -> 0.6 | E41: =Controls!$C$8 -> 0.9 | F41: =IF(C41="","",IF(C41>=G41,"KNOCKOUT",IF(C41<=D41,"GREEN",IF(C41>=E41,"RED","YELLOW")))) -> GREEN | G41: =Controls!$D$8 -> 1.25 | H41: =D41+'Historical Score'!$C$36*(E41-D41) -> 0.6
B42: # positions (incl. new) | C42: =IF(C24=0,"",C34+1) -> 2 | D42: =Controls!$B$9 -> 2 | E42: =Controls!$C$9 -> 5 | F42: =IF(C42="","",IF(C42>=G42,"KNOCKOUT",IF(C42<=D42,"GREEN",IF(C42>=E42,"RED","YELLOW")))) -> GREEN | G42: =Controls!$D$9 -> 6
B43: Revenue trend (avg MoM) | C43: =G24 -> 0.026817356 | D43: =Controls!$B$10 -> -0.05 | E43: =Controls!$C$10 -> -0.15 | F43: =IF(C24=0,"",IF(NOT(ISNUMBER(C43)),"YELLOW",IF(C43<=G43,"KNOCKOUT",IF(C43>=D43,"GREEN",IF(C43<=E43,"RED","YELLOW"))))) -> GREEN | G43: =Controls!$D$10 -> -0.3
B44: Neg days + NSFs (total) | C44: =E24+F24 -> 2 | D44: =Controls!$B$11 -> 1 | E44: =Controls!$C$11 -> 6 | F44: =IF(C44="","",IF(C44>=G44,"KNOCKOUT",IF(C44<=D44,"GREEN",IF(C44>=E44,"RED","YELLOW")))) -> YELLOW | G44: =Controls!$D$11 -> 10
...

Sheet Historical Score
A1: HISTORICAL SCORE
A4: DEAL BEING MATCHED
B5: New deal or renewal | C5: =IF(Deal!$K$14="","",Deal!$K$14) -> New Deal
B6: Position (Deal C42) | C6: =IF(Deal!$C$42="","",Deal!$C$42) -> 2
B7: Industry | C7: =IF(Deal!$K$13="","",Deal!$K$13) -> Eating & Drinking Places
B8: ISO | C8: =IF(Deal!$K$12="","",Deal!$K$12) -> Fundwell
B10: Seasoned-book principal lost rate (baseline) | C10: =IF($F$20="",0,$F$20) -> 0.41
B11: Seasoned-book return on funded | C11: =IF($G$20="",0,$G$20) -> -0.24333333
A13: Tier | B13: Cohort | C13: Seasoned deals | D13: Funded $ (seasoned) | E13: Meets min? | F13: Principal lost rate | G13: Return on funded | H13: Index
A14: 1 | B14: T1: new/renewal + industry + position | C14: =SUMPRODUCT('Historical Data'!$AU$2:$AU$9*'Historical Data'!$AP$2:$AP$9) -> 0 | D14: =SUMPRODUCT('Historical Data'!$AU$2:$AU$9*'Historical Data'!$AP$2:$AP$9*'Historical Data'!$N$2:$N$9) -> 0 | E14: =IF(AND(C14>=Controls!$B$40,D14>=Controls!$B$41),"Yes","No") -> No | F14: =IF(OR(C14<Controls!$B$43,D14=0),"",SUMPRODUCT('Historical Data'!$AU$2:$AU$9*'Historical Data'!$AP$2:$AP$9*'Historical Data'!$AK$2:$AK$9)/D14) | G14: =IF(OR(C14<Controls!$B$43,D14=0),"",SUMPRODUCT('Historical Data'!$AU$2:$AU$9*'Historical Data'!$AP$2:$AP$9*'Historical Data'!$AJ$2:$AJ$9)/D14) | H14: =IF(OR(F14="",$C$10=0),"",F14/$C$10)
A15: 2 | B15: T2: new/renewal + ISO + position | C15: =SUMPRODUCT('Historical Data'!$AV$2:$AV$9*'Historical Data'!$AP$2:$AP$9) -> 0 | D15: =SUMPRODUCT('Historical Data'!$AV$2:$AV$9*'Historical Data'!$AP$2:$AP$9*'Historical Data'!$N$2:$N$9) -> 0 | E15: =IF(AND(C15>=Controls!$B$40,D15>=Controls!$B$41),"Yes","No") -> No | F15: =IF(OR(C15<Controls!$B$43,D15=0),"",SUMPRODUCT('Historical Data'!$AV$2:$AV$9*'Historical Data'!$AP$2:$AP$9*'Historical Data'!$AK$2:$AK$9)/D15) | G15: =IF(OR(C15<Controls!$B$43,D15=0),"",SUMPRODUCT('Historical Data'!$AV$2:$AV$9*'Historical Data'!$AP$2:$AP$9*'Historical Data'!$AJ$2:$AJ$9)/D15) | H15: =IF(OR(F15="",$C$10=0),"",F15/$C$10)
A16: 3 | B16: T3: new/renewal + industry | C16: =SUMPRODUCT('Historical Data'!$AW$2:$AW$9*'Historical Data'!$AP$2:$AP$9) -> 1 | D16: =SUMPRODUCT('Historical Data'!$AW$2:$AW$9*'Historical Data'!$AP$2:$AP$9*'Historical Data'!$N$2:$N$9) -> 10000 | E16: =IF(AND(C16>=Controls!$B$40,D16>=Controls!$B$41),"Yes","No") -> No | F16: =IF(OR(C16<Controls!$B$43,D16=0),"",SUMPRODUCT('Historical Data'!$AW$2:$AW$9*'Historical Data'!$AP$2:$AP$9*'Historical Data'!$AK$2:$AK$9)/D16) | G16: =IF(OR(C16<Controls!$B$43,D16=0),"",SUMPRODUCT('Historical Data'!$AW$2:$AW$9*'Historical Data'!$AP$2:$AP$9*'Historical Data'!$AJ$2:$AJ$9)/D16) | H16: =IF(OR(F16="",$C$10=0),"",F16/$C$10)
A17: 4 | B17: T4: new/renewal + ISO | C17: =SUMPRODUCT('Historical Data'!$AX$2:$AX$9*'Historical Data'!$AP$2:$AP$9) -> 2 | D17: =SUMPRODUCT('Historical Data'!$AX$2:$AX$9*'Historical Data'!$AP$2:$AP$9*'Historical Data'!$N$2:$N$9) -> 40000 | E17: =IF(AND(C17>=Controls!$B$40,D17>=Controls!$B$41),"Yes","No") -> No | F17: =IF(OR(C17<Controls!$B$43,D17=0),"",SUMPRODUCT('Historical Data'!$AX$2:$AX$9*'Historical Data'!$AP$2:$AP$9*'Historical Data'!$AK$2:$AK$9)/D17) -> 0.525 | G17: =IF(OR(C17<Controls!$B$43,D17=0),"",SUMPRODUCT('Historical Data'!$AX$2:$AX$9*'Historical Data'!$AP$2:$AP$9*'Historical Data'!$AJ$2:$AJ$9)/D17) -> -0.4 | H17: =IF(OR(F17="",$C$10=0),"",F17/$C$10) -> 1.2804878
A18: 5 | B18: T5: new/renewal + position | C18: =SUMPRODUCT('Historical Data'!$AY$2:$AY$9*'Historical Data'!$AP$2:$AP$9) -> 0 | D18: =SUMPRODUCT('Historical Data'!$AY$2:$AY$9*'Historical Data'!$AP$2:$AP$9*'Historical Data'!$N$2:$N$9) -> 0 | E18: =IF(AND(C18>=Controls!$B$40,D18>=Controls!$B$41),"Yes","No") -> No | F18: =IF(OR(C18<Controls!$B$43,D18=0),"",SUMPRODUCT('Historical Data'!$AY$2:$AY$9*'Historical Data'!$AP$2:$AP$9*'Historical Data'!$AK$2:$AK$9)/D18) | G18: =IF(OR(C18<Controls!$B$43,D18=0),"",SUMPRODUCT('Historical Data'!$AY$2:$AY$9*'Historical Data'!$AP$2:$AP$9*'Historical Data'!$AJ$2:$AJ$9)/D18) | H18: =IF(OR(F18="",$C$10=0),"",F18/$C$10)
A19: 6 | B19: T6: new/renewal only | C19: =SUMPRODUCT('Historical Data'!$AZ$2:$AZ$9*'Historical Data'!$AP$2:$AP$9) -> 5 | D19: =SUMPRODUCT('Historical Data'!$AZ$2:$AZ$9*'Historical Data'!$AP$2:$AP$9*'Historical Data'!$N$2:$N$9) -> 120000 | E19: =IF(AND(C19>=Controls!$B$40,D19>=Controls!$B$41),"Yes","No") -> Yes | F19: =IF(OR(C19<Controls!$B$43,D19=0),"",SUMPRODUCT('Historical Data'!$AZ$2:$AZ$9*'Historical Data'!$AP$2:$AP$9*'Historical Data'!$AK$2:$AK$9)/D19) -> 0.50833333 | G19: =IF(OR(C19<Controls!$B$43,D19=0),"",SUMPRODUCT('Historical Data'!$AZ$2:$AZ$9*'Historical Data'!$AP$2:$AP$9*'Historical Data'!$AJ$2:$AJ$9)/D19) -> -0.38333333 | H19: =IF(OR(F19="",$C$10=0),"",F19/$C$10) -> 1.2398374
A20: 7 | B20: T7: seasoned book (baseline) | C20: =SUMPRODUCT('Historical Data'!$BA$2:$BA$9*'Historical Data'!$AP$2:$AP$9) -> 7 | D20: =SUMPRODUCT('Historical Data'!$BA$2:$BA$9*'Historical Data'!$AP$2:$AP$9*'Historical Data'!$N$2:$N$9) -> 150000 | E20: =IF(AND(C20>=Controls!$B$40,D20>=Controls!$B$41),"Yes","No") -> Yes | F20: =IF(OR(C20<Controls!$B$43,D20=0),"",SUMPRODUCT('Historical Data'!$BA$2:$BA$9*'Historical Data'!$AP$2:$AP$9*'Historical Data'!$AK$2:$AK$9)/D20) -> 0.41 | G20: =IF(OR(C20<Controls!$B$43,D20=0),"",SUMPRODUCT('Historical Data'!$BA$2:$BA$9*'Historical Data'!$AP$2:$AP$9*'Historical Data'!$AJ$2:$AJ$9)/D20) -> -0.24333333 | H20: =IF(OR(F20="",$C$10=0),"",F20/$C$10) -> 1
B21: SINGLE-DIMENSION EVIDENCE (feeds the C2 block and the largest-impact test; does not pick the cohort) | I21: |PLR - book PLR|
A22: S1 | B22: Position only | C22: =SUMPRODUCT('Historical Data'!$AQ$2:$AQ$9*'Historical Data'!$AP$2:$AP$9) -> 2 | D22: =SUMPRODUCT('Historical Data'!$AQ$2:$AQ$9*'Historical Data'!$AP$2:$AP$9*'Historical Data'!$N$2:$N$9) -> 30000 | E22: =IF(AND(C22>=Controls!$B$40,D22>=Controls!$B$41),"Yes","No") -> No | F22: =IF(OR(C22<Controls!$B$43,D22=0),"",SUMPRODUCT('Historical Data'!$AQ$2:$AQ$9*'Historical Data'!$AP$2:$AP$9*'Historical Data'!$AK$2:$AK$9)/D22) -> 0.016666667 | G22: =IF(OR(C22<Controls!$B$43,D22=0),"",SUMPRODUCT('Historical Data'!$AQ$2:$AQ$9*'Historical Data'!$AP$2:$AP$9*'Historical Data'!$AJ$2:$AJ$9)/D22) -> 0.31666667 | H22: =IF(OR(F22="",$C$10=0),"",F22/$C$10) -> 0.040650406 | I22: =IF(F22="",0,ABS(F22-$C$10)) -> 0.39333333
A23: S2 | B23: New/renewal only | C23: =SUMPRODUCT('Historical Data'!$AR$2:$AR$9*'Historical Data'!$AP$2:$AP$9) -> 5 | D23: =SUMPRODUCT('Historical Data'!$AR$2:$AR$9*'Historical Data'!$AP$2:$AP$9*'Historical Data'!$N$2:$N$9) -> 120000 | E23: =IF(AND(C23>=Controls!$B$40,D23>=Controls!$B$41),"Yes","No") -> Yes | F23: =IF(OR(C23<Controls!$B$43,D23=0),"",SUMPRODUCT('Historical Data'!$AR$2:$AR$9*'Historical Data'!$AP$2:$AP$9*'Historical Data'!$AK$2:$AK$9)/D23) -> 0.50833333 | G23: =IF(OR(C23<Controls!$B$43,D23=0),"",SUMPRODUCT('Historical Data'!$AR$2:$AR$9*'Historical Data'!$AP$2:$AP$9*'Historical Data'!$AJ$2:$AJ$9)/D23) -> -0.38333333 | H23: =IF(OR(F23="",$C$10=0),"",F23/$C$10) -> 1.2398374 | I23: =IF(F23="",0,ABS(F23-$C$10)) -> 0.098333333
A24: S3 | B24: Industry only | C24: =SUMPRODUCT('Historical Data'!$AS$2:$AS$9*'Historical Data'!$AP$2:$AP$9) -> 1 | D24: =SUMPRODUCT('Historical Data'!$AS$2:$AS$9*'Historical Data'!$AP$2:$AP$9*'Historical Data'!$N$2:$N$9) -> 10000 | E24: =IF(AND(C24>=Controls!$B$40,D24>=Controls!$B$41),"Yes","No") -> No | F24: =IF(OR(C24<Controls!$B$43,D24=0),"",SUMPRODUCT('Historical Data'!$AS$2:$AS$9*'Historical Data'!$AP$2:$AP$9*'Historical Data'!$AK$2:$AK$9)/D24) | G24: =IF(OR(C24<Controls!$B$43,D24=0),"",SUMPRODUCT('Historical Data'!$AS$2:$AS$9*'Historical Data'!$AP$2:$AP$9*'Historical Data'!$AJ$2:$AJ$9)/D24) | H24: =IF(OR(F24="",$C$10=0),"",F24/$C$10) | I24: =IF(F24="",0,ABS(F24-$C$10)) -> 0
A25: S4 | B25: ISO only | C25: =SUMPRODUCT('Historical Data'!$AT$2:$AT$9*'Historical Data'!$AP$2:$AP$9) -> 3 | D25: =SUMPRODUCT('Historical Data'!$AT$2:$AT$9*'Historical Data'!$AP$2:$AP$9*'Historical Data'!$N$2:$N$9) -> 50000 | E25: =IF(AND(C25>=Controls!$B$40,D25>=Controls!$B$41),"Yes","No") -> Yes | F25: =IF(OR(C25<Controls!$B$43,D25=0),"",SUMPRODUCT('Historical Data'!$AT$2:$AT$9*'Historical Data'!$AP$2:$AP$9*'Historical Data'!$AK$2:$AK$9)/D25) -> 0.43 | G25: =IF(OR(C25<Controls!$B$43,D25=0),"",SUMPRODUCT('Historical Data'!$AT$2:$AT$9*'Historical Data'!$AP$2:$AP$9*'Historical Data'!$AJ$2:$AJ$9)/D25) -> -0.33 | H25: =IF(OR(F25="",$C$10=0),"",F25/$C$10) -> 1.0487805 | I25: =IF(F25="",0,ABS(F25-$C$10)) -> 0.02
A28: RESULT
B29: Primary tier = the LOWEST tier number that meets both minimums | C29: =IFERROR(MATCH("Yes",$E$14:$E$20,0),7) -> 6
B30: Primary cohort | C30: {=INDEX($B$14:$B$20,$C$29)} -> T6: new/renewal only
B31: Seasoned deals in it | C31: {=INDEX($C$14:$C$20,$C$29)} -> 5
B32: Its principal lost rate | C32: {=INDEX($F$14:$F$20,$C$29)} -> 0.50833333
B33: Its return on funded | C33: {=INDEX($G$14:$G$20,$C$29)} -> -0.38333333
B34: Index (its PLR / book PLR) | C34: {=INDEX($H$14:$H$20,$C$29)} -> 1.2398374
B35: HOUSE-BOOK OUTCOME | C35: =IF(OR(C29=7,C34=""),"Neutral",IF(C34<=Controls!$B$49,"Supportive",IF(C34>Controls!$B$50,"Negative","Neutral"))) -> Negative
B36: Sizing flex applied to section C (Supportive only) | C36: =IF(C35="Supportive",Controls!$B$51,0) -> 0
B37: Largest-impact variable (position / new-renewal / industry / ISO) | C37: {=IF(MAX($I$22:$I$25)=0,"none rated",INDEX($B$22:$B$25,MATCH(MAX($I$22:$I$25),$I$22:$I$25,0))&": "&TEXT(INDEX($F$22:$F$25,MATCH(MAX($I$22:$I$25),$I$22:$I$25,0)),"0.0%")&" PLR vs "&TEXT($C$10,"0.0%")&" book")} -> Position only: 1.7% PLR vs 41.0% book

Sheet Comparable Deals
A1: COMPARABLE DEALS
A4: Contract ID | B4: DBA | C4: Status | D4: Funded | E4: Position | F4: Industry | G4: ISO | H4: New/renewal | I4: Factor | J4: Advance | K4: Collected | L4: % paid | M4: Net cash | N4: Principal lost | O4: Term (bd) | P4: Age (bd) | Q4: Days on book | R4: Seasoned | S4: Default | T4: Open | U4: Best tier (1 = closest) | V4: In primary cohort
A5: ='Historical Data'!A2 -> A-001 | B5: ='Historical Data'!B2 -> Ridgeline Cafe | C5: ='Historical Data'!D2 -> Closed | D5: ='Historical Data'!E2 -> 45672 | E5: ='Historical Data'!G2 -> 1 | F5: ='Historical Data'!Y2 -> Eating & Drinking Places | G5: ='Historical Data'!K2 -> Fundwell | H5: ='Historical Data'!L2 -> New Deal | I5: ='Historical Data'!M2 -> 1.5 | J5: ='Historical Data'!N2 -> 10000 | K5: ='Historical Data'!Q2 -> 15000 | L5: ='Historical Data'!S2 -> 1 | M5: ='Historical Data'!AJ2 -> 5000 | N5: ='Historical Data'!AK2 -> 0 | O5: ='Historical Data'!AA2 -> 108.275 | P5: ='Historical Data'!AB2 -> 405 | Q5: ='Historical Data'!AN2 -> 105 | R5: ='Historical Data'!AC2 -> 1 | S5: ='Historical Data'!AE2 -> 0 | T5: ='Historical Data'!AH2 -> 0 | U5: ='Historical Data'!BB2 -> 3 | V5: ='Historical Data'!BC2 -> 1
A6: ='Historical Data'!A3 -> A-002 | B6: ='Historical Data'!B3 -> Delta Freight | C6: ='Historical Data'!D3 -> Closed | D6: ='Historical Data'!E3 -> 45698 | E6: ='Historical Data'!G3 -> 2 | F6: ='Historical Data'!Y3 -> Trucking & Warehousing | G6: ='Historical Data'!K3 -> Westwood | H6: ='Historical Data'!L3 -> Renewal | I6: ='Historical Data'!M3 -> 1.5 | J6: ='Historical Data'!N3 -> 20000 | K6: ='Historical Data'!Q3 -> 30000 | L6: ='Historical Data'!S3 -> 1 | M6: ='Historical Data'!AJ3 -> 10000 | N6: ='Historical Data'!AK3 -> 0 | O6: ='Historical Data'!AA3 -> 100 | P6: ='Historical Data'!AB3 -> 388 | Q6: ='Historical Data'!AN3 -> 105 | R6: ='Historical Data'!AC3 -> 1 | S6: ='Historical Data'!AE3 -> 0 | T6: ='Historical Data'!AH3 -> 0 | U6: ='Historical Data'!BB3 -> 7 | V6: ='Historical Data'!BC3 -> 0
A7: ='Historical Data'!A4 -> A-003 | B7: ='Historical Data'!B4 -> Kane Construction | C7: ='Historical Data'!D4 -> Legal | D7: ='Historical Data'!E4 -> 45721 | E7: ='Historical Data'!G4 -> 3 | F7: ='Historical Data'!Y4 -> General Building Contractors | G7: ='Historical Data'!K4 -> Fundwell | H7: ='Historical Data'!L4 -> New Deal | I7: ='Historical Data'!M4 -> 1.5 | J7: ='Historical Data'!N4 -> 30000 | K7: ='Historical Data'!Q4 -> 9000 | L7: ='Historical Data'!S4 -> 0.2 | M7: ='Historical Data'!AJ4 -> -21000 | N7: ='Historical Data'!AK4 -> 21000 | O7: ='Historical Data'!AA4 -> 129.93 | P7: ='Historical Data'!AB4 -> 372 | Q7: ='Historical Data'!AN4 -> 66 | R7: ='Historical Data'!AC4 -> 1 | S7: ='Historical Data'!AE4 -> 1 | T7: ='Historical Data'!AH4 -> 0 | U7: ='Historical Data'!BB4 -> 4 | V7: ='Historical Data'!BC4 -> 1
A8: ='Historical Data'!A5 -> A-004 | B8: ='Historical Data'!B5 -> Baymont Auto Body | C8: ='Historical Data'!D5 -> In House Collection | D8: ='Historical Data'!E5 -> 45768 | E8: ='Historical Data'!G5 -> 3 | F8: ='Historical Data'!Y5 -> Auto Repair & Services | G8: ='Historical Data'!K5 -> Westwood | H8: ='Historical Data'!L5 -> New Deal | I8: ='Historical Data'!M5 -> 1.5 | J8: ='Historical Data'!N5 -> 40000 | K8: ='Historical Data'!Q5 -> 20000 | L8: ='Historical Data'!S5 -> 0.33333333 | M8: ='Historical Data'!AJ5 -> -20000 | N8: ='Historical Data'!AK5 -> 20000 | O8: ='Historical Data'!AA5 -> 120 | P8: ='Historical Data'!AB5 -> 339 | Q8: ='Historical Data'!AN5 -> 85 | R8: ='Historical Data'!AC5 -> 1 | S8: ='Historical Data'!AE5 -> 1 | T8: ='Historical Data'!AH5 -> 0 | U8: ='Historical Data'!BB5 -> 6 | V8: ='Historical Data'!BC5 -> 1
A9: ='Historical Data'!A6 -> A-005 | B9: ='Historical Data'!B6 -> Sunset Nails | C9: ='Historical Data'!D6 -> Written-Off | D9: ='Historical Data'!E6 -> 45789 | E9: ='Historical Data'!G6 -> 2 | F9: ='Historical Data'!Y6 -> Personal Services | G9: ='Historical Data'!K6 -> Fundwell | H9: ='Historical Data'!L6 -> Renewal | I9: ='Historical Data'!M6 -> 1.5 | J9: ='Historical Data'!N6 -> 10000 | K9: ='Historical Data'!Q6 -> 9500 | L9: ='Historical Data'!S6 -> 0.63333333 | M9: ='Historical Data'!AJ6 -> -500 | N9: ='Historical Data'!AK6 -> 500 | O9: ='Historical Data'!AA6 -> 86.62 | P9: ='Historical Data'!AB6 -> 324 | Q9: ='Historical Data'!AN6 -> 127 | R9: ='Historical Data'!AC6 -> 1 | S9: ='Historical Data'!AE6 -> 1 | T9: ='Historical Data'!AH6 -> 0 | U9: ='Historical Data'!BB6 -> 7 | V9: ='Historical Data'!BC6 -> 0
A10: ='Historical Data'!A7 -> A-006 | B10: ='Historical Data'!B7 -> Orchard Supply | C10: ='Historical Data'!D7 -> Bankruptcy | D10: ='Historical Data'!E7 -> 45826 | E10: ='Historical Data'!G7 -> 4 | F10: ='Historical Data'!Y7 -> No SIC | G10: ='Historical Data'!K7 -> Westwood | H10: ='Historical Data'!L7 -> New Deal | I10: ='Historical Data'!M7 -> 1.5 | J10: ='Historical Data'!N7 -> 20000 | K10: ='Historical Data'!Q7 -> 0 | L10: ='Historical Data'!S7 -> 0 | M10: ='Historical Data'!AJ7 -> -20000 | N10: ='Historical Data'!AK7 -> 20000 | O10: ='Historical Data'!AA7 -> 80 | P10: ='Historical Data'!AB7 -> 298 | Q10: ='Historical Data'!AN7 -> 64 | R10: ='Historical Data'!AC7 -> 1 | S10: ='Historical Data'!AE7 -> 1 | T10: ='Historical Data'!AH7 -> 0 | U10: ='Historical Data'!BB7 -> 6 | V10: ='Historical Data'!BC7 -> 1
A11: ='Historical Data'!A8 -> A-007 | B11: ='Historical Data'!B8 -> Pinewood Dental | C11: ='Historical Data'!D8 -> Open | D11: ='Historical Data'!E8 -> 46030 | E11: ='Historical Data'!G8 -> 1 | F11: ='Historical Data'!Y8 -> Health Services | G11: ='Historical Data'!K8 -> Fundwell | H11: ='Historical Data'!L8 -> New Deal | I11: ='Historical Data'!M8 -> 1.5 | J11: ='Historical Data'!N8 -> 50000 | K11: ='Historical Data'!Q8 -> 30000 | L11: ='Historical Data'!S8 -> 0.4 | M11: ='Historical Data'!AJ8 -> -20000 | N11: ='Historical Data'!AK8 -> 0 | O11: ='Historical Data'!AA8 -> 129.93 | P11: ='Historical Data'!AB8 -> 160 | Q11: ='Historical Data'!AN8 -> 144 | R11: ='Historical Data'!AC8 -> 0 | S11: ='Historical Data'!AE8 -> 0 | T11: ='Historical Data'!AH8 -> 1 | U11: ='Historical Data'!BB8 -> 4 | V11: ='Historical Data'!BC8 -> 1
A12: ='Historical Data'!A9 -> A-008 | B12: ='Historical Data'!B9 -> Harbor Cleaning | C12: ='Historical Data'!D9 -> Closed/NSF Unpaid | D12: ='Historical Data'!E9 -> 45852 | E12: ='Historical Data'!G9 -> 3 | F12: ='Historical Data'!Y9 -> Business Services | G12: ='Historical Data'!K9 -> Westwood | H12: ='Historical Data'!L9 -> New Deal | I12: ='Historical Data'!M9 -> 1.5 | J12: ='Historical Data'!N9 -> 20000 | K12: ='Historical Data'!Q9 -> 30000 | L12: ='Historical Data'!S9 -> 1 | M12: ='Historical Data'!AJ9 -> 10000 | N12: ='Historical Data'!AK9 -> 0 | O12: ='Historical Data'!AA9 -> 100 | P12: ='Historical Data'!AB9 -> 282 | Q12: ='Historical Data'!AN9 -> 107 | R12: ='Historical Data'!AC9 -> 1 | S12: ='Historical Data'!AE9 -> 0 | T12: ='Historical Data'!AH9 -> 0 | U12: ='Historical Data'!BB9 -> 6 | V12: ='Historical Data'!BC9 -> 1

Sheet Historical Data
A1: Contract ID | B1: DBA | C1: Legal name | D1: Status | E1: Start date | F1: Last active | G1: Position | H1: SIC | I1: SIC2 | J1: State | K1: ISO | L1: New or renewal | M1: Factor | N1: Advance | O1: Commission | P1: Payback | Q1: Collected | R1: Balance | S1: % paid | T1: Exp dur (raw) | U1: NSF count | V1: Avg rev/mo | W1: Holdback % | X1: Biz start | Y1: Industry | Z1: Pay frequency | AA1: Term (bus. days) | AB1: Age at as-of (bus. days) | AC1: Seasoned | AD1: In window | AE1: Default | AF1: Resolved | AG1: Closed family | AH1: Open | AI1: Status valid | AJ1: Net cash | AK1: Principal lost | AL1: Adv / revenue | AM1: Has revenue | AN1: Days on book (bus.) | AO1: Renewal | AP1: Eligible (seasoned & in window) | AQ1: m: position | AR1: m: new/renewal | AS1: m: industry | AT1: m: ISO | AU1: T1 NR+Ind+Pos | AV1: T2 NR+ISO+Pos | AW1: T3 NR+Ind | AX1: T4 NR+ISO | AY1: T5 NR+Pos | AZ1: T6 NR | BA1: T7 Book | BB1: Best tier | BC1: In primary cohort
A2: A-001 | B2: Ridgeline Cafe | C2: Ridgeline Cafe LLC | D2: Closed | E2: 45672 | F2: 45821 | G2: 1 | H2: 5812 | I2: 58 | J2: NJ | K2: Fundwell | L2: New Deal | M2: 1.5 | N2: 10000 | O2: 1000 | P2: 15000 | Q2: 15000 | R2: 0 | S2: 1 | T2: 5 | U2: 0 | V2: 50000 | W2: 0.12 | X2: 43160 | Y2: =IF(I2="","No SIC",IFERROR(VLOOKUP(I2,Ref!$A$2:$B$65,2,FALSE()),"Unclassified")) -> Eating & Drinking Places | Z2: =IF(T2="","",IF(T2<12,"Daily","Weekly")) -> Daily | AA2: =IF(T2="",0,IF(T2<12,T2*Controls!$B$29,T2*5)) -> 108.275 | AB2: =IF(E2="",0,NETWORKDAYS(E2,Controls!$B$36,Ref!$K$2:$K$42)) -> 405 | AC2: =IF(AND(AA2>0,AB2>=Controls!$B$39*AA2),1,0) -> 1 | AD2: =IF(AND(E2<>"",E2>=Controls!$B$37,E2<=Controls!$B$38),1,0) -> 1 | AE2: =IF(IFERROR(VLOOKUP(D2,Controls!$A$59:$E$69,2,FALSE()),"No")="Yes",1,0) -> 0 | AF2: =IF(IFERROR(VLOOKUP(D2,Controls!$A$59:$E$69,3,FALSE()),"No")="Yes",1,0) -> 1 | AG2: =IF(IFERROR(VLOOKUP(D2,Controls!$A$59:$E$69,4,FALSE()),"No")="Yes",1,0) -> 1 | AH2: =IF(IFERROR(VLOOKUP(D2,Controls!$A$59:$E$69,5,FALSE()),"No")="Yes",1,0) -> 0 | AI2: =IF(ISNUMBER(MATCH(D2,Controls!$A$59:$A$69,0)),1,0) -> 1 | AJ2: =Q2-N2 -> 5000 | AK2: =IF(AE2=1,MAX(0,N2-Q2),0) -> 0 | AL2: =IF(OR(V2="",V2=0),0,N2/V2) -> 0.2 | AM2: =IF(OR(V2="",V2=0),0,1) -> 1 | AN2: =IF(OR(E2="",F2=""),0,NETWORKDAYS(E2,F2,Ref!$K$2:$K$42)) -> 105 | AO2: =IF(L2="Renewal",1,0) -> 0 | AP2: =AC2*AD2 -> 1 | AQ2: =IF(AND(G2<>"",'Historical Score'!$C$6<>""),IF(G2='Historical Score'!$C$6,1,0),0) -> 0 | AR2: =IF(AND(L2<>"",'Historical Score'!$C$5<>""),IF(L2='Historical Score'!$C$5,1,0),0) -> 1 | AS2: =IF(AND(Y2<>"",'Historical Score'!$C$7<>""),IF(Y2='Historical Score'!$C$7,1,0),0) -> 1 | AT2: =IF(AND(K2<>"",'Historical Score'!$C$8<>""),IF(K2='Historical Score'!$C$8,1,0),0) -> 1 | AU2: =AR2*AS2*AQ2 -> 0 | AV2: =AR2*AT2*AQ2 -> 0 | AW2: =AR2*AS2 -> 1 | AX2: =AR2*AT2 -> 1 | AY2: =AR2*AQ2 -> 0 | AZ2: =AR2 -> 1 | BA2: =1 -> 1 | BB2: =IF(AU2=1,1,IF(AV2=1,2,IF(AW2=1,3,IF(AX2=1,4,IF(AY2=1,5,IF(AZ2=1,6,7)))))) -> 3 | BC2: =IF(AD2=1,CHOOSE('Historical Score'!$C$29,AU2,AV2,AW2,AX2,AY2,AZ2,BA2),0) -> 1
A3: A-002 | B3: Delta Freight | C3: Delta Freight Group LLC | D3: Closed | E3: 45698 | F3: 45848 | G3: 2 | H3: 4213 | I3: 42 | J3: TX | K3: Westwood | L3: Renewal | M3: 1.5 | N3: 20000 | O3: 2000 | P3: 30000 | Q3: 30000 | R3: 0 | S3: 1 | T3: 20 | U3: 0 | V3: 100000 | W3: 0.09 | X3: 42170 | Y3: =IF(I3="","No SIC",IFERROR(VLOOKUP(I3,Ref!$A$2:$B$65,2,FALSE()),"Unclassified")) -> Trucking & Warehousing | Z3: =IF(T3="","",IF(T3<12,"Daily","Weekly")) -> Weekly | AA3: =IF(T3="",0,IF(T3<12,T3*Controls!$B$29,T3*5)) -> 100 | AB3: =IF(E3="",0,NETWORKDAYS(E3,Controls!$B$36,Ref!$K$2:$K$42)) -> 388 | AC3: =IF(AND(AA3>0,AB3>=Controls!$B$39*AA3),1,0) -> 1 | AD3: =IF(AND(E3<>"",E3>=Controls!$B$37,E3<=Controls!$B$38),1,0) -> 1 | AE3: =IF(IFERROR(VLOOKUP(D3,Controls!$A$59:$E$69,2,FALSE()),"No")="Yes",1,0) -> 0 | AF3: =IF(IFERROR(VLOOKUP(D3,Controls!$A$59:$E$69,3,FALSE()),"No")="Yes",1,0) -> 1 | AG3: =IF(IFERROR(VLOOKUP(D3,Controls!$A$59:$E$69,4,FALSE()),"No")="Yes",1,0) -> 1 | AH3: =IF(IFERROR(VLOOKUP(D3,Controls!$A$59:$E$69,5,FALSE()),"No")="Yes",1,0) -> 0 | AI3: =IF(ISNUMBER(MATCH(D3,Controls!$A$59:$A$69,0)),1,0) -> 1 | AJ3: =Q3-N3 -> 10000 | AK3: =IF(AE3=1,MAX(0,N3-Q3),0) -> 0 | AL3: =IF(OR(V3="",V3=0),0,N3/V3) -> 0.2 | AM3: =IF(OR(V3="",V3=0),0,1) -> 1 | AN3: =IF(OR(E3="",F3=""),0,NETWORKDAYS(E3,F3,Ref!$K$2:$K$42)) -> 105 | AO3: =IF(L3="Renewal",1,0) -> 1 | AP3: =AC3*AD3 -> 1 | AQ3: =IF(AND(G3<>"",'Historical Score'!$C$6<>""),IF(G3='Historical Score'!$C$6,1,0),0) -> 1 | AR3: =IF(AND(L3<>"",'Historical Score'!$C$5<>""),IF(L3='Historical Score'!$C$5,1,0),0) -> 0 | AS3: =IF(AND(Y3<>"",'Historical Score'!$C$7<>""),IF(Y3='Historical Score'!$C$7,1,0),0) -> 0 | AT3: =IF(AND(K3<>"",'Historical Score'!$C$8<>""),IF(K3='Historical Score'!$C$8,1,0),0) -> 0 | AU3: =AR3*AS3*AQ3 -> 0 | AV3: =AR3*AT3*AQ3 -> 0 | AW3: =AR3*AS3 -> 0 | AX3: =AR3*AT3 -> 0 | AY3: =AR3*AQ3 -> 0 | AZ3: =AR3 -> 0 | BA3: =1 -> 1 | BB3: =IF(AU3=1,1,IF(AV3=1,2,IF(AW3=1,3,IF(AX3=1,4,IF(AY3=1,5,IF(AZ3=1,6,7)))))) -> 7 | BC3: =IF(AD3=1,CHOOSE('Historical Score'!$C$29,AU3,AV3,AW3,AX3,AY3,AZ3,BA3),0) -> 0
A4: A-003 | B4: Kane Construction | C4: Kane Construction Inc | D4: Legal | E4: 45721 | F4: 45813 | G4: 3 | H4: 1542 | I4: 15 | J4: NJ | K4: Fundwell | L4: New Deal | M4: 1.5 | N4: 30000 | O4: 3000 | P4: 45000 | Q4: 9000 | R4: 36000 | S4: 0.2 | T4: 6 | U4: 4 | V4: 60000 | W4: 0.15 | X4: 43840 | Y4: =IF(I4="","No SIC",IFERROR(VLOOKUP(I4,Ref!$A$2:$B$65,2,FALSE()),"Unclassified")) -> General Building Contractors | Z4: =IF(T4="","",IF(T4<12,"Daily","Weekly")) -> Daily | AA4: =IF(T4="",0,IF(T4<12,T4*Controls!$B$29,T4*5)) -> 129.93 | AB4: =IF(E4="",0,NETWORKDAYS(E4,Controls!$B$36,Ref!$K$2:$K$42)) -> 372 | AC4: =IF(AND(AA4>0,AB4>=Controls!$B$39*AA4),1,0) -> 1 | AD4: =IF(AND(E4<>"",E4>=Controls!$B$37,E4<=Controls!$B$38),1,0) -> 1 | AE4: =IF(IFERROR(VLOOKUP(D4,Controls!$A$59:$E$69,2,FALSE()),"No")="Yes",1,0) -> 1 | AF4: =IF(IFERROR(VLOOKUP(D4,Controls!$A$59:$E$69,3,FALSE()),"No")="Yes",1,0) -> 0 | AG4: =IF(IFERROR(VLOOKUP(D4,Controls!$A$59:$E$69,4,FALSE()),"No")="Yes",1,0) -> 0 | AH4: =IF(IFERROR(VLOOKUP(D4,Controls!$A$59:$E$69,5,FALSE()),"No")="Yes",1,0) -> 0 | AI4: =IF(ISNUMBER(MATCH(D4,Controls!$A$59:$A$69,0)),1,0) -> 1 | AJ4: =Q4-N4 -> -21000 | AK4: =IF(AE4=1,MAX(0,N4-Q4),0) -> 21000 | AL4: =IF(OR(V4="",V4=0),0,N4/V4) -> 0.5 | AM4: =IF(OR(V4="",V4=0),0,1) -> 1 | AN4: =IF(OR(E4="",F4=""),0,NETWORKDAYS(E4,F4,Ref!$K$2:$K$42)) -> 66 | AO4: =IF(L4="Renewal",1,0) -> 0 | AP4: =AC4*AD4 -> 1 | AQ4: =IF(AND(G4<>"",'Historical Score'!$C$6<>""),IF(G4='Historical Score'!$C$6,1,0),0) -> 0 | AR4: =IF(AND(L4<>"",'Historical Score'!$C$5<>""),IF(L4='Historical Score'!$C$5,1,0),0) -> 1 | AS4: =IF(AND(Y4<>"",'Historical Score'!$C$7<>""),IF(Y4='Historical Score'!$C$7,1,0),0) -> 0 | AT4: =IF(AND(K4<>"",'Historical Score'!$C$8<>""),IF(K4='Historical Score'!$C$8,1,0),0) -> 1 | AU4: =AR4*AS4*AQ4 -> 0 | AV4: =AR4*AT4*AQ4 -> 0 | AW4: =AR4*AS4 -> 0 | AX4: =AR4*AT4 -> 1 | AY4: =AR4*AQ4 -> 0 | AZ4: =AR4 -> 1 | BA4: =1 -> 1 | BB4: =IF(AU4=1,1,IF(AV4=1,2,IF(AW4=1,3,IF(AX4=1,4,IF(AY4=1,5,IF(AZ4=1,6,7)))))) -> 4 | BC4: =IF(AD4=1,CHOOSE('Historical Score'!$C$29,AU4,AV4,AW4,AX4,AY4,AZ4,BA4),0) -> 1
A5: A-004 | B5: Baymont Auto Body | C5: Baymont Auto Body LLC | D5: In House Collection | E5: 45768 | F5: 45889 | G5: 3 | H5: 7538 | I5: 75 | J5: TX | K5: Westwood | L5: New Deal | M5: 1.5 | N5: 40000 | O5: 4000 | P5: 60000 | Q5: 20000 | R5: 40000 | S5: 0.33333333 | T5: 24 | U5: 7 | V5: 80000 | W5: 0.11 | X5: 41182 | Y5: =IF(I5="","No SIC",IFERROR(VLOOKUP(I5,Ref!$A$2:$B$65,2,FALSE()),"Unclassified")) -> Auto Repair & Services | Z5: =IF(T5="","",IF(T5<12,"Daily","Weekly")) -> Weekly | AA5: =IF(T5="",0,IF(T5<12,T5*Controls!$B$29,T5*5)) -> 120 | AB5: =IF(E5="",0,NETWORKDAYS(E5,Controls!$B$36,Ref!$K$2:$K$42)) -> 339 | AC5: =IF(AND(AA5>0,AB5>=Controls!$B$39*AA5),1,0) -> 1 | AD5: =IF(AND(E5<>"",E5>=Controls!$B$37,E5<=Controls!$B$38),1,0) -> 1 | AE5: =IF(IFERROR(VLOOKUP(D5,Controls!$A$59:$E$69,2,FALSE()),"No")="Yes",1,0) -> 1 | AF5: =IF(IFERROR(VLOOKUP(D5,Controls!$A$59:$E$69,3,FALSE()),"No")="Yes",1,0) -> 0 | AG5: =IF(IFERROR(VLOOKUP(D5,Controls!$A$59:$E$69,4,FALSE()),"No")="Yes",1,0) -> 0 | AH5: =IF(IFERROR(VLOOKUP(D5,Controls!$A$59:$E$69,5,FALSE()),"No")="Yes",1,0) -> 0 | AI5: =IF(ISNUMBER(MATCH(D5,Controls!$A$59:$A$69,0)),1,0) -> 1 | AJ5: =Q5-N5 -> -20000 | AK5: =IF(AE5=1,MAX(0,N5-Q5),0) -> 20000 | AL5: =IF(OR(V5="",V5=0),0,N5/V5) -> 0.5 | AM5: =IF(OR(V5="",V5=0),0,1) -> 1 | AN5: =IF(OR(E5="",F5=""),0,NETWORKDAYS(E5,F5,Ref!$K$2:$K$42)) -> 85 | AO5: =IF(L5="Renewal",1,0) -> 0 | AP5: =AC5*AD5 -> 1 | AQ5: =IF(AND(G5<>"",'Historical Score'!$C$6<>""),IF(G5='Historical Score'!$C$6,1,0),0) -> 0 | AR5: =IF(AND(L5<>"",'Historical Score'!$C$5<>""),IF(L5='Historical Score'!$C$5,1,0),0) -> 1 | AS5: =IF(AND(Y5<>"",'Historical Score'!$C$7<>""),IF(Y5='Historical Score'!$C$7,1,0),0) -> 0 | AT5: =IF(AND(K5<>"",'Historical Score'!$C$8<>""),IF(K5='Historical Score'!$C$8,1,0),0) -> 0 | AU5: =AR5*AS5*AQ5 -> 0 | AV5: =AR5*AT5*AQ5 -> 0 | AW5: =AR5*AS5 -> 0 | AX5: =AR5*AT5 -> 0 | AY5: =AR5*AQ5 -> 0 | AZ5: =AR5 -> 1 | BA5: =1 -> 1 | BB5: =IF(AU5=1,1,IF(AV5=1,2,IF(AW5=1,3,IF(AX5=1,4,IF(AY5=1,5,IF(AZ5=1,6,7)))))) -> 6 | BC5: =IF(AD5=1,CHOOSE('Historical Score'!$C$29,AU5,AV5,AW5,AX5,AY5,AZ5,BA5),0) -> 1
A6: A-005 | B6: Sunset Nails | C6: Sunset Nails Corp | D6: Written-Off | E6: 45789 | F6: 45973 | G6: 2 | H6: 7231 | I6: 72 | J6: NJ | K6: Fundwell | L6: Renewal | M6: 1.5 | N6: 10000 | O6: 1000 | P6: 15000 | Q6: 9500 | R6: 5500 | S6: 0.63333333 | T6: 4 | U6: 2 | V6: 20000 | W6: 0.14 | X6: 43774 | Y6: =IF(I6="","No SIC",IFERROR(VLOOKUP(I6,Ref!$A$2:$B$65,2,FALSE()),"Unclassified")) -> Personal Services | Z6: =IF(T6="","",IF(T6<12,"Daily","Weekly")) -> Daily | AA6: =IF(T6="",0,IF(T6<12,T6*Controls!$B$29,T6*5)) -> 86.62 | AB6: =IF(E6="",0,NETWORKDAYS(E6,Controls!$B$36,Ref!$K$2:$K$42)) -> 324 | AC6: =IF(AND(AA6>0,AB6>=Controls!$B$39*AA6),1,0) -> 1 | AD6: =IF(AND(E6<>"",E6>=Controls!$B$37,E6<=Controls!$B$38),1,0) -> 1 | AE6: =IF(IFERROR(VLOOKUP(D6,Controls!$A$59:$E$69,2,FALSE()),"No")="Yes",1,0) -> 1 | AF6: =IF(IFERROR(VLOOKUP(D6,Controls!$A$59:$E$69,3,FALSE()),"No")="Yes",1,0) -> 1 | AG6: =IF(IFERROR(VLOOKUP(D6,Controls!$A$59:$E$69,4,FALSE()),"No")="Yes",1,0) -> 0 | AH6: =IF(IFERROR(VLOOKUP(D6,Controls!$A$59:$E$69,5,FALSE()),"No")="Yes",1,0) -> 0 | AI6: =IF(ISNUMBER(MATCH(D6,Controls!$A$59:$A$69,0)),1,0) -> 1 | AJ6: =Q6-N6 -> -500 | AK6: =IF(AE6=1,MAX(0,N6-Q6),0) -> 500 | AL6: =IF(OR(V6="",V6=0),0,N6/V6) -> 0.5 | AM6: =IF(OR(V6="",V6=0),0,1) -> 1 | AN6: =IF(OR(E6="",F6=""),0,NETWORKDAYS(E6,F6,Ref!$K$2:$K$42)) -> 127 | AO6: =IF(L6="Renewal",1,0) -> 1 | AP6: =AC6*AD6 -> 1 | AQ6: =IF(AND(G6<>"",'Historical Score'!$C$6<>""),IF(G6='Historical Score'!$C$6,1,0),0) -> 1 | AR6: =IF(AND(L6<>"",'Historical Score'!$C$5<>""),IF(L6='Historical Score'!$C$5,1,0),0) -> 0 | AS6: =IF(AND(Y6<>"",'Historical Score'!$C$7<>""),IF(Y6='Historical Score'!$C$7,1,0),0) -> 0 | AT6: =IF(AND(K6<>"",'Historical Score'!$C$8<>""),IF(K6='Historical Score'!$C$8,1,0),0) -> 1 | AU6: =AR6*AS6*AQ6 -> 0 | AV6: =AR6*AT6*AQ6 -> 0 | AW6: =AR6*AS6 -> 0 | AX6: =AR6*AT6 -> 0 | AY6: =AR6*AQ6 -> 0 | AZ6: =AR6 -> 0 | BA6: =1 -> 1 | BB6: =IF(AU6=1,1,IF(AV6=1,2,IF(AW6=1,3,IF(AX6=1,4,IF(AY6=1,5,IF(AZ6=1,6,7)))))) -> 7 | BC6: =IF(AD6=1,CHOOSE('Historical Score'!$C$29,AU6,AV6,AW6,AX6,AY6,AZ6,BA6),0) -> 0
A7: A-006 | B7: Orchard Supply | C7: Orchard Supply Co LLC | D7: Bankruptcy | E7: 45826 | F7: 45918 | G7: 4 | J7: TX | K7: Westwood | L7: New Deal | M7: 1.5 | N7: 20000 | O7: 2000 | P7: 30000 | Q7: 0 | R7: 30000 | S7: 0 | T7: 16 | U7: 9 | V7: 100000 | W7: 0.1 | X7: 44305 | Y7: =IF(I7="","No SIC",IFERROR(VLOOKUP(I7,Ref!$A$2:$B$65,2,FALSE()),"Unclassified")) -> No SIC | Z7: =IF(T7="","",IF(T7<12,"Daily","Weekly")) -> Weekly | AA7: =IF(T7="",0,IF(T7<12,T7*Controls!$B$29,T7*5)) -> 80 | AB7: =IF(E7="",0,NETWORKDAYS(E7,Controls!$B$36,Ref!$K$2:$K$42)) -> 298 | AC7: =IF(AND(AA7>0,AB7>=Controls!$B$39*AA7),1,0) -> 1 | AD7: =IF(AND(E7<>"",E7>=Controls!$B$37,E7<=Controls!$B$38),1,0) -> 1 | AE7: =IF(IFERROR(VLOOKUP(D7,Controls!$A$59:$E$69,2,FALSE()),"No")="Yes",1,0) -> 1 | AF7: =IF(IFERROR(VLOOKUP(D7,Controls!$A$59:$E$69,3,FALSE()),"No")="Yes",1,0) -> 1 | AG7: =IF(IFERROR(VLOOKUP(D7,Controls!$A$59:$E$69,4,FALSE()),"No")="Yes",1,0) -> 0 | AH7: =IF(IFERROR(VLOOKUP(D7,Controls!$A$59:$E$69,5,FALSE()),"No")="Yes",1,0) -> 0 | AI7: =IF(ISNUMBER(MATCH(D7,Controls!$A$59:$A$69,0)),1,0) -> 1 | AJ7: =Q7-N7 -> -20000 | AK7: =IF(AE7=1,MAX(0,N7-Q7),0) -> 20000 | AL7: =IF(OR(V7="",V7=0),0,N7/V7) -> 0.2 | AM7: =IF(OR(V7="",V7=0),0,1) -> 1 | AN7: =IF(OR(E7="",F7=""),0,NETWORKDAYS(E7,F7,Ref!$K$2:$K$42)) -> 64 | AO7: =IF(L7="Renewal",1,0) -> 0 | AP7: =AC7*AD7 -> 1 | AQ7: =IF(AND(G7<>"",'Historical Score'!$C$6<>""),IF(G7='Historical Score'!$C$6,1,0),0) -> 0 | AR7: =IF(AND(L7<>"",'Historical Score'!$C$5<>""),IF(L7='Historical Score'!$C$5,1,0),0) -> 1 | AS7: =IF(AND(Y7<>"",'Historical Score'!$C$7<>""),IF(Y7='Historical Score'!$C$7,1,0),0) -> 0 | AT7: =IF(AND(K7<>"",'Historical Score'!$C$8<>""),IF(K7='Historical Score'!$C$8,1,0),0) -> 0 | AU7: =AR7*AS7*AQ7 -> 0 | AV7: =AR7*AT7*AQ7 -> 0 | AW7: =AR7*AS7 -> 0 | AX7: =AR7*AT7 -> 0 | AY7: =AR7*AQ7 -> 0 | AZ7: =AR7 -> 1 | BA7: =1 -> 1 | BB7: =IF(AU7=1,1,IF(AV7=1,2,IF(AW7=1,3,IF(AX7=1,4,IF(AY7=1,5,IF(AZ7=1,6,7)))))) -> 6 | BC7: =IF(AD7=1,CHOOSE('Historical Score'!$C$29,AU7,AV7,AW7,AX7,AY7,AZ7,BA7),0) -> 1
A8: A-007 | B8: Pinewood Dental | C8: Pinewood Dental PC | D8: Open | E8: 46030 | F8: 46237 | G8: 1 | H8: 8021 | I8: 80 | J8: NJ | K8: Fundwell | L8: New Deal | M8: 1.5 | N8: 50000 | O8: 5000 | P8: 75000 | Q8: 30000 | R8: 45000 | S8: 0.4 | T8: 6 | U8: 0 | V8: 250000 | W8: 0.08 | X8: 40211 | Y8: =IF(I8="","No SIC",IFERROR(VLOOKUP(I8,Ref!$A$2:$B$65,2,FALSE()),"Unclassified")) -> Health Services | Z8: =IF(T8="","",IF(T8<12,"Daily","Weekly")) -> Daily | AA8: =IF(T8="",0,IF(T8<12,T8*Controls!$B$29,T8*5)) -> 129.93 | AB8: =IF(E8="",0,NETWORKDAYS(E8,Controls!$B$36,Ref!$K$2:$K$42)) -> 160 | AC8: =IF(AND(AA8>0,AB8>=Controls!$B$39*AA8),1,0) -> 0 | AD8: =IF(AND(E8<>"",E8>=Controls!$B$37,E8<=Controls!$B$38),1,0) -> 1 | AE8: =IF(IFERROR(VLOOKUP(D8,Controls!$A$59:$E$69,2,FALSE()),"No")="Yes",1,0) -> 0 | AF8: =IF(IFERROR(VLOOKUP(D8,Controls!$A$59:$E$69,3,FALSE()),"No")="Yes",1,0) -> 0 | AG8: =IF(IFERROR(VLOOKUP(D8,Controls!$A$59:$E$69,4,FALSE()),"No")="Yes",1,0) -> 0 | AH8: =IF(IFERROR(VLOOKUP(D8,Controls!$A$59:$E$69,5,FALSE()),"No")="Yes",1,0) -> 1 | AI8: =IF(ISNUMBER(MATCH(D8,Controls!$A$59:$A$69,0)),1,0) -> 1 | AJ8: =Q8-N8 -> -20000 | AK8: =IF(AE8=1,MAX(0,N8-Q8),0) -> 0 | AL8: =IF(OR(V8="",V8=0),0,N8/V8) -> 0.2 | AM8: =IF(OR(V8="",V8=0),0,1) -> 1 | AN8: =IF(OR(E8="",F8=""),0,NETWORKDAYS(E8,F8,Ref!$K$2:$K$42)) -> 144 | AO8: =IF(L8="Renewal",1,0) -> 0 | AP8: =AC8*AD8 -> 0 | AQ8: =IF(AND(G8<>"",'Historical Score'!$C$6<>""),IF(G8='Historical Score'!$C$6,1,0),0) -> 0 | AR8: =IF(AND(L8<>"",'Historical Score'!$C$5<>""),IF(L8='Historical Score'!$C$5,1,0),0) -> 1 | AS8: =IF(AND(Y8<>"",'Historical Score'!$C$7<>""),IF(Y8='Historical Score'!$C$7,1,0),0) -> 0 | AT8: =IF(AND(K8<>"",'Historical Score'!$C$8<>""),IF(K8='Historical Score'!$C$8,1,0),0) -> 1 | AU8: =AR8*AS8*AQ8 -> 0 | AV8: =AR8*AT8*AQ8 -> 0 | AW8: =AR8*AS8 -> 0 | AX8: =AR8*AT8 -> 1 | AY8: =AR8*AQ8 -> 0 | AZ8: =AR8 -> 1 | BA8: =1 -> 1 | BB8: =IF(AU8=1,1,IF(AV8=1,2,IF(AW8=1,3,IF(AX8=1,4,IF(AY8=1,5,IF(AZ8=1,6,7)))))) -> 4 | BC8: =IF(AD8=1,CHOOSE('Historical Score'!$C$29,AU8,AV8,AW8,AX8,AY8,AZ8,BA8),0) -> 1
A9: A-008 | B9: Harbor Cleaning | C9: Harbor Cleaning Services LLC | D9: Closed/NSF Unpaid | E9: 45852 | F9: 46006 | G9: 3 | H9: 7349 | I9: 73 | J9: TX | K9: Westwood | L9: New Deal | M9: 1.5 | N9: 20000 | O9: 2000 | P9: 30000 | Q9: 30000 | R9: 0 | S9: 1 | T9: 20 | U9: 11 | W9: 0.13 | X9: 44781 | Y9: =IF(I9="","No SIC",IFERROR(VLOOKUP(I9,Ref!$A$2:$B$65,2,FALSE()),"Unclassified")) -> Business Services | Z9: =IF(T9="","",IF(T9<12,"Daily","Weekly")) -> Weekly | AA9: =IF(T9="",0,IF(T9<12,T9*Controls!$B$29,T9*5)) -> 100 | AB9: =IF(E9="",0,NETWORKDAYS(E9,Controls!$B$36,Ref!$K$2:$K$42)) -> 282 | AC9: =IF(AND(AA9>0,AB9>=Controls!$B$39*AA9),1,0) -> 1 | AD9: =IF(AND(E9<>"",E9>=Controls!$B$37,E9<=Controls!$B$38),1,0) -> 1 | AE9: =IF(IFERROR(VLOOKUP(D9,Controls!$A$59:$E$69,2,FALSE()),"No")="Yes",1,0) -> 0 | AF9: =IF(IFERROR(VLOOKUP(D9,Controls!$A$59:$E$69,3,FALSE()),"No")="Yes",1,0) -> 1 | AG9: =IF(IFERROR(VLOOKUP(D9,Controls!$A$59:$E$69,4,FALSE()),"No")="Yes",1,0) -> 1 | AH9: =IF(IFERROR(VLOOKUP(D9,Controls!$A$59:$E$69,5,FALSE()),"No")="Yes",1,0) -> 0 | AI9: =IF(ISNUMBER(MATCH(D9,Controls!$A$59:$A$69,0)),1,0) -> 1 | AJ9: =Q9-N9 -> 10000 | AK9: =IF(AE9=1,MAX(0,N9-Q9),0) -> 0 | AL9: =IF(OR(V9="",V9=0),0,N9/V9) -> 0 | AM9: =IF(OR(V9="",V9=0),0,1) -> 0 | AN9: =IF(OR(E9="",F9=""),0,NETWORKDAYS(E9,F9,Ref!$K$2:$K$42)) -> 107 | AO9: =IF(L9="Renewal",1,0) -> 0 | AP9: =AC9*AD9 -> 1 | AQ9: =IF(AND(G9<>"",'Historical Score'!$C$6<>""),IF(G9='Historical Score'!$C$6,1,0),0) -> 0 | AR9: =IF(AND(L9<>"",'Historical Score'!$C$5<>""),IF(L9='Historical Score'!$C$5,1,0),0) -> 1 | AS9: =IF(AND(Y9<>"",'Historical Score'!$C$7<>""),IF(Y9='Historical Score'!$C$7,1,0),0) -> 0 | AT9: =IF(AND(K9<>"",'Historical Score'!$C$8<>""),IF(K9='Historical Score'!$C$8,1,0),0) -> 0 | AU9: =AR9*AS9*AQ9 -> 0 | AV9: =AR9*AT9*AQ9 -> 0 | AW9: =AR9*AS9 -> 0 | AX9: =AR9*AT9 -> 0 | AY9: =AR9*AQ9 -> 0 | AZ9: =AR9 -> 1 | BA9: =1 -> 1 | BB9: =IF(AU9=1,1,IF(AV9=1,2,IF(AW9=1,3,IF(AX9=1,4,IF(AY9=1,5,IF(AZ9=1,6,7)))))) -> 6 | BC9: =IF(AD9=1,CHOOSE('Historical Score'!$C$29,AU9,AV9,AW9,AX9,AY9,AZ9,BA9),0) -> 1

Sheet Controls
A1: CONTROLS
A3: 1. CASH-FLOW THRESHOLDS
A4: Metric | B4: Green (at or better) | C4: Red (at or worse) | D4: Knockout
A5: Total LVG | B5: 0.3 | C5: 0.45 | D5: 0.55
A6: New holdback SP% | B6: 0.18 | C6: 0.25 | D6: 0.35
A7: Daily debt / balance | B7: 0.18 | C7: 0.3 | D7: 0.35
A8: Fund / revenue | B8: 0.6 | C8: 0.9 | D8: 1.25
A9: # positions (incl. new) | B9: 2 | C9: 5 | D9: 6
A10: Revenue trend (avg MoM) | B10: -0.05 | C10: -0.15 | D10: -0.3
A11: Neg days + NSFs (total) | B11: 1 | C11: 6 | D11: 10
A12: Credit score (FICO) | B12: 650 | C12: 630 | D12: 0
A13: Decline if red flags (RED + KNOCKOUT) >= | B13: 2
A14: Minimum fund $ | B14: 10000
A15: Underwriting fee % | B15: 0.05
A17: 2. PRICING BANDS
A18: Score >= | B18: Term cap (daily pmts) | C18: Factor
A19: 0 | B19: 100 | C19: 1.49
A20: 5 | B20: 130 | C20: 1.45
A21: 6 | B21: 150 | C21: 1.45
A22: 7 | B22: 195 | C22: 1.4
A23: Max term (months) | B23: 9
A24: Approved factor tiers (low -> high) | B24: 1.4 | C24: 1.45 | D24: 1.49
A25: Tier cut-offs on 7-point scale: Strong / Solid / Moderate | B25: 6.5 | C25: 5 | D25: 3.5
A27: 3. CONVERSION CONSTANTS
A28: Weeks per month (ours) | B28: 4.331
A29: Business days per month (ours) | B29: 21.655
A30: MoneyBadger weeks per month | B30: 4
A31: MoneyBadger business days per month | B31: 21
A32: Calendar days per month | B32: 30.4375
A33: Assumed factor on existing positions | B33: 1.45
A35: 4. HISTORICAL EVIDENCE SETTINGS
A36: As-of date for seasoning (date of the CRM export) | B36: 46259
A37: Window: funded on or after | B37: 45597
A38: Window: funded on or before | B38: 46259
A39: Seasoning multiple (age >= multiple x contracted term) | B39: 1.25
A40: Minimum seasoned deals for a cohort to be PRIMARY | B40: 3
A41: Minimum seasoned funded $ for a cohort to be PRIMARY | B41: 30000
A42: (reserved) Credibility constant K - NOT USED in v3 | B42: 30
A43: Minimum seasoned deals before a rate is shown | B43: 2
A44: Seasoned deals for the sample-size indicator to be GREEN | B44: 5
...

Sheet Ref
A1: SIC2 | B1: Industry (SIC major group) | C1: Division | E1: ISO (house-book spelling) | G1: Industry list | K1: Fed holiday | M1: Status list
A2: 01 | B2: Agricultural Production - Crops | C2: Agriculture, Forestry & Fishing | E2: Ace Partners | G2: Administration of Economic Programs | K2: 45292 | M2: Closed
A3: 02 | B3: Agricultural Production - Livestock | C3: Agriculture, Forestry & Fishing | E3: Advance Consolidations | G3: Agricultural Production - Crops | K3: 45306 | M3: Open
A4: 07 | B4: Agricultural Services | C4: Agriculture, Forestry & Fishing | E4: ALLSTATE FUND PROS LLC | G4: Agricultural Production - Livestock | K4: 45341 | M4: Legal
A5: 08 | B5: Forestry | C5: Agriculture, Forestry & Fishing | E5: Alternative Solutions Funding | G5: Agricultural Services | K5: 45439 | M5: In House Collection
A6: 13 | B6: Oil & Gas Extraction | C6: Mining | E6: alvara capital | G6: Air Transportation | K6: 45462 | M6: Lowered Payments
A7: 14 | B7: Nonmetallic Minerals Mining | C7: Mining | E7: American Funding Association 1 | G7: Amusement & Recreation Services | K7: 45477 | M7: Written-Off
A8: 15 | B8: General Building Contractors | C8: Construction | E8: Amerishop Financial services | G8: Apparel & Accessory Stores | K8: 45537 | M8: Bankruptcy
A9: 16 | B9: Heavy Construction | C9: Construction | E9: Aspire Funding | G9: Apparel & Textile Products | K9: 45579 | M9: Settlement Agreement
A10: 17 | B10: Special Trade Contractors | C10: Construction | E10: Atla Finance | G10: Auto Dealers & Gas Stations | K10: 45607 | M10: Closed/NSF
A11: 20 | B11: Food & Kindred Products | C11: Manufacturing | E11: AVON ADVANCE | G11: Auto Repair & Services | K11: 45624 | M11: Closed/NSF Unpaid
A12: 23 | B12: Apparel & Textile Products | C12: Manufacturing | E12: Ballicci | G12: Building Materials & Garden Supply | K12: 45651 | M12: At-Risk
A13: 24 | B13: Lumber & Wood Products | C13: Manufacturing | E13: BFA 3 | G13: Business Services | K13: 45658
A14: 25 | B14: Furniture & Fixtures | C14: Manufacturing | E14: Bingo advance LLC | G14: Chemicals & Allied Products | K14: 45677
A15: 27 | B15: Printing & Publishing | C15: Manufacturing | E15: Birkin Capital Inc | G15: Communications | K15: 45705
A16: 28 | B16: Chemicals & Allied Products | C16: Manufacturing | E16: biz advance now | G16: Eating & Drinking Places | K16: 45803
A17: 30 | B17: Rubber & Plastics | C17: Manufacturing | E17: Biz fuel | G17: Educational Services | K17: 45827
A18: 32 | B18: Stone, Clay, Glass & Concrete | C18: Manufacturing | E18: BizFin LLC | G18: Electric, Gas & Sanitary Services | K18: 45842
A19: 33 | B19: Primary Metal Industries | C19: Manufacturing | E19: black flag funding | G19: Electronic & Electrical Equipment | K19: 45901
A20: 34 | B20: Fabricated Metal Products | C20: Manufacturing | E20: Black Tie Funding | G20: Engineering, Accounting & Management | K20: 45943
A21: 35 | B21: Industrial Machinery & Equipment | C21: Manufacturing | E21: Blue Oak Advance | G21: Environmental Quality & Housing | K21: 45972
A22: 36 | B22: Electronic & Electrical Equipment | C22: Manufacturing | E22: bridge consolidation | G22: Fabricated Metal Products | K22: 45988
A23: 37 | B23: Transportation Equipment | C23: Manufacturing | E23: Broadway Advance LLC | G23: Food & Kindred Products | K23: 46016
A24: 38 | B24: Instruments & Related Products | C24: Manufacturing | E24: Business Fund USA 4 | G24: Food Stores | K24: 46023
... A42: 59 | B42: Miscellaneous Retail | C42: Retail Trade | E42: ecp business capital | G42: Miscellaneous Manufacturing | K42: 46716
A43: 62 | B43: Security & Commodity Brokers | C43: Finance, Insurance & Real Estate | E43: Elite Advance 5 | G43: Miscellaneous Repair Services
A44: 63 | B44: Insurance Carriers | C44: Finance, Insurance & Real Estate | E44: elite finance team | G44: Miscellaneous Retail
A45: 64 | B45: Insurance Agents & Brokers | C45: Finance, Insurance & Real Estate | E45: ELITE FUNDING PARTNERS LLC 6 | G45: Motion Pictures
A46: 65 | B46: Real Estate | C46: Finance, Insurance & Real Estate | E46: EVR GREEN LLC | G46: Museums & Botanical Gardens
A47: 70 | B47: Hotels & Lodging | C47: Services | E47: EZ ADVANCE LLC | G47: National Security & Intl Affairs
A48: 72 | B48: Personal Services | C48: Services | E48: ez alternative solutions | G48: Nonmetallic Minerals Mining
A49: 73 | B49: Business Services | C49: Services | E49: FC ADVANCE | G49: Oil & Gas Extraction
A50: 75 | B50: Auto Repair & Services | C50: Services | E50: Fidelity Funding | G50: Personal Services
A51: 76 | B51: Miscellaneous Repair Services | C51: Services | E51: FIFTH VENTURE | G51: Primary Metal Industries
A52: 78 | B52: Motion Pictures | C52: Services | E52: FIMACAP INC | G52: Printing & Publishing
A53: 79 | B53: Amusement & Recreation Services | C53: Services | E53: Financial Express LLC | G53: Real Estate
A54: 80 | B54: Health Services | C54: Services | E54: Financity | G54: Rubber & Plastics
... A65: 97 | B65: National Security & Intl Affairs | C65: Public Administration | E65: Go Ai Ez LLC Dba:Gova Funding | G65: Wholesale Trade - Nondurable Goods
E66: GREYSTONE | G66: No SIC
E67: GROWTH RATE CAPITAL INC | G67: Unclassified
...
